Workbook

Sheet Shop Order
A1: Serial Number | B1: Workstation | C1: Process | D1: Qty | E1: Unit Status | F1: Last Updated | G1: Work order | H1: Part number | I1: Priority | J1: Comments | K1: Shipping date | L1: asdas
A2: YK260300123 | B2: NOT-IN-PROCESS | C2: NOT-IN-PROCESS | D2: 1 | E2: Unit Component (60) | F2: 46065.449 | G2: QT17IA14.00 | H2: QTNSN095288A.X03 | I2: =VLOOKUP(G2,Sheet2!A:J,10,0) -> 1
A3: YK260300124 | B3: NOT-IN-PROCESS | C3: NOT-IN-PROCESS | D3: 1 | E3: Unit Component (60) | F3: 46065.45 | G3: QT17IA14.00 | H3: QTNSN095288A.X03 | I3: =VLOOKUP(G3,Sheet2!A:J,10,0) -> 1
A4: YK260300125 | B4: NOT-IN-PROCESS | C4: NOT-IN-PROCESS | D4: 1 | E4: Unit Component (60) | F4: 46071.552 | G4: QT17IA14.00 | H4: QTNSN095288A.X03 | I4: =VLOOKUP(G4,Sheet2!A:J,10,0) -> 1
A5: YK260300126 | B5: NOT-IN-PROCESS | C5: NOT-IN-PROCESS | D5: 1 | E5: Unit Component (60) | F5: 46072.29 | G5: QT17IA14.00 | H5: QTNSN095288A.X03 | I5: =VLOOKUP(G5,Sheet2!A:J,10,0) -> 1
A6: YK260300127 | B6: NOT-IN-PROCESS | C6: NOT-IN-PROCESS | D6: 1 | E6: Unit Component (60) | F6: 46076.37 | G6: QT17IA14.00 | H6: QTNSN095288A.X03 | I6: =VLOOKUP(G6,Sheet2!A:J,10,0) -> 1
A7: YK260300128 | B7: SHIP Shipping | C7: Shipped to Customer | D7: 1 | E7: Shipped (40) | F7: 46112.311 | G7: QT17IA14.00 | H7: QTNSN095288A.X03 | I7: =VLOOKUP(G7,Sheet2!A:J,10,0) -> 1
A8: YK260300129 | B8: NOT-IN-PROCESS | C8: NOT-IN-PROCESS | D8: 1 | E8: Unit Component (60) | F8: 46065.432 | G8: QT17IA14.00 | H8: QTNSN095288A.X03 | I8: =VLOOKUP(G8,Sheet2!A:J,10,0) -> 1
A9: YK260300130 | B9: NOT-IN-PROCESS | C9: NOT-IN-PROCESS | D9: 1 | E9: Unit Component (60) | F9: 46071.282 | G9: QT17IA14.00 | H9: QTNSN095288A.X03 | I9: =VLOOKUP(G9,Sheet2!A:J,10,0) -> 1
A10: YK260300131 | B10: NOT-IN-PROCESS | C10: NOT-IN-PROCESS | D10: 1 | E10: Unit Component (60) | F10: 46076.374 | G10: QT17IA14.00 | H10: QTNSN095288A.X03 | I10: =VLOOKUP(G10,Sheet2!A:J,10,0) -> 1
A11: YK260300132 | B11: NOT-IN-PROCESS | C11: NOT-IN-PROCESS | D11: 1 | E11: Unit Component (60) | F11: 46065.431 | G11: QT17IA14.00 | H11: QTNSN095288A.X03 | I11: =VLOOKUP(G11,Sheet2!A:J,10,0) -> 1
A12: YK260300133 | B12: NOT-IN-PROCESS | C12: NOT-IN-PROCESS | D12: 1 | E12: Unit Component (60) | F12: 46072.486 | G12: QT17IA14.00 | H12: QTNSN095288A.X03 | I12: =VLOOKUP(G12,Sheet2!A:J,10,0) -> 1
A13: YK260300134 | B13: NOT-IN-PROCESS | C13: NOT-IN-PROCESS | D13: 1 | E13: Unit Component (60) | F13: 46065.449 | G13: QT17IA14.00 | H13: QTNSN095288A.X03 | I13: =VLOOKUP(G13,Sheet2!A:J,10,0) -> 1
... A158: YK260900007 | B158: NOT-IN-PROCESS | C158: NOT-IN-PROCESS | D158: 1 | E158: Unit Component (60) | F158: 46150.392 | G158: QT17IA14.20 | H158: QTNSN095289A.X11 | I158: =VLOOKUP(G158,Sheet2!A:J,10,0) -> 7
A159: YK260900008 | B159: SHIP Shipping | C159: Shipped to Customer | D159: 1 | E159: Shipped (40) | F159: 46123.268 | G159: QT17IA14.20 | H159: QTNSN095289A.X11 | I159: =VLOOKUP(G159,Sheet2!A:J,10,0) -> 7 | K159: 46105
A160: YK260900009 | B160: SHIP Shipping | C160: Shipped to Customer | D160: 1 | E160: Shipped (40) | F160: 46123.268 | G160: QT17IA14.20 | H160: QTNSN095289A.X11 | I160: =VLOOKUP(G160,Sheet2!A:J,10,0) -> 7 | K160: 46105
A161: YK260900010 | B161: RWK1 Repair Test | C161: Rework-1 | D161: 1 | E161: In Repair (25) | F161: 46135.342 | G161: QT17IA14.20 | H161: QTNSN095289A.X11 | I161: =VLOOKUP(G161,Sheet2!A:J,10,0) -> 7
A162: YK260900011 | B162: SHIP Shipping | C162: Shipped to Customer | D162: 1 | E162: Shipped (40) | F162: 46123.268 | G162: QT17IA14.20 | H162: QTNSN095289A.X11 | I162: =VLOOKUP(G162,Sheet2!A:J,10,0) -> 7 | K162: 46105
A163: YK260900012 | B163: SHIP Shipping | C163: Shipped to Customer | D163: 1 | E163: Shipped (40) | F163: 46154.373 | G163: QT17IA14.20 | H163: QTNSN095289A.X11 | I163: =VLOOKUP(G163,Sheet2!A:J,10,0) -> 7 | K163: 46156
A164: YK260900013 | B164: NOT-IN-PROCESS | C164: NOT-IN-PROCESS | D164: 1 | E164: Unit Component (60) | F164: 46153.505 | G164: QT17IA14.20 | H164: QTNSN095289A.X11 | I164: =VLOOKUP(G164,Sheet2!A:J,10,0) -> 7
A165: YK260900014 | B165: NOT-IN-PROCESS | C165: NOT-IN-PROCESS | D165: 1 | E165: Unit Component (60) | F165: 46140.311 | G165: QT17IA14.20 | H165: QTNSN095289A.X11 | I165: =VLOOKUP(G165,Sheet2!A:J,10,0) -> 7
A166: YK260900015 | B166: DBG1 Debug Test | C166: Xfr to Debug Test | D166: 1 | E166: In Repair Hold (29) | F166: 46128.38 | G166: QT17IA14.20 | H166: QTNSN095289A.X11 | I166: =VLOOKUP(G166,Sheet2!A:J,10,0) -> 7
A167: YK260900016 | B167: NOT-IN-PROCESS | C167: NOT-IN-PROCESS | D167: 1 | E167: Unit Component (60) | F167: 46146.277 | G167: QT17IA14.20 | H167: QTNSN095289A.X11 | I167: =VLOOKUP(G167,Sheet2!A:J,10,0) -> 7
A168: YK260900017 | B168: CMP1 Complete | C168: Complete | D168: 1 | E168: Finished (30) | F168: 46139.587 | G168: QT17IA14.20 | H168: QTNSN095289A.X11 | I168: =VLOOKUP(G168,Sheet2!A:J,10,0) -> 7
A169: YK260900018 | B169: SHIP Shipping | C169: Shipped to Customer | D169: 1 | E169: Shipped (40) | F169: 46123.268 | G169: QT17IA14.20 | H169: QTNSN095289A.X11 | I169: =VLOOKUP(G169,Sheet2!A:J,10,0) -> 7 | K169: 46097
A170: YK260900019 | B170: RWK3 Repair Test | C170: Rework-3 | D170: 1 | E170: In Repair (25) | F170: 46148.356 | G170: QT17IA14.20 | H170: QTNSN095289A.X11 | I170: =VLOOKUP(G170,Sheet2!A:J,10,0) -> 7
A171: YK260900020 | B171: NOT-IN-PROCESS | C171: NOT-IN-PROCESS | D171: 1 | E171: Unit Component (60) | F171: 46153.435 | G171: QT17IA14.20 | H171: QTNSN095289A.X11 | I171: =VLOOKUP(G171,Sheet2!A:J,10,0) -> 7
A172: YK260900021 | B172: FUN1 Func Test | C172: Functional Test-1 | D172: 1 | E172: On The Line (20) | F172: 46122.381 | G172: QT17IA14.20 | H172: QTNSN095289A.X11 | I172: =VLOOKUP(G172,Sheet2!A:J,10,0) -> 7
A173: YK260900022 | B173: SHIP Shipping | C173: Shipped to Customer | D173: 1 | E173: Shipped (40) | F173: 46174.475 | G173: QT17IA14.20 | H173: QTNSN095289A.X11 | I173: =VLOOKUP(G173,Sheet2!A:J,10,0) -> 7 | K173: 46128
A174: YK260900023 | B174: RWK1 Repair Test | C174: Rework-1 | D174: 1 | E174: In Repair (25) | F174: 46134.411 | G174: QT17IA14.20 | H174: QTNSN095289A.X11 | I174: =VLOOKUP(G174,Sheet2!A:J,10,0) -> 7
A175: YK260900024 | B175: CMP1 Complete | C175: Complete | D175: 1 | E175: Finished (30) | F175: 46128.361 | G175: QT17IA14.20 | H175: QTNSN095289A.X11 | I175: =VLOOKUP(G175,Sheet2!A:J,10,0) -> 7
A176: YK260900025 | B176: CMP1 Complete | C176: Complete | D176: 1 | E176: Finished (30) | F176: 46135.443 | G176: QT17IA14.20 | H176: QTNSN095289A.X11 | I176: =VLOOKUP(G176,Sheet2!A:J,10,0) -> 7
A177: YK260900026 | B177: RWK1 Repair Test | C177: Rework-1 | D177: 1 | E177: In Repair (25) | F177: 46134.363 | G177: QT17IA14.20 | H177: QTNSN095289A.X11 | I177: =VLOOKUP(G177,Sheet2!A:J,10,0) -> 7
A178: YK260900027 | B178: FUN1 Func Test | C178: Functional Test-1 | D178: 1 | E178: On The Line (20) | F178: 46122.382 | G178: QT17IA14.20 | H178: QTNSN095289A.X11 | I178: =VLOOKUP(G178,Sheet2!A:J,10,0) -> 7
A179: YK260900028 | B179: CMP1 Complete | C179: Complete | D179: 1 | E179: Finished (30) | F179: 46134.597 | G179: QT17IA14.20 | H179: QTNSN095289A.X11 | I179: =VLOOKUP(G179,Sheet2!A:J,10,0) -> 7
A180: YK260900029 | B180: SHIP Shipping | C180: Shipped to Customer | D180: 1 | E180: Shipped (40) | F180: 46123.268 | G180: QT17IA14.20 | H180: QTNSN095289A.X11 | I180: =VLOOKUP(G180,Sheet2!A:J,10,0) -> 7 | K180: 46097
A181: YK260900030 | B181: SHIP Shipping | C181: Shipped to Customer | D181: 1 | E181: Shipped (40) | F181: 46123.268 | G181: QT17IA14.20 | H181: QTNSN095289A.X11 | I181: =VLOOKUP(G181,Sheet2!A:J,10,0) -> 7 | K181: 46105
A182: YK260900031 | B182: SHIP Shipping | C182: Shipped to Customer | D182: 1 | E182: Shipped (40) | F182: 46123.268 | G182: QT17IA14.20 | H182: QTNSN095289A.X11 | I182: =VLOOKUP(G182,Sheet2!A:J,10,0) -> 7 | K182: 46112
A183: YK260900032 | B183: FUN1 Func Test | C183: Functional Test-1 | D183: 1 | E183: On The Line (20) | F183: 46115.654 | G183: QT17IA14.20 | H183: QTNSN095289A.X11 | I183: =VLOOKUP(G183,Sheet2!A:J,10,0) -> 7
A184: YK260900033 | B184: DBG1 Debug Test | C184: Xfr to Debug Test | D184: 1 | E184: In Repair Hold (29) | F184: 46128.399 | G184: QT17IA14.20 | H184: QTNSN095289A.X11 | I184: =VLOOKUP(G184,Sheet2!A:J,10,0) -> 7
...

Sheet Sheet15
A1: Serial Number | B1: Workstation | C1: Process | D1: Qty | E1: Unit Status | F1: Last Updated | G1: Work order | H1: Part number | I1: Priority | J1: Comments | K1: Shipping date | L1: asdas
A2: YK262300821 | B2: ASY1 T/L Assembly | C2: Xfr to T/L Assembly | D2: 1 | E2: On The Line Hold (28) | F2: 46198.313 | G2: QT17IA44.10 | H2: QTNSN476757A.X12 | I2: 14

Sheet Sheet17
A1: Serial Number | B1: Workstation | C1: Process | D1: Qty | E1: Unit Status | F1: Last Updated | G1: Work order | H1: Part number | I1: Priority | J1: Comments | K1: Shipping date | L1: asdas
A2: YK262300821 | B2: ASY1 T/L Assembly | C2: Xfr to T/L Assembly | D2: 1 | E2: On The Line Hold (28) | F2: 46198.313 | G2: QT17IA44.10 | H2: QTNSN476757A.X12 | I2: 14

Sheet Sheet18
A1: Serial Number | B1: Workstation | C1: Process | D1: Qty | E1: Unit Status | F1: Last Updated | G1: Work order | H1: Part number | I1: Priority | J1: Comments | K1: Shipping date | L1: asdas
A2: YK262300820 | B2: 1DBG Debug Test | C2: Debug Test-1 | D2: 1 | E2: In Repair (25) | F2: 46198.305 | G2: QT17IA44.10 | H2: QTNSN476757A.X12 | I2: 14
A3: YK262300810 | B3: 1DBG Debug Test | C3: Debug Test-1 | D3: 1 | E3: In Repair (25) | F3: 46190.566 | G3: QT17IA44.10 | H3: QTNSN476757A.X12 | I3: 14

Sheet Summary
A1: Row Labels | B1: Work order | C1: Part number | D1: Process | E1: Unit Status | F1: Count of Qty
A2: 1 | B2: QT17IA14.00 | C2: QTNSN095288A.X03 | D2: NOT-IN-PROCESS | E2: Unit Component (60) | F2: 64 | I2: =MID(B2,3,21) -> 17IA14.00
D3: Shipped to Customer | E3: Shipped (40) | F3: 6 | I3: =MID(B3,3,21)
A4: 2 | B4: QT17IA14.10 | C4: QTNSN095289A.X03 | D4: NOT-IN-PROCESS | E4: Unit Component (60) | F4: 64 | I4: =MID(B4,3,21) -> 17IA14.10
D5: Shipped to Customer | E5: Shipped (40) | F5: 16 | I5: =MID(B5,3,21)
A6: 3 | B6: QT17IA23.00 | C6: QTNSN095266A.X02 | D6: NOT-IN-PROCESS | E6: Unit Component (60) | F6: 11 | I6: =MID(B6,3,21) -> 17IA23.00
D7: Shipped to Customer | E7: Shipped (40) | F7: 14 | I7: =MID(B7,3,21)
A8: 4 | B8: QT17IA43.00 | C8: QTNSN476757A.X02 | D8: Shipped to Customer | E8: Shipped (40) | F8: 20 | I8: =MID(B8,3,21) -> 17IA43.00
A9: 5 | B9: QT17IA14.30 | C9: QTNSN095288A.X11 | D9: Complete | E9: Finished (30) | F9: 13 | I9: =MID(B9,3,21) -> 17IA14.30
D10: Functional Test-1 | E10: On The Line (20) | F10: 2 | I10: =MID(B10,3,21)
D11: NOT-IN-PROCESS | E11: Unit Component (60) | F11: 11 | I11: =MID(B11,3,21)
D12: Shipped to Customer | E12: Shipped (40) | F12: 8 | I12: =MID(B12,3,21)
D13: UNTT | E13: On The Line (20) | F13: 1 | I13: =MID(B13,3,21)
D14: Rework-1 | E14: In Repair (25) | F14: 2 | I14: =MID(B14,3,21)
A15: 6 | B15: QT17IA14.31 | C15: QTNSN095288A.X11 | D15: Complete | E15: Finished (30) | F15: 12 | I15: =MID(B15,3,21) -> 17IA14.31
D16: Functional Test-1 | E16: On The Line (20) | F16: 1 | I16: =MID(B16,3,21)
D17: NOT-IN-PROCESS | E17: Unit Component (60) | F17: 12 | I17: =MID(B17,3,21)
D18: Shipped to Customer | E18: Shipped (40) | F18: 8 | I18: =MID(B18,3,21)
D19: Xfr to Debug Test | E19: In Repair Hold (29) | F19: 1 | I19: =MID(B19,3,21)
D20: Rework-1 | E20: In Repair (25) | F20: 1 | I20: =MID(B20,3,21)
D21: Rework-3 | E21: In Repair (25) | F21: 2 | I21: =MID(B21,3,21)
A22: 7 | B22: QT17IA14.20 | C22: QTNSN095289A.X11 | D22: Complete | E22: Finished (30) | F22: 4 | I22: =MID(B22,3,21) -> 17IA14.20
D23: Functional Test-1 | E23: On The Line (20) | F23: 5 | I23: =MID(B23,3,21)
D24: NOT-IN-PROCESS | E24: Unit Component (60) | F24: 8 | I24: =MID(B24,3,21)
D25: Shipped to Customer | E25: Shipped (40) | F25: 10 | I25: =MID(B25,3,21)
D26: Xfr to Debug Test | E26: In Repair Hold (29) | F26: 4 | I26: =MID(B26,3,21)
D27: Rework-1 | E27: In Repair (25) | F27: 3 | I27: =MID(B27,3,21)
D28: Rework-3 | E28: In Repair (25) | F28: 3 | I28: =MID(B28,3,21)
A29: 8 | B29: QT17IA14.21 | C29: QTNSN095289A.X11 | D29: Functional Test-1 | E29: On The Line (20) | F29: 3 | I29: =MID(B29,3,21) -> 17IA14.21
D30: NOT-IN-PROCESS | E30: Unit Component (60) | F30: 20 | I30: =MID(B30,3,21)
D31: Shipped to Customer | E31: Shipped (40) | F31: 10 | I31: =MID(B31,3,21)
D32: Xfr to Debug Test | E32: In Repair Hold (29) | F32: 4 | I32: =MID(B32,3,21)
A33: 9 | B33: QT17IA24.00 | C33: QTNSN095266A.X11 | D33: NOT-IN-PROCESS | E33: Unit Component (60) | F33: 15 | I33: =MID(B33,3,21) -> 17IA24.00
D34: Shipped to Customer | E34: Shipped (40) | F34: 14 | I34: =MID(B34,3,21)
A35: 10 | B35: QT17IA44.00 | C35: QTNSN476757A.X11 | D35: Shipped to Customer | E35: Shipped (40) | F35: 11 | I35: =MID(B35,3,21) -> 17IA44.00
D36: Packout | E36: On The Line (20) | F36: 4 | I36: =MID(B36,3,21)
A37: 11 | B37: QT17IA14.50 | C37: QTNSN095288A.X11 | D37: Complete | E37: Finished (30) | F37: 29 | I37: =MID(B37,3,21) -> 17IA14.50
D38: Functional Test-1 | E38: On The Line (20) | F38: 46 | I38: =MID(B38,3,21)
D39: NOT-IN-PROCESS | E39: Unit Component (60) | F39: 37 | I39: =MID(B39,3,21)
D40: Shipped to Customer | E40: Shipped (40) | F40: 9 | I40: =MID(B40,3,21)
...

Sheet Sheet2
A1: Unique id | C1: WO | G1: Part number | H1: Desc | I1: Qty | J1: Priority | K1: STI/ Comments
A2: QT17IA14.00 | B2: =MID(A2,3,11) -> 17IA14.00 | C2: =VLOOKUP(A2,Summary!B:B,1,0) -> QT17IA14.00 | F2: =VLOOKUP(A2,'[1]Plan - US NPI'!$C$6:$E$192,3,0) -> #N/A | G2: QTNSN095288A.X03 | H2: #N/A | I2: 70 | J2: 1 | Q2: Mh lot codes to MRB
A3: QT17IA14.10 | B3: =MID(A3,3,11) -> 17IA14.10 | C3: =VLOOKUP(A3,Summary!B:B,1,0) -> QT17IA14.10 | F3: =VLOOKUP(A3,'[1]Plan - US NPI'!$C$6:$E$192,3,0) -> #N/A | G3: QTNSN095289A.X03 | H3: #N/A | I3: 80 | J3: 2 | Q3: Solder paste Qtys
A4: QT17IA23.00 | B4: =MID(A4,3,11) -> 17IA23.00 | C4: =VLOOKUP(A4,Summary!B:B,1,0) -> QT17IA23.00 | F4: =VLOOKUP(A4,'[1]Plan - US NPI'!$C$6:$E$192,3,0) -> #N/A | G4: QTNSN095266A.X02 | H4: #N/A | I4: 25 | J4: 3
A5: QT17IA43.00 | B5: =MID(A5,3,11) -> 17IA43.00 | C5: =VLOOKUP(A5,Summary!B:B,1,0) -> QT17IA43.00 | F5: =VLOOKUP(A5,'[1]Plan - US NPI'!$C$6:$E$192,3,0) -> #N/A | G5: QTNSN476757A.X02 | H5: #N/A | I5: 20 | J5: 4
A6: QT17IA14.30 | B6: =MID(A6,3,11) -> 17IA14.30 | C6: =VLOOKUP(A6,Summary!B:B,1,0) -> QT17IA14.30 | F6: =VLOOKUP(A6,'[1]Plan - US NPI'!$C$6:$E$192,3,0) -> AXFIA | G6: QTNSN095288A.X11 | H6: QT PA ASSY, 095288A. REV X11, B25 PA ASSEMBLY FOR AXFIA/AXFIB | I6: 37 | J6: 5 | K6: eSTI PE53499. PE53575 add a note to remove shield and pre-drive, and for 840135A to use X1 version. PE53746 sent 03/13
A7: QT17IA14.31 | B7: =MID(A7,3,11) -> 17IA14.31 | C7: =VLOOKUP(A7,Summary!B:B,1,0) -> QT17IA14.31 | F7: =VLOOKUP(A7,'[1]Plan - US NPI'!$C$6:$E$192,3,0) -> AXFIA | G7: QTNSN095288A.X11 | H7: QT PA ASSY, 095288A. REV X11, B25 PA ASSEMBLY FOR AXFIA/AXFIB | I7: 37 | J7: 6 | K7: eSTI PE53499. PE53575 add a note to remove shield and pre-drive, and for 840135A to use X1 version. PE53684 sent 03/13
A8: QT17IA14.20 | B8: =MID(A8,3,11) -> 17IA14.20 | C8: =VLOOKUP(A8,Summary!B:B,1,0) -> QT17IA14.20 | F8: =VLOOKUP(A8,'[1]Plan - US NPI'!$C$6:$E$192,3,0) -> AXFIA | G8: QTNSN095289A.X11 | H8: QT PA ASSY, 095289A. REV X11, B66 PA ASSEMBLY FOR AXFIA/AXFIB | I8: 37 | J8: 7 | K8: STI PE53554 for 840135A to use X1 version. PE53499, .
A9: QT17IA14.21 | B9: =MID(A9,3,11) -> 17IA14.21 | C9: =VLOOKUP(A9,Summary!B:B,1,0) -> QT17IA14.21 | F9: =VLOOKUP(A9,'[1]Plan - US NPI'!$C$6:$E$192,3,0) -> AXFIA | G9: QTNSN095289A.X11 | H9: QT PA ASSY, 095289A. REV X11, B66 PA ASSEMBLY FOR AXFIA/AXFIB | I9: 37 | J9: 8 | K9: PE53571 for 17IA14.21,add a note to remove shield and pre-driver. Create new eSTI for 17IA14.20 adding the same note. NEW PE53611
A10: QT17IA24.00 | B10: =MID(A10,3,11) -> 17IA24.00 | C10: =VLOOKUP(A10,Summary!B:B,1,0) -> QT17IA24.00 | F10: =VLOOKUP(A10,'[1]Plan - US NPI'!$C$6:$E$192,3,0) -> #N/A | G10: QTNSN095266A.X11 | H10: QT TRX ASSY, 095266A. REV X11, TRX ASSEMBLY FOR AXFIA | I10: 29 | J10: 9 | K10: PE53604, PE53707,PE53847
A11: QT17IA44.00 | B11: =MID(A11,3,11) -> 17IA44.00 | C11: =VLOOKUP(A11,Summary!B:B,1,0) -> QT17IA44.00 | F11: =VLOOKUP(A11,'[1]Plan - US NPI'!$C$6:$E$192,3,0) -> #N/A | G11: QTNSN476757A.X11 | H11: RRH X11 | I11: 15 | J11: 10 | K11: PE53701
A12: QT17IA14.50 | B12: =MID(A12,3,11) -> 17IA14.50 | C12: =VLOOKUP(A12,Summary!B:B,1,0) -> QT17IA14.50 | F12: =VLOOKUP(A12,'[1]Plan - US NPI'!$C$6:$E$192,3,0) -> AXFIA | G12: QTNSN095288A.X11 | H12: QT PA ASSY, 095288A. REV X11, B25 PA ASSEMBLY FOR AXFIA/AXFIB | I12: 124 | J12: 11 | K12: PE53891 | N12: MATLNOB476795A.P03
A13: QT17IA14.40 | B13: =MID(A13,3,11) -> 17IA14.40 | C13: =VLOOKUP(A13,Summary!B:B,1,0) -> QT17IA14.40 | F13: =VLOOKUP(A13,'[1]Plan - US NPI'!$C$6:$E$192,3,0) -> AXFIA | G13: QTNSN095289A.X11 | H13: QT PA ASSY, 095289A. REV X11, B66 PA ASSEMBLY FOR AXFIA/AXFIB | I13: 124 | J13: 12 | K13: PE54018
A14: QT17IA24.10 | B14: =MID(A14,3,11) -> 17IA24.10 | C14: =VLOOKUP(A14,Summary!B:B,1,0) -> QT17IA24.10 | F14: =VLOOKUP(A14,'[1]Plan - US NPI'!$C$6:$E$192,3,0) -> AXFIA | G14: QTNSN095266A.X12 | H14: QT TRX ASSY, 095266A. REV X12, TRX ASSEMBLY FOR AXFIA | I14: 41 | J14: 13 | K14: X12 Bom released - PE54073
A15: QT17IA44.10 | B15: =MID(A15,3,11) -> 17IA44.10 | C15: =VLOOKUP(A15,Summary!B:B,1,0) -> QT17IA44.10 | F15: =VLOOKUP(A15,'[1]Plan - US NPI'!$C$6:$E$192,3,0) -> AXFIA | G15: QTNSN476757A.X12 | H15: QT T/L UNIT ASSY, 476757A. REV X12, AXFIA AirScale RRH 4T8R n25/66 720W | I15: 30 | J15: 14 | K15: Esti releasesed- Release wo- PE54404- Wo released 29-May-26 | Min of 15 units next week
A16: QT17IA15.80 | B16: =MID(A16,3,11) -> 17IA15.80 | C16: =VLOOKUP(A16,Summary!B:B,1,0) -> QT17IA15.80 | F16: =VLOOKUP(A16,'[1]Plan - US NPI'!$C$6:$E$192,3,0) -> #N/A | G16: QTNSN095289A.X12 | H16: QT PA ASSY, 095289A. REV X12, B66 PA ASSEMBLY FOR AXFIA/AXFIB | I16: 62 | J16: 18 | K16: New PWB- Order 2 sets of stencils- new profile board needed - New profile needed - Need STI- Checkplots being worked - PE54185
A17: QT17IA15.90 | B17: =MID(A17,3,11) -> 17IA15.90 | C17: =VLOOKUP(A17,Summary!B:B,1,0) -> QT17IA15.90 | F17: =VLOOKUP(A17,'[1]Plan - US NPI'!$C$6:$E$192,3,0) -> AXFIA | G17: QTNSN095288A.X12 | H17: QT PA ASSY, 095288A. REV X12, B25 PA ASSEMBLY FOR AXFIA/AXFIB | I17: 62 | J17: 17 | K17: New PWB- Order 2 sets of stencils- new profile board needed - New profile needed - Need STI- Stencil 04/23- PE54164 | P17: 46139
A18: QT19BA11.00 | B18: =MID(A18,3,11) -> 19BA11.00 | C18: =VLOOKUP(A18,Summary!B:B,1,0) -> QT19BA11.00 | F18: =VLOOKUP(A18,'[1]Plan - US NPI'!$C$6:$E$192,3,0) -> AXOLA | G18: QTNSN095290A.X02 | H18: QT PA ASSY, 095290A. REV X02, B71 PA ASSEMBLY FOR AXOLBA | I18: 14 | J18: 19 | K18: Stencils due on the 27- Apr- No Esti
A19: QT19BA11.10 | B19: =MID(A19,3,11) -> 19BA11.10 | C19: =VLOOKUP(A19,Summary!B:B,1,0) -> QT19BA11.10 | F19: =VLOOKUP(A19,'[1]Plan - US NPI'!$C$6:$E$192,3,0) -> AXOLA | G19: QTNSN095291A.X02 | H19: QT PA ASSY, 095291A. REV X02, B85 PA ASSEMBLY FOR AXOLBA | I19: 14 | J19: 20 | K19: Stencils due on the 27- Apr- No Esti- Tracking# 707296329356
A20: QT20LA21.00 | B20: =MID(A20,3,11) -> 20LA21.00 | C20: =VLOOKUP(A20,Summary!B:B,1,0) -> QT20LA21.00 | F20: =VLOOKUP(A20,'[1]Plan - US NPI'!$C$6:$E$192,3,0) -> AXOLA | G20: QTNSN095286A.X02 | H20: QT TRX ASSY, 095286A. REV X02, TRX ASSEMBLY FOR AXOLA | I20: 10 | J20: 21 | K20: PWB X6 | PE54313 to be cp'd rpleace P7000738 with P67 | AOI and Xray data & Dage available -Send data ASAP | PE54792 - Released 25-Jun-26
A21: QT17IA25.30 | B21: =MID(A21,3,11) -> 17IA25.30 | C21: =VLOOKUP(A21,Summary!B:B,1,0) -> QT17IA25.30 | D21: =MID(A21,3,11) -> 17IA25.30 | E21: Clean | F21: =VLOOKUP(A21,'[1]Plan - US NPI'!$C$6:$E$192,3,0) -> AXFIA | G21: QTNSN095266A.X12 | H21: QT TRX ASSY, 095266A. REV X12, TRX ASSEMBLY FOR AXFIA | I21: 47 | J21: 22 | K21: Kick off 21-May-26- ESTI -PE54408 - Released 29-May-26 | One more ESTI to be released | Stencil ETA 03-Jun-26 | PE54513- Work order relased 06/03 | L21: Released -06/03 | Confirm SMT Start date
A22: QT17IA15.60 | B22: =MID(A22,3,11) -> 17IA15.60 | C22: =VLOOKUP(A22,Summary!B:B,1,0) -> QT17IA15.60 | F22: =VLOOKUP(A22,'[1]Plan - US NPI'!$C$6:$E$192,3,0) -> AXFIA | G22: QTNSN095289A.X12 | H22: QT PA ASSY, 095289A. REV X12, B66 PA ASSEMBLY FOR AXFIA/AXFIB | I22: 188 | J22: 23 | K22: Kick off 21-May-26- ESTI - PE54407- WO Released 29-May-26 | L22: Durafuse
A23: QT17IA15.70 | B23: =MID(A23,3,11) -> 17IA15.70 | C23: =VLOOKUP(A23,Summary!B:B,1,0) -> QT17IA15.70 | F23: =VLOOKUP(A23,'[1]Plan - US NPI'!$C$6:$E$192,3,0) -> AXFIA | G23: QTNSN095288A.X12 | H23: QT PA ASSY, 095288A. REV X12, B25 PA ASSEMBLY FOR AXFIA/AXFIB | I23: 188 | J23: 24 | K23: Kick off 21-May-26- ESTI - PE54405- WO Released 29-May-26 | L23: Durafuse
A24: QT17IA45.30 | B24: =MID(A24,3,11) -> 17IA45.30 | C24: =VLOOKUP(A24,Summary!B:B,1,0) -> QT17IA45.30 | D24: =MID(A24,3,11) -> 17IA45.30 | E24: Clean | F24: =VLOOKUP(A24,'[1]Plan - US NPI'!$C$6:$E$192,3,0) -> AXFIA | G24: QTNSN476757A.X12 | H24: QT T/L UNIT ASSY, 476757A. REV X12, AXFIA AirScale RRH 4T8R n25/66 720W | I24: 47 | J24: 25 | K24: PE54409 - Released 29-May-26_ need to release work order- Relased 15-Jun-26 | L24: Sent to Paula
A25: QT17IA45.40 | B25: =MID(A25,3,11) -> 17IA45.40 | C25: =VLOOKUP(A25,Summary!B:B,1,0) -> QT17IA45.40 | F25: =VLOOKUP(A25,'[1]Plan - US NPI'!$C$6:$E$192,3,0) -> AXFIA | G25: QTNSN476757A.X12 | H25: QT T/L UNIT ASSY, 476757A. REV X12, AXFIA AirScale RRH 4T8R n25/66 720W | I25: 11 | J25: 26 | K25: Kick off- ESTI PE54381 - WO released
A26: QT17IA15.95 | B26: =MID(A26,3,11) -> 17IA15.95 | C26: =VLOOKUP(A26,Summary!B:B,1,0) -> QT17IA15.95 | F26: =VLOOKUP(A26,'[1]Plan - US NPI'!$C$6:$E$192,3,0) -> AXFIA | G26: QTNSN095289A.X12 | H26: QT PA ASSY, 095289A. REV X12, B66 PA ASSEMBLY FOR AXFIA/AXFIB | I26: 140 | J26: 27 | K26: Stencils , same PWB, STI for Solder paste PE54356- requested to run on the 2oth of May | New profile needed for Different solder paste
A27: QT17IA15.96 | B27: =MID(A27,3,11) -> 17IA15.96 | C27: =VLOOKUP(A27,Summary!B:B,1,0) -> QT17IA15.96 | F27: =VLOOKUP(A27,'[1]Plan - US NPI'!$C$6:$E$192,3,0) -> AXFIA | G27: QTNSN095288A.X12 | H27: QT PA ASSY, 095288A. REV X12, B25 PA ASSEMBLY FOR AXFIA/AXFIB | I27: 140 | J27: 28 | K27: PE54357- Solder paste STI- Received | New profile needed for Different solder paste
A28: QT20LA12.00 | B28: =MID(A28,3,11) -> 20LA12.00 | C28: =VLOOKUP(A28,Summary!B:B,1,0) -> QT20LA12.00 | F28: =VLOOKUP(A28,'[1]Plan - US NPI'!$C$6:$E$192,3,0) -> AXOLA | G28: QTNSN095290A.X02 | H28: QT PA ASSY, 095290A. REV X02, B71 PA ASSEMBLY FOR AXOLBA | I28: 64 | J28: 29 | K28: Esti releasesed- PE54413- WO released 27-May-26- need profile approved
A29: QT20LA12.10 | B29: =MID(A29,3,11) -> 20LA12.10 | C29: =VLOOKUP(A29,Summary!B:B,1,0) -> QT20LA12.10 | F29: =VLOOKUP(A29,'[1]Plan - US NPI'!$C$6:$E$192,3,0) -> AXOLA | G29: QTNSN095291A.X02 | H29: QT PA ASSY, 095291A. REV X02, B85 PA ASSEMBLY FOR AXOLBA | I29: 64 | J29: 30 | K29: Esti releasesed- WO released 27-May-26- Need profile approved
A30: QT20LA41.00 | B30: =MID(A30,3,11) -> 20LA41.00 | C30: =VLOOKUP(A30,Summary!B:B,1,0) -> QT20LA41.00 | D30: =MID(A30,3,11) -> 20LA41.00 | E30: Clean | F30: =VLOOKUP(A30,'[1]Plan - US NPI'!$C$6:$E$192,3,0) -> AXOLA | G30: QTNSN476797A.X11 | H30: QT T/L UNIT ASSY, 476797A.REV X11, AXOLA AirScale RRH 4T4R n71/85 320W | I30: 8 | J30: 31 | K30: CTB- ESTI PE54470 | WO release today 03-Jun-26- Followed up on ESTI | TRX rework need to look at material
A31: QT19BA21.00 | B31: =MID(A31,3,11) -> 19BA21.00 | C31: Released | D31: =MID(A31,3,11) -> 19BA21.00 | F31: =VLOOKUP(A31,'[1]Plan - US NPI'!$C$6:$E$192,3,0) -> AXOLBA | G31: QTNSN095804A.X11 | I31: 22 | J31: 32 | K31: Relased 06/12- Critical components | 2 pcs Skipping FT | L31: Quote avialable
A32: QT19BA12.20 | B32: =MID(A32,3,11) -> 19BA12.20 | C32: =VLOOKUP(A32,Summary!B:B,1,0) -> #N/A | D32: =MID(A32,3,11) -> 19BA12.20 | E32: Clean | F32: =VLOOKUP(A32,'[1]Plan - US NPI'!$C$6:$E$192,3,0) -> AXOLBA | G32: QTNSN095290A.X02 | I32: 32 | J32: 33 | K32: ESTI - Sac305 PE54542- Work order QT20LA12.00 increased to 64 units
A33: QT19BA12.30 | B33: =MID(A33,3,11) -> 19BA12.30 | C33: =VLOOKUP(A33,Summary!B:B,1,0) -> #N/A | D33: =MID(A33,3,11) -> 19BA12.30 | E33: Clean | F33: =VLOOKUP(A33,'[1]Plan - US NPI'!$C$6:$E$192,3,0) -> AXOLBA | G33: QTNSN095291A.X02 | I33: 32 | J33: 34 | K33: ESTI - Sac305 PE54541- Work order QT20LA12.10 increased to 64 units
A34: QT19BA41.00 | B34: =MID(A34,3,11) -> 19BA41.00 | C34: Released | D34: =MID(A34,3,11) -> 19BA41.00 | F34: =VLOOKUP(A34,'[1]Plan - US NPI'!$C$6:$E$192,3,0) -> AXOLBA | G34: QTNSN476971A.X11 | I34: 8 | J34: 35 | K34: No ESTI_ Nokia checking -06/16 | Chassis and Filter check stock | ESTI to be released PE54770 | L34: Quote | M34: We need 1 Radio built as soon as TRX is availabel
A35: QT17IA24.20 | B35: =MID(A35,3,11) -> 17IA24.20 | C35: =VLOOKUP(A35,Summary!B:B,1,0) -> QT17IA24.20 | D35: =MID(A35,3,11) -> 17IA24.20 | F35: =VLOOKUP(A35,'[1]Plan - US NPI'!$C$6:$E$192,3,0) -> AXFIA | G35: QTNSN095266A.X21 | I35: 29 | J35: 37 | K35: RelaseD 06/15 | Old profile can be used- Review with Jose current issues on the X12 build | L35: Quote
A36: QT17IA14.70 | B36: =MID(A36,3,11) -> 17IA14.70 | C36: Released | D36: =MID(A36,3,11) -> 17IA14.70 | F36: AXFIA | G36: QTNSN095288A.X21 | I36: 74 | J36: 39 | K36: PE54718 | PE54609 | PE54651 - Jose Stencils- Clean released 24-Jun-26 | L36: Quote
A37: QT17IA14.60 | B37: =MID(A37,3,11) -> 17IA14.60 | C37: Released | D37: =MID(A37,3,11) -> 17IA14.60 | F37: =VLOOKUP(A37,'[1]Plan - US NPI'!$C$6:$E$192,3,0) -> AXFIA | G37: QTNSN095289A.X21 | I37: 74 | J37: 40 | K37: PE54719, PE54667 ,PE54611 STI- Jose Stencils- 3 shortages- not clean- 2 MTRs to Oulu, 1 Po from Distro | L37: Quote
A38: QT18OA21.00 | B38: =MID(A38,3,11) -> 18OA21.00 | C38: Shortages | D38: =MID(A38,3,11) -> 18OA21.00 | F38: =VLOOKUP(A38,'[1]Plan - US NPI'!$C$6:$E$192,3,0) -> AXOA | G38: QTNSN095725A.X12 | I38: 11 | J38: 41 | K38: Bom being updated- 06/16 | 2 Boards to be built without fixtures | P399539- STI to skip saw filter & one more STI to be released tooling PE54722-Jose Stencils| Oven profile needed | L38: Quote
A39: QT20LA22.00 | B39: =MID(A39,3,11) -> 20LA22.00 | C39: Released | D39: =MID(A39,3,11) -> 20LA22.00 | F39: =VLOOKUP(A39,'[1]Plan - US NPI'!$C$6:$E$192,3,0) -> AXOLA | G39: QTNSN095803A.X03 | I39: 14 | J39: 42 | K39: 1 component dif from the 804A.X11 Build | STI PE54748 - released today

Sheet Sheet14
A1: Shop Order: QT17IA14.00 | D1: Status: Released
A2: Part Number: QTNSN095288A.X03 | D2: Status Change: 2/3/2026 7:33:59 AM
A3: Revision: X03 | D3: Project: mes_e35_01
A4: Board/Panel: 1 | D4: Customer: Nokia
A5: Qty: 70
A7: Serial Number | B7: Workstation | C7: Process | D7: Qty | E7: Unit Status | F7: Last Updated
A8: YK260300123 | B8: NOT-IN-PROCESS | C8: NOT-IN-PROCESS | D8: 1 | E8: Unit Component (60) | F8: 46065.449 | G8: QT17IA14.00 | H8: QTNSN095288A.X03
A9: YK260300124 | B9: NOT-IN-PROCESS | C9: NOT-IN-PROCESS | D9: 1 | E9: Unit Component (60) | F9: 46065.45 | G9: QT17IA14.00 | H9: QTNSN095288A.X03
A10: YK260300125 | B10: NOT-IN-PROCESS | C10: NOT-IN-PROCESS | D10: 1 | E10: Unit Component (60) | F10: 46071.552 | G10: QT17IA14.00 | H10: QTNSN095288A.X03
A11: YK260300126 | B11: NOT-IN-PROCESS | C11: NOT-IN-PROCESS | D11: 1 | E11: Unit Component (60) | F11: 46072.29 | G11: QT17IA14.00 | H11: QTNSN095288A.X03
A12: YK260300127 | B12: NOT-IN-PROCESS | C12: NOT-IN-PROCESS | D12: 1 | E12: Unit Component (60) | F12: 46076.37 | G12: QT17IA14.00 | H12: QTNSN095288A.X03
A13: YK260300128 | B13: SHIP Shipping | C13: Shipped to Customer | D13: 1 | E13: Shipped (40) | F13: 46112.311 | G13: QT17IA14.00 | H13: QTNSN095288A.X03
A14: YK260300129 | B14: NOT-IN-PROCESS | C14: NOT-IN-PROCESS | D14: 1 | E14: Unit Component (60) | F14: 46065.432 | G14: QT17IA14.00 | H14: QTNSN095288A.X03
A15: YK260300130 | B15: NOT-IN-PROCESS | C15: NOT-IN-PROCESS | D15: 1 | E15: Unit Component (60) | F15: 46071.282 | G15: QT17IA14.00 | H15: QTNSN095288A.X03
A16: YK260300131 | B16: NOT-IN-PROCESS | C16: NOT-IN-PROCESS | D16: 1 | E16: Unit Component (60) | F16: 46076.374 | G16: QT17IA14.00 | H16: QTNSN095288A.X03
A17: YK260300132 | B17: NOT-IN-PROCESS | C17: NOT-IN-PROCESS | D17: 1 | E17: Unit Component (60) | F17: 46065.431 | G17: QT17IA14.00 | H17: QTNSN095288A.X03
A18: YK260300133 | B18: NOT-IN-PROCESS | C18: NOT-IN-PROCESS | D18: 1 | E18: Unit Component (60) | F18: 46072.486 | G18: QT17IA14.00 | H18: QTNSN095288A.X03
A19: YK260300134 | B19: NOT-IN-PROCESS | C19: NOT-IN-PROCESS | D19: 1 | E19: Unit Component (60) | F19: 46065.449 | G19: QT17IA14.00 | H19: QTNSN095288A.X03
... A1817: YK262500734 | B1817: NOT-IN-PROCESS | C1817: NOT-IN-PROCESS | D1817: 1 | E1817: Traveler Printed (15) | F1817: 46190.5 | G1817: QT20LA41.00 | H1817: QTNSN476797A.X11
