Workbook

Sheet Sheet9
A1: Process | B1: (Multiple Items) | F1: Process | G1: (Multiple Items) | J1: Process | K1: (Multiple Items)
A3: Row Labels | B3: Sum of Qty | F3: Row Labels | G3: Sum of Qty | J3: Row Labels | K3: Sum of Qty
A4: 5DX1 SMT 5DX | B4: 235 | F4: 5DX1 SMT 5DX | G4: 221 | J4: 5DX1 SMT 5DX | K4: 57
A5: AOI1 AOI Inspect S1 | B5: 495 | F5: AOI1 AOI Inspect S1 | G5: 510 | J5: AOI1 AOI Inspect S1 | K5: 723
A6: AOI2 AOI Inspect S2 | B6: 10 | F6: AOI2 AOI Inspect S2 | G6: 10 | J6: AOI2 AOI Inspect S2 | K6: 10
A7: AOR1 AOI RWK S1 | B7: 32 | F7: AOR1 AOI RWK S1 | G7: 28 | J7: AOR1 AOI RWK S1 | K7: 13
A8: AOR2 AOI RWK S2 | B8: 13 | F8: AOR2 AOI RWK S2 | G8: 12 | J8: AOR2 AOI RWK S2 | K8: 13
A9: Grand Total | B9: 785 | F9: Grand Total | G9: 783 | J9: Grand Total | K9: 816

Sheet Shop Order
A1: Serial Number | B1: Workstation | C1: Process | D1: Qty | E1: Unit Status | F1: Last Updated | G1: Work order | H1: Part number | I1: Priority | J1: Comments | K1: Shipping date | L1: asdas
A2: YK260300123 | B2: NOT-IN-PROCESS | C2: NOT-IN-PROCESS | D2: 1 | E2: Unit Component (60) | F2: 46065.449 | G2: QT17IA14.00 | H2: QTNSN095288A.X03 | I2: =VLOOKUP(G2,WO!A:J,10,0) -> 1
A3: YK260300124 | B3: NOT-IN-PROCESS | C3: NOT-IN-PROCESS | D3: 1 | E3: Unit Component (60) | F3: 46065.45 | G3: QT17IA14.00 | H3: QTNSN095288A.X03 | I3: =VLOOKUP(G3,WO!A:J,10,0) -> 1
A4: YK260300125 | B4: NOT-IN-PROCESS | C4: NOT-IN-PROCESS | D4: 1 | E4: Unit Component (60) | F4: 46071.552 | G4: QT17IA14.00 | H4: QTNSN095288A.X03 | I4: =VLOOKUP(G4,WO!A:J,10,0) -> 1
A5: YK260300126 | B5: NOT-IN-PROCESS | C5: NOT-IN-PROCESS | D5: 1 | E5: Unit Component (60) | F5: 46072.29 | G5: QT17IA14.00 | H5: QTNSN095288A.X03 | I5: =VLOOKUP(G5,WO!A:J,10,0) -> 1
A6: YK260300127 | B6: NOT-IN-PROCESS | C6: NOT-IN-PROCESS | D6: 1 | E6: Unit Component (60) | F6: 46076.37 | G6: QT17IA14.00 | H6: QTNSN095288A.X03 | I6: =VLOOKUP(G6,WO!A:J,10,0) -> 1
A7: YK260300128 | B7: SHIP Shipping | C7: Shipped to Customer | D7: 1 | E7: Shipped (40) | F7: 46112.311 | G7: QT17IA14.00 | H7: QTNSN095288A.X03 | I7: =VLOOKUP(G7,WO!A:J,10,0) -> 1
A8: YK260300129 | B8: NOT-IN-PROCESS | C8: NOT-IN-PROCESS | D8: 1 | E8: Unit Component (60) | F8: 46065.432 | G8: QT17IA14.00 | H8: QTNSN095288A.X03 | I8: =VLOOKUP(G8,WO!A:J,10,0) -> 1
A9: YK260300130 | B9: NOT-IN-PROCESS | C9: NOT-IN-PROCESS | D9: 1 | E9: Unit Component (60) | F9: 46071.282 | G9: QT17IA14.00 | H9: QTNSN095288A.X03 | I9: =VLOOKUP(G9,WO!A:J,10,0) -> 1
A10: YK260300131 | B10: NOT-IN-PROCESS | C10: NOT-IN-PROCESS | D10: 1 | E10: Unit Component (60) | F10: 46076.374 | G10: QT17IA14.00 | H10: QTNSN095288A.X03 | I10: =VLOOKUP(G10,WO!A:J,10,0) -> 1
A11: YK260300132 | B11: NOT-IN-PROCESS | C11: NOT-IN-PROCESS | D11: 1 | E11: Unit Component (60) | F11: 46065.431 | G11: QT17IA14.00 | H11: QTNSN095288A.X03 | I11: =VLOOKUP(G11,WO!A:J,10,0) -> 1
A12: YK260300133 | B12: NOT-IN-PROCESS | C12: NOT-IN-PROCESS | D12: 1 | E12: Unit Component (60) | F12: 46072.486 | G12: QT17IA14.00 | H12: QTNSN095288A.X03 | I12: =VLOOKUP(G12,WO!A:J,10,0) -> 1
A13: YK260300134 | B13: NOT-IN-PROCESS | C13: NOT-IN-PROCESS | D13: 1 | E13: Unit Component (60) | F13: 46065.449 | G13: QT17IA14.00 | H13: QTNSN095288A.X03 | I13: =VLOOKUP(G13,WO!A:J,10,0) -> 1
... A153: YK260900002 | B153: NOT-IN-PROCESS | C153: NOT-IN-PROCESS | D153: 1 | E153: Unit Component (60) | F153: 46146.277 | G153: QT17IA14.20 | H153: QTNSN095289A.X11 | I153: =VLOOKUP(G153,WO!A:J,10,0) -> 7
A154: YK260900003 | B154: SHIP Shipping | C154: Shipped to Customer | D154: 1 | E154: Shipped (40) | F154: 46246.556 | G154: QT17IA14.20 | H154: QTNSN095289A.X11 | I154: =VLOOKUP(G154,WO!A:J,10,0) -> 7 | K154: 46248
A155: YK260900004 | B155: FUN1 Func Test | C155: Functional Test-1 | D155: 1 | E155: On The Line (20) | F155: 46122.38 | G155: QT17IA14.20 | H155: QTNSN095289A.X11 | I155: =VLOOKUP(G155,WO!A:J,10,0) -> 7
A156: YK260900005 | B156: NOT-IN-PROCESS | C156: NOT-IN-PROCESS | D156: 1 | E156: Unit Component (60) | F156: 46150.392 | G156: QT17IA14.20 | H156: QTNSN095289A.X11 | I156: =VLOOKUP(G156,WO!A:J,10,0) -> 7
A157: YK260900006 | B157: SHIP Shipping | C157: Shipped to Customer | D157: 1 | E157: Shipped (40) | F157: 46246.581 | G157: QT17IA14.20 | H157: QTNSN095289A.X11 | I157: =VLOOKUP(G157,WO!A:J,10,0) -> 7 | K157: 46248
A158: YK260900007 | B158: NOT-IN-PROCESS | C158: NOT-IN-PROCESS | D158: 1 | E158: Unit Component (60) | F158: 46150.392 | G158: QT17IA14.20 | H158: QTNSN095289A.X11 | I158: =VLOOKUP(G158,WO!A:J,10,0) -> 7
A159: YK260900008 | B159: SHIP Shipping | C159: Shipped to Customer | D159: 1 | E159: Shipped (40) | F159: 46123.268 | G159: QT17IA14.20 | H159: QTNSN095289A.X11 | I159: =VLOOKUP(G159,WO!A:J,10,0) -> 7 | K159: 46105
A160: YK260900009 | B160: SHIP Shipping | C160: Shipped to Customer | D160: 1 | E160: Shipped (40) | F160: 46123.268 | G160: QT17IA14.20 | H160: QTNSN095289A.X11 | I160: =VLOOKUP(G160,WO!A:J,10,0) -> 7 | K160: 46105
A161: YK260900010 | B161: SHIP Shipping | C161: Shipped to Customer | D161: 1 | E161: Shipped (40) | F161: 46248.37 | G161: QT17IA14.20 | H161: QTNSN095289A.X11 | I161: =VLOOKUP(G161,WO!A:J,10,0) -> 7 | K161: 46248
A162: YK260900011 | B162: SHIP Shipping | C162: Shipped to Customer | D162: 1 | E162: Shipped (40) | F162: 46123.268 | G162: QT17IA14.20 | H162: QTNSN095289A.X11 | I162: =VLOOKUP(G162,WO!A:J,10,0) -> 7 | K162: 46105
A163: YK260900012 | B163: SHIP Shipping | C163: Shipped to Customer | D163: 1 | E163: Shipped (40) | F163: 46154.373 | G163: QT17IA14.20 | H163: QTNSN095289A.X11 | I163: =VLOOKUP(G163,WO!A:J,10,0) -> 7 | K163: 46156
A164: YK260900013 | B164: NOT-IN-PROCESS | C164: NOT-IN-PROCESS | D164: 1 | E164: Unit Component (60) | F164: 46153.505 | G164: QT17IA14.20 | H164: QTNSN095289A.X11 | I164: =VLOOKUP(G164,WO!A:J,10,0) -> 7
A165: YK260900014 | B165: NOT-IN-PROCESS | C165: NOT-IN-PROCESS | D165: 1 | E165: Unit Component (60) | F165: 46140.311 | G165: QT17IA14.20 | H165: QTNSN095289A.X11 | I165: =VLOOKUP(G165,WO!A:J,10,0) -> 7
A166: YK260900015 | B166: SHIP Shipping | C166: Shipped to Customer | D166: 1 | E166: Shipped (40) | F166: 46246.579 | G166: QT17IA14.20 | H166: QTNSN095289A.X11 | I166: =VLOOKUP(G166,WO!A:J,10,0) -> 7 | K166: 46248
A167: YK260900016 | B167: NOT-IN-PROCESS | C167: NOT-IN-PROCESS | D167: 1 | E167: Unit Component (60) | F167: 46146.277 | G167: QT17IA14.20 | H167: QTNSN095289A.X11 | I167: =VLOOKUP(G167,WO!A:J,10,0) -> 7
A168: YK260900017 | B168: CMP1 Complete | C168: Complete | D168: 1 | E168: Finished (30) | F168: 46139.587 | G168: QT17IA14.20 | H168: QTNSN095289A.X11 | I168: =VLOOKUP(G168,WO!A:J,10,0) -> 7
A169: YK260900018 | B169: SHIP Shipping | C169: Shipped to Customer | D169: 1 | E169: Shipped (40) | F169: 46123.268 | G169: QT17IA14.20 | H169: QTNSN095289A.X11 | I169: =VLOOKUP(G169,WO!A:J,10,0) -> 7 | K169: 46097
A170: YK260900019 | B170: SHIP Shipping | C170: Shipped to Customer | D170: 1 | E170: Shipped (40) | F170: 46246.583 | G170: QT17IA14.20 | H170: QTNSN095289A.X11 | I170: =VLOOKUP(G170,WO!A:J,10,0) -> 7 | K170: 46248
A171: YK260900020 | B171: NOT-IN-PROCESS | C171: NOT-IN-PROCESS | D171: 1 | E171: Unit Component (60) | F171: 46153.435 | G171: QT17IA14.20 | H171: QTNSN095289A.X11 | I171: =VLOOKUP(G171,WO!A:J,10,0) -> 7
A172: YK260900021 | B172: FUN1 Func Test | C172: Functional Test-1 | D172: 1 | E172: On The Line (20) | F172: 46122.381 | G172: QT17IA14.20 | H172: QTNSN095289A.X11 | I172: =VLOOKUP(G172,WO!A:J,10,0) -> 7
A173: YK260900022 | B173: SHIP Shipping | C173: Shipped to Customer | D173: 1 | E173: Shipped (40) | F173: 46174.475 | G173: QT17IA14.20 | H173: QTNSN095289A.X11 | I173: =VLOOKUP(G173,WO!A:J,10,0) -> 7 | K173: 46128
A174: YK260900023 | B174: SHIP Shipping | C174: Shipped to Customer | D174: 1 | E174: Shipped (40) | F174: 46248.401 | G174: QT17IA14.20 | H174: QTNSN095289A.X11 | I174: =VLOOKUP(G174,WO!A:J,10,0) -> 7 | K174: 46248
A175: YK260900024 | B175: SHIP Shipping | C175: Shipped to Customer | D175: 1 | E175: Shipped (40) | F175: 46248.4 | G175: QT17IA14.20 | H175: QTNSN095289A.X11 | I175: =VLOOKUP(G175,WO!A:J,10,0) -> 7 | K175: 46248
A176: YK260900025 | B176: SHIP Shipping | C176: Shipped to Customer | D176: 1 | E176: Shipped (40) | F176: 46246.556 | G176: QT17IA14.20 | H176: QTNSN095289A.X11 | I176: =VLOOKUP(G176,WO!A:J,10,0) -> 7 | K176: 46248
A177: YK260900026 | B177: SHIP Shipping | C177: Shipped to Customer | D177: 1 | E177: Shipped (40) | F177: 46248.401 | G177: QT17IA14.20 | H177: QTNSN095289A.X11 | I177: =VLOOKUP(G177,WO!A:J,10,0) -> 7 | K177: 46248
A178: YK260900027 | B178: FUN1 Func Test | C178: Functional Test-1 | D178: 1 | E178: On The Line (20) | F178: 46122.382 | G178: QT17IA14.20 | H178: QTNSN095289A.X11 | I178: =VLOOKUP(G178,WO!A:J,10,0) -> 7
A179: YK260900028 | B179: SHIP Shipping | C179: Shipped to Customer | D179: 1 | E179: Shipped (40) | F179: 46246.559 | G179: QT17IA14.20 | H179: QTNSN095289A.X11 | I179: =VLOOKUP(G179,WO!A:J,10,0) -> 7 | K179: 46248
...

Sheet Summary
A1: Row Labels | B1: Work order | C1: Part number | D1: Process | E1: Unit Status | F1: Count of Qty
A2: 1 | B2: QT17IA14.00 | C2: QTNSN095288A.X03 | D2: NOT-IN-PROCESS | E2: Unit Component (60) | F2: 64
D3: Shipped to Customer | E3: Shipped (40) | F3: 6
A4: 2 | B4: QT17IA14.10 | C4: QTNSN095289A.X03 | D4: NOT-IN-PROCESS | E4: Unit Component (60) | F4: 64
D5: Shipped to Customer | E5: Shipped (40) | F5: 16
A6: 3 | B6: QT17IA23.00 | C6: QTNSN095266A.X02 | D6: NOT-IN-PROCESS | E6: Unit Component (60) | F6: 11
D7: Shipped to Customer | E7: Shipped (40) | F7: 14
A8: 4 | B8: QT17IA43.00 | C8: QTNSN476757A.X02 | D8: Shipped to Customer | E8: Shipped (40) | F8: 20
A9: 5 | B9: QT17IA14.30 | C9: QTNSN095288A.X11 | D9: Functional Test-1 | E9: On The Line (20) | F9: 2
D10: NOT-IN-PROCESS | E10: Unit Component (60) | F10: 11
D11: Shipped to Customer | E11: Shipped (40) | F11: 24
A12: 6 | B12: QT17IA14.31 | C12: QTNSN095288A.X11 | D12: Functional Test-1 | E12: On The Line (20) | F12: 1
D13: NOT-IN-PROCESS | E13: Unit Component (60) | F13: 12
D14: Shipped to Customer | E14: Shipped (40) | F14: 24
A15: 7 | B15: QT17IA14.20 | C15: QTNSN095289A.X11 | D15: Complete | E15: Finished (30) | F15: 1
D16: Functional Test-1 | E16: On The Line (20) | F16: 5
D17: NOT-IN-PROCESS | E17: Unit Component (60) | F17: 8
D18: Shipped to Customer | E18: Shipped (40) | F18: 23
A19: 8 | B19: QT17IA14.21 | C19: QTNSN095289A.X11 | D19: Functional Test-1 | E19: On The Line (20) | F19: 3
D20: NOT-IN-PROCESS | E20: Unit Component (60) | F20: 20
D21: Shipped to Customer | E21: Shipped (40) | F21: 14
A22: 9 | B22: QT17IA24.00 | C22: QTNSN095266A.X11 | D22: NOT-IN-PROCESS | E22: Unit Component (60) | F22: 16
D23: Shipped to Customer | E23: Shipped (40) | F23: 13
A24: 10 | B24: QT17IA44.00 | C24: QTNSN476757A.X11 | D24: Shipped to Customer | E24: Shipped (40) | F24: 15
A25: 11 | B25: QT17IA14.50 | C25: QTNSN095288A.X11 | D25: Complete | E25: Finished (30) | F25: 8
D26: Functional Test-1 | E26: On The Line (20) | F26: 5
D27: NOT-IN-PROCESS | E27: Unit Component (60) | F27: 37
D28: Shipped to Customer | E28: Shipped (40) | F28: 81
D29: Xfr to Debug Test | E29: In Repair Hold (29) | F29: 1
A30: 12 | B30: QT17IA14.40 | C30: QTNSN095289A.X11 | D30: NOT-IN-PROCESS | E30: Unit Component (60) | F30: 32
D31: Shipped to Customer | E31: Shipped (40) | F31: 100
A32: 13 | B32: QT17IA24.10 | C32: QTNSN095266A.X12 | D32: Complete | E32: Finished (30) | F32: 1
D33: Functional Test-1 | E33: On The Line (20) | F33: 1
D34: NOT-IN-PROCESS | E34: Unit Component (60) | F34: 38
D35: Rework-2 | E35: In Repair (25) | F35: 1
A36: 14 | B36: QT17IA44.10 | C36: QTNSN476757A.X12 | D36: Shipped to Customer | E36: Shipped (40) | F36: 30
A37: 15 | B37: QT17IA15.80 | C37: QTNSN095289A.X12 | D37: NOT-IN-PROCESS | E37: Unit Component (60) | F37: 44
D38: Shipped to Customer | E38: Shipped (40) | F38: 18
A39: 16 | B39: QT17IA15.90 | C39: QTNSN095288A.X12 | D39: Complete | E39: Finished (30) | F39: 1
D40: NOT-IN-PROCESS | E40: Unit Component (60) | F40: 47
...

Sheet WO
A1: Unique id | C1: WO | E1: Program | F1: Type | G1: Part number | H1: Desc | I1: Qty | J1: Priority | K1: STI | L1: STI/ Comments | M1: Quote
A2: QT17IA14.00 | B2: =MID(A2,3,11) -> 17IA14.00 | C2: WIP | D2: =VLOOKUP(A2,'[1]Plan - US NPI'!$C$6:$E$192,3,0) -> #N/A | E2: =VLOOKUP($A2,'[2]Plan - US NPI'!$C$6:$K$191,3,0) -> #N/A | F2: =VLOOKUP($A2,'[2]Plan - US NPI'!$C$6:$K$191,9,0) -> #N/A | G2: QTNSN095288A.X03 | H2: #N/A | I2: 70 | J2: 1 | R2: Mh lot codes to MRB
A3: QT17IA14.10 | B3: =MID(A3,3,11) -> 17IA14.10 | C3: WIP | D3: =VLOOKUP(A3,'[1]Plan - US NPI'!$C$6:$E$192,3,0) -> #N/A | E3: =VLOOKUP($A3,'[2]Plan - US NPI'!$C$6:$K$191,3,0) -> #N/A | F3: =VLOOKUP($A3,'[2]Plan - US NPI'!$C$6:$K$191,9,0) -> #N/A | G3: QTNSN095289A.X03 | H3: #N/A | I3: 80 | J3: 2 | R3: Solder paste Qtys
A4: QT17IA23.00 | B4: =MID(A4,3,11) -> 17IA23.00 | C4: WIP | D4: =VLOOKUP(A4,'[1]Plan - US NPI'!$C$6:$E$192,3,0) -> #N/A | E4: =VLOOKUP($A4,'[2]Plan - US NPI'!$C$6:$K$191,3,0) -> #N/A | F4: =VLOOKUP($A4,'[2]Plan - US NPI'!$C$6:$K$191,9,0) -> #N/A | G4: QTNSN095266A.X02 | H4: #N/A | I4: 25 | J4: 3
A5: QT17IA43.00 | B5: =MID(A5,3,11) -> 17IA43.00 | C5: WIP | D5: =VLOOKUP(A5,'[1]Plan - US NPI'!$C$6:$E$192,3,0) -> #N/A | E5: =VLOOKUP($A5,'[2]Plan - US NPI'!$C$6:$K$191,3,0) -> #N/A | F5: =VLOOKUP($A5,'[2]Plan - US NPI'!$C$6:$K$191,9,0) -> #N/A | G5: QTNSN476757A.X02 | H5: #N/A | I5: 20 | J5: 4
A6: QT17IA14.30 | B6: =MID(A6,3,11) -> 17IA14.30 | C6: WIP | D6: =VLOOKUP(A6,'[1]Plan - US NPI'!$C$6:$E$192,3,0) -> #N/A | E6: =VLOOKUP($A6,'[2]Plan - US NPI'!$C$6:$K$191,3,0) -> AXFIA | F6: =VLOOKUP($A6,'[2]Plan - US NPI'!$C$6:$K$191,9,0) -> PA Assembly | G6: QTNSN095288A.X11 | H6: QT PA ASSY, 095288A. REV X11, B25 PA ASSEMBLY FOR AXFIA/AXFIB | I6: 37 | J6: 5 | L6: eSTI PE53499. PE53575 add a note to remove shield and pre-drive, and for 840135A to use X1 version. PE53746 sent 03/13
A7: QT17IA14.31 | B7: =MID(A7,3,11) -> 17IA14.31 | C7: WIP | D7: =VLOOKUP(A7,'[1]Plan - US NPI'!$C$6:$E$192,3,0) -> #N/A | E7: =VLOOKUP($A7,'[2]Plan - US NPI'!$C$6:$K$191,3,0) -> AXFIA | F7: =VLOOKUP($A7,'[2]Plan - US NPI'!$C$6:$K$191,9,0) -> PA Assembly | G7: QTNSN095288A.X11 | H7: QT PA ASSY, 095288A. REV X11, B25 PA ASSEMBLY FOR AXFIA/AXFIB | I7: 37 | J7: 6 | L7: eSTI PE53499. PE53575 add a note to remove shield and pre-drive, and for 840135A to use X1 version. PE53684 sent 03/13
A8: QT17IA14.20 | B8: =MID(A8,3,11) -> 17IA14.20 | C8: WIP | D8: =VLOOKUP(A8,'[1]Plan - US NPI'!$C$6:$E$192,3,0) -> #N/A | E8: =VLOOKUP($A8,'[2]Plan - US NPI'!$C$6:$K$191,3,0) -> AXFIA | F8: =VLOOKUP($A8,'[2]Plan - US NPI'!$C$6:$K$191,9,0) -> PA Assembly | G8: QTNSN095289A.X11 | H8: QT PA ASSY, 095289A. REV X11, B66 PA ASSEMBLY FOR AXFIA/AXFIB | I8: 37 | J8: 7 | L8: STI PE53554 for 840135A to use X1 version. PE53499, .
A9: QT17IA14.21 | B9: =MID(A9,3,11) -> 17IA14.21 | C9: WIP | D9: =VLOOKUP(A9,'[1]Plan - US NPI'!$C$6:$E$192,3,0) -> #N/A | E9: =VLOOKUP($A9,'[2]Plan - US NPI'!$C$6:$K$191,3,0) -> AXFIA | F9: =VLOOKUP($A9,'[2]Plan - US NPI'!$C$6:$K$191,9,0) -> PA Assembly | G9: QTNSN095289A.X11 | H9: QT PA ASSY, 095289A. REV X11, B66 PA ASSEMBLY FOR AXFIA/AXFIB | I9: 37 | J9: 8 | L9: PE53571 for 17IA14.21,add a note to remove shield and pre-driver. Create new eSTI for 17IA14.20 adding the same note. NEW PE53611
A10: QT17IA24.00 | B10: =MID(A10,3,11) -> 17IA24.00 | C10: WIP | D10: =VLOOKUP(A10,'[1]Plan - US NPI'!$C$6:$E$192,3,0) -> #N/A | E10: =VLOOKUP($A10,'[2]Plan - US NPI'!$C$6:$K$191,3,0) -> #N/A | F10: =VLOOKUP($A10,'[2]Plan - US NPI'!$C$6:$K$191,9,0) -> #N/A | G10: QTNSN095266A.X11 | H10: QT TRX ASSY, 095266A. REV X11, TRX ASSEMBLY FOR AXFIA | I10: 29 | J10: 9 | L10: PE53604, PE53707,PE53847
A11: QT17IA44.00 | B11: =MID(A11,3,11) -> 17IA44.00 | C11: WIP | D11: =VLOOKUP(A11,'[1]Plan - US NPI'!$C$6:$E$192,3,0) -> #N/A | E11: =VLOOKUP($A11,'[2]Plan - US NPI'!$C$6:$K$191,3,0) -> #N/A | F11: =VLOOKUP($A11,'[2]Plan - US NPI'!$C$6:$K$191,9,0) -> #N/A | G11: QTNSN476757A.X11 | H11: RRH X11 | I11: 15 | J11: 10 | L11: PE53701
A12: QT17IA14.50 | B12: =MID(A12,3,11) -> 17IA14.50 | C12: WIP | D12: =VLOOKUP(A12,'[1]Plan - US NPI'!$C$6:$E$192,3,0) -> #N/A | E12: =VLOOKUP($A12,'[2]Plan - US NPI'!$C$6:$K$191,3,0) -> AXFIA | F12: =VLOOKUP($A12,'[2]Plan - US NPI'!$C$6:$K$191,9,0) -> PA Assembly | G12: QTNSN095288A.X11 | H12: QT PA ASSY, 095288A. REV X11, B25 PA ASSEMBLY FOR AXFIA/AXFIB | I12: 124 | J12: 11 | L12: PE53891
A13: QT17IA14.40 | B13: =MID(A13,3,11) -> 17IA14.40 | C13: WIP | D13: =VLOOKUP(A13,'[1]Plan - US NPI'!$C$6:$E$192,3,0) -> #N/A | E13: =VLOOKUP($A13,'[2]Plan - US NPI'!$C$6:$K$191,3,0) -> AXFIA | F13: =VLOOKUP($A13,'[2]Plan - US NPI'!$C$6:$K$191,9,0) -> PA Assembly | G13: QTNSN095289A.X11 | H13: QT PA ASSY, 095289A. REV X11, B66 PA ASSEMBLY FOR AXFIA/AXFIB | I13: 124 | J13: 12 | L13: PE54018
A14: QT17IA24.10 | B14: =MID(A14,3,11) -> 17IA24.10 | C14: WIP | D14: =VLOOKUP(A14,'[1]Plan - US NPI'!$C$6:$E$192,3,0) -> #N/A | E14: =VLOOKUP($A14,'[2]Plan - US NPI'!$C$6:$K$191,3,0) -> AXFIA | F14: =VLOOKUP($A14,'[2]Plan - US NPI'!$C$6:$K$191,9,0) -> TRX/PSU/BB Assembly | G14: QTNSN095266A.X12 | H14: QT TRX ASSY, 095266A. REV X12, TRX ASSEMBLY FOR AXFIA | I14: 41 | J14: 13 | L14: X12 Bom released - PE54073
A15: QT17IA44.10 | B15: =MID(A15,3,11) -> 17IA44.10 | C15: WIP | D15: =VLOOKUP(A15,'[1]Plan - US NPI'!$C$6:$E$192,3,0) -> #N/A | E15: =VLOOKUP($A15,'[2]Plan - US NPI'!$C$6:$K$191,3,0) -> AXFIA | F15: =VLOOKUP($A15,'[2]Plan - US NPI'!$C$6:$K$191,9,0) -> RRH Unit | G15: QTNSN476757A.X12 | H15: QT T/L UNIT ASSY, 476757A. REV X12, AXFIA AirScale RRH 4T8R n25/66 720W | I15: 30 | J15: 14 | L15: Esti releasesed- Release wo- PE54404- Wo released 29-May-26 | Min of 15 units next week | Work order complete
A16: QT17IA15.80 | B16: =MID(A16,3,11) -> 17IA15.80 | C16: WIP | D16: =VLOOKUP(A16,'[1]Plan - US NPI'!$C$6:$E$192,3,0) -> #N/A | E16: AXFIA | F16: PA Assembly | G16: QTNSN095289A.X12 | H16: QT PA ASSY, 095289A. REV X12, B66 PA ASSEMBLY FOR AXFIA/AXFIB | I16: 62 | J16: 15 | L16: New PWB- Order 2 sets of stencils- new profile board needed - New profile needed - Need STI- Checkplots being worked - PE54185
A17: QT17IA15.90 | B17: =MID(A17,3,11) -> 17IA15.90 | C17: WIP | D17: =VLOOKUP(A17,'[1]Plan - US NPI'!$C$6:$E$192,3,0) -> #N/A | E17: =VLOOKUP($A17,'[2]Plan - US NPI'!$C$6:$K$191,3,0) -> AXFIA | F17: =VLOOKUP($A17,'[2]Plan - US NPI'!$C$6:$K$191,9,0) -> PA Assembly | G17: QTNSN095288A.X12 | H17: QT PA ASSY, 095288A. REV X12, B25 PA ASSEMBLY FOR AXFIA/AXFIB | I17: 62 | J17: 16 | L17: New PWB- Order 2 sets of stencils- new profile board needed - New profile needed - Need STI- Stencil 04/23- PE54164 | Q17: 46139
A18: QT19BA11.00 | B18: =MID(A18,3,11) -> 19BA11.00 | C18: WIP | D18: =VLOOKUP(A18,'[1]Plan - US NPI'!$C$6:$E$192,3,0) -> #N/A | E18: =VLOOKUP($A18,'[2]Plan - US NPI'!$C$6:$K$191,3,0) -> AXOLA | F18: =VLOOKUP($A18,'[2]Plan - US NPI'!$C$6:$K$191,9,0) -> PA Assembly | G18: QTNSN095290A.X02 | H18: QT PA ASSY, 095290A. REV X02, B71 PA ASSEMBLY FOR AXOLBA | I18: 14 | J18: 17 | L18: Stencils due on the 27- Apr- No Esti
A19: QT19BA11.10 | B19: =MID(A19,3,11) -> 19BA11.10 | C19: WIP | D19: =VLOOKUP(A19,'[1]Plan - US NPI'!$C$6:$E$192,3,0) -> #N/A | E19: =VLOOKUP($A19,'[2]Plan - US NPI'!$C$6:$K$191,3,0) -> AXOLA | F19: =VLOOKUP($A19,'[2]Plan - US NPI'!$C$6:$K$191,9,0) -> PA Assembly | G19: QTNSN095291A.X02 | H19: QT PA ASSY, 095291A. REV X02, B85 PA ASSEMBLY FOR AXOLBA | I19: 14 | J19: 18 | L19: Stencils due on the 27- Apr- No Esti- Tracking# 707296329356
A20: QT20LA21.00 | B20: =MID(A20,3,11) -> 20LA21.00 | C20: WIP | D20: =VLOOKUP(A20,'[1]Plan - US NPI'!$C$6:$E$192,3,0) -> #N/A | E20: =VLOOKUP($A20,'[2]Plan - US NPI'!$C$6:$K$191,3,0) -> AXOLA | F20: =VLOOKUP($A20,'[2]Plan - US NPI'!$C$6:$K$191,9,0) -> TRX/PSU/BB Assembly | G20: QTNSN095286A.X02 | H20: QT TRX ASSY, 095286A. REV X02, TRX ASSEMBLY FOR AXOLA | I20: 10 | J20: 19 | L20: New CP today - Check material
A21: QT17IA25.30 | B21: =MID(A21,3,11) -> 17IA25.30 | C21: WIP | D21: =VLOOKUP(A21,'[1]Plan - US NPI'!$C$6:$E$192,3,0) -> #N/A | E21: =VLOOKUP($A21,'[2]Plan - US NPI'!$C$6:$K$191,3,0) -> AXFIA | F21: =VLOOKUP($A21,'[2]Plan - US NPI'!$C$6:$K$191,9,0) -> TRX/PSU/BB Assembly | G21: QTNSN095266A.X12 | H21: QT TRX ASSY, 095266A. REV X12, TRX ASSEMBLY FOR AXFIA | I21: 47 | J21: 20 | L21: Kick off 21-May-26- ESTI -PE54408 - Released 29-May-26 | One more ESTI to be released | Stencil ETA 03-Jun-26 | PE54513- Work order relased 06/03
A22: QT17IA15.60 | B22: =MID(A22,3,11) -> 17IA15.60 | C22: WIP | D22: =VLOOKUP(A22,'[1]Plan - US NPI'!$C$6:$E$192,3,0) -> #N/A | E22: =VLOOKUP($A22,'[2]Plan - US NPI'!$C$6:$K$191,3,0) -> AXFIA | F22: =VLOOKUP($A22,'[2]Plan - US NPI'!$C$6:$K$191,9,0) -> PA Assembly | G22: QTNSN095289A.X12 | H22: QT PA ASSY, 095289A. REV X12, B66 PA ASSEMBLY FOR AXFIA/AXFIB | I22: 188 | J22: 21 | L22: Kick off 21-May-26- ESTI - PE54407- WO Released 29-May-26
A23: QT17IA15.70 | B23: =MID(A23,3,11) -> 17IA15.70 | C23: WIP | D23: =VLOOKUP(A23,'[1]Plan - US NPI'!$C$6:$E$192,3,0) -> #N/A | E23: =VLOOKUP($A23,'[2]Plan - US NPI'!$C$6:$K$191,3,0) -> AXFIA | F23: =VLOOKUP($A23,'[2]Plan - US NPI'!$C$6:$K$191,9,0) -> PA Assembly | G23: QTNSN095288A.X12 | H23: QT PA ASSY, 095288A. REV X12, B25 PA ASSEMBLY FOR AXFIA/AXFIB | I23: 188 | J23: 22 | L23: Kick off 21-May-26- ESTI - PE54405- WO Released 29-May-26
A24: QT17IA45.30 | B24: =MID(A24,3,11) -> 17IA45.30 | C24: WIP | D24: =VLOOKUP(A24,'[1]Plan - US NPI'!$C$6:$E$192,3,0) -> #N/A | E24: =VLOOKUP($A24,'[2]Plan - US NPI'!$C$6:$K$191,3,0) -> AXFIA | F24: =VLOOKUP($A24,'[2]Plan - US NPI'!$C$6:$K$191,9,0) -> RRH Unit | G24: QTNSN476757A.X12 | H24: QT T/L UNIT ASSY, 476757A. REV X12, AXFIA AirScale RRH 4T8R n25/66 720W | I24: 47 | J24: 23 | L24: PE54409 & PE54856 - Released 29-May-26_ need to release work order- Relased 15-Jun-26 | Rework on the Chassis | Committing 22 pcs for next week | P55306
A25: QT17IA45.40 | B25: =MID(A25,3,11) -> 17IA45.40 | C25: WIP | D25: =VLOOKUP(A25,'[1]Plan - US NPI'!$C$6:$E$192,3,0) -> #N/A | E25: AXFIA | F25: RRH Unit | G25: QTNSN476757A.X12 | H25: QT T/L UNIT ASSY, 476757A. REV X12, AXFIA AirScale RRH 4T8R n25/66 720W | I25: 11 | J25: 24 | L25: Kick off- ESTI PE54381 - WO released
A26: QT17IA15.95 | B26: =MID(A26,3,11) -> 17IA15.95 | C26: WIP | D26: =VLOOKUP(A26,'[1]Plan - US NPI'!$C$6:$E$192,3,0) -> #N/A | E26: =VLOOKUP($A26,'[2]Plan - US NPI'!$C$6:$K$191,3,0) -> AXFIA | F26: =VLOOKUP($A26,'[2]Plan - US NPI'!$C$6:$K$191,9,0) -> PA Assembly | G26: QTNSN095289A.X12 | H26: QT PA ASSY, 095289A. REV X12, B66 PA ASSEMBLY FOR AXFIA/AXFIB | I26: 140 | J26: 25 | L26: Stencils , same PWB, STI for Solder paste PE54356- requested to run on the 2oth of May | New profile needed for Different solder paste
A27: QT17IA15.96 | B27: =MID(A27,3,11) -> 17IA15.96 | C27: WIP | D27: =VLOOKUP(A27,'[1]Plan - US NPI'!$C$6:$E$192,3,0) -> #N/A | E27: =VLOOKUP($A27,'[2]Plan - US NPI'!$C$6:$K$191,3,0) -> AXFIA | F27: =VLOOKUP($A27,'[2]Plan - US NPI'!$C$6:$K$191,9,0) -> PA Assembly | G27: QTNSN095288A.X12 | H27: QT PA ASSY, 095288A. REV X12, B25 PA ASSEMBLY FOR AXFIA/AXFIB | I27: 140 | J27: 26 | L27: PE54357- Solder paste STI- Received | New profile needed for Different solder paste
A28: QT20LA12.00 | B28: =MID(A28,3,11) -> 20LA12.00 | C28: WIP | D28: =VLOOKUP(A28,'[1]Plan - US NPI'!$C$6:$E$192,3,0) -> #N/A | E28: =VLOOKUP($A28,'[2]Plan - US NPI'!$C$6:$K$191,3,0) -> AXOLA | F28: =VLOOKUP($A28,'[2]Plan - US NPI'!$C$6:$K$191,9,0) -> PA Assembly | G28: QTNSN095290A.X02 | H28: QT PA ASSY, 095290A. REV X02, B71 PA ASSEMBLY FOR AXOLBA | I28: 64 | J28: 27 | L28: Esti releasesed- PE54413- WO released 27-May-26- need profile approved
A29: QT20LA12.10 | B29: =MID(A29,3,11) -> 20LA12.10 | C29: WIP | D29: =VLOOKUP(A29,'[1]Plan - US NPI'!$C$6:$E$192,3,0) -> #N/A | E29: =VLOOKUP($A29,'[2]Plan - US NPI'!$C$6:$K$191,3,0) -> AXOLA | F29: =VLOOKUP($A29,'[2]Plan - US NPI'!$C$6:$K$191,9,0) -> PA Assembly | G29: QTNSN095291A.X02 | H29: QT PA ASSY, 095291A. REV X02, B85 PA ASSEMBLY FOR AXOLBA | I29: 64 | J29: 28 | L29: Esti releasesed- WO released 27-May-26- Need profile approved
A30: QT20LA41.00 | B30: =MID(A30,3,11) -> 20LA41.00 | C30: WIP | D30: =VLOOKUP(A30,'[1]Plan - US NPI'!$C$6:$E$192,3,0) -> #N/A | E30: =VLOOKUP($A30,'[2]Plan - US NPI'!$C$6:$K$191,3,0) -> AXOLA | F30: =VLOOKUP($A30,'[2]Plan - US NPI'!$C$6:$K$191,9,0) -> RRH Unit | G30: QTNSN476797A.X11 | H30: QT T/L UNIT ASSY, 476797A.REV X11, AXOLA AirScale RRH 4T4R n71/85 320W | I30: 8 | J30: 29 | L30: CTB- ESTI PE54470 | WO release today 03-Jun-26- Followed up on ESTI | TRX rework need to look at material | STI released -
A31: QT19BA21.00A | B31: =MID(A31,3,11) -> 19BA21.00A | C31: WIP | D31: =VLOOKUP(A31,'[1]Plan - US NPI'!$C$6:$E$192,3,0) -> #N/A | E31: AXOLBA | F31: TRX/PSU/BB Assembly | G31: QTNSN095804A.X11 | I31: 22 | J31: 30 | L31: Relased 06/12- Critical components | 2 pcs Skipping FT- Nokia to pick up | Parametric Data- * 8 boards need rework STI to be released- Cannot test | PE55020- Rework STI with 3 parts that we need to buy-Load independent demand- Rework quote 12 boards- Quote needed pull parts to Soka | M31: Quote sent
A32: QT19BA12.20 | B32: =MID(A32,3,11) -> 19BA12.20 | C32: WIP | D32: =VLOOKUP(A32,'[1]Plan - US NPI'!$C$6:$E$192,3,0) -> #N/A | E32: =VLOOKUP($A32,'[2]Plan - US NPI'!$C$6:$K$191,3,0) -> AXOLBA | F32: =VLOOKUP($A32,'[2]Plan - US NPI'!$C$6:$K$191,9,0) -> PA Assembly | G32: QTNSN095290A.X02 | I32: 32 | J32: 31 | L32: ESTI - Sac305 PE54542- Work order QT20LA12.00 increased to 64 units
A33: QT19BA12.30 | B33: =MID(A33,3,11) -> 19BA12.30 | C33: WIP | D33: =VLOOKUP(A33,'[1]Plan - US NPI'!$C$6:$E$192,3,0) -> #N/A | E33: =VLOOKUP($A33,'[2]Plan - US NPI'!$C$6:$K$191,3,0) -> AXOLBA | F33: =VLOOKUP($A33,'[2]Plan - US NPI'!$C$6:$K$191,9,0) -> PA Assembly | G33: QTNSN095291A.X02 | I33: 32 | J33: 32 | L33: ESTI - Sac305 PE54541- Work order QT20LA12.10 increased to 64 units
A34: QT19BA41.00 | B34: =MID(A34,3,11) -> 19BA41.00 | C34: WIP | D34: =VLOOKUP(A34,'[1]Plan - US NPI'!$C$6:$E$192,3,0) -> #N/A | E34: =VLOOKUP($A34,'[2]Plan - US NPI'!$C$6:$K$191,3,0) -> AXOLBA | F34: =VLOOKUP($A34,'[2]Plan - US NPI'!$C$6:$K$191,9,0) -> RRH Unit | G34: QTNSN476971A.X11 | I34: 8 | J34: 33 | L34: No ESTI_ Nokia checking -06/16 | Chassis and Filter check stock | ESTI to be released PE54770- Share costed bom- New CP To be loaded today | Assembly to be stopped| Commiting to 8 wk 31 | M34: Quote sent-20-Jul-26 | N34: Press plate and Carriers - Delivered from CNC
A35: QT17IA24.20 | B35: =MID(A35,3,11) -> 17IA24.20 | C35: WIP | D35: =VLOOKUP(A35,'[1]Plan - US NPI'!$C$6:$E$192,3,0) -> #N/A | E35: =VLOOKUP($A35,'[2]Plan - US NPI'!$C$6:$K$191,3,0) -> AXFIA | F35: =VLOOKUP($A35,'[2]Plan - US NPI'!$C$6:$K$191,9,0) -> TRX/PSU/BB Assembly | G35: QTNSN095266A.X21 | I35: 29 | J35: 34 | L35: RelaseD 06/15 | Old profile can be used- Review with Jose current issues on the X12 build | Same profile as AXOLBA
A36: QT17IA14.70 | B36: =MID(A36,3,11) -> 17IA14.70 | C36: WIP | D36: AXFIA | E36: AXFIA | F36: PA Assembly | G36: QTNSN095288A.X21 | I36: 74 | J36: 35 | K36: PE55485 | L36: PE54718 | PE54609 | PE54651 - Jose Stencils- Clean released 24-Jun-26- New ESTI for preform ( )| Any date for the Macom part P620299
A37: QT17IA14.60 | B37: =MID(A37,3,11) -> 17IA14.60 | C37: WIP | D37: =VLOOKUP(A37,'[1]Plan - US NPI'!$C$6:$E$192,3,0) -> #N/A | E37: =VLOOKUP($A37,'[2]Plan - US NPI'!$C$6:$K$191,3,0) -> AXFIA | F37: =VLOOKUP($A37,'[2]Plan - US NPI'!$C$6:$K$191,9,0) -> PA Assembly | G37: QTNSN095289A.X21 | I37: 74 | J37: 36 | L37: PE54719, PE54667 ,PE54611 STI- Jose Stencils- 3 shortages- not clean- 2 MTRs to Oulu, 1 Po from Distro-New STI to be released- Labels
A38: QT18OA21.00A | B38: =MID(A38,3,11) -> 18OA21.00A | C38: WIP | D38: Need to release work order | E38: AXOA | F38: TRX | G38: QTNSN095725A.X11 | I38: 11 | J38: 37 | L38: need STI for X11 Bom | 4 STIS- PE54721,PE54724,PE55044,PE55107 & New STI to be released to run 4 boards without carriers on reflow | M38: Sent 21-Aug-26
A39: QT20LA22.00 | B39: =MID(A39,3,11) -> 20LA22.00 | C39: WIP | D39: =VLOOKUP(A39,'[1]Plan - US NPI'!$C$6:$E$192,3,0) -> #N/A | E39: =VLOOKUP($A39,'[2]Plan - US NPI'!$C$6:$K$191,3,0) -> AXOLA | F39: =VLOOKUP($A39,'[2]Plan - US NPI'!$C$6:$K$191,9,0) -> TRX/PSU/BB Assembly | G39: QTNSN095803A.X03 | I39: 14 | J39: 38 | L39: 1 component dif from the 804A.X11 Build | STI PE54748 - released today | Stencil Same as 804 | ON HOLD- YK262800086 Ship "as-is" to Salvador | Bom Update needed or STI| PE55140 to skip test and bom changes for the remainning boards | Close at 4 - new build for the remainning 095286A.xo2 | M39: Quote sent 13-July-26
A40: QT20LA15.93 | B40: =MID(A40,3,11) -> 20LA15.93 | C40: WIP | E40: =VLOOKUP($A40,'[2]Plan - US NPI'!$C$6:$K$191,3,0) -> AXOLA | F40: =VLOOKUP($A40,'[2]Plan - US NPI'!$C$6:$K$191,9,0) -> PA Assembly | G40: QTNSN095290A.X02 | I40: 13 | J40: 39 | L40: PE54809- Release Work order-PWB supplier info- Clean - Complete | M40: Quote sent 16-July-26
...

Sheet Sheet1
A1: PA build plan | E1: Qty | F1: SMT Build start date | G1: SMT Build end date | H1: Special instructions | I1: Comments | K1: Material Clear / Planned
A2: 19BA13.00 | B2: 095290A.X02 | C2: AXOLA/BA | D2: B71 | E2: 220 | F2: 46234 | G2: 46237 | H2: Innolot - Alpha P689340 | I2: Completed | J2: SMT Complete. | K2: 46227
A3: 19BA14.10 | B3: 095291A.X02 | C3: AXOLA/BA | D3: B85/14 | E3: 220 | F3: 46238 | G3: 46240 | H3: Innolot - Alpha P689340 | I3: Completed | J3: Aug 05: 2pc at AOI -programming underway. Delay: Machine couldn’t read fiducials.
A4: 20LA11.00 | B4: 095939A.X01 | C4: AXOLA | D4: B85/14 | E4: 13 | F4: 46241 | G4: 46241 | H4: Innolot - Alpha/Durafuse | I4: Next on the line, Kit pull complete | J4: Material pending CTB, LE TBD / Stencil need to order / SMT program -not yet available | K4: TBD
J5: Need to release w/o -pending material >1430316 resistor 0805 -No PO placed, SanCar shows demand -stock in disty per Terry, SanCar will place PO today, 2311411 Fedex 875083144774 stuck in customs, still in India, 987922X1 Fedex 875137617745 & 875139824951 stuck in customs. SMT programming need to create. Stencil Need to order.
A6: 17IA14.90 | B6: 095288A.X21 | C6: AXFIA | D6: B25 | E6: 226 | F6: 46244 | G6: 46246 | H6: Innolot - Alpha HR Solder Paste P689340 | I6: Kit released - Waiting for confirmation on Kit pull | J6: need this kit pulled -has w/o been released? eSTI CP'd - request to release w/o today | K6: material clear
A7: 17IA14.80 | B7: 095289A.X21 | C7: AXFIA | D7: B66 | E7: 226 | F7: 46246 | G7: 46248 | H7: Innolot - Alpha HR Solder Paste P689340 | I7: Waiting on STI to be released | J7: need this kit pulled -has w/o been released? Need eSTI. | K7: 46219
A8: 19BA13.00 | B8: 095290A.X02 | C8: AXOLA/BA | D8: B71 | E8: 234 | F8: 46251 | G8: 46253 | H8: Durafuse P683943 | J8: Kit on floor | K8: 46227
A9: 19BA14.10 | B9: 095291A.X02 | C9: AXOLA/BA | D9: B85/14 | E9: 234 | F9: 46254 | G9: 46258 | H9: Durafuse P683943 | I9: 179 pending | J9: Kit on floor
A10: 18OA12.00 | B10: 095724A.X11 | C10: AXOA | D10: B71 | E10: 14 | F10: 46259 | I10: Kit pull completed | J10: Kit released ready for pick up from stock room - low priority. stencil not ordered / SMT program -not yet available | K10: 46231
A13: TRX build plan | E13: Qty | F13: SMT Build start date | G13: SMT Build end date | H13: Special instructions | I13: Comments
A14: 19BA22.00 | B14: 095804A.X12 | C14: AXOLBA | E14: 64 | F14: 46244 | G14: 46248 | I14: 32 pending | J14: W/O released - stock room to start pulling today. Material clear. No eSTI. Stencil: Need SanCar to confirm if new stencil is needed. SMT target Aug 10th. | K14: 46238
A15: 20LA23.10 | B15: 095286A.X02 | C15: AXOLA - Re KO Aug 7 | E15: 10 | F15: LE to start?? | I15: eSTI ~20 lines -Need BOM uprev | On hold | J15: eSTI ~20 lines -Need BOM uprev
J16: Material: P689154 ETA Aug 7, P667029 ..- Ez to share CTB eSTI: 20+ lines need to up rev BOM. Stencil: on hand.
A17: 18OA21.00 | B17: 095725A.X11 | C17: AXOA | E17: 11 | I17: Need to release work order- previous work order cancelld due to bom update | K17: 46247
B18: AXFIA Aug 6 KO
C19: Need kits released and moved to floor
A22: RRH | E22: Qty | F22: SMT Build start date | G22: SMT Build end date | H22: Special instructions | I22: Comments
A23: QT19BA41.00 | B23: 476971A.X11 | C23: AXOLBA | D23: RF8 | E23: 8 | H23: Pre | I23: on line building. Chassis 095371A.X11 -holes not tapped
A24: QT17IA45.30 | B24: 476757A.X12 | C24: AXFIA | D24: RF8 | E24: 47 | H24: Main Build X12 | I24: on line building. Need B66, TRX -3pc available
A25: QT17IA44.20 | B25: 476757A.X21 | C25: AXFIA | D25: RF8 | E25: 15 | H25: Pre Build X21 | I25: Need kit released - eSTI CP'd
A26: QT18OA41.00 | B26: 477124A.X11 | C26: AXOA | D26: RF8 | E26: 6

Sheet Shipped
A1: Serial Number | B1: Ship Date
A2: YK262700652 | B2: 46230
A3: YK262700643 | B3: 46230
A4: YK262700652 | B4: 46248
A5: YK262700643 | B5: 46248
A6: YK261100764 | B6: 46248
A7: YK261400112 | B7: 46248
A8: YK261400076 | B8: 46248
A9: YK261400107 | B9: 46248
A10: YK261400027 | B10: 46248
A11: YK261400132 | B11: 46248
A12: YK261400126 | B12: 46248
A13: YK261400111 | B13: 46248
... A230: YK261600091 | B230: 46254
