Workbook

Sheet Shop Order
A1: Serial Number | B1: Workstation | C1: Process | D1: Qty | E1: Unit Status | F1: Last Updated | G1: Work order | H1: Part number | I1: Priority | J1: Comments | K1: das | L1: asdas
A2: YK260300123 | B2: NOT-IN-PROCESS | C2: NOT-IN-PROCESS | D2: 1 | E2: Unit Component (60) | F2: 46065.449 | G2: QT17IA14.00 | H2: QTNSN095288A.X03 | I2: =VLOOKUP(G2,Sheet2!A:D,4,0) -> 1
A3: YK260300124 | B3: NOT-IN-PROCESS | C3: NOT-IN-PROCESS | D3: 1 | E3: Unit Component (60) | F3: 46065.45 | G3: QT17IA14.00 | H3: QTNSN095288A.X03 | I3: =VLOOKUP(G3,Sheet2!A:D,4,0) -> 1
A4: YK260300125 | B4: NOT-IN-PROCESS | C4: NOT-IN-PROCESS | D4: 1 | E4: Unit Component (60) | F4: 46071.552 | G4: QT17IA14.00 | H4: QTNSN095288A.X03 | I4: =VLOOKUP(G4,Sheet2!A:D,4,0) -> 1
A5: YK260300126 | B5: NOT-IN-PROCESS | C5: NOT-IN-PROCESS | D5: 1 | E5: Unit Component (60) | F5: 46072.29 | G5: QT17IA14.00 | H5: QTNSN095288A.X03 | I5: =VLOOKUP(G5,Sheet2!A:D,4,0) -> 1
A6: YK260300127 | B6: NOT-IN-PROCESS | C6: NOT-IN-PROCESS | D6: 1 | E6: Unit Component (60) | F6: 46076.37 | G6: QT17IA14.00 | H6: QTNSN095288A.X03 | I6: =VLOOKUP(G6,Sheet2!A:D,4,0) -> 1
A7: YK260300128 | B7: SHIP Shipping | C7: Shipped to Customer | D7: 1 | E7: Shipped (40) | F7: 46112.311 | G7: QT17IA14.00 | H7: QTNSN095288A.X03 | I7: =VLOOKUP(G7,Sheet2!A:D,4,0) -> 1
A8: YK260300129 | B8: NOT-IN-PROCESS | C8: NOT-IN-PROCESS | D8: 1 | E8: Unit Component (60) | F8: 46065.432 | G8: QT17IA14.00 | H8: QTNSN095288A.X03 | I8: =VLOOKUP(G8,Sheet2!A:D,4,0) -> 1
A9: YK260300130 | B9: NOT-IN-PROCESS | C9: NOT-IN-PROCESS | D9: 1 | E9: Unit Component (60) | F9: 46071.282 | G9: QT17IA14.00 | H9: QTNSN095288A.X03 | I9: =VLOOKUP(G9,Sheet2!A:D,4,0) -> 1
A10: YK260300131 | B10: NOT-IN-PROCESS | C10: NOT-IN-PROCESS | D10: 1 | E10: Unit Component (60) | F10: 46076.374 | G10: QT17IA14.00 | H10: QTNSN095288A.X03 | I10: =VLOOKUP(G10,Sheet2!A:D,4,0) -> 1
A11: YK260300132 | B11: NOT-IN-PROCESS | C11: NOT-IN-PROCESS | D11: 1 | E11: Unit Component (60) | F11: 46065.431 | G11: QT17IA14.00 | H11: QTNSN095288A.X03 | I11: =VLOOKUP(G11,Sheet2!A:D,4,0) -> 1
A12: YK260300133 | B12: NOT-IN-PROCESS | C12: NOT-IN-PROCESS | D12: 1 | E12: Unit Component (60) | F12: 46072.486 | G12: QT17IA14.00 | H12: QTNSN095288A.X03 | I12: =VLOOKUP(G12,Sheet2!A:D,4,0) -> 1
A13: YK260300134 | B13: NOT-IN-PROCESS | C13: NOT-IN-PROCESS | D13: 1 | E13: Unit Component (60) | F13: 46065.449 | G13: QT17IA14.00 | H13: QTNSN095288A.X03 | I13: =VLOOKUP(G13,Sheet2!A:D,4,0) -> 1
... A304: YK261400005 | B304: NOT-IN-PROCESS | C304: NOT-IN-PROCESS | D304: 1 | E304: Traveler Printed (15) | F304: 46112.357 | G304: QT17IA14.50 | H304: QTNSN095288A.X11 | I304: =VLOOKUP(G304,Sheet2!A:D,4,0) -> 12
A305: YK261400006 | B305: NOT-IN-PROCESS | C305: NOT-IN-PROCESS | D305: 1 | E305: Traveler Printed (15) | F305: 46112.357 | G305: QT17IA14.50 | H305: QTNSN095288A.X11 | I305: =VLOOKUP(G305,Sheet2!A:D,4,0) -> 12 | J305: Shipping
A306: YK261400007 | B306: NOT-IN-PROCESS | C306: NOT-IN-PROCESS | D306: 1 | E306: Traveler Printed (15) | F306: 46112.357 | G306: QT17IA14.50 | H306: QTNSN095288A.X11 | I306: =VLOOKUP(G306,Sheet2!A:D,4,0) -> 12
A307: YK261400008 | B307: NOT-IN-PROCESS | C307: NOT-IN-PROCESS | D307: 1 | E307: Traveler Printed (15) | F307: 46112.357 | G307: QT17IA14.50 | H307: QTNSN095288A.X11 | I307: =VLOOKUP(G307,Sheet2!A:D,4,0) -> 12
A308: YK261400009 | B308: NOT-IN-PROCESS | C308: NOT-IN-PROCESS | D308: 1 | E308: Traveler Printed (15) | F308: 46112.357 | G308: QT17IA14.50 | H308: QTNSN095288A.X11 | I308: =VLOOKUP(G308,Sheet2!A:D,4,0) -> 12 | J308: Shipping
A309: YK261400010 | B309: NOT-IN-PROCESS | C309: NOT-IN-PROCESS | D309: 1 | E309: Traveler Printed (15) | F309: 46112.357 | G309: QT17IA14.50 | H309: QTNSN095288A.X11 | I309: =VLOOKUP(G309,Sheet2!A:D,4,0) -> 12
A310: YK261400011 | B310: NOT-IN-PROCESS | C310: NOT-IN-PROCESS | D310: 1 | E310: Traveler Printed (15) | F310: 46112.357 | G310: QT17IA14.50 | H310: QTNSN095288A.X11 | I310: =VLOOKUP(G310,Sheet2!A:D,4,0) -> 12
A311: YK261400012 | B311: NOT-IN-PROCESS | C311: NOT-IN-PROCESS | D311: 1 | E311: Traveler Printed (15) | F311: 46112.357 | G311: QT17IA14.50 | H311: QTNSN095288A.X11 | I311: =VLOOKUP(G311,Sheet2!A:D,4,0) -> 12
A312: YK261400013 | B312: NOT-IN-PROCESS | C312: NOT-IN-PROCESS | D312: 1 | E312: Traveler Printed (15) | F312: 46112.357 | G312: QT17IA14.50 | H312: QTNSN095288A.X11 | I312: =VLOOKUP(G312,Sheet2!A:D,4,0) -> 12 | J312: Shipping
A313: YK261400014 | B313: NOT-IN-PROCESS | C313: NOT-IN-PROCESS | D313: 1 | E313: Traveler Printed (15) | F313: 46112.357 | G313: QT17IA14.50 | H313: QTNSN095288A.X11 | I313: =VLOOKUP(G313,Sheet2!A:D,4,0) -> 12
A314: YK261400015 | B314: NOT-IN-PROCESS | C314: NOT-IN-PROCESS | D314: 1 | E314: Traveler Printed (15) | F314: 46112.357 | G314: QT17IA14.50 | H314: QTNSN095288A.X11 | I314: =VLOOKUP(G314,Sheet2!A:D,4,0) -> 12 | J314: With RRH
A315: YK261400016 | B315: NOT-IN-PROCESS | C315: NOT-IN-PROCESS | D315: 1 | E315: Traveler Printed (15) | F315: 46112.357 | G315: QT17IA14.50 | H315: QTNSN095288A.X11 | I315: =VLOOKUP(G315,Sheet2!A:D,4,0) -> 12 | J315: Failed
A316: YK261400017 | B316: NOT-IN-PROCESS | C316: NOT-IN-PROCESS | D316: 1 | E316: Traveler Printed (15) | F316: 46112.357 | G316: QT17IA14.50 | H316: QTNSN095288A.X11 | I316: =VLOOKUP(G316,Sheet2!A:D,4,0) -> 12
A317: YK261400018 | B317: NOT-IN-PROCESS | C317: NOT-IN-PROCESS | D317: 1 | E317: Traveler Printed (15) | F317: 46112.357 | G317: QT17IA14.50 | H317: QTNSN095288A.X11 | I317: =VLOOKUP(G317,Sheet2!A:D,4,0) -> 12
A318: YK261400019 | B318: NOT-IN-PROCESS | C318: NOT-IN-PROCESS | D318: 1 | E318: Traveler Printed (15) | F318: 46112.357 | G318: QT17IA14.50 | H318: QTNSN095288A.X11 | I318: =VLOOKUP(G318,Sheet2!A:D,4,0) -> 12
A319: YK261400020 | B319: NOT-IN-PROCESS | C319: NOT-IN-PROCESS | D319: 1 | E319: Traveler Printed (15) | F319: 46112.357 | G319: QT17IA14.50 | H319: QTNSN095288A.X11 | I319: =VLOOKUP(G319,Sheet2!A:D,4,0) -> 12 | J319: Failed
A320: YK261400021 | B320: NOT-IN-PROCESS | C320: NOT-IN-PROCESS | D320: 1 | E320: Traveler Printed (15) | F320: 46112.357 | G320: QT17IA14.50 | H320: QTNSN095288A.X11 | I320: =VLOOKUP(G320,Sheet2!A:D,4,0) -> 12
A321: YK261400022 | B321: NOT-IN-PROCESS | C321: NOT-IN-PROCESS | D321: 1 | E321: Traveler Printed (15) | F321: 46112.357 | G321: QT17IA14.50 | H321: QTNSN095288A.X11 | I321: =VLOOKUP(G321,Sheet2!A:D,4,0) -> 12 | J321: With RRH
A322: YK261400023 | B322: NOT-IN-PROCESS | C322: NOT-IN-PROCESS | D322: 1 | E322: Traveler Printed (15) | F322: 46112.357 | G322: QT17IA14.50 | H322: QTNSN095288A.X11 | I322: =VLOOKUP(G322,Sheet2!A:D,4,0) -> 12 | J322: Failed
A323: YK261400024 | B323: NOT-IN-PROCESS | C323: NOT-IN-PROCESS | D323: 1 | E323: Traveler Printed (15) | F323: 46112.357 | G323: QT17IA14.50 | H323: QTNSN095288A.X11 | I323: =VLOOKUP(G323,Sheet2!A:D,4,0) -> 12 | J323: Failed
A324: YK261400025 | B324: NOT-IN-PROCESS | C324: NOT-IN-PROCESS | D324: 1 | E324: Traveler Printed (15) | F324: 46112.357 | G324: QT17IA14.50 | H324: QTNSN095288A.X11 | I324: =VLOOKUP(G324,Sheet2!A:D,4,0) -> 12
A325: YK261400026 | B325: NOT-IN-PROCESS | C325: NOT-IN-PROCESS | D325: 1 | E325: Traveler Printed (15) | F325: 46112.357 | G325: QT17IA14.50 | H325: QTNSN095288A.X11 | I325: =VLOOKUP(G325,Sheet2!A:D,4,0) -> 12
A326: YK261400027 | B326: NOT-IN-PROCESS | C326: NOT-IN-PROCESS | D326: 1 | E326: Traveler Printed (15) | F326: 46112.357 | G326: QT17IA14.50 | H326: QTNSN095288A.X11 | I326: =VLOOKUP(G326,Sheet2!A:D,4,0) -> 12
A327: YK261400028 | B327: NOT-IN-PROCESS | C327: NOT-IN-PROCESS | D327: 1 | E327: Traveler Printed (15) | F327: 46112.357 | G327: QT17IA14.50 | H327: QTNSN095288A.X11 | I327: =VLOOKUP(G327,Sheet2!A:D,4,0) -> 12
A328: YK261400029 | B328: NOT-IN-PROCESS | C328: NOT-IN-PROCESS | D328: 1 | E328: Traveler Printed (15) | F328: 46112.357 | G328: QT17IA14.50 | H328: QTNSN095288A.X11 | I328: =VLOOKUP(G328,Sheet2!A:D,4,0) -> 12
A329: YK261400030 | B329: NOT-IN-PROCESS | C329: NOT-IN-PROCESS | D329: 1 | E329: Traveler Printed (15) | F329: 46112.357 | G329: QT17IA14.50 | H329: QTNSN095288A.X11 | I329: =VLOOKUP(G329,Sheet2!A:D,4,0) -> 12
A330: YK261400031 | B330: NOT-IN-PROCESS | C330: NOT-IN-PROCESS | D330: 1 | E330: Traveler Printed (15) | F330: 46112.357 | G330: QT17IA14.50 | H330: QTNSN095288A.X11 | I330: =VLOOKUP(G330,Sheet2!A:D,4,0) -> 12
...

Sheet Need to confirm
A1: Serial Number | B1: Workstation | C1: Process | D1: Qty | E1: Unit Status | F1: Last Updated | G1: Work order | H1: Part number | I1: Priority | J1: Comments | K1: das | L1: asdas | M1: Column1
A2: YK261100798 | B2: DBG1 Debug Test | C2: Xfr to Debug Test | D2: 1 | E2: In Repair Hold (29) | F2: 46106.404 | G2: QT17IA14.31 | H2: QTNSN095288A.X11 | I2: 6 | M2: Stencil or Manual ??
A3: YK261100797 | B3: DBG1 Debug Test | C3: Xfr to Debug Test | D3: 1 | E3: In Repair Hold (29) | F3: 46106.405 | G3: QT17IA14.31 | H3: QTNSN095288A.X11 | I3: 6 | M3: Retest with new limits
A4: YK261100792 | B4: DBG1 Debug Test | C4: Xfr to Debug Test | D4: 1 | E4: In Repair Hold (29) | F4: 46106.402 | G4: QT17IA14.31 | H4: QTNSN095288A.X11 | I4: 6
A5: YK261100788 | B5: DBG1 Debug Test | C5: Xfr to Debug Test | D5: 1 | E5: In Repair Hold (29) | F5: 46106.41 | G5: QT17IA14.31 | H5: QTNSN095288A.X11 | I5: 6
A6: YK261100773 | B6: DBG1 Debug Test | C6: Xfr to Debug Test | D6: 1 | E6: In Repair Hold (29) | F6: 46107.547 | G6: QT17IA14.31 | H6: QTNSN095288A.X11 | I6: 6
A7: YK261100772 | B7: DBG1 Debug Test | C7: Xfr to Debug Test | D7: 1 | E7: In Repair Hold (29) | F7: 46107.516 | G7: QT17IA14.31 | H7: QTNSN095288A.X11 | I7: 6 | M7: Stencil or Manual ??

Sheet Sheet6
A1: Serial Number | B1: Workstation | C1: Process | D1: Qty | E1: Unit Status | F1: Last Updated | G1: Work order | H1: Part number | I1: Priority | J1: Comments | K1: das | L1: asdas
A2: YK261100017 | B2: FUN1 Func Test | C2: Functional Test-1 | D2: 1 | E2: On The Line (20) | F2: 46111.406 | G2: QT17IA24.00 | H2: QTNSN095266A.X11 | I2: 9
A3: YK261100015 | B3: FUN1 Func Test | C3: Functional Test-1 | D3: 1 | E3: On The Line (20) | F3: 46107.561 | G3: QT17IA24.00 | H3: QTNSN095266A.X11 | I3: 9

Sheet Summary
A1: Row Labels | B1: Work order | C1: Part number | D1: Process | E1: Unit Status | F1: Count of Qty
A2: 1 | B2: QT17IA14.00 | C2: QTNSN095288A.X03 | D2: NOT-IN-PROCESS | E2: Unit Component (60) | F2: 64
D3: Shipped to Customer | E3: Shipped (40) | F3: 5
D4: Xfr to Debug Test | E4: In Repair Hold (29) | F4: 1
A5: 2 | B5: QT17IA14.10 | C5: QTNSN095289A.X03 | D5: Functional Test-1 | E5: On The Line (20) | F5: 2
D6: NOT-IN-PROCESS | E6: Unit Component (60) | F6: 64
D7: Shipped to Customer | E7: Shipped (40) | F7: 14
A8: 3 | B8: QT17IA23.00 | C8: QTNSN095266A.X02 | D8: NOT-IN-PROCESS | E8: Unit Component (60) | F8: 11
D9: Shipped to Customer | E9: Shipped (40) | F9: 7
D10: Xfr to Debug Test | E10: In Repair Hold (29) | F10: 7
A11: 4 | B11: QT17IA43.00 | C11: QTNSN476757A.X02 | D11: Complete | E11: Finished (30) | F11: 3
D12: Shipped to Customer | E12: Shipped (40) | F12: 16
D13: Assembly 1 - 1B | E13: On The Line Hold (28) | F13: 1
A14: 5 | B14: QT17IA14.30 | C14: QTNSN095288A.X11 | D14: Complete | E14: Finished (30) | F14: 34
D15: Functional Test-1 | E15: On The Line (20) | F15: 1 | G15: Need to update status in 42 Q | H15: Tested and paassed
D16: Xfr to Debug Test | E16: In Repair Hold (29) | F16: 2 | G16: Need to update 3 up sheet
A17: 6 | B17: QT17IA14.31 | C17: QTNSN095288A.X11 | D17: Complete | E17: Finished (30) | F17: 25
D18: Functional Test-1 | E18: On The Line (20) | F18: 2 | G18: Need to retest
D19: Shipped to Customer | E19: Shipped (40) | F19: 4 | O19: =TODAY()+71 -> 46186
D20: Xfr to Debug Test | E20: In Repair Hold (29) | F20: 6 | G20: 3 up
A21: 7 | B21: QT17IA14.20 | C21: QTNSN095289A.X11 | D21: Complete | E21: Finished (30) | F21: 22
D22: Functional Test-1 | E22: On The Line (20) | F22: 2
D23: Shipped to Customer | E23: Shipped (40) | F23: 1
D24: Xfr to Debug Test | E24: In Repair Hold (29) | F24: 12
A25: 8 | B25: QT17IA14.21 | C25: QTNSN095289A.X11 | D25: Complete | E25: Finished (30) | F25: 32
D26: Shipped to Customer | E26: Shipped (40) | F26: 3
D27: Xfr to Debug Test | E27: In Repair Hold (29) | F27: 2
A28: 9 | B28: QT17IA24.00 | C28: QTNSN095266A.X11 | D28: Functional Test-1 | E28: On The Line (20) | F28: 2 | G28: Final QC Signs off on this- Engineering mode
D29: Shipped to Customer | E29: Shipped (40) | F29: 1
D30: Assembly 1 - 1B | E30: On The Line (20) | F30: 1
D31: AOI Inspect | E31: On The Line (20) | F31: 2
D32: Inspect SMT2 | E32: On The Line (20) | F32: 1
D33: 5DX | E33: On The Line (20) | F33: 11
D34: AOR2 AOI Repair S2 | E34: In Repair (25) | F34: 7
D35: AOI | E35: On The Line (20) | F35: 2
D36: RWK SMT2 | E36: In Repair (25) | F36: 1
D37: AOR1 AOI Repair S1 | E37: In Repair (25) | F37: 1
A38: 10 | B38: QT17IA44.00 | C38: QTNSN476757A.X11 | D38: NOT-IN-PROCESS | E38: Traveler Printed (15) | F38: 14
D39: Xfr to T/L Assembly | E39: On The Line Hold (28) | F39: 1
A40: 12 | B40: QT17IA14.50 | C40: QTNSN095288A.X11 | D40: NOT-IN-PROCESS | E40: Traveler Printed (15) | F40: 131
...

Sheet Sheet2
A1: Unique id | B1: Part number | C1: Qty | D1: Priority | E1: STI
A2: QT17IA14.00 | B2: QTNSN095288A.X03 | C2: 70 | D2: 1
A3: QT17IA14.10 | B3: QTNSN095289A.X03 | C3: 80 | D3: 2
A4: QT17IA23.00 | B4: QTNSN095266A.X02 | C4: 25 | D4: 3 | K4: Test fixtures
A5: QT17IA43.00 | B5: QTNSN476757A.X02 | C5: 20 | D5: 4 | K5: RRH Fixture | L5: 2 Fixtures | M5: Electrical Plans required for the testers
A6: QT17IA14.30 | B6: QTNSN095288A.X11 | C6: 37 | D6: 5 | E6: eSTI PE53499. PE53575 add a note to remove shield and pre-drive, and for 840135A to use X1 version. PE53746 sent 03/13 | K6: 1 unit tester | L6: Need to be hooked up powered on | M6: Layout Plan- Sebastian
A7: QT17IA14.31 | B7: QTNSN095288A.X11 | C7: 37 | D7: 6 | E7: eSTI PE53499. PE53575 add a note to remove shield and pre-drive, and for 840135A to use X1 version. PE53684 sent 03/13 | K7: RTWP Tester | L7: Need to be hooked up powered on
A8: QT17IA14.20 | B8: QTNSN095289A.X11 | C8: 37 | D8: 7 | E8: STI PE53554 for 840135A to use X1 version. PE53499, . | K8: LBTS | L8: Need to be powered up
A9: QT17IA14.21 | B9: QTNSN095289A.X11 | C9: 37 | D9: 8 | E9: PE53571 for 17IA14.21,add a note to remove shield and pre-driver. Create new eSTI for 17IA14.20 adding the same note. NEW PE53611 | K9: 3D chasis weight | L9: Right next to the TRX Tester rack
A10: QT17IA24.00 | B10: QTNSN095266A.X11 | C10: 29 | D10: 9 | E10: PE53604, PE53707,PE53847 | K10: Filter | L10: Need to be delivered
A11: QT17IA44.00 | B11: QTNSN476757A.X11 | C11: 15 | D11: 10 | E11: PE53701
A12: QT17IA14.40 | B12: QTNSN095289A.X11 | C12: 124 | D12: 11 | E12: STI To be released | F12: Quote
A13: QT17IA14.50 | B13: QTNSN095289A.X11 | C13: 124 | D13: 12 | E13: PE53891 | F13: Quote
A14: QT17IA24.10 | B14: QTNSN095266A.X11 | C14: 36 | D14: 13 | E14: STI To be released | F14: Quote
A15: QT17IA44.10 | E15: STI To be released
