Workbook

Sheet Sheet9
A1: Process | B1: (Multiple Items) | K1: Process | L1: (Multiple Items)
A2: Program | B2: (All)
K3: Row Labels | L3: Sum of Qty
A4: Sum of Qty | B4: Column Labels | K4: 5DX1 SMT 5DX | L4: 242 | T4: AXFIA | U4: P3
A5: Row Labels | B5: PA Assembly | C5: TRX/PSU/BB Assembly | D5: Grand Total | J5: =D5-55 -> #VALUE! | K5: AOI1 AOI Inspect S1 | L5: 461 | T5: AXOLA | U5: P1
A6: 5DX1 SMT 5DX | B6: 326 | C6: 6 | D6: 332 | K6: AOI2 AOI Inspect S2 | L6: 14 | T6: AXOLBA | U6: P2
A7: 5DXR 5DX RWK | B7: 23 | C7: 5 | D7: 28 | K7: AOR1 AOI RWK S1 | L7: 38 | T7: AXOA | U7: P4
A8: AOI1 AOI Inspect S1 | B8: 281 | C8: 85 | D8: 366 | K8: AOR2 AOI RWK S2 | L8: 8
A9: AOI2 AOI Inspect S2 | C9: 6 | D9: 6 | K9: Grand Total | L9: 763
A10: AOR1 AOI RWK S1 | B10: 85 | C10: 1 | D10: 86
A11: AOR2 AOI RWK S2 | C11: 14 | D11: 14
A12: Grand Total | B12: 715 | C12: 117 | D12: 832
A19: Sum of Qty | B19: Column Labels
A20: Row Labels | B20: PA Assembly | C20: TRX/PSU/BB Assembly | D20: Grand Total
A21: 5DX1 SMT 5DX | B21: 112 | D21: 112
A22: 5DXR 5DX RWK | B22: 14 | D22: 14
A23: AOI1 AOI Inspect S1 | B23: 58 | C23: 29 | D23: 87
A24: AOI2 AOI Inspect S2 | C24: 15 | D24: 15
A25: AOR1 AOI RWK S1 | B25: 30 | D25: 30
A26: AOR2 AOI RWK S2 | C26: 1 | D26: 1
A27: Grand Total | B27: 214 | C27: 45 | D27: 259

Sheet Shop Order
A1: Serial Number | B1: Workstation | C1: Process | D1: Qty | E1: Unit Status | F1: Last Updated | G1: Work order | H1: Part number | I1: Priority | J1: UID | K1: Program | L1: Type | M1: Comments | N1: Shipping date | O1: asdas
A2: YK263403030 | B2: PACK Packout | C2: Packout | D2: 1 | E2: On The Line (20) | F2: 46283.349 | G2: QT17IA44.20 | H2: QTNSN476757A.X21 | I2: =VLOOKUP(G2,WO!A:J,10,0) -> 45 | J2: =MID(G2,3,9) -> 17IA44.20 | K2: =VLOOKUP(J2,WO!B:E,4,0) -> AXFIA | L2: =VLOOKUP(J2,WO!B:F,5,0) -> RRH Unit | M2: Pack out | N2: =_xlfn.XLOOKUP(A2,Shipped!I:I,Shipped!J:J) -> 46283
A3: YK263403032 | B3: PACK Packout | C3: Packout | D3: 1 | E3: On The Line (20) | F3: 46283.344 | G3: QT17IA44.20 | H3: QTNSN476757A.X21 | I3: =VLOOKUP(G3,WO!A:J,10,0) -> 45 | J3: =MID(G3,3,9) -> 17IA44.20 | K3: =VLOOKUP(J3,WO!B:E,4,0) -> AXFIA | L3: =VLOOKUP(J3,WO!B:F,5,0) -> RRH Unit | N3: =_xlfn.XLOOKUP(A3,Shipped!I:I,Shipped!J:J) -> 46283
A4: YK263403033 | B4: PACK Packout | C4: Packout | D4: 1 | E4: On The Line (20) | F4: 46283.355 | G4: QT17IA44.20 | H4: QTNSN476757A.X21 | I4: =VLOOKUP(G4,WO!A:J,10,0) -> 45 | J4: =MID(G4,3,9) -> 17IA44.20 | K4: =VLOOKUP(J4,WO!B:E,4,0) -> AXFIA | L4: =VLOOKUP(J4,WO!B:F,5,0) -> RRH Unit | N4: =_xlfn.XLOOKUP(A4,Shipped!I:I,Shipped!J:J) -> 46283
A5: YK263501067 | B5: PACK Packout | C5: Packout | D5: 1 | E5: On The Line (20) | F5: 46283.34 | G5: QT19BA42.00 | H5: QTNSN476971A.X12 | I5: =VLOOKUP(G5,WO!A:J,10,0) -> 44 | J5: =MID(G5,3,9) -> 19BA42.00 | K5: =VLOOKUP(J5,WO!B:E,4,0) -> AXOLBA | L5: =VLOOKUP(J5,WO!B:F,5,0) -> RRH Unit | N5: =_xlfn.XLOOKUP(A5,Shipped!I:I,Shipped!J:J) -> 46283
A6: YK263501068 | B6: FNLI Final Inspect | C6: Final Inspect-1 | D6: 1 | E6: On The Line (20) | F6: 46283.495 | G6: QT19BA42.00 | H6: QTNSN476971A.X12 | I6: =VLOOKUP(G6,WO!A:J,10,0) -> 44 | J6: =MID(G6,3,9) -> 19BA42.00 | K6: =VLOOKUP(J6,WO!B:E,4,0) -> AXOLBA | L6: =VLOOKUP(J6,WO!B:F,5,0) -> RRH Unit | N6: =_xlfn.XLOOKUP(A6,Shipped!I:I,Shipped!J:J) -> 46283
A7: YK263501072 | B7: PACK Packout | C7: Packout | D7: 1 | E7: On The Line (20) | F7: 46283.482 | G7: QT19BA42.00 | H7: QTNSN476971A.X12 | I7: =VLOOKUP(G7,WO!A:J,10,0) -> 44 | J7: =MID(G7,3,9) -> 19BA42.00 | K7: =VLOOKUP(J7,WO!B:E,4,0) -> AXOLBA | L7: =VLOOKUP(J7,WO!B:F,5,0) -> RRH Unit | N7: =_xlfn.XLOOKUP(A7,Shipped!I:I,Shipped!J:J) -> 46283
A8: YK263501074 | B8: PACK Packout | C8: Packout | D8: 1 | E8: On The Line (20) | F8: 46283.343 | G8: QT19BA42.00 | H8: QTNSN476971A.X12 | I8: =VLOOKUP(G8,WO!A:J,10,0) -> 44 | J8: =MID(G8,3,9) -> 19BA42.00 | K8: =VLOOKUP(J8,WO!B:E,4,0) -> AXOLBA | L8: =VLOOKUP(J8,WO!B:F,5,0) -> RRH Unit | N8: =_xlfn.XLOOKUP(A8,Shipped!I:I,Shipped!J:J) -> 46283
A9: YK263700002 | B9: PACK Packout | C9: Packout | D9: 1 | E9: On The Line (20) | F9: 46283.353 | G9: QT20LA42.00 | H9: QTNSN476797A.X11 | I9: =VLOOKUP(G9,WO!A:J,10,0) -> 57 | J9: =MID(G9,3,9) -> 20LA42.00 | K9: =VLOOKUP(J9,WO!B:E,4,0) -> AXOLA | L9: =VLOOKUP(J9,WO!B:F,5,0) -> RRH Unit | N9: =_xlfn.XLOOKUP(A9,Shipped!I:I,Shipped!J:J) -> 46283
A10: YK263700003 | B10: PACK Packout | C10: Packout | D10: 1 | E10: On The Line (20) | F10: 46283.481 | G10: QT20LA42.00 | H10: QTNSN476797A.X11 | I10: =VLOOKUP(G10,WO!A:J,10,0) -> 57 | J10: =MID(G10,3,9) -> 20LA42.00 | K10: =VLOOKUP(J10,WO!B:E,4,0) -> AXOLA | L10: =VLOOKUP(J10,WO!B:F,5,0) -> RRH Unit | N10: =_xlfn.XLOOKUP(A10,Shipped!I:I,Shipped!J:J) -> 46283
A11: YK263700005 | B11: FNLI Final Inspect | C11: Final Inspect-1 | D11: 1 | E11: On The Line (20) | F11: 46283.494 | G11: QT20LA42.00 | H11: QTNSN476797A.X11 | I11: =VLOOKUP(G11,WO!A:J,10,0) -> 57 | J11: =MID(G11,3,9) -> 20LA42.00 | K11: =VLOOKUP(J11,WO!B:E,4,0) -> AXOLA | L11: =VLOOKUP(J11,WO!B:F,5,0) -> RRH Unit | N11: =_xlfn.XLOOKUP(A11,Shipped!I:I,Shipped!J:J) -> 46283
A12: YK263501057 | B12: PACK Packout | C12: Packout | D12: 1 | E12: On The Line (20) | F12: 46268.459 | G12: QT19BA42.00 | H12: QTNSN476971A.X12 | I12: =VLOOKUP(G12,WO!A:J,10,0) -> 44 | J12: =MID(G12,3,9) -> 19BA42.00 | K12: =VLOOKUP(J12,WO!B:E,4,0) -> AXOLBA | L12: =VLOOKUP(J12,WO!B:F,5,0) -> RRH Unit | N12: =_xlfn.XLOOKUP(A12,Shipped!I:I,Shipped!J:J) -> 46274
A13: YK263501064 | B13: SHIP Shipping | C13: Shipped to Customer | D13: 1 | E13: Shipped (40) | F13: 46269.452 | G13: QT19BA42.00 | H13: QTNSN476971A.X12 | I13: =VLOOKUP(G13,WO!A:J,10,0) -> 44 | J13: =MID(G13,3,9) -> 19BA42.00 | K13: =VLOOKUP(J13,WO!B:E,4,0) -> AXOLBA | L13: =VLOOKUP(J13,WO!B:F,5,0) -> RRH Unit | N13: =_xlfn.XLOOKUP(A13,Shipped!I:I,Shipped!J:J) -> 46274
A14: YK261802219 | B14: CMP1 Complete | C14: Complete | D14: 1 | E14: Finished (30) | F14: 46218.535 | G14: QT17IA15.90 | H14: QTNSN095288A.X12 | I14: =VLOOKUP(G14,WO!A:J,10,0) -> 16 | J14: =MID(G14,3,9) -> 17IA15.90 | K14: =VLOOKUP(J14,WO!B:E,4,0) -> AXFIA | L14: =VLOOKUP(J14,WO!B:F,5,0) -> PA Assembly | N14: =_xlfn.XLOOKUP(A14,Shipped!I:I,Shipped!J:J) -> 46273
... A58: YK261400047 | B58: SHIP Shipping | C58: Shipped to Customer | D58: 1 | E58: Shipped (40) | F58: 46246.513 | G58: QT17IA14.50 | H58: QTNSN095288A.X11 | I58: =VLOOKUP(G58,WO!A:J,10,0) -> 11 | J58: =MID(G58,3,9) -> 17IA14.50 | K58: =VLOOKUP(J58,WO!B:E,4,0) -> AXFIA | L58: =VLOOKUP(J58,WO!B:F,5,0) -> PA Assembly | N58: =_xlfn.XLOOKUP(A58,Shipped!I:I,Shipped!J:J) -> 46254
A59: YK261400050 | B59: SHIP Shipping | C59: Shipped to Customer | D59: 1 | E59: Shipped (40) | F59: 46246.508 | G59: QT17IA14.50 | H59: QTNSN095288A.X11 | I59: =VLOOKUP(G59,WO!A:J,10,0) -> 11 | J59: =MID(G59,3,9) -> 17IA14.50 | K59: =VLOOKUP(J59,WO!B:E,4,0) -> AXFIA | L59: =VLOOKUP(J59,WO!B:F,5,0) -> PA Assembly | M59: Update to shipped | N59: =_xlfn.XLOOKUP(A59,Shipped!I:I,Shipped!J:J) -> 46254
A60: YK261400052 | B60: SHIP Shipping | C60: Shipped to Customer | D60: 1 | E60: Shipped (40) | F60: 46246.518 | G60: QT17IA14.50 | H60: QTNSN095288A.X11 | I60: =VLOOKUP(G60,WO!A:J,10,0) -> 11 | J60: =MID(G60,3,9) -> 17IA14.50 | K60: =VLOOKUP(J60,WO!B:E,4,0) -> AXFIA | L60: =VLOOKUP(J60,WO!B:F,5,0) -> PA Assembly | N60: =_xlfn.XLOOKUP(A60,Shipped!I:I,Shipped!J:J) -> 46254
A61: YK261400056 | B61: FUN1 Func Test | C61: Functional Test-1 | D61: 1 | E61: On The Line (20) | F61: 46123.242 | G61: QT17IA14.50 | H61: QTNSN095288A.X11 | I61: =VLOOKUP(G61,WO!A:J,10,0) -> 11 | J61: =MID(G61,3,9) -> 17IA14.50 | K61: =VLOOKUP(J61,WO!B:E,4,0) -> AXFIA | L61: =VLOOKUP(J61,WO!B:F,5,0) -> PA Assembly | N61: =_xlfn.XLOOKUP(A61,Shipped!I:I,Shipped!J:J) -> 46254
A62: YK261400059 | B62: SHIP Shipping | C62: Shipped to Customer | D62: 1 | E62: Shipped (40) | F62: 46246.508 | G62: QT17IA14.50 | H62: QTNSN095288A.X11 | I62: =VLOOKUP(G62,WO!A:J,10,0) -> 11 | J62: =MID(G62,3,9) -> 17IA14.50 | K62: =VLOOKUP(J62,WO!B:E,4,0) -> AXFIA | L62: =VLOOKUP(J62,WO!B:F,5,0) -> PA Assembly | N62: =_xlfn.XLOOKUP(A62,Shipped!I:I,Shipped!J:J) -> 46254
A63: YK261400078 | B63: SHIP Shipping | C63: Shipped to Customer | D63: 1 | E63: Shipped (40) | F63: 46246.511 | G63: QT17IA14.50 | H63: QTNSN095288A.X11 | I63: =VLOOKUP(G63,WO!A:J,10,0) -> 11 | J63: =MID(G63,3,9) -> 17IA14.50 | K63: =VLOOKUP(J63,WO!B:E,4,0) -> AXFIA | L63: =VLOOKUP(J63,WO!B:F,5,0) -> PA Assembly | N63: =_xlfn.XLOOKUP(A63,Shipped!I:I,Shipped!J:J) -> 46254
A64: YK261400081 | B64: SHIP Shipping | C64: Shipped to Customer | D64: 1 | E64: Shipped (40) | F64: 46246.509 | G64: QT17IA14.50 | H64: QTNSN095288A.X11 | I64: =VLOOKUP(G64,WO!A:J,10,0) -> 11 | J64: =MID(G64,3,9) -> 17IA14.50 | K64: =VLOOKUP(J64,WO!B:E,4,0) -> AXFIA | L64: =VLOOKUP(J64,WO!B:F,5,0) -> PA Assembly | N64: =_xlfn.XLOOKUP(A64,Shipped!I:I,Shipped!J:J) -> 46254
A65: YK261400082 | B65: SHIP Shipping | C65: Shipped to Customer | D65: 1 | E65: Shipped (40) | F65: 46246.517 | G65: QT17IA14.50 | H65: QTNSN095288A.X11 | I65: =VLOOKUP(G65,WO!A:J,10,0) -> 11 | J65: =MID(G65,3,9) -> 17IA14.50 | K65: =VLOOKUP(J65,WO!B:E,4,0) -> AXFIA | L65: =VLOOKUP(J65,WO!B:F,5,0) -> PA Assembly | N65: =_xlfn.XLOOKUP(A65,Shipped!I:I,Shipped!J:J) -> 46254
A66: YK261400085 | B66: SHIP Shipping | C66: Shipped to Customer | D66: 1 | E66: Shipped (40) | F66: 46246.512 | G66: QT17IA14.50 | H66: QTNSN095288A.X11 | I66: =VLOOKUP(G66,WO!A:J,10,0) -> 11 | J66: =MID(G66,3,9) -> 17IA14.50 | K66: =VLOOKUP(J66,WO!B:E,4,0) -> AXFIA | L66: =VLOOKUP(J66,WO!B:F,5,0) -> PA Assembly | N66: =_xlfn.XLOOKUP(A66,Shipped!I:I,Shipped!J:J) -> 46254
A67: YK261400088 | B67: SHIP Shipping | C67: Shipped to Customer | D67: 1 | E67: Shipped (40) | F67: 46246.509 | G67: QT17IA14.50 | H67: QTNSN095288A.X11 | I67: =VLOOKUP(G67,WO!A:J,10,0) -> 11 | J67: =MID(G67,3,9) -> 17IA14.50 | K67: =VLOOKUP(J67,WO!B:E,4,0) -> AXFIA | L67: =VLOOKUP(J67,WO!B:F,5,0) -> PA Assembly | N67: =_xlfn.XLOOKUP(A67,Shipped!I:I,Shipped!J:J) -> 46254
A68: YK261400089 | B68: SHIP Shipping | C68: Shipped to Customer | D68: 1 | E68: Shipped (40) | F68: 46246.515 | G68: QT17IA14.50 | H68: QTNSN095288A.X11 | I68: =VLOOKUP(G68,WO!A:J,10,0) -> 11 | J68: =MID(G68,3,9) -> 17IA14.50 | K68: =VLOOKUP(J68,WO!B:E,4,0) -> AXFIA | L68: =VLOOKUP(J68,WO!B:F,5,0) -> PA Assembly | N68: =_xlfn.XLOOKUP(A68,Shipped!I:I,Shipped!J:J) -> 46254
A69: YK261400091 | B69: SHIP Shipping | C69: Shipped to Customer | D69: 1 | E69: Shipped (40) | F69: 46246.516 | G69: QT17IA14.50 | H69: QTNSN095288A.X11 | I69: =VLOOKUP(G69,WO!A:J,10,0) -> 11 | J69: =MID(G69,3,9) -> 17IA14.50 | K69: =VLOOKUP(J69,WO!B:E,4,0) -> AXFIA | L69: =VLOOKUP(J69,WO!B:F,5,0) -> PA Assembly | N69: =_xlfn.XLOOKUP(A69,Shipped!I:I,Shipped!J:J) -> 46254
A70: YK261400102 | B70: SHIP Shipping | C70: Shipped to Customer | D70: 1 | E70: Shipped (40) | F70: 46246.518 | G70: QT17IA14.50 | H70: QTNSN095288A.X11 | I70: =VLOOKUP(G70,WO!A:J,10,0) -> 11 | J70: =MID(G70,3,9) -> 17IA14.50 | K70: =VLOOKUP(J70,WO!B:E,4,0) -> AXFIA | L70: =VLOOKUP(J70,WO!B:F,5,0) -> PA Assembly | N70: =_xlfn.XLOOKUP(A70,Shipped!I:I,Shipped!J:J) -> 46254
A71: YK261400103 | B71: SHIP Shipping | C71: Shipped to Customer | D71: 1 | E71: Shipped (40) | F71: 46246.518 | G71: QT17IA14.50 | H71: QTNSN095288A.X11 | I71: =VLOOKUP(G71,WO!A:J,10,0) -> 11 | J71: =MID(G71,3,9) -> 17IA14.50 | K71: =VLOOKUP(J71,WO!B:E,4,0) -> AXFIA | L71: =VLOOKUP(J71,WO!B:F,5,0) -> PA Assembly | N71: =_xlfn.XLOOKUP(A71,Shipped!I:I,Shipped!J:J) -> 46254
... A189: YK261600092 | B189: SHIP Shipping | C189: Shipped to Customer | D189: 1 | E189: Shipped (40) | F189: 46248.397 | G189: QT17IA14.40 | H189: QTNSN095289A.X11 | I189: =VLOOKUP(G189,WO!A:J,10,0) -> 12 | J189: =MID(G189,3,9) -> 17IA14.40 | K189: =VLOOKUP(J189,WO!B:E,4,0) -> AXFIA | L189: =VLOOKUP(J189,WO!B:F,5,0) -> PA Assembly | N189: =_xlfn.XLOOKUP(A189,Shipped!I:I,Shipped!J:J) -> 46248
A190: YK261600094 | B190: SHIP Shipping | C190: Shipped to Customer | D190: 1 | E190: Shipped (40) | F190: 46248.371 | G190: QT17IA14.40 | H190: QTNSN095289A.X11 | I190: =VLOOKUP(G190,WO!A:J,10,0) -> 12 | J190: =MID(G190,3,9) -> 17IA14.40 | K190: =VLOOKUP(J190,WO!B:E,4,0) -> AXFIA | L190: =VLOOKUP(J190,WO!B:F,5,0) -> PA Assembly | M190: Update to shipped | N190: =_xlfn.XLOOKUP(A190,Shipped!I:I,Shipped!J:J) -> 46248
A191: YK261600095 | B191: SHIP Shipping | C191: Shipped to Customer | D191: 1 | E191: Shipped (40) | F191: 46246.56 | G191: QT17IA14.40 | H191: QTNSN095289A.X11 | I191: =VLOOKUP(G191,WO!A:J,10,0) -> 12 | J191: =MID(G191,3,9) -> 17IA14.40 | K191: =VLOOKUP(J191,WO!B:E,4,0) -> AXFIA | L191: =VLOOKUP(J191,WO!B:F,5,0) -> PA Assembly | N191: =_xlfn.XLOOKUP(A191,Shipped!I:I,Shipped!J:J) -> 46248
A192: YK261600097 | B192: SHIP Shipping | C192: Shipped to Customer | D192: 1 | E192: Shipped (40) | F192: 46245.594 | G192: QT17IA14.40 | H192: QTNSN095289A.X11 | I192: =VLOOKUP(G192,WO!A:J,10,0) -> 12 | J192: =MID(G192,3,9) -> 17IA14.40 | K192: =VLOOKUP(J192,WO!B:E,4,0) -> AXFIA | L192: =VLOOKUP(J192,WO!B:F,5,0) -> PA Assembly | N192: =_xlfn.XLOOKUP(A192,Shipped!I:I,Shipped!J:J) -> 46248
A193: YK261600098 | B193: SHIP Shipping | C193: Shipped to Customer | D193: 1 | E193: Shipped (40) | F193: 46248.377 | G193: QT17IA14.40 | H193: QTNSN095289A.X11 | I193: =VLOOKUP(G193,WO!A:J,10,0) -> 12 | J193: =MID(G193,3,9) -> 17IA14.40 | K193: =VLOOKUP(J193,WO!B:E,4,0) -> AXFIA | L193: =VLOOKUP(J193,WO!B:F,5,0) -> PA Assembly | N193: =_xlfn.XLOOKUP(A193,Shipped!I:I,Shipped!J:J) -> 46248
A194: YK261600099 | B194: SHIP Shipping | C194: Shipped to Customer | D194: 1 | E194: Shipped (40) | F194: 46245.593 | G194: QT17IA14.40 | H194: QTNSN095289A.X11 | I194: =VLOOKUP(G194,WO!A:J,10,0) -> 12 | J194: =MID(G194,3,9) -> 17IA14.40 | K194: =VLOOKUP(J194,WO!B:E,4,0) -> AXFIA | L194: =VLOOKUP(J194,WO!B:F,5,0) -> PA Assembly | N194: =_xlfn.XLOOKUP(A194,Shipped!I:I,Shipped!J:J) -> 46248
A195: YK261600101 | B195: SHIP Shipping | C195: Shipped to Customer | D195: 1 | E195: Shipped (40) | F195: 46248.366 | G195: QT17IA14.40 | H195: QTNSN095289A.X11 | I195: =VLOOKUP(G195,WO!A:J,10,0) -> 12 | J195: =MID(G195,3,9) -> 17IA14.40 | K195: =VLOOKUP(J195,WO!B:E,4,0) -> AXFIA | L195: =VLOOKUP(J195,WO!B:F,5,0) -> PA Assembly | N195: =_xlfn.XLOOKUP(A195,Shipped!I:I,Shipped!J:J) -> 46248
A196: YK261600102 | B196: SHIP Shipping | C196: Shipped to Customer | D196: 1 | E196: Shipped (40) | F196: 46248.389 | G196: QT17IA14.40 | H196: QTNSN095289A.X11 | I196: =VLOOKUP(G196,WO!A:J,10,0) -> 12 | J196: =MID(G196,3,9) -> 17IA14.40 | K196: =VLOOKUP(J196,WO!B:E,4,0) -> AXFIA | L196: =VLOOKUP(J196,WO!B:F,5,0) -> PA Assembly | N196: =_xlfn.XLOOKUP(A196,Shipped!I:I,Shipped!J:J) -> 46248
A197: YK261600103 | B197: SHIP Shipping | C197: Shipped to Customer | D197: 1 | E197: Shipped (40) | F197: 46248.396 | G197: QT17IA14.40 | H197: QTNSN095289A.X11 | I197: =VLOOKUP(G197,WO!A:J,10,0) -> 12 | J197: =MID(G197,3,9) -> 17IA14.40 | K197: =VLOOKUP(J197,WO!B:E,4,0) -> AXFIA | L197: =VLOOKUP(J197,WO!B:F,5,0) -> PA Assembly | N197: =_xlfn.XLOOKUP(A197,Shipped!I:I,Shipped!J:J) -> 46248
A198: YK261600104 | B198: SHIP Shipping | C198: Shipped to Customer | D198: 1 | E198: Shipped (40) | F198: 46248.382 | G198: QT17IA14.40 | H198: QTNSN095289A.X11 | I198: =VLOOKUP(G198,WO!A:J,10,0) -> 12 | J198: =MID(G198,3,9) -> 17IA14.40 | K198: =VLOOKUP(J198,WO!B:E,4,0) -> AXFIA | L198: =VLOOKUP(J198,WO!B:F,5,0) -> PA Assembly | N198: =_xlfn.XLOOKUP(A198,Shipped!I:I,Shipped!J:J) -> 46248
A199: YK261600105 | B199: SHIP Shipping | C199: Shipped to Customer | D199: 1 | E199: Shipped (40) | F199: 46246.522 | G199: QT17IA14.40 | H199: QTNSN095289A.X11 | I199: =VLOOKUP(G199,WO!A:J,10,0) -> 12 | J199: =MID(G199,3,9) -> 17IA14.40 | K199: =VLOOKUP(J199,WO!B:E,4,0) -> AXFIA | L199: =VLOOKUP(J199,WO!B:F,5,0) -> PA Assembly | N199: =_xlfn.XLOOKUP(A199,Shipped!I:I,Shipped!J:J) -> 46248
A200: YK261600106 | B200: SHIP Shipping | C200: Shipped to Customer | D200: 1 | E200: Shipped (40) | F200: 46248.396 | G200: QT17IA14.40 | H200: QTNSN095289A.X11 | I200: =VLOOKUP(G200,WO!A:J,10,0) -> 12 | J200: =MID(G200,3,9) -> 17IA14.40 | K200: =VLOOKUP(J200,WO!B:E,4,0) -> AXFIA | L200: =VLOOKUP(J200,WO!B:F,5,0) -> PA Assembly | N200: =_xlfn.XLOOKUP(A200,Shipped!I:I,Shipped!J:J) -> 46248
...

Sheet Summary
A1: Program | B1: AXOLA
A2: Type | B2: (All)
A3: Work order | B3: (All)
A5: Row Labels | B5: Part number | C5: Process | D5: Unit Status | E5: Count of Qty
A6: 17 | B6: QTNSN095290A.X02 | C6: Shipped to Customer | D6: Shipped (40) | E6: 14
A7: 18 | B7: QTNSN095291A.X02 | C7: Shipped to Customer | D7: Shipped (40) | E7: 14
A8: 19 | B8: QTNSN095286A.X02 | C8: NOT-IN-PROCESS | D8: Unit Component (60) | E8: 8
C9: Shipped to Customer | D9: Shipped (40) | E9: 2
A10: 27 | B10: QTNSN095290A.X02 | C10: Complete | D10: Finished (30) | E10: 4
C11: NOT-IN-PROCESS | D11: Unit Component (60) | E11: 57
C12: Shipped to Customer | D12: Shipped (40) | E12: 1
C13: Xfr to Debug Test | D13: In Repair Hold (29) | E13: 1
C14: Rework-1 | D14: In Repair (25) | E14: 1
A15: 28 | B15: QTNSN095291A.X02 | C15: Complete | D15: Finished (30) | E15: 5
C16: NOT-IN-PROCESS | D16: Unit Component (60) | E16: 55
C17: Shipped to Customer | D17: Shipped (40) | E17: 1
C18: Xfr to Debug Test | D18: In Repair Hold (29) | E18: 1
C19: Rework-1 | D19: In Repair (25) | E19: 2
A20: 29 | B20: QTNSN476797A.X11 | C20: Shipped to Customer | D20: Shipped (40) | E20: 8
A21: 38 | B21: QTNSN095803A.X03 | C21: NOT-IN-PROCESS | D21: Unit Skeleton (64) | E21: 10
C22: Shipped to Customer | D22: Shipped (40) | E22: 4
A23: 39 | B23: QTNSN095290A.X02 | C23: Shipped to Customer | D23: Shipped (40) | E23: 13
A24: 40 | B24: QTNSN095291A.X02 | C24: Complete | D24: Finished (30) | E24: 1
C25: Shipped to Customer | D25: Shipped (40) | E25: 12
A26: 46 | B26: QTNSN095939A.X01 | C26: Shipped to Customer | D26: Shipped (40) | E26: 13
A27: 50 | B27: QTNSN095286A.X14 | C27: Functional Test-1 | D27: On The Line (20) | E27: 1
C28: NOT-IN-PROCESS | D28: Unit Component (60) | E28: 4
C29: Shipped to Customer | D29: Shipped (40) | E29: 2
C30: Xfr to Debug Test | D30: In Repair Hold (29) | E30: 3
A31: 53 | B31: QTNSN095286A.X14 | C31: NOT-IN-PROCESS | D31: Unit Component (60) | E31: 1
C32: AOI Inspect | D32: On The Line (20) | E32: 42
C33: Inspect SMT2 | D33: On The Line (20) | E33: 1
C34: RWK Paired Brd Insp | D34: In Repair Hold (29) | E34: 1
A35: 57 | B35: QTNSN476797A.X11 | C35: Functional Test-1 | D35: On The Line (20) | E35: 1
C36: NOT-IN-PROCESS | D36: Traveler Printed (15) | E36: 37
C37: Debug Test-1 | D37: In Repair (25) | E37: 1
C38: Xfr to T/L Assembly | D38: On The Line Hold (28) | E38: 2
C39: Assembly 1-1B | D39: On The Line Hold (28) | E39: 1
C40: Packout | D40: On The Line (20) | E40: 2
C41: Final Inspect-1 | D41: On The Line (20) | E41: 1
...

Sheet Post Meeting Follow Ups 9-21

Sheet 18-Sep-26 Shipment Log
A1: Serial Number | B1: Unique ID | C1: QT | D1: Item | E1: Description | F1: Product | G1: Nokia PO | H1: Order No | I1: Invoice # | J1: Ship Qty | K1: Ship Date | L1: Packing slip # | M1: AWB# | N1: Ship to City | O1: Month | P1: Unit/TRX/PA | Q1: Program | R1: Week
A2: YK263403032 | B2: 17IA44.20 | C2: QT17IA44.20 | D2: QTNSN476757A.X21 | E2: QT T/L UNIT ASSY, 476757A | F2: AXFIA | G2: 52046555 | H2: 1810097 | I2: 1002797353 | J2: 1 | K2: 46283 | L2: 77240880 | M2: S01554112 | N2: Coppell, TX | O2: 2026 - Sep | P2: Unit | Q2: RF8 | R2: 38
A3: YK263403033 | B3: 17IA44.20 | C3: QT17IA44.20 | D3: QTNSN476757A.X21 | E3: QT T/L UNIT ASSY, 476757A | F3: AXFIA | G3: 52046555 | H3: 1810097 | I3: 1002797353 | J3: 1 | K3: 46283 | L3: 77240880 | M3: S01554112 | N3: Coppell, TX | O3: 2026 - Sep | P3: Unit | Q3: RF8 | R3: 38
A4: YK263403030 | B4: 17IA44.20 | C4: QT17IA44.20 | D4: QTNSN476757A.X21 | E4: QT T/L UNIT ASSY, 476757A | F4: AXFIA | G4: 52046556 | H4: 1810095 | I4: 1002797354 | J4: 1 | K4: 46283 | L4: 77240883 | M4: S01554112 | N4: Coppell, TX | O4: 2026 - Sep | P4: Unit | Q4: RF8 | R4: 38
A5: YK263501068 | B5: 19BA42.00 | C5: QT19BA42.00 | D5: QTNSN476971A.X12 | E5: QT TL UNIT ASSY, 476971A. | F5: AXOLBA | G5: 52076745 | H5: 1810253 | I5: 1002797484 | J5: 1 | K5: 46283 | L5: 77241228 | M5: S01554224 | N5: Coppell, TX | O5: 2026 - Sep | P5: Unit | Q5: RF8 | R5: 38
A6: YK263501072 | B6: 19BA42.00 | C6: QT19BA42.00 | D6: QTNSN476971A.X12 | E6: QT TL UNIT ASSY, 476971A. | F6: AXOLBA | G6: 52076746 | H6: 1810251 | I6: 1002797477 | J6: 1 | K6: 46283 | L6: 77241223 | M6: S01554224 | N6: Coppell, TX | O6: 2026 - Sep | P6: Unit | Q6: RF8 | R6: 38
A7: YK263501074 | B7: 19BA42.00 | C7: QT19BA42.00 | D7: QTNSN476971A.X12 | E7: QT TL UNIT ASSY, 476971A. | F7: AXOLBA | G7: 52081142 | H7: 1810290 | I7: 1002797355 | J7: 1 | K7: 46283 | L7: 77240876 | M7: S01554112 | N7: Coppell, TX | O7: 2026 - Sep | P7: Unit | Q7: RF8 | R7: 38
A8: YK263501067 | B8: 19BA42.00 | C8: QT19BA42.00 | D8: QTNSN476971A.X12 | E8: QT TL UNIT ASSY, 476971A. | F8: AXOLBA | G8: 52081142 | H8: 1810290 | I8: 1002797355 | J8: 1 | K8: 46283 | L8: 77240876 | M8: S01554112 | N8: Coppell, TX | O8: 2026 - Sep | P8: Unit | Q8: RF8 | R8: 38
A9: YK263700002 | B9: 20LA41.00 | C9: QT20LA41.00 | D9: QTNSN476797A.X11 | E9: QT T/L UNIT ASSY, 476797A | F9: AXOLA | G9: 52123156 | H9: 1810515 | I9: 1002797481 | J9: 1 | K9: 46283 | L9: 77241271 | M9: S01554224 | N9: Coppell, TX | O9: 2026 - Sep | P9: Unit | Q9: RF8 | R9: 38
A10: YK263700003 | B10: 20LA41.00 | C10: QT20LA41.00 | D10: QTNSN476797A.X11 | E10: QT T/L UNIT ASSY, 476797A | F10: AXOLA | G10: 52123164 | H10: 1810520 | I10: 1002797478 | J10: 1 | K10: 46283 | L10: 77241238 | M10: S01554224 | N10: Coppell, TX | O10: 2026 - Sep | P10: Unit | Q10: RF8 | R10: 38
A11: YK263700005 | B11: 20LA41.00 | C11: QT20LA41.00 | D11: QTNSN476797A.X11 | E11: QT T/L UNIT ASSY, 476797A | F11: AXOLA | G11: 52123164 | H11: 1810520 | I11: 1002797478 | J11: 1 | K11: 46283 | L11: 77241238 | M11: S01554224 | N11: Coppell, TX | O11: 2026 - Sep | P11: Unit | Q11: RF8 | R11: 38

Sheet Shipped
A1: Serial Number | B1: Ship Date | I1: Serial Number | J1: Shipping date
A2: YK262700652 | B2: 46230 | I2: YK263403032 | J2: 46283
A3: YK262700643 | B3: 46230 | I3: YK263403033 | J3: 46283
A4: YK262700652 | B4: 46248 | I4: YK263403030 | J4: 46283
A5: YK262700643 | B5: 46248 | I5: YK263501068 | J5: 46283
A6: YK261100764 | B6: 46248 | I6: YK263501072 | J6: 46283
A7: YK261400112 | B7: 46248 | I7: YK263501074 | J7: 46283
A8: YK261400076 | B8: 46248 | I8: YK263501067 | J8: 46283
A9: YK261400107 | B9: 46248 | I9: YK263700002 | J9: 46283
A10: YK261400027 | B10: 46248 | I10: YK263700003 | J10: 46283
A11: YK261400132 | B11: 46248 | I11: YK263700005 | J11: 46283
A12: YK261400126 | B12: 46248 | I12: PCS Part | J12: 46282
A13: YK261400111 | B13: 46248 | I13: YK263501057 | J13: 46274
... A230: YK261600091 | B230: 46254 | I230: YK261400025 | J230: 46248
I231: YK261400026 | J231: 46248
I232: YK261400027 | J232: 46248
I233: YK261400031 | J233: 46248
I234: YK261400035 | J234: 46248
I235: YK261400039 | J235: 46248
I236: YK261400040 | J236: 46248
I237: YK261400041 | J237: 46248
I238: YK261400045 | J238: 46248
I239: YK261400046 | J239: 46248
I240: YK261400054 | J240: 46248
I241: YK261400064 | J241: 46248
I242: YK261400074 | J242: 46248
... I595: YK260400003 | J595: 46058

Sheet WO
A1: Unique id | C1: WO | E1: Program | F1: Type | G1: Part number | H1: Desc | I1: Qty | J1: Priority | K1: STI | L1: STI/ Comments | M1: Quote
A2: QT17IA14.00 | B2: =MID(A2,3,9) -> 17IA14.00 | C2: WIP | D2: =VLOOKUP(A2,'[1]Plan - US NPI'!$C$6:$E$192,3,0) -> #N/A | E2: AXFIA | F2: PA Assembly | G2: QTNSN095288A.X03 | H2: #N/A | I2: 70 | J2: 1 | R2: Mh lot codes to MRB
A3: QT17IA14.10 | B3: =MID(A3,3,9) -> 17IA14.10 | C3: WIP | D3: =VLOOKUP(A3,'[1]Plan - US NPI'!$C$6:$E$192,3,0) -> #N/A | E3: AXFIA | F3: PA Assembly | G3: QTNSN095289A.X03 | H3: #N/A | I3: 80 | J3: 2 | R3: Solder paste Qtys
A4: QT17IA23.00 | B4: =MID(A4,3,9) -> 17IA23.00 | C4: WIP | D4: =VLOOKUP(A4,'[1]Plan - US NPI'!$C$6:$E$192,3,0) -> #N/A | E4: AXFIA | F4: TRX/PSU/BB Assembly | G4: QTNSN095266A.X02 | H4: #N/A | I4: 25 | J4: 3
A5: QT17IA43.00 | B5: =MID(A5,3,9) -> 17IA43.00 | C5: WIP | D5: =VLOOKUP(A5,'[1]Plan - US NPI'!$C$6:$E$192,3,0) -> #N/A | E5: AXFIA | F5: RRH | G5: QTNSN476757A.X02 | H5: #N/A | I5: 20 | J5: 4
A6: QT17IA14.30 | B6: =MID(A6,3,9) -> 17IA14.30 | C6: WIP | D6: =VLOOKUP(A6,'[1]Plan - US NPI'!$C$6:$E$192,3,0) -> #N/A | E6: =VLOOKUP($A6,'[2]Plan - US NPI'!$C$6:$K$191,3,0) -> AXFIA | F6: =VLOOKUP($A6,'[2]Plan - US NPI'!$C$6:$K$191,9,0) -> PA Assembly | G6: QTNSN095288A.X11 | H6: QT PA ASSY, 095288A. REV X11, B25 PA ASSEMBLY FOR AXFIA/AXFIB | I6: 37 | J6: 5 | L6: eSTI PE53499. PE53575 add a note to remove shield and pre-drive, and for 840135A to use X1 version. PE53746 sent 03/13
A7: QT17IA14.31 | B7: =MID(A7,3,9) -> 17IA14.31 | C7: WIP | D7: =VLOOKUP(A7,'[1]Plan - US NPI'!$C$6:$E$192,3,0) -> #N/A | E7: =VLOOKUP($A7,'[2]Plan - US NPI'!$C$6:$K$191,3,0) -> AXFIA | F7: =VLOOKUP($A7,'[2]Plan - US NPI'!$C$6:$K$191,9,0) -> PA Assembly | G7: QTNSN095288A.X11 | H7: QT PA ASSY, 095288A. REV X11, B25 PA ASSEMBLY FOR AXFIA/AXFIB | I7: 37 | J7: 6 | L7: eSTI PE53499. PE53575 add a note to remove shield and pre-drive, and for 840135A to use X1 version. PE53684 sent 03/13
A8: QT17IA14.20 | B8: =MID(A8,3,9) -> 17IA14.20 | C8: WIP | D8: =VLOOKUP(A8,'[1]Plan - US NPI'!$C$6:$E$192,3,0) -> #N/A | E8: =VLOOKUP($A8,'[2]Plan - US NPI'!$C$6:$K$191,3,0) -> AXFIA | F8: =VLOOKUP($A8,'[2]Plan - US NPI'!$C$6:$K$191,9,0) -> PA Assembly | G8: QTNSN095289A.X11 | H8: QT PA ASSY, 095289A. REV X11, B66 PA ASSEMBLY FOR AXFIA/AXFIB | I8: 37 | J8: 7 | L8: STI PE53554 for 840135A to use X1 version. PE53499, .
A9: QT17IA14.21 | B9: =MID(A9,3,9) -> 17IA14.21 | C9: WIP | D9: =VLOOKUP(A9,'[1]Plan - US NPI'!$C$6:$E$192,3,0) -> #N/A | E9: =VLOOKUP($A9,'[2]Plan - US NPI'!$C$6:$K$191,3,0) -> AXFIA | F9: =VLOOKUP($A9,'[2]Plan - US NPI'!$C$6:$K$191,9,0) -> PA Assembly | G9: QTNSN095289A.X11 | H9: QT PA ASSY, 095289A. REV X11, B66 PA ASSEMBLY FOR AXFIA/AXFIB | I9: 37 | J9: 8 | L9: PE53571 for 17IA14.21,add a note to remove shield and pre-driver. Create new eSTI for 17IA14.20 adding the same note. NEW PE53611
A10: QT17IA24.00 | B10: =MID(A10,3,9) -> 17IA24.00 | C10: WIP | D10: =VLOOKUP(A10,'[1]Plan - US NPI'!$C$6:$E$192,3,0) -> #N/A | E10: AXFIA | F10: TRX/PSU/BB Assembly | G10: QTNSN095266A.X11 | H10: QT TRX ASSY, 095266A. REV X11, TRX ASSEMBLY FOR AXFIA | I10: 29 | J10: 9 | L10: PE53604, PE53707,PE53847
A11: QT17IA44.00 | B11: =MID(A11,3,9) -> 17IA44.00 | C11: WIP | D11: =VLOOKUP(A11,'[1]Plan - US NPI'!$C$6:$E$192,3,0) -> #N/A | E11: AXFIA | F11: RRH | G11: QTNSN476757A.X11 | H11: RRH X11 | I11: 15 | J11: 10 | L11: PE53701
A12: QT17IA14.50 | B12: =MID(A12,3,9) -> 17IA14.50 | C12: WIP | D12: =VLOOKUP(A12,'[1]Plan - US NPI'!$C$6:$E$192,3,0) -> #N/A | E12: =VLOOKUP($A12,'[2]Plan - US NPI'!$C$6:$K$191,3,0) -> AXFIA | F12: =VLOOKUP($A12,'[2]Plan - US NPI'!$C$6:$K$191,9,0) -> PA Assembly | G12: QTNSN095288A.X11 | H12: QT PA ASSY, 095288A. REV X11, B25 PA ASSEMBLY FOR AXFIA/AXFIB | I12: 124 | J12: 11 | L12: PE53891
A13: QT17IA14.40 | B13: =MID(A13,3,9) -> 17IA14.40 | C13: WIP | D13: =VLOOKUP(A13,'[1]Plan - US NPI'!$C$6:$E$192,3,0) -> #N/A | E13: =VLOOKUP($A13,'[2]Plan - US NPI'!$C$6:$K$191,3,0) -> AXFIA | F13: =VLOOKUP($A13,'[2]Plan - US NPI'!$C$6:$K$191,9,0) -> PA Assembly | G13: QTNSN095289A.X11 | H13: QT PA ASSY, 095289A. REV X11, B66 PA ASSEMBLY FOR AXFIA/AXFIB | I13: 124 | J13: 12 | L13: PE54018
A14: QT17IA24.10 | B14: =MID(A14,3,9) -> 17IA24.10 | C14: WIP | D14: =VLOOKUP(A14,'[1]Plan - US NPI'!$C$6:$E$192,3,0) -> #N/A | E14: =VLOOKUP($A14,'[2]Plan - US NPI'!$C$6:$K$191,3,0) -> AXFIA | F14: =VLOOKUP($A14,'[2]Plan - US NPI'!$C$6:$K$191,9,0) -> TRX/PSU/BB Assembly | G14: QTNSN095266A.X12 | H14: QT TRX ASSY, 095266A. REV X12, TRX ASSEMBLY FOR AXFIA | I14: 41 | J14: 13 | L14: X12 Bom released - PE54073
A15: QT17IA44.10 | B15: =MID(A15,3,9) -> 17IA44.10 | C15: WIP | D15: =VLOOKUP(A15,'[1]Plan - US NPI'!$C$6:$E$192,3,0) -> #N/A | E15: =VLOOKUP($A15,'[2]Plan - US NPI'!$C$6:$K$191,3,0) -> AXFIA | F15: =VLOOKUP($A15,'[2]Plan - US NPI'!$C$6:$K$191,9,0) -> RRH Unit | G15: QTNSN476757A.X12 | H15: QT T/L UNIT ASSY, 476757A. REV X12, AXFIA AirScale RRH 4T8R n25/66 720W | I15: 30 | J15: 14 | L15: Esti releasesed- Release wo- PE54404- Wo released 29-May-26 | Min of 15 units next week | Work order complete
A16: QT17IA15.80 | B16: =MID(A16,3,9) -> 17IA15.80 | C16: WIP | D16: =VLOOKUP(A16,'[1]Plan - US NPI'!$C$6:$E$192,3,0) -> #N/A | E16: AXFIA | F16: PA Assembly | G16: QTNSN095289A.X12 | H16: QT PA ASSY, 095289A. REV X12, B66 PA ASSEMBLY FOR AXFIA/AXFIB | I16: 62 | J16: 15 | L16: New PWB- Order 2 sets of stencils- new profile board needed - New profile needed - Need STI- Checkplots being worked - PE54185
A17: QT17IA15.90 | B17: =MID(A17,3,9) -> 17IA15.90 | C17: WIP | D17: =VLOOKUP(A17,'[1]Plan - US NPI'!$C$6:$E$192,3,0) -> #N/A | E17: =VLOOKUP($A17,'[2]Plan - US NPI'!$C$6:$K$191,3,0) -> AXFIA | F17: =VLOOKUP($A17,'[2]Plan - US NPI'!$C$6:$K$191,9,0) -> PA Assembly | G17: QTNSN095288A.X12 | H17: QT PA ASSY, 095288A. REV X12, B25 PA ASSEMBLY FOR AXFIA/AXFIB | I17: 62 | J17: 16 | L17: New PWB- Order 2 sets of stencils- new profile board needed - New profile needed - Need STI- Stencil 04/23- PE54164 | Q17: 46139
A18: QT19BA11.00 | B18: =MID(A18,3,9) -> 19BA11.00 | C18: WIP | D18: =VLOOKUP(A18,'[1]Plan - US NPI'!$C$6:$E$192,3,0) -> #N/A | E18: =VLOOKUP($A18,'[2]Plan - US NPI'!$C$6:$K$191,3,0) -> AXOLA | F18: =VLOOKUP($A18,'[2]Plan - US NPI'!$C$6:$K$191,9,0) -> PA Assembly | G18: QTNSN095290A.X02 | H18: QT PA ASSY, 095290A. REV X02, B71 PA ASSEMBLY FOR AXOLBA | I18: 14 | J18: 17 | L18: Stencils due on the 27- Apr- No Esti
A19: QT19BA11.10 | B19: =MID(A19,3,9) -> 19BA11.10 | C19: WIP | D19: =VLOOKUP(A19,'[1]Plan - US NPI'!$C$6:$E$192,3,0) -> #N/A | E19: =VLOOKUP($A19,'[2]Plan - US NPI'!$C$6:$K$191,3,0) -> AXOLA | F19: =VLOOKUP($A19,'[2]Plan - US NPI'!$C$6:$K$191,9,0) -> PA Assembly | G19: QTNSN095291A.X02 | H19: QT PA ASSY, 095291A. REV X02, B85 PA ASSEMBLY FOR AXOLBA | I19: 14 | J19: 18 | L19: Stencils due on the 27- Apr- No Esti- Tracking# 707296329356
A20: QT20LA21.00 | B20: =MID(A20,3,9) -> 20LA21.00 | C20: WIP | D20: =VLOOKUP(A20,'[1]Plan - US NPI'!$C$6:$E$192,3,0) -> #N/A | E20: =VLOOKUP($A20,'[2]Plan - US NPI'!$C$6:$K$191,3,0) -> AXOLA | F20: =VLOOKUP($A20,'[2]Plan - US NPI'!$C$6:$K$191,9,0) -> TRX/PSU/BB Assembly | G20: QTNSN095286A.X02 | H20: QT TRX ASSY, 095286A. REV X02, TRX ASSEMBLY FOR AXOLA | I20: 10 | J20: 19 | L20: New CP today - Check material
A21: QT17IA25.30 | B21: =MID(A21,3,9) -> 17IA25.30 | C21: WIP | D21: =VLOOKUP(A21,'[1]Plan - US NPI'!$C$6:$E$192,3,0) -> #N/A | E21: =VLOOKUP($A21,'[2]Plan - US NPI'!$C$6:$K$191,3,0) -> AXFIA | F21: =VLOOKUP($A21,'[2]Plan - US NPI'!$C$6:$K$191,9,0) -> TRX/PSU/BB Assembly | G21: QTNSN095266A.X12 | H21: QT TRX ASSY, 095266A. REV X12, TRX ASSEMBLY FOR AXFIA | I21: 47 | J21: 20 | L21: Kick off 21-May-26- ESTI -PE54408 - Released 29-May-26 | One more ESTI to be released | Stencil ETA 03-Jun-26 | PE54513- Work order relased 06/03
A22: QT17IA15.60 | B22: =MID(A22,3,9) -> 17IA15.60 | C22: WIP | D22: =VLOOKUP(A22,'[1]Plan - US NPI'!$C$6:$E$192,3,0) -> #N/A | E22: =VLOOKUP($A22,'[2]Plan - US NPI'!$C$6:$K$191,3,0) -> AXFIA | F22: =VLOOKUP($A22,'[2]Plan - US NPI'!$C$6:$K$191,9,0) -> PA Assembly | G22: QTNSN095289A.X12 | H22: QT PA ASSY, 095289A. REV X12, B66 PA ASSEMBLY FOR AXFIA/AXFIB | I22: 188 | J22: 21 | L22: Kick off 21-May-26- ESTI - PE54407- WO Released 29-May-26
A23: QT17IA15.70 | B23: =MID(A23,3,9) -> 17IA15.70 | C23: WIP | D23: =VLOOKUP(A23,'[1]Plan - US NPI'!$C$6:$E$192,3,0) -> #N/A | E23: =VLOOKUP($A23,'[2]Plan - US NPI'!$C$6:$K$191,3,0) -> AXFIA | F23: =VLOOKUP($A23,'[2]Plan - US NPI'!$C$6:$K$191,9,0) -> PA Assembly | G23: QTNSN095288A.X12 | H23: QT PA ASSY, 095288A. REV X12, B25 PA ASSEMBLY FOR AXFIA/AXFIB | I23: 188 | J23: 22 | L23: Kick off 21-May-26- ESTI - PE54405- WO Released 29-May-26
A24: QT17IA45.30 | B24: =MID(A24,3,9) -> 17IA45.30 | C24: WIP | D24: =VLOOKUP(A24,'[1]Plan - US NPI'!$C$6:$E$192,3,0) -> #N/A | E24: =VLOOKUP($A24,'[2]Plan - US NPI'!$C$6:$K$191,3,0) -> AXFIA | F24: =VLOOKUP($A24,'[2]Plan - US NPI'!$C$6:$K$191,9,0) -> RRH Unit | G24: QTNSN476757A.X12 | H24: QT T/L UNIT ASSY, 476757A. REV X12, AXFIA AirScale RRH 4T8R n25/66 720W | I24: 47 | J24: 23 | L24: PE54409 & PE54856 - Released 29-May-26_ need to release work order- Relased 15-Jun-26 | Rework on the Chassis | Committing 22 pcs for next week | P55306
A25: QT17IA45.40 | B25: =MID(A25,3,9) -> 17IA45.40 | C25: WIP | D25: =VLOOKUP(A25,'[1]Plan - US NPI'!$C$6:$E$192,3,0) -> #N/A | E25: AXFIA | F25: RRH Unit | G25: QTNSN476757A.X12 | H25: QT T/L UNIT ASSY, 476757A. REV X12, AXFIA AirScale RRH 4T8R n25/66 720W | I25: 11 | J25: 24 | L25: Kick off- ESTI PE54381 - WO released
A26: QT17IA15.95 | B26: =MID(A26,3,9) -> 17IA15.95 | C26: WIP | D26: =VLOOKUP(A26,'[1]Plan - US NPI'!$C$6:$E$192,3,0) -> #N/A | E26: =VLOOKUP($A26,'[2]Plan - US NPI'!$C$6:$K$191,3,0) -> AXFIA | F26: =VLOOKUP($A26,'[2]Plan - US NPI'!$C$6:$K$191,9,0) -> PA Assembly | G26: QTNSN095289A.X12 | H26: QT PA ASSY, 095289A. REV X12, B66 PA ASSEMBLY FOR AXFIA/AXFIB | I26: 140 | J26: 25 | L26: Stencils , same PWB, STI for Solder paste PE54356- requested to run on the 2oth of May | New profile needed for Different solder paste
A27: QT17IA15.96 | B27: =MID(A27,3,9) -> 17IA15.96 | C27: WIP | D27: =VLOOKUP(A27,'[1]Plan - US NPI'!$C$6:$E$192,3,0) -> #N/A | E27: =VLOOKUP($A27,'[2]Plan - US NPI'!$C$6:$K$191,3,0) -> AXFIA | F27: =VLOOKUP($A27,'[2]Plan - US NPI'!$C$6:$K$191,9,0) -> PA Assembly | G27: QTNSN095288A.X12 | H27: QT PA ASSY, 095288A. REV X12, B25 PA ASSEMBLY FOR AXFIA/AXFIB | I27: 140 | J27: 26 | L27: PE54357- Solder paste STI- Received | New profile needed for Different solder paste
A28: QT20LA12.00 | B28: =MID(A28,3,9) -> 20LA12.00 | C28: WIP | D28: =VLOOKUP(A28,'[1]Plan - US NPI'!$C$6:$E$192,3,0) -> #N/A | E28: =VLOOKUP($A28,'[2]Plan - US NPI'!$C$6:$K$191,3,0) -> AXOLA | F28: =VLOOKUP($A28,'[2]Plan - US NPI'!$C$6:$K$191,9,0) -> PA Assembly | G28: QTNSN095290A.X02 | H28: QT PA ASSY, 095290A. REV X02, B71 PA ASSEMBLY FOR AXOLBA | I28: 64 | J28: 27 | L28: Esti releasesed- PE54413- WO released 27-May-26- need profile approved
A29: QT20LA12.10 | B29: =MID(A29,3,9) -> 20LA12.10 | C29: WIP | D29: =VLOOKUP(A29,'[1]Plan - US NPI'!$C$6:$E$192,3,0) -> #N/A | E29: =VLOOKUP($A29,'[2]Plan - US NPI'!$C$6:$K$191,3,0) -> AXOLA | F29: =VLOOKUP($A29,'[2]Plan - US NPI'!$C$6:$K$191,9,0) -> PA Assembly | G29: QTNSN095291A.X02 | H29: QT PA ASSY, 095291A. REV X02, B85 PA ASSEMBLY FOR AXOLBA | I29: 64 | J29: 28 | L29: Esti releasesed- WO released 27-May-26- Need profile approved
A30: QT20LA41.00 | B30: =MID(A30,3,9) -> 20LA41.00 | C30: WIP | D30: =VLOOKUP(A30,'[1]Plan - US NPI'!$C$6:$E$192,3,0) -> #N/A | E30: =VLOOKUP($A30,'[2]Plan - US NPI'!$C$6:$K$191,3,0) -> AXOLA | F30: =VLOOKUP($A30,'[2]Plan - US NPI'!$C$6:$K$191,9,0) -> RRH Unit | G30: QTNSN476797A.X11 | H30: QT T/L UNIT ASSY, 476797A.REV X11, AXOLA AirScale RRH 4T4R n71/85 320W | I30: 8 | J30: 29 | L30: CTB- ESTI PE54470 | WO release today 03-Jun-26- Followed up on ESTI | TRX rework need to look at material | STI released -
A31: QT19BA21.00A | B31: =MID(A31,3,9) -> 19BA21.00 | C31: WIP | D31: =VLOOKUP(A31,'[1]Plan - US NPI'!$C$6:$E$192,3,0) -> #N/A | E31: AXOLBA | F31: TRX/PSU/BB Assembly | G31: QTNSN095804A.X11 | I31: 22 | J31: 30 | L31: Relased 06/12- Critical components | 2 pcs Skipping FT- Nokia to pick up | Parametric Data- * 8 boards need rework STI to be released- Cannot test | PE55020- Rework STI with 3 parts that we need to buy-Load independent demand- Rework quote 12 boards- Quote needed pull parts to Soka | M31: Quote sent
A32: QT19BA12.20 | B32: =MID(A32,3,9) -> 19BA12.20 | C32: WIP | D32: =VLOOKUP(A32,'[1]Plan - US NPI'!$C$6:$E$192,3,0) -> #N/A | E32: =VLOOKUP($A32,'[2]Plan - US NPI'!$C$6:$K$191,3,0) -> AXOLBA | F32: =VLOOKUP($A32,'[2]Plan - US NPI'!$C$6:$K$191,9,0) -> PA Assembly | G32: QTNSN095290A.X02 | I32: 32 | J32: 31 | L32: ESTI - Sac305 PE54542- Work order QT20LA12.00 increased to 64 units
A33: QT19BA12.30 | B33: =MID(A33,3,9) -> 19BA12.30 | C33: WIP | D33: =VLOOKUP(A33,'[1]Plan - US NPI'!$C$6:$E$192,3,0) -> #N/A | E33: =VLOOKUP($A33,'[2]Plan - US NPI'!$C$6:$K$191,3,0) -> AXOLBA | F33: =VLOOKUP($A33,'[2]Plan - US NPI'!$C$6:$K$191,9,0) -> PA Assembly | G33: QTNSN095291A.X02 | I33: 32 | J33: 32 | L33: ESTI - Sac305 PE54541- Work order QT20LA12.10 increased to 64 units
A34: QT19BA41.00 | B34: =MID(A34,3,9) -> 19BA41.00 | C34: WIP | D34: =VLOOKUP(A34,'[1]Plan - US NPI'!$C$6:$E$192,3,0) -> #N/A | E34: =VLOOKUP($A34,'[2]Plan - US NPI'!$C$6:$K$191,3,0) -> AXOLBA | F34: =VLOOKUP($A34,'[2]Plan - US NPI'!$C$6:$K$191,9,0) -> RRH Unit | G34: QTNSN476971A.X11 | I34: 8 | J34: 33 | L34: No ESTI_ Nokia checking -06/16 | Chassis and Filter check stock | ESTI to be released PE54770- Share costed bom- New CP To be loaded today | Assembly to be stopped| Commiting to 8 wk 31 | M34: Quote sent-20-Jul-26 | N34: Press plate and Carriers - Delivered from CNC
A35: QT17IA24.20 | B35: =MID(A35,3,9) -> 17IA24.20 | C35: WIP | D35: =VLOOKUP(A35,'[1]Plan - US NPI'!$C$6:$E$192,3,0) -> #N/A | E35: =VLOOKUP($A35,'[2]Plan - US NPI'!$C$6:$K$191,3,0) -> AXFIA | F35: =VLOOKUP($A35,'[2]Plan - US NPI'!$C$6:$K$191,9,0) -> TRX/PSU/BB Assembly | G35: QTNSN095266A.X21 | I35: 29 | J35: 34 | K35: PE55517 | L35: RelaseD 06/15 | Old profile can be used- Review with Jose current issues on the X12 build | Same profile as AXOLBA | Waiting on Quote for rework
A36: QT17IA14.70 | B36: =MID(A36,3,9) -> 17IA14.70 | C36: WIP | D36: AXFIA | E36: AXFIA | F36: PA Assembly | G36: QTNSN095288A.X21 | I36: 74 | J36: 35 | K36: PE55485 | L36: PE54718 | PE54609 | PE54651 - Jose Stencils- Clean released 24-Jun-26- New ESTI for preform ( )| Any date for the Macom part P620299
A37: QT17IA14.60 | B37: =MID(A37,3,9) -> 17IA14.60 | C37: WIP | D37: =VLOOKUP(A37,'[1]Plan - US NPI'!$C$6:$E$192,3,0) -> #N/A | E37: =VLOOKUP($A37,'[2]Plan - US NPI'!$C$6:$K$191,3,0) -> AXFIA | F37: =VLOOKUP($A37,'[2]Plan - US NPI'!$C$6:$K$191,9,0) -> PA Assembly | G37: QTNSN095289A.X21 | I37: 74 | J37: 36 | L37: PE54719, PE54667 ,PE54611 STI- Jose Stencils- 3 shortages- not clean- 2 MTRs to Oulu, 1 Po from Distro-New STI to be released- Labels
A38: QT18OA21.00A | B38: =MID(A38,3,9) -> 18OA21.00 | C38: WIP | D38: Need to release work order | E38: AXOA | F38: TRX/PSU/BB Assembly | G38: QTNSN095725A.X11 | I38: 11 | J38: 37 | L38: need STI for X11 Bom | 4 STIS- PE54721,PE54724,PE55044,PE55107 & New STI to be released to run 4 boards without carriers on reflow | M38: Sent 21-Aug-26
A39: QT20LA22.00 | B39: =MID(A39,3,9) -> 20LA22.00 | C39: WIP | D39: =VLOOKUP(A39,'[1]Plan - US NPI'!$C$6:$E$192,3,0) -> #N/A | E39: =VLOOKUP($A39,'[2]Plan - US NPI'!$C$6:$K$191,3,0) -> AXOLA | F39: =VLOOKUP($A39,'[2]Plan - US NPI'!$C$6:$K$191,9,0) -> TRX/PSU/BB Assembly | G39: QTNSN095803A.X03 | I39: 14 | J39: 38 | L39: 1 component dif from the 804A.X11 Build | STI PE54748 - released today | Stencil Same as 804 | ON HOLD- YK262800086 Ship "as-is" to Salvador | Bom Update needed or STI| PE55140 to skip test and bom changes for the remainning boards | Close at 4 - new build for the remainning 095286A.xo2 | M39: Quote sent 13-July-26
A40: QT20LA15.93 | B40: =MID(A40,3,9) -> 20LA15.93 | C40: WIP | E40: =VLOOKUP($A40,'[2]Plan - US NPI'!$C$6:$K$191,3,0) -> AXOLA | F40: =VLOOKUP($A40,'[2]Plan - US NPI'!$C$6:$K$191,9,0) -> PA Assembly | G40: QTNSN095290A.X02 | I40: 13 | J40: 39 | L40: PE54809- Release Work order-PWB supplier info- Clean - Complete | M40: Quote sent 16-July-26
...

Sheet Rework
A1: TRX | D1: STI | E1: Work order | F1: Qty
A2: Program | B2: Comments | C2: Priorty | D2: STI | E2: Work order | F2: QTY | G2: Part number | H2: Qty not being reworked | I2: Time | J2: Total mins
A3: AXOLA | B3: No Aoi and 5 DX no Final QC, No testing | C3: P1 | D3: PE55549 | E3: 20LA23.10 | F3: 8 | G3: 095286A.X14 | H3: 2 units shipped | I3: 10 | J3: =F3*I3 -> 80
A4: AXOLBA | B4: NO Aoi and 5 DX , Final QC and Need to test the board | C4: P2 | D4: PE55526 | E4: 19BA22.00 | F4: 56 | G4: 095804A.X12 | H4: 8 units on Radios | I4: =10+20 -> 30 | J4: =F4*I4 -> 1680
A5: AXFIA | B5: NO Aoi and 5 DX , Final QC and Need to test the board | C5: P3 | D5: PE55522 | E5: 17IA24.30 | F5: 52 | G5: 095266A.X21 | I5: =10+20 -> 30 | J5: =F5*I5 -> 1560
A6: AXFIA | B6: NO Aoi and 5 DX , Final QC and Need to test the board | C6: P3 | D6: PE55517 | E6: 17IA24.20 | F6: 16 | G6: 095266A.X21 | H6: 10 shipped and 3 radios | I6: 30 | J6: =(4*30)+(12*10) -> 240
J7: =SUM(J3:J6) -> 3560
A13: Program | B13: Comments | C13: Priorty | D13: STI | E13: Work order | F13: QTY | G13: Part number | H13: Qty not being reworked | J13: Rework time | K13: Test time | L13: Total Time
A14: AXOLA | B14: No Aoi and 5 DX , Final QC, No testing | C14: P1 | D14: PE55549 | E14: 20LA23.10 | F14: 8 | G14: 095286A.X14 | H14: 2 units shipped | I14: 10 | J14: 80 | K14: 0 | L14: =J14+K14 -> 80
A15: AXOLBA | B15: NO Aoi and 5 DX , Final QC and Need to test the board | C15: P2 | D15: PE55526 | E15: 19BA22.00 | F15: 56 | G15: 095804A.X12 | H15: 8 units on Radios | I15: 10 | J15: 560 | K15: 200 | L15: =J15+K15 -> 760 | M15: 10 boards needs to be retested
A16: AXFIA | B16: NO Aoi and 5 DX , Final QC and Need to test the board | C16: P3 | D16: PE55522 | E16: 17IA24.30 | F16: 52 | G16: 095266A.X21 | I16: 10 | J16: 520 | K16: 0 | L16: =J16+K16 -> 520
A17: AXFIA | B17: NO Aoi and 5 DX , Final QC and Need to test the board( No need to test boards that have already passed) | C17: P3 | D17: PE55517 | E17: 17IA24.20 | F17: 16 | G17: 095266A.X21 | H17: 10 shipped and 3 radios | I17: 10 | J17: 160 | K17: 80 | L17: =J17+K17 -> 240 | M17: 4 boards need to be retested
J18: 1320 | K18: 280 | L18: =SUM(L14:L17) -> 1600
A26: Program | B26: Comments | C26: Priorty | D26: STI | E26: Work order | F26: QTY | H26: Part number | I26: Qty not being reworked | J26: Rework time | K26: Test time | L26: Total Time
A27: AXOLA | B27: No Aoi and 5 DX , Final QC, No testing | C27: P1 | D27: PE55549 | E27: 20LA23.10 | F27: 8 | G27: 8 | H27: 095286A.X14 | I27: 2 units shipped | J27: 80 | K27: 0 | L27: =J27+K27 -> 80
A28: AXOLBA | B28: NO Aoi and 5 DX , Final QC and Need to test the board | C28: P2 | D28: PE55526 | E28: 19BA22.00 | F28: 56 | H28: 095804A.X12 | I28: 8 units on Radios | J28: 560 | K28: 200 | L28: =J28+K28 -> 760 | M28: 10 boards needs to be retested
A29: AXFIA | B29: NO Aoi and 5 DX , Final QC and Need to test the board | C29: P3 | D29: PE55522 | E29: 17IA24.30 | F29: 52 | H29: 095266A.X21 | J29: 520 | K29: 0 | L29: =J29+K29 -> 520
A30: AXFIA | B30: NO Aoi and 5 DX , Final QC and Need to test the board( No need to test boards that have already passed) | C30: P3 | D30: PE55517 | E30: 17IA24.20 | F30: 16 | G30: 16 | H30: 095266A.X21 | I30: 10 shipped and 3 radios | J30: 160 | K30: 80 | L30: =J30+K30 -> 240 | M30: 4 boards need to be retested
J31: 1320 | K31: 280 | L31: =SUM(L27:L30) -> 1600
