Workbook

Sheet Shop Order
A1: Serial Number | B1: Workstation | C1: Process | D1: Qty | E1: Unit Status | F1: Last Updated | G1: Work order | H1: Part number | I1: Priority | J1: Comments | K1: Shipping date | L1: asdas
A2: YK260300123 | B2: NOT-IN-PROCESS | C2: NOT-IN-PROCESS | D2: 1 | E2: Unit Component (60) | F2: 46065.449 | G2: QT17IA14.00 | H2: QTNSN095288A.X03 | I2: =VLOOKUP(G2,Sheet2!A:D,4,0) -> 1
A3: YK260300124 | B3: NOT-IN-PROCESS | C3: NOT-IN-PROCESS | D3: 1 | E3: Unit Component (60) | F3: 46065.45 | G3: QT17IA14.00 | H3: QTNSN095288A.X03 | I3: =VLOOKUP(G3,Sheet2!A:D,4,0) -> 1
A4: YK260300125 | B4: NOT-IN-PROCESS | C4: NOT-IN-PROCESS | D4: 1 | E4: Unit Component (60) | F4: 46071.552 | G4: QT17IA14.00 | H4: QTNSN095288A.X03 | I4: =VLOOKUP(G4,Sheet2!A:D,4,0) -> 1
A5: YK260300126 | B5: NOT-IN-PROCESS | C5: NOT-IN-PROCESS | D5: 1 | E5: Unit Component (60) | F5: 46072.29 | G5: QT17IA14.00 | H5: QTNSN095288A.X03 | I5: =VLOOKUP(G5,Sheet2!A:D,4,0) -> 1
A6: YK260300127 | B6: NOT-IN-PROCESS | C6: NOT-IN-PROCESS | D6: 1 | E6: Unit Component (60) | F6: 46076.37 | G6: QT17IA14.00 | H6: QTNSN095288A.X03 | I6: =VLOOKUP(G6,Sheet2!A:D,4,0) -> 1
A7: YK260300128 | B7: SHIP Shipping | C7: Shipped to Customer | D7: 1 | E7: Shipped (40) | F7: 46112.311 | G7: QT17IA14.00 | H7: QTNSN095288A.X03 | I7: =VLOOKUP(G7,Sheet2!A:D,4,0) -> 1
A8: YK260300129 | B8: NOT-IN-PROCESS | C8: NOT-IN-PROCESS | D8: 1 | E8: Unit Component (60) | F8: 46065.432 | G8: QT17IA14.00 | H8: QTNSN095288A.X03 | I8: =VLOOKUP(G8,Sheet2!A:D,4,0) -> 1
A9: YK260300130 | B9: NOT-IN-PROCESS | C9: NOT-IN-PROCESS | D9: 1 | E9: Unit Component (60) | F9: 46071.282 | G9: QT17IA14.00 | H9: QTNSN095288A.X03 | I9: =VLOOKUP(G9,Sheet2!A:D,4,0) -> 1
A10: YK260300131 | B10: NOT-IN-PROCESS | C10: NOT-IN-PROCESS | D10: 1 | E10: Unit Component (60) | F10: 46076.374 | G10: QT17IA14.00 | H10: QTNSN095288A.X03 | I10: =VLOOKUP(G10,Sheet2!A:D,4,0) -> 1
A11: YK260300132 | B11: NOT-IN-PROCESS | C11: NOT-IN-PROCESS | D11: 1 | E11: Unit Component (60) | F11: 46065.431 | G11: QT17IA14.00 | H11: QTNSN095288A.X03 | I11: =VLOOKUP(G11,Sheet2!A:D,4,0) -> 1
A12: YK260300133 | B12: NOT-IN-PROCESS | C12: NOT-IN-PROCESS | D12: 1 | E12: Unit Component (60) | F12: 46072.486 | G12: QT17IA14.00 | H12: QTNSN095288A.X03 | I12: =VLOOKUP(G12,Sheet2!A:D,4,0) -> 1
A13: YK260300134 | B13: NOT-IN-PROCESS | C13: NOT-IN-PROCESS | D13: 1 | E13: Unit Component (60) | F13: 46065.449 | G13: QT17IA14.00 | H13: QTNSN095288A.X03 | I13: =VLOOKUP(G13,Sheet2!A:D,4,0) -> 1
... A158: YK260900007 | B158: NOT-IN-PROCESS | C158: NOT-IN-PROCESS | D158: 1 | E158: Unit Component (60) | F158: 46150.392 | G158: QT17IA14.20 | H158: QTNSN095289A.X11 | I158: =VLOOKUP(G158,Sheet2!A:D,4,0) -> 7
A159: YK260900008 | B159: SHIP Shipping | C159: Shipped to Customer | D159: 1 | E159: Shipped (40) | F159: 46123.268 | G159: QT17IA14.20 | H159: QTNSN095289A.X11 | I159: =VLOOKUP(G159,Sheet2!A:D,4,0) -> 7 | K159: 46105
A160: YK260900009 | B160: SHIP Shipping | C160: Shipped to Customer | D160: 1 | E160: Shipped (40) | F160: 46123.268 | G160: QT17IA14.20 | H160: QTNSN095289A.X11 | I160: =VLOOKUP(G160,Sheet2!A:D,4,0) -> 7 | K160: 46105
A161: YK260900010 | B161: RWK1 Repair Test | C161: Rework-1 | D161: 1 | E161: In Repair (25) | F161: 46135.342 | G161: QT17IA14.20 | H161: QTNSN095289A.X11 | I161: =VLOOKUP(G161,Sheet2!A:D,4,0) -> 7
A162: YK260900011 | B162: SHIP Shipping | C162: Shipped to Customer | D162: 1 | E162: Shipped (40) | F162: 46123.268 | G162: QT17IA14.20 | H162: QTNSN095289A.X11 | I162: =VLOOKUP(G162,Sheet2!A:D,4,0) -> 7 | K162: 46105
A163: YK260900012 | B163: SHIP Shipping | C163: Shipped to Customer | D163: 1 | E163: Shipped (40) | F163: 46154.373 | G163: QT17IA14.20 | H163: QTNSN095289A.X11 | I163: =VLOOKUP(G163,Sheet2!A:D,4,0) -> 7 | K163: 46156
A164: YK260900013 | B164: NOT-IN-PROCESS | C164: NOT-IN-PROCESS | D164: 1 | E164: Unit Component (60) | F164: 46153.505 | G164: QT17IA14.20 | H164: QTNSN095289A.X11 | I164: =VLOOKUP(G164,Sheet2!A:D,4,0) -> 7
A165: YK260900014 | B165: NOT-IN-PROCESS | C165: NOT-IN-PROCESS | D165: 1 | E165: Unit Component (60) | F165: 46140.311 | G165: QT17IA14.20 | H165: QTNSN095289A.X11 | I165: =VLOOKUP(G165,Sheet2!A:D,4,0) -> 7
A166: YK260900015 | B166: DBG1 Debug Test | C166: Xfr to Debug Test | D166: 1 | E166: In Repair Hold (29) | F166: 46128.38 | G166: QT17IA14.20 | H166: QTNSN095289A.X11 | I166: =VLOOKUP(G166,Sheet2!A:D,4,0) -> 7
A167: YK260900016 | B167: NOT-IN-PROCESS | C167: NOT-IN-PROCESS | D167: 1 | E167: Unit Component (60) | F167: 46146.277 | G167: QT17IA14.20 | H167: QTNSN095289A.X11 | I167: =VLOOKUP(G167,Sheet2!A:D,4,0) -> 7
A168: YK260900017 | B168: CMP1 Complete | C168: Complete | D168: 1 | E168: Finished (30) | F168: 46139.587 | G168: QT17IA14.20 | H168: QTNSN095289A.X11 | I168: =VLOOKUP(G168,Sheet2!A:D,4,0) -> 7
A169: YK260900018 | B169: SHIP Shipping | C169: Shipped to Customer | D169: 1 | E169: Shipped (40) | F169: 46123.268 | G169: QT17IA14.20 | H169: QTNSN095289A.X11 | I169: =VLOOKUP(G169,Sheet2!A:D,4,0) -> 7 | K169: 46097
A170: YK260900019 | B170: RWK3 Repair Test | C170: Rework-3 | D170: 1 | E170: In Repair (25) | F170: 46148.356 | G170: QT17IA14.20 | H170: QTNSN095289A.X11 | I170: =VLOOKUP(G170,Sheet2!A:D,4,0) -> 7
A171: YK260900020 | B171: NOT-IN-PROCESS | C171: NOT-IN-PROCESS | D171: 1 | E171: Unit Component (60) | F171: 46153.435 | G171: QT17IA14.20 | H171: QTNSN095289A.X11 | I171: =VLOOKUP(G171,Sheet2!A:D,4,0) -> 7
A172: YK260900021 | B172: FUN1 Func Test | C172: Functional Test-1 | D172: 1 | E172: On The Line (20) | F172: 46122.381 | G172: QT17IA14.20 | H172: QTNSN095289A.X11 | I172: =VLOOKUP(G172,Sheet2!A:D,4,0) -> 7
A173: YK260900022 | B173: CMP1 Complete | C173: Complete | D173: 1 | E173: Finished (30) | F173: 46123.559 | G173: QT17IA14.20 | H173: QTNSN095289A.X11 | I173: =VLOOKUP(G173,Sheet2!A:D,4,0) -> 7
A174: YK260900023 | B174: RWK1 Repair Test | C174: Rework-1 | D174: 1 | E174: In Repair (25) | F174: 46134.411 | G174: QT17IA14.20 | H174: QTNSN095289A.X11 | I174: =VLOOKUP(G174,Sheet2!A:D,4,0) -> 7
A175: YK260900024 | B175: CMP1 Complete | C175: Complete | D175: 1 | E175: Finished (30) | F175: 46128.361 | G175: QT17IA14.20 | H175: QTNSN095289A.X11 | I175: =VLOOKUP(G175,Sheet2!A:D,4,0) -> 7
A176: YK260900025 | B176: CMP1 Complete | C176: Complete | D176: 1 | E176: Finished (30) | F176: 46135.443 | G176: QT17IA14.20 | H176: QTNSN095289A.X11 | I176: =VLOOKUP(G176,Sheet2!A:D,4,0) -> 7
A177: YK260900026 | B177: RWK1 Repair Test | C177: Rework-1 | D177: 1 | E177: In Repair (25) | F177: 46134.363 | G177: QT17IA14.20 | H177: QTNSN095289A.X11 | I177: =VLOOKUP(G177,Sheet2!A:D,4,0) -> 7
A178: YK260900027 | B178: FUN1 Func Test | C178: Functional Test-1 | D178: 1 | E178: On The Line (20) | F178: 46122.382 | G178: QT17IA14.20 | H178: QTNSN095289A.X11 | I178: =VLOOKUP(G178,Sheet2!A:D,4,0) -> 7
A179: YK260900028 | B179: CMP1 Complete | C179: Complete | D179: 1 | E179: Finished (30) | F179: 46134.597 | G179: QT17IA14.20 | H179: QTNSN095289A.X11 | I179: =VLOOKUP(G179,Sheet2!A:D,4,0) -> 7
A180: YK260900029 | B180: SHIP Shipping | C180: Shipped to Customer | D180: 1 | E180: Shipped (40) | F180: 46123.268 | G180: QT17IA14.20 | H180: QTNSN095289A.X11 | I180: =VLOOKUP(G180,Sheet2!A:D,4,0) -> 7 | K180: 46097
A181: YK260900030 | B181: SHIP Shipping | C181: Shipped to Customer | D181: 1 | E181: Shipped (40) | F181: 46123.268 | G181: QT17IA14.20 | H181: QTNSN095289A.X11 | I181: =VLOOKUP(G181,Sheet2!A:D,4,0) -> 7 | K181: 46105
A182: YK260900031 | B182: SHIP Shipping | C182: Shipped to Customer | D182: 1 | E182: Shipped (40) | F182: 46123.268 | G182: QT17IA14.20 | H182: QTNSN095289A.X11 | I182: =VLOOKUP(G182,Sheet2!A:D,4,0) -> 7 | K182: 46112
A183: YK260900032 | B183: FUN1 Func Test | C183: Functional Test-1 | D183: 1 | E183: On The Line (20) | F183: 46115.654 | G183: QT17IA14.20 | H183: QTNSN095289A.X11 | I183: =VLOOKUP(G183,Sheet2!A:D,4,0) -> 7
A184: YK260900033 | B184: DBG1 Debug Test | C184: Xfr to Debug Test | D184: 1 | E184: In Repair Hold (29) | F184: 46128.399 | G184: QT17IA14.20 | H184: QTNSN095289A.X11 | I184: =VLOOKUP(G184,Sheet2!A:D,4,0) -> 7
...

Sheet Sheet1
A1: Serial Number | B1: Workstation | C1: Process | D1: Qty | E1: Unit Status | F1: Last Updated | G1: Work order | H1: Part number | I1: Priority | J1: Comments | K1: Shipping date | L1: asdas
A2: YK261900003 | B2: XRAY | C2: XRAY DAGE | D2: 1 | E2: On The Line (20) | F2: 46154.709 | G2: QT19BA11.00 | H2: QTNSN095290A.X02 | I2: 19

Sheet Sheet3
A1: Serial Number | B1: Workstation | C1: Process | D1: Qty | E1: Unit Status | F1: Last Updated | G1: Work order | H1: Part number | I1: Priority | J1: Comments | K1: Shipping date | L1: asdas
A2: YK261900025 | B2: PBAI Inspect | C2: PBA Inspection | D2: 1 | E2: On The Line (20) | F2: 46157.368 | G2: QT19BA11.10 | H2: QTNSN095291A.X02 | I2: 20

Sheet Sheet4
A1: Serial Number | B1: Workstation | C1: Process | D1: Qty | E1: Unit Status | F1: Last Updated | G1: Work order | H1: Part number | I1: Priority | J1: Comments | K1: Shipping date | L1: asdas
A2: YK261900027 | B2: RWK2 Repair Test | C2: Rework-2 | D2: 1 | E2: In Repair (25) | F2: 46157.369 | G2: QT19BA11.10 | H2: QTNSN095291A.X02 | I2: 20
A3: YK261900015 | B3: RWK2 Repair Test | C3: Rework-2 | D3: 1 | E3: In Repair (25) | F3: 46156.595 | G3: QT19BA11.10 | H3: QTNSN095291A.X02 | I3: 20

Sheet Sheet5
A1: Serial Number | B1: Workstation | C1: Process | D1: Qty | E1: Unit Status | F1: Last Updated | G1: Work order | H1: Part number | I1: Priority | J1: Comments | K1: Shipping date | L1: asdas
A2: YK261700038 | B2: CMP1 Complete | C2: Complete | D2: 1 | E2: Finished (30) | F2: 46162.347 | G2: QT17IA24.10 | H2: QTNSN095266A.X12 | I2: 13
A3: YK261700024 | B3: CMP1 Complete | C3: Complete | D3: 1 | E3: Finished (30) | F3: 46162.366 | G3: QT17IA24.10 | H3: QTNSN095266A.X12 | I3: 13
A4: YK261700019 | B4: CMP1 Complete | C4: Complete | D4: 1 | E4: Finished (30) | F4: 46162.322 | G4: QT17IA24.10 | H4: QTNSN095266A.X12 | I4: 13

Sheet Sheet6
A1: Serial Number | B1: Workstation | C1: Process | D1: Qty | E1: Unit Status | F1: Last Updated | G1: Work order | H1: Part number | I1: Priority | J1: Comments | K1: Shipping date | L1: asdas
A2: YK261700041 | B2: FUN1 Func Test | C2: Functional Test-1 | D2: 1 | E2: On The Line (20) | F2: 46162.336 | G2: QT17IA24.10 | H2: QTNSN095266A.X12 | I2: 13
A3: YK261700039 | B3: FUN1 Func Test | C3: Functional Test-1 | D3: 1 | E3: On The Line (20) | F3: 46162.265 | G3: QT17IA24.10 | H3: QTNSN095266A.X12 | I3: 13
A4: YK261700036 | B4: FUN1 Func Test | C4: Functional Test-1 | D4: 1 | E4: On The Line (20) | F4: 46162.249 | G4: QT17IA24.10 | H4: QTNSN095266A.X12 | I4: 13
A5: YK261700032 | B5: FUN1 Func Test | C5: Functional Test-1 | D5: 1 | E5: On The Line (20) | F5: 46162.269 | G5: QT17IA24.10 | H5: QTNSN095266A.X12 | I5: 13
A6: YK261700028 | B6: FUN1 Func Test | C6: Functional Test-1 | D6: 1 | E6: On The Line (20) | F6: 46162.283 | G6: QT17IA24.10 | H6: QTNSN095266A.X12 | I6: 13

Sheet Sheet7
A1: Serial Number | B1: Workstation | C1: Process | D1: Qty | E1: Unit Status | F1: Last Updated | G1: Work order | H1: Part number | I1: Priority | J1: Comments | K1: Shipping date | L1: asdas
A2: YK261700033 | B2: DBG1 Debug Test | C2: Xfr to Debug Test | D2: 1 | E2: In Repair Hold (29) | F2: 46162.371 | G2: QT17IA24.10 | H2: QTNSN095266A.X12 | I2: 13
A3: YK261700031 | B3: DBG1 Debug Test | C3: Xfr to Debug Test | D3: 1 | E3: In Repair Hold (29) | F3: 46162.285 | G3: QT17IA24.10 | H3: QTNSN095266A.X12 | I3: 13
A4: YK261700022 | B4: DBG1 Debug Test | C4: Xfr to Debug Test | D4: 1 | E4: In Repair Hold (29) | F4: 46162.369 | G4: QT17IA24.10 | H4: QTNSN095266A.X12 | I4: 13
A5: YK261700005 | B5: DBG1 Debug Test | C5: Xfr to Debug Test | D5: 1 | E5: In Repair Hold (29) | F5: 46162.275 | G5: QT17IA24.10 | H5: QTNSN095266A.X12 | I5: 13
A6: YK261700002 | B6: DBG1 Debug Test | C6: Xfr to Debug Test | D6: 1 | E6: In Repair Hold (29) | F6: 46162.305 | G6: QT17IA24.10 | H6: QTNSN095266A.X12 | I6: 13

Sheet Sheet8
A1: Serial Number | B1: Workstation | C1: Process | D1: Qty | E1: Unit Status | F1: Last Updated | G1: Work order | H1: Part number | I1: Priority | J1: Comments | K1: Shipping date | L1: asdas | M1: Column1
A2: YK261802240 | B2: RWK2 Repair Test | C2: Rework-2 | D2: 1 | E2: In Repair (25) | F2: 46157.63 | G2: QT17IA15.90 | H2: QTNSN095288A.X12 | I2: 17 | M2: GS07 - "Voids, Pinholes, Blowholes"Ref.Des:Z100
A3: YK261802239 | B3: RWK2 Repair Test | C3: Rework-2 | D3: 1 | E3: In Repair (25) | F3: 46161.351 | G3: QT17IA15.90 | H3: QTNSN095288A.X12 | I3: 17
A4: YK261802237 | B4: RWK2 Repair Test | C4: Rework-2 | D4: 1 | E4: In Repair (25) | F4: 46161.351 | G4: QT17IA15.90 | H4: QTNSN095288A.X12 | I4: 17
A5: YK261802235 | B5: RWK2 Repair Test | C5: Rework-2 | D5: 1 | E5: In Repair (25) | F5: 46161.351 | G5: QT17IA15.90 | H5: QTNSN095288A.X12 | I5: 17
A6: YK261802234 | B6: RWK2 Repair Test | C6: Rework-2 | D6: 1 | E6: In Repair (25) | F6: 46161.287 | G6: QT17IA15.90 | H6: QTNSN095288A.X12 | I6: 17
A7: YK261802233 | B7: RWK2 Repair Test | C7: Rework-2 | D7: 1 | E7: In Repair (25) | F7: 46160.646 | G7: QT17IA15.90 | H7: QTNSN095288A.X12 | I7: 17
A8: YK261802231 | B8: RWK2 Repair Test | C8: Rework-2 | D8: 1 | E8: In Repair (25) | F8: 46160.646 | G8: QT17IA15.90 | H8: QTNSN095288A.X12 | I8: 17
A9: YK261802229 | B9: RWK2 Repair Test | C9: Rework-2 | D9: 1 | E9: In Repair (25) | F9: 46160.646 | G9: QT17IA15.90 | H9: QTNSN095288A.X12 | I9: 17
A10: YK261802228 | B10: RWK2 Repair Test | C10: Rework-2 | D10: 1 | E10: In Repair (25) | F10: 46160.646 | G10: QT17IA15.90 | H10: QTNSN095288A.X12 | I10: 17
A11: YK261802227 | B11: RWK2 Repair Test | C11: Rework-2 | D11: 1 | E11: In Repair (25) | F11: 46157.63 | G11: QT17IA15.90 | H11: QTNSN095288A.X12 | I11: 17
A12: YK261802225 | B12: RWK2 Repair Test | C12: Rework-2 | D12: 1 | E12: In Repair (25) | F12: 46157.533 | G12: QT17IA15.90 | H12: QTNSN095288A.X12 | I12: 17
A13: YK261802224 | B13: RWK2 Repair Test | C13: Rework-2 | D13: 1 | E13: In Repair (25) | F13: 46160.492 | G13: QT17IA15.90 | H13: QTNSN095288A.X12 | I13: 17
A14: YK261802222 | B14: RWK2 Repair Test | C14: Rework-2 | D14: 1 | E14: In Repair (25) | F14: 46160.491 | G14: QT17IA15.90 | H14: QTNSN095288A.X12 | I14: 17
... A40: YK261802183 | B40: RWK2 Repair Test | C40: Rework-2 | D40: 1 | E40: In Repair (25) | F40: 46155.36 | G40: QT17IA15.90 | H40: QTNSN095288A.X12 | I40: 17

Sheet Summary
A1: Row Labels | B1: Work order | C1: Part number | D1: Process | E1: Unit Status | F1: Count of Qty | M1: Actions
A2: 1 | B2: QT17IA14.00 | C2: QTNSN095288A.X03 | D2: NOT-IN-PROCESS | E2: Unit Component (60) | F2: 64 | M2: TRX wrong part- Alvin 19 locations- Nico Working on rework instructions & Route
D3: Shipped to Customer | E3: Shipped (40) | F3: 6 | M3: Doc control to release deviation
A4: 2 | B4: QT17IA14.10 | C4: QTNSN095289A.X03 | D4: NOT-IN-PROCESS | E4: Unit Component (60) | F4: 64
D5: Shipped to Customer | E5: Shipped (40) | F5: 16
A6: 3 | B6: QT17IA23.00 | C6: QTNSN095266A.X02 | D6: NOT-IN-PROCESS | E6: Unit Component (60) | F6: 11
D7: Shipped to Customer | E7: Shipped (40) | F7: 7
D8: Xfr to Debug Test | E8: In Repair Hold (29) | F8: 7
A9: 4 | B9: QT17IA43.00 | C9: QTNSN476757A.X02 | D9: Shipped to Customer | E9: Shipped (40) | F9: 20
A10: 5 | B10: QT17IA14.30 | C10: QTNSN095288A.X11 | D10: Complete | E10: Finished (30) | F10: 13
D11: Functional Test-1 | E11: On The Line (20) | F11: 2
D12: NOT-IN-PROCESS | E12: Unit Component (60) | F12: 11
D13: Shipped to Customer | E13: Shipped (40) | F13: 5
D14: Xfr to Debug Test | E14: In Repair Hold (29) | F14: 2
D15: UNTT | E15: On The Line (20) | F15: 1
D16: Rework-1 | E16: In Repair (25) | F16: 2
D17: Debug Test-1 | E17: In Repair (25) | F17: 1
A18: 6 | B18: QT17IA14.31 | C18: QTNSN095288A.X11 | D18: Complete | E18: Finished (30) | F18: 12
D19: Functional Test-1 | E19: On The Line (20) | F19: 1
D20: NOT-IN-PROCESS | E20: Unit Component (60) | F20: 12
D21: Shipped to Customer | E21: Shipped (40) | F21: 6
D22: Xfr to Debug Test | E22: In Repair Hold (29) | F22: 3
D23: Rework-1 | E23: In Repair (25) | F23: 1
D24: Rework-3 | E24: In Repair (25) | F24: 2
A25: 7 | B25: QT17IA14.20 | C25: QTNSN095289A.X11 | D25: Complete | E25: Finished (30) | F25: 5
D26: Functional Test-1 | E26: On The Line (20) | F26: 5
D27: NOT-IN-PROCESS | E27: Unit Component (60) | F27: 8
D28: Shipped to Customer | E28: Shipped (40) | F28: 9
D29: Xfr to Debug Test | E29: In Repair Hold (29) | F29: 4
D30: Rework-1 | E30: In Repair (25) | F30: 3
D31: Rework-3 | E31: In Repair (25) | F31: 3
A32: 8 | B32: QT17IA14.21 | C32: QTNSN095289A.X11 | D32: Complete | E32: Finished (30) | F32: 1
D33: Functional Test-1 | E33: On The Line (20) | F33: 3
D34: NOT-IN-PROCESS | E34: Unit Component (60) | F34: 20
D35: Shipped to Customer | E35: Shipped (40) | F35: 9
D36: Xfr to Debug Test | E36: In Repair Hold (29) | F36: 4
A37: 9 | B37: QT17IA24.00 | C37: QTNSN095266A.X11 | D37: Complete | E37: Finished (30) | F37: 9 | G37: Parametric data- Hot !!
D38: Functional Test-1 | E38: On The Line (20) | F38: 1
D39: NOT-IN-PROCESS | E39: Unit Component (60) | F39: 15
D40: Shipped to Customer | E40: Shipped (40) | F40: 3
...

Sheet Sheet2
A1: Unique id | B1: Part number | C1: Qty | D1: Priority | E1: STI/ Comments
A2: QT17IA14.00 | B2: QTNSN095288A.X03 | C2: 70 | D2: 1 | K2: Mh lot codes to MRB
A3: QT17IA14.10 | B3: QTNSN095289A.X03 | C3: 80 | D3: 2 | K3: Solder paste Qtys
A4: QT17IA23.00 | B4: QTNSN095266A.X02 | C4: 25 | D4: 3
A5: QT17IA43.00 | B5: QTNSN476757A.X02 | C5: 20 | D5: 4
A6: QT17IA14.30 | B6: QTNSN095288A.X11 | C6: 37 | D6: 5 | E6: eSTI PE53499. PE53575 add a note to remove shield and pre-drive, and for 840135A to use X1 version. PE53746 sent 03/13
A7: QT17IA14.31 | B7: QTNSN095288A.X11 | C7: 37 | D7: 6 | E7: eSTI PE53499. PE53575 add a note to remove shield and pre-drive, and for 840135A to use X1 version. PE53684 sent 03/13
A8: QT17IA14.20 | B8: QTNSN095289A.X11 | C8: 37 | D8: 7 | E8: STI PE53554 for 840135A to use X1 version. PE53499, .
A9: QT17IA14.21 | B9: QTNSN095289A.X11 | C9: 37 | D9: 8 | E9: PE53571 for 17IA14.21,add a note to remove shield and pre-driver. Create new eSTI for 17IA14.20 adding the same note. NEW PE53611
A10: QT17IA24.00 | B10: QTNSN095266A.X11 | C10: 29 | D10: 9 | E10: PE53604, PE53707,PE53847
A11: QT17IA44.00 | B11: QTNSN476757A.X11 | C11: 15 | D11: 10 | E11: PE53701
A12: QT17IA14.50 | B12: QTNSN095288A.X11 | C12: 124 | D12: 11 | E12: PE53891
A13: QT17IA14.40 | B13: QTNSN095289A.X11 | C13: 124 | D13: 12 | E13: PE54018
A14: QT17IA24.10 | B14: QTNSN095266A.X12 | C14: 41 | D14: 13 | E14: X12 Bom released - PE54073
A15: QT17IA44.10 | B15: QTNSN476757A.X12 | C15: 30 | D15: 14 | E15: Doc control to load bom 13-May-26
A16: QT19BA22.10A | B16: QTNSN095741A.X02 | C16: 27 | D16: 15 | E16: PE54044, PE54111- Stencil ETA 04/23
A17: QT19BA21.00 | B17: QTNSN095741A.X01 | C17: 10 | D17: 16 | E17: PE54033,PE54110- Stencil ETA 04/23
... A22: QT20LA21.00 | B22: QTNSN095286A.X02 | C22: 10 | D22: 21 | E22: PWB X6 | PE54313 to be cp'd rpleace P7000738 with P67
A23: QT17IA25.30 | B23: QTNSN095266A.X12 | C23: 47 | E23: Kick off today 21-May-26
A24: QT17IA15.60 | B24: QTNSN095289A.X12 | C24: 188 | E24: Kick off today 21-May-26
A25: QT17IA15.70 | B25: QTNSN095288A.X12 | C25: 188 | E25: Kick off today 21-May-26
A26: QT17IA45.30 | B26: QTNSN476757A.X12 | C26: 47
A27: QT17IA45.40 | B27: QTNSN476757A.X12 | C27: 11 | E27: Kick off- ESTI PE54381 - Released Relase work order today | F27: Quote
A28: QT17IA15.95 | B28: QTNSN095289A.X12 | C28: 140 | E28: Stencils , same PWB, STI for Solder paste PE54356- requested to run on the 2oth of May
A29: QT17IA15.96 | B29: QTNSN095288A.X12 | C29: 140 | E29: PE54357- Solder paste STI- Received
A30: QT20LA12.00 | B30: 095290A.X02 | C30: 32
A31: QT20LA12.10 | B31: 095291A.X02 | C31: 32
A32: QT20LA41.00 | B32: 476797A.X11 | C32: 8
