Workbook

Sheet Sheet9
A1: Process | B1: (Multiple Items) | K1: Process | L1: (Multiple Items)
A2: Program | B2: (All)
K3: Row Labels | L3: Sum of Qty
A4: Sum of Qty | B4: Column Labels | K4: 5DX1 SMT 5DX | L4: 242 | T4: AXFIA | U4: P3
A5: Row Labels | B5: PA Assembly | C5: TRX/PSU/BB Assembly | D5: Grand Total | J5: =D5-55 -> #VALUE! | K5: AOI1 AOI Inspect S1 | L5: 461 | T5: AXOLA | U5: P1
A6: 5DX1 SMT 5DX | B6: 325 | C6: 6 | D6: 331 | K6: AOI2 AOI Inspect S2 | L6: 14 | T6: AXOLBA | U6: P2
A7: 5DXR 5DX RWK | B7: 23 | C7: 5 | D7: 28 | K7: AOR1 AOI RWK S1 | L7: 38 | T7: AXOA | U7: P4
A8: AOI1 AOI Inspect S1 | B8: 186 | C8: 93 | D8: 279 | K8: AOR2 AOI RWK S2 | L8: 8
A9: AOI2 AOI Inspect S2 | C9: 10 | D9: 10 | K9: Grand Total | L9: 763
A10: AOR1 AOI RWK S1 | B10: 90 | C10: 1 | D10: 91
A11: AOR2 AOI RWK S2 | C11: 8 | D11: 8
A12: Grand Total | B12: 624 | C12: 123 | D12: 747
A19: Sum of Qty | B19: Column Labels
A20: Row Labels | B20: PA Assembly | C20: TRX/PSU/BB Assembly | D20: Grand Total
A21: 5DX1 SMT 5DX | B21: 112 | D21: 112
A22: 5DXR 5DX RWK | B22: 14 | D22: 14
A23: AOI1 AOI Inspect S1 | B23: 58 | C23: 29 | D23: 87
A24: AOI2 AOI Inspect S2 | C24: 15 | D24: 15
A25: AOR1 AOI RWK S1 | B25: 30 | D25: 30
A26: AOR2 AOI RWK S2 | C26: 1 | D26: 1
A27: Grand Total | B27: 214 | C27: 45 | D27: 259

Sheet Shop Order
A1: Serial Number | B1: Workstation | C1: Process | D1: Qty | E1: Unit Status | F1: Last Updated | G1: Work order | H1: Part number | I1: Priority | J1: UID | K1: Program | L1: Type | M1: Comments | N1: Shipping date | O1: asdas
A2: YK263700056 | B2: NOT-IN-PROCESS | C2: NOT-IN-PROCESS | D2: 1 | E2: Traveler Printed (15) | F2: 46276.268 | G2: QT156G85.00 | H2: QTNSN094513A.101 | I2: =VLOOKUP(G2,WO!A:J,10,0) -> 56 | J2: =MID(G2,3,9) -> 156G85.00 | K2: =VLOOKUP(J2,WO!B:E,4,0) -> Chewy | L2: =VLOOKUP(J2,WO!B:F,5,0) -> RF Board | N2: =IFERROR(VLOOKUP(A2,Shipped!I:J,2,)," ")
A3: YK263700057 | B3: NOT-IN-PROCESS | C3: NOT-IN-PROCESS | D3: 1 | E3: Traveler Printed (15) | F3: 46276.268 | G3: QT156G85.00 | H3: QTNSN094513A.101 | I3: =VLOOKUP(G3,WO!A:J,10,0) -> 56 | J3: =MID(G3,3,9) -> 156G85.00 | K3: =VLOOKUP(J3,WO!B:E,4,0) -> Chewy | L3: =VLOOKUP(J3,WO!B:F,5,0) -> RF Board | N3: =IFERROR(VLOOKUP(A3,Shipped!I:J,2,)," ")
A4: YK263700058 | B4: NOT-IN-PROCESS | C4: NOT-IN-PROCESS | D4: 1 | E4: Traveler Printed (15) | F4: 46276.268 | G4: QT156G85.00 | H4: QTNSN094513A.101 | I4: =VLOOKUP(G4,WO!A:J,10,0) -> 56 | J4: =MID(G4,3,9) -> 156G85.00 | K4: =VLOOKUP(J4,WO!B:E,4,0) -> Chewy | L4: =VLOOKUP(J4,WO!B:F,5,0) -> RF Board | N4: =IFERROR(VLOOKUP(A4,Shipped!I:J,2,)," ")
A5: YK263700059 | B5: NOT-IN-PROCESS | C5: NOT-IN-PROCESS | D5: 1 | E5: Traveler Printed (15) | F5: 46276.268 | G5: QT156G85.00 | H5: QTNSN094513A.101 | I5: =VLOOKUP(G5,WO!A:J,10,0) -> 56 | J5: =MID(G5,3,9) -> 156G85.00 | K5: =VLOOKUP(J5,WO!B:E,4,0) -> Chewy | L5: =VLOOKUP(J5,WO!B:F,5,0) -> RF Board | N5: =IFERROR(VLOOKUP(A5,Shipped!I:J,2,)," ")
A6: YK263700060 | B6: NOT-IN-PROCESS | C6: NOT-IN-PROCESS | D6: 1 | E6: Traveler Printed (15) | F6: 46276.268 | G6: QT156G85.00 | H6: QTNSN094513A.101 | I6: =VLOOKUP(G6,WO!A:J,10,0) -> 56 | J6: =MID(G6,3,9) -> 156G85.00 | K6: =VLOOKUP(J6,WO!B:E,4,0) -> Chewy | L6: =VLOOKUP(J6,WO!B:F,5,0) -> RF Board | N6: =IFERROR(VLOOKUP(A6,Shipped!I:J,2,)," ")
A7: YK263700061 | B7: NOT-IN-PROCESS | C7: NOT-IN-PROCESS | D7: 1 | E7: Traveler Printed (15) | F7: 46276.268 | G7: QT156G85.00 | H7: QTNSN094513A.101 | I7: =VLOOKUP(G7,WO!A:J,10,0) -> 56 | J7: =MID(G7,3,9) -> 156G85.00 | K7: =VLOOKUP(J7,WO!B:E,4,0) -> Chewy | L7: =VLOOKUP(J7,WO!B:F,5,0) -> RF Board | N7: =IFERROR(VLOOKUP(A7,Shipped!I:J,2,)," ")
A8: YK263700062 | B8: NOT-IN-PROCESS | C8: NOT-IN-PROCESS | D8: 1 | E8: Traveler Printed (15) | F8: 46276.268 | G8: QT156G85.00 | H8: QTNSN094513A.101 | I8: =VLOOKUP(G8,WO!A:J,10,0) -> 56 | J8: =MID(G8,3,9) -> 156G85.00 | K8: =VLOOKUP(J8,WO!B:E,4,0) -> Chewy | L8: =VLOOKUP(J8,WO!B:F,5,0) -> RF Board | N8: =IFERROR(VLOOKUP(A8,Shipped!I:J,2,)," ")
A9: YK263700063 | B9: NOT-IN-PROCESS | C9: NOT-IN-PROCESS | D9: 1 | E9: Traveler Printed (15) | F9: 46276.268 | G9: QT156G85.00 | H9: QTNSN094513A.101 | I9: =VLOOKUP(G9,WO!A:J,10,0) -> 56 | J9: =MID(G9,3,9) -> 156G85.00 | K9: =VLOOKUP(J9,WO!B:E,4,0) -> Chewy | L9: =VLOOKUP(J9,WO!B:F,5,0) -> RF Board | N9: =IFERROR(VLOOKUP(A9,Shipped!I:J,2,)," ")
A10: YK263700064 | B10: NOT-IN-PROCESS | C10: NOT-IN-PROCESS | D10: 1 | E10: Traveler Printed (15) | F10: 46276.268 | G10: QT156G85.00 | H10: QTNSN094513A.101 | I10: =VLOOKUP(G10,WO!A:J,10,0) -> 56 | J10: =MID(G10,3,9) -> 156G85.00 | K10: =VLOOKUP(J10,WO!B:E,4,0) -> Chewy | L10: =VLOOKUP(J10,WO!B:F,5,0) -> RF Board | N10: =IFERROR(VLOOKUP(A10,Shipped!I:J,2,)," ")
A11: YK263700065 | B11: NOT-IN-PROCESS | C11: NOT-IN-PROCESS | D11: 1 | E11: Traveler Printed (15) | F11: 46276.268 | G11: QT156G85.00 | H11: QTNSN094513A.101 | I11: =VLOOKUP(G11,WO!A:J,10,0) -> 56 | J11: =MID(G11,3,9) -> 156G85.00 | K11: =VLOOKUP(J11,WO!B:E,4,0) -> Chewy | L11: =VLOOKUP(J11,WO!B:F,5,0) -> RF Board | N11: =IFERROR(VLOOKUP(A11,Shipped!I:J,2,)," ")
A12: YK263700066 | B12: NOT-IN-PROCESS | C12: NOT-IN-PROCESS | D12: 1 | E12: Traveler Printed (15) | F12: 46276.268 | G12: QT156G85.00 | H12: QTNSN094513A.101 | I12: =VLOOKUP(G12,WO!A:J,10,0) -> 56 | J12: =MID(G12,3,9) -> 156G85.00 | K12: =VLOOKUP(J12,WO!B:E,4,0) -> Chewy | L12: =VLOOKUP(J12,WO!B:F,5,0) -> RF Board | N12: =IFERROR(VLOOKUP(A12,Shipped!I:J,2,)," ")
A13: YK263700067 | B13: NOT-IN-PROCESS | C13: NOT-IN-PROCESS | D13: 1 | E13: Traveler Printed (15) | F13: 46276.268 | G13: QT156G85.00 | H13: QTNSN094513A.101 | I13: =VLOOKUP(G13,WO!A:J,10,0) -> 56 | J13: =MID(G13,3,9) -> 156G85.00 | K13: =VLOOKUP(J13,WO!B:E,4,0) -> Chewy | L13: =VLOOKUP(J13,WO!B:F,5,0) -> RF Board | N13: =IFERROR(VLOOKUP(A13,Shipped!I:J,2,)," ")
... A434: YK261600093 | B434: SHIP Shipping | C434: Shipped to Customer | D434: 1 | E434: Shipped (40) | F434: 46246.55 | G434: QT17IA14.40 | H434: QTNSN095289A.X11 | I434: =VLOOKUP(G434,WO!A:J,10,0) -> 12 | J434: =MID(G434,3,9) -> 17IA14.40 | K434: =VLOOKUP(J434,WO!B:E,4,0) -> AXFIA | L434: =VLOOKUP(J434,WO!B:F,5,0) -> PA Assembly | N434: =IFERROR(VLOOKUP(A434,Shipped!I:J,2,)," ") -> 46254
A435: YK261600094 | B435: SHIP Shipping | C435: Shipped to Customer | D435: 1 | E435: Shipped (40) | F435: 46248.371 | G435: QT17IA14.40 | H435: QTNSN095289A.X11 | I435: =VLOOKUP(G435,WO!A:J,10,0) -> 12 | J435: =MID(G435,3,9) -> 17IA14.40 | K435: =VLOOKUP(J435,WO!B:E,4,0) -> AXFIA | L435: =VLOOKUP(J435,WO!B:F,5,0) -> PA Assembly | M435: Update to shipped | N435: =IFERROR(VLOOKUP(A435,Shipped!I:J,2,)," ") -> 46248
A436: YK261600095 | B436: SHIP Shipping | C436: Shipped to Customer | D436: 1 | E436: Shipped (40) | F436: 46246.56 | G436: QT17IA14.40 | H436: QTNSN095289A.X11 | I436: =VLOOKUP(G436,WO!A:J,10,0) -> 12 | J436: =MID(G436,3,9) -> 17IA14.40 | K436: =VLOOKUP(J436,WO!B:E,4,0) -> AXFIA | L436: =VLOOKUP(J436,WO!B:F,5,0) -> PA Assembly | N436: =IFERROR(VLOOKUP(A436,Shipped!I:J,2,)," ") -> 46248
A437: YK261600096 | B437: NOT-IN-PROCESS | C437: NOT-IN-PROCESS | D437: 1 | E437: Unit Component (60) | F437: 46147.375 | G437: QT17IA14.40 | H437: QTNSN095289A.X11 | I437: =VLOOKUP(G437,WO!A:J,10,0) -> 12 | J437: =MID(G437,3,9) -> 17IA14.40 | K437: =VLOOKUP(J437,WO!B:E,4,0) -> AXFIA | L437: =VLOOKUP(J437,WO!B:F,5,0) -> PA Assembly | N437: =IFERROR(VLOOKUP(A437,Shipped!I:J,2,)," ")
A438: YK261600097 | B438: SHIP Shipping | C438: Shipped to Customer | D438: 1 | E438: Shipped (40) | F438: 46245.594 | G438: QT17IA14.40 | H438: QTNSN095289A.X11 | I438: =VLOOKUP(G438,WO!A:J,10,0) -> 12 | J438: =MID(G438,3,9) -> 17IA14.40 | K438: =VLOOKUP(J438,WO!B:E,4,0) -> AXFIA | L438: =VLOOKUP(J438,WO!B:F,5,0) -> PA Assembly | N438: =IFERROR(VLOOKUP(A438,Shipped!I:J,2,)," ") -> 46248
A439: YK261600098 | B439: SHIP Shipping | C439: Shipped to Customer | D439: 1 | E439: Shipped (40) | F439: 46248.377 | G439: QT17IA14.40 | H439: QTNSN095289A.X11 | I439: =VLOOKUP(G439,WO!A:J,10,0) -> 12 | J439: =MID(G439,3,9) -> 17IA14.40 | K439: =VLOOKUP(J439,WO!B:E,4,0) -> AXFIA | L439: =VLOOKUP(J439,WO!B:F,5,0) -> PA Assembly | N439: =IFERROR(VLOOKUP(A439,Shipped!I:J,2,)," ") -> 46248
A440: YK261600099 | B440: SHIP Shipping | C440: Shipped to Customer | D440: 1 | E440: Shipped (40) | F440: 46245.593 | G440: QT17IA14.40 | H440: QTNSN095289A.X11 | I440: =VLOOKUP(G440,WO!A:J,10,0) -> 12 | J440: =MID(G440,3,9) -> 17IA14.40 | K440: =VLOOKUP(J440,WO!B:E,4,0) -> AXFIA | L440: =VLOOKUP(J440,WO!B:F,5,0) -> PA Assembly | N440: =IFERROR(VLOOKUP(A440,Shipped!I:J,2,)," ") -> 46248
A441: YK261600100 | B441: NOT-IN-PROCESS | C441: NOT-IN-PROCESS | D441: 1 | E441: Unit Component (60) | F441: 46148.445 | G441: QT17IA14.40 | H441: QTNSN095289A.X11 | I441: =VLOOKUP(G441,WO!A:J,10,0) -> 12 | J441: =MID(G441,3,9) -> 17IA14.40 | K441: =VLOOKUP(J441,WO!B:E,4,0) -> AXFIA | L441: =VLOOKUP(J441,WO!B:F,5,0) -> PA Assembly | N441: =IFERROR(VLOOKUP(A441,Shipped!I:J,2,)," ")
A442: YK261600101 | B442: SHIP Shipping | C442: Shipped to Customer | D442: 1 | E442: Shipped (40) | F442: 46248.366 | G442: QT17IA14.40 | H442: QTNSN095289A.X11 | I442: =VLOOKUP(G442,WO!A:J,10,0) -> 12 | J442: =MID(G442,3,9) -> 17IA14.40 | K442: =VLOOKUP(J442,WO!B:E,4,0) -> AXFIA | L442: =VLOOKUP(J442,WO!B:F,5,0) -> PA Assembly | N442: =IFERROR(VLOOKUP(A442,Shipped!I:J,2,)," ") -> 46248
A443: YK261600102 | B443: SHIP Shipping | C443: Shipped to Customer | D443: 1 | E443: Shipped (40) | F443: 46248.389 | G443: QT17IA14.40 | H443: QTNSN095289A.X11 | I443: =VLOOKUP(G443,WO!A:J,10,0) -> 12 | J443: =MID(G443,3,9) -> 17IA14.40 | K443: =VLOOKUP(J443,WO!B:E,4,0) -> AXFIA | L443: =VLOOKUP(J443,WO!B:F,5,0) -> PA Assembly | N443: =IFERROR(VLOOKUP(A443,Shipped!I:J,2,)," ") -> 46248
A444: YK261600103 | B444: SHIP Shipping | C444: Shipped to Customer | D444: 1 | E444: Shipped (40) | F444: 46248.396 | G444: QT17IA14.40 | H444: QTNSN095289A.X11 | I444: =VLOOKUP(G444,WO!A:J,10,0) -> 12 | J444: =MID(G444,3,9) -> 17IA14.40 | K444: =VLOOKUP(J444,WO!B:E,4,0) -> AXFIA | L444: =VLOOKUP(J444,WO!B:F,5,0) -> PA Assembly | N444: =IFERROR(VLOOKUP(A444,Shipped!I:J,2,)," ") -> 46248
A445: YK261600104 | B445: SHIP Shipping | C445: Shipped to Customer | D445: 1 | E445: Shipped (40) | F445: 46248.382 | G445: QT17IA14.40 | H445: QTNSN095289A.X11 | I445: =VLOOKUP(G445,WO!A:J,10,0) -> 12 | J445: =MID(G445,3,9) -> 17IA14.40 | K445: =VLOOKUP(J445,WO!B:E,4,0) -> AXFIA | L445: =VLOOKUP(J445,WO!B:F,5,0) -> PA Assembly | N445: =IFERROR(VLOOKUP(A445,Shipped!I:J,2,)," ") -> 46248
A446: YK261600105 | B446: SHIP Shipping | C446: Shipped to Customer | D446: 1 | E446: Shipped (40) | F446: 46246.522 | G446: QT17IA14.40 | H446: QTNSN095289A.X11 | I446: =VLOOKUP(G446,WO!A:J,10,0) -> 12 | J446: =MID(G446,3,9) -> 17IA14.40 | K446: =VLOOKUP(J446,WO!B:E,4,0) -> AXFIA | L446: =VLOOKUP(J446,WO!B:F,5,0) -> PA Assembly | N446: =IFERROR(VLOOKUP(A446,Shipped!I:J,2,)," ") -> 46248
A447: YK261600106 | B447: SHIP Shipping | C447: Shipped to Customer | D447: 1 | E447: Shipped (40) | F447: 46248.396 | G447: QT17IA14.40 | H447: QTNSN095289A.X11 | I447: =VLOOKUP(G447,WO!A:J,10,0) -> 12 | J447: =MID(G447,3,9) -> 17IA14.40 | K447: =VLOOKUP(J447,WO!B:E,4,0) -> AXFIA | L447: =VLOOKUP(J447,WO!B:F,5,0) -> PA Assembly | N447: =IFERROR(VLOOKUP(A447,Shipped!I:J,2,)," ") -> 46248
... A486: YK261400013 | B486: SHIP Shipping | C486: Shipped to Customer | D486: 1 | E486: Shipped (40) | F486: 46245.391 | G486: QT17IA14.50 | H486: QTNSN095288A.X11 | I486: =VLOOKUP(G486,WO!A:J,10,0) -> 11 | J486: =MID(G486,3,9) -> 17IA14.50 | K486: =VLOOKUP(J486,WO!B:E,4,0) -> AXFIA | L486: =VLOOKUP(J486,WO!B:F,5,0) -> PA Assembly | N486: =IFERROR(VLOOKUP(A486,Shipped!I:J,2,)," ") -> 46248
A487: YK261400014 | B487: CMP1 Complete | C487: Complete | D487: 1 | E487: Finished (30) | F487: 46189.251 | G487: QT17IA14.50 | H487: QTNSN095288A.X11 | I487: =VLOOKUP(G487,WO!A:J,10,0) -> 11 | J487: =MID(G487,3,9) -> 17IA14.50 | K487: =VLOOKUP(J487,WO!B:E,4,0) -> AXFIA | L487: =VLOOKUP(J487,WO!B:F,5,0) -> PA Assembly | M487: Update to shipped | N487: =IFERROR(VLOOKUP(A487,Shipped!I:J,2,)," ")
A488: YK261400015 | B488: SHIP Shipping | C488: Shipped to Customer | D488: 1 | E488: Shipped (40) | F488: 46245.372 | G488: QT17IA14.50 | H488: QTNSN095288A.X11 | I488: =VLOOKUP(G488,WO!A:J,10,0) -> 11 | J488: =MID(G488,3,9) -> 17IA14.50 | K488: =VLOOKUP(J488,WO!B:E,4,0) -> AXFIA | L488: =VLOOKUP(J488,WO!B:F,5,0) -> PA Assembly | N488: =IFERROR(VLOOKUP(A488,Shipped!I:J,2,)," ") -> 46248
A489: YK261400016 | B489: NOT-IN-PROCESS | C489: NOT-IN-PROCESS | D489: 1 | E489: Unit Component (60) | F489: 46150.323 | G489: QT17IA14.50 | H489: QTNSN095288A.X11 | I489: =VLOOKUP(G489,WO!A:J,10,0) -> 11 | J489: =MID(G489,3,9) -> 17IA14.50 | K489: =VLOOKUP(J489,WO!B:E,4,0) -> AXFIA | L489: =VLOOKUP(J489,WO!B:F,5,0) -> PA Assembly | N489: =IFERROR(VLOOKUP(A489,Shipped!I:J,2,)," ")
A490: YK261400017 | B490: SHIP Shipping | C490: Shipped to Customer | D490: 1 | E490: Shipped (40) | F490: 46246.517 | G490: QT17IA14.50 | H490: QTNSN095288A.X11 | I490: =VLOOKUP(G490,WO!A:J,10,0) -> 11 | J490: =MID(G490,3,9) -> 17IA14.50 | K490: =VLOOKUP(J490,WO!B:E,4,0) -> AXFIA | L490: =VLOOKUP(J490,WO!B:F,5,0) -> PA Assembly | N490: =IFERROR(VLOOKUP(A490,Shipped!I:J,2,)," ") -> 46254
A491: YK261400018 | B491: SHIP Shipping | C491: Shipped to Customer | D491: 1 | E491: Shipped (40) | F491: 46245.379 | G491: QT17IA14.50 | H491: QTNSN095288A.X11 | I491: =VLOOKUP(G491,WO!A:J,10,0) -> 11 | J491: =MID(G491,3,9) -> 17IA14.50 | K491: =VLOOKUP(J491,WO!B:E,4,0) -> AXFIA | L491: =VLOOKUP(J491,WO!B:F,5,0) -> PA Assembly | N491: =IFERROR(VLOOKUP(A491,Shipped!I:J,2,)," ") -> 46248
A492: YK261400019 | B492: SHIP Shipping | C492: Shipped to Customer | D492: 1 | E492: Shipped (40) | F492: 46246.514 | G492: QT17IA14.50 | H492: QTNSN095288A.X11 | I492: =VLOOKUP(G492,WO!A:J,10,0) -> 11 | J492: =MID(G492,3,9) -> 17IA14.50 | K492: =VLOOKUP(J492,WO!B:E,4,0) -> AXFIA | L492: =VLOOKUP(J492,WO!B:F,5,0) -> PA Assembly | N492: =IFERROR(VLOOKUP(A492,Shipped!I:J,2,)," ") -> 46254
A493: YK261400020 | B493: SHIP Shipping | C493: Shipped to Customer | D493: 1 | E493: Shipped (40) | F493: 46246.512 | G493: QT17IA14.50 | H493: QTNSN095288A.X11 | I493: =VLOOKUP(G493,WO!A:J,10,0) -> 11 | J493: =MID(G493,3,9) -> 17IA14.50 | K493: =VLOOKUP(J493,WO!B:E,4,0) -> AXFIA | L493: =VLOOKUP(J493,WO!B:F,5,0) -> PA Assembly | N493: =IFERROR(VLOOKUP(A493,Shipped!I:J,2,)," ") -> 46254
A494: YK261400021 | B494: FUN1 Func Test | C494: Functional Test-1 | D494: 1 | E494: On The Line (20) | F494: 46134.271 | G494: QT17IA14.50 | H494: QTNSN095288A.X11 | I494: =VLOOKUP(G494,WO!A:J,10,0) -> 11 | J494: =MID(G494,3,9) -> 17IA14.50 | K494: =VLOOKUP(J494,WO!B:E,4,0) -> AXFIA | L494: =VLOOKUP(J494,WO!B:F,5,0) -> PA Assembly | N494: =IFERROR(VLOOKUP(A494,Shipped!I:J,2,)," ")
A495: YK261400022 | B495: SHIP Shipping | C495: Shipped to Customer | D495: 1 | E495: Shipped (40) | F495: 46119.518 | G495: QT17IA14.50 | H495: QTNSN095288A.X11 | I495: =VLOOKUP(G495,WO!A:J,10,0) -> 11 | J495: =MID(G495,3,9) -> 17IA14.50 | K495: =VLOOKUP(J495,WO!B:E,4,0) -> AXFIA | L495: =VLOOKUP(J495,WO!B:F,5,0) -> PA Assembly | N495: =IFERROR(VLOOKUP(A495,Shipped!I:J,2,)," ") -> 46119
A496: YK261400023 | B496: SHIP Shipping | C496: Shipped to Customer | D496: 1 | E496: Shipped (40) | F496: 46245.349 | G496: QT17IA14.50 | H496: QTNSN095288A.X11 | I496: =VLOOKUP(G496,WO!A:J,10,0) -> 11 | J496: =MID(G496,3,9) -> 17IA14.50 | K496: =VLOOKUP(J496,WO!B:E,4,0) -> AXFIA | L496: =VLOOKUP(J496,WO!B:F,5,0) -> PA Assembly | N496: =IFERROR(VLOOKUP(A496,Shipped!I:J,2,)," ") -> 46248
A497: YK261400024 | B497: NOT-IN-PROCESS | C497: NOT-IN-PROCESS | D497: 1 | E497: Unit Component (60) | F497: 46147.373 | G497: QT17IA14.50 | H497: QTNSN095288A.X11 | I497: =VLOOKUP(G497,WO!A:J,10,0) -> 11 | J497: =MID(G497,3,9) -> 17IA14.50 | K497: =VLOOKUP(J497,WO!B:E,4,0) -> AXFIA | L497: =VLOOKUP(J497,WO!B:F,5,0) -> PA Assembly | N497: =IFERROR(VLOOKUP(A497,Shipped!I:J,2,)," ")
A498: YK261400025 | B498: SHIP Shipping | C498: Shipped to Customer | D498: 1 | E498: Shipped (40) | F498: 46245.379 | G498: QT17IA14.50 | H498: QTNSN095288A.X11 | I498: =VLOOKUP(G498,WO!A:J,10,0) -> 11 | J498: =MID(G498,3,9) -> 17IA14.50 | K498: =VLOOKUP(J498,WO!B:E,4,0) -> AXFIA | L498: =VLOOKUP(J498,WO!B:F,5,0) -> PA Assembly | N498: =IFERROR(VLOOKUP(A498,Shipped!I:J,2,)," ") -> 46248
...

Sheet Summary
A1: Program | B1: AXFIA
A2: Type | B2: (All)
A4: Row Labels | B4: Work order | C4: Part number | D4: Process | E4: Unit Status | F4: Count of Qty
A5: 1 | B5: QT17IA14.00 | C5: QTNSN095288A.X03 | D5: NOT-IN-PROCESS | E5: Unit Component (60) | F5: 64
D6: Shipped to Customer | E6: Shipped (40) | F6: 6
A7: 2 | B7: QT17IA14.10 | C7: QTNSN095289A.X03 | D7: NOT-IN-PROCESS | E7: Unit Component (60) | F7: 64
D8: Shipped to Customer | E8: Shipped (40) | F8: 16
A9: 3 | B9: QT17IA23.00 | C9: QTNSN095266A.X02 | D9: NOT-IN-PROCESS | E9: Unit Component (60) | F9: 11
D10: Shipped to Customer | E10: Shipped (40) | F10: 14
A11: 4 | B11: QT17IA43.00 | C11: QTNSN476757A.X02 | D11: Shipped to Customer | E11: Shipped (40) | F11: 20
A12: 5 | B12: QT17IA14.30 | C12: QTNSN095288A.X11 | D12: Functional Test-1 | E12: On The Line (20) | F12: 2
D13: NOT-IN-PROCESS | E13: Unit Component (60) | F13: 11
D14: Shipped to Customer | E14: Shipped (40) | F14: 24
A15: 6 | B15: QT17IA14.31 | C15: QTNSN095288A.X11 | D15: Functional Test-1 | E15: On The Line (20) | F15: 1
D16: NOT-IN-PROCESS | E16: Unit Component (60) | F16: 12
D17: Shipped to Customer | E17: Shipped (40) | F17: 24
A18: 7 | B18: QT17IA14.20 | C18: QTNSN095289A.X11 | D18: Complete | E18: Finished (30) | F18: 1
D19: Functional Test-1 | E19: On The Line (20) | F19: 5
D20: NOT-IN-PROCESS | E20: Unit Component (60) | F20: 8
D21: Shipped to Customer | E21: Shipped (40) | F21: 23
A22: 8 | B22: QT17IA14.21 | C22: QTNSN095289A.X11 | D22: Functional Test-1 | E22: On The Line (20) | F22: 3
D23: NOT-IN-PROCESS | E23: Unit Component (60) | F23: 20
D24: Shipped to Customer | E24: Shipped (40) | F24: 14
A25: 9 | B25: QT17IA24.00 | C25: QTNSN095266A.X11 | D25: NOT-IN-PROCESS | E25: Unit Component (60) | F25: 16
D26: Shipped to Customer | E26: Shipped (40) | F26: 13
A27: 10 | B27: QT17IA44.00 | C27: QTNSN476757A.X11 | D27: Shipped to Customer | E27: Shipped (40) | F27: 15
A28: 11 | B28: QT17IA14.50 | C28: QTNSN095288A.X11 | D28: Complete | E28: Finished (30) | F28: 8
D29: Functional Test-1 | E29: On The Line (20) | F29: 5
D30: NOT-IN-PROCESS | E30: Unit Component (60) | F30: 37
D31: Shipped to Customer | E31: Shipped (40) | F31: 81
D32: Xfr to Debug Test | E32: In Repair Hold (29) | F32: 1
A33: 12 | B33: QT17IA14.40 | C33: QTNSN095289A.X11 | D33: NOT-IN-PROCESS | E33: Unit Component (60) | F33: 32
D34: Shipped to Customer | E34: Shipped (40) | F34: 100
A35: 13 | B35: QT17IA24.10 | C35: QTNSN095266A.X12 | D35: Complete | E35: Finished (30) | F35: 1
D36: Functional Test-1 | E36: On The Line (20) | F36: 1
D37: NOT-IN-PROCESS | E37: Unit Component (60) | F37: 38
D38: Rework-2 | E38: In Repair (25) | F38: 1
A39: 14 | B39: QT17IA44.10 | C39: QTNSN476757A.X12 | D39: Shipped to Customer | E39: Shipped (40) | F39: 30
A40: 15 | B40: QT17IA15.80 | C40: QTNSN095289A.X12 | D40: NOT-IN-PROCESS | E40: Unit Component (60) | F40: 44
D41: Shipped to Customer | E41: Shipped (40) | F41: 18
...

Sheet Shipped
A1: Serial Number | B1: Ship Date | I1: Serial Number | J1: Shipping date
A2: YK262700652 | B2: 46230 | I2: YK260900003 | J2: 46248
A3: YK262700643 | B3: 46230 | I3: YK260900006 | J3: 46248
A4: YK262700652 | B4: 46248 | I4: YK260900008 | J4: 46105
A5: YK262700643 | B5: 46248 | I5: YK260900009 | J5: 46105
A6: YK261100764 | B6: 46248 | I6: YK260900010 | J6: 46248
A7: YK261400112 | B7: 46248 | I7: YK260900011 | J7: 46105
A8: YK261400076 | B8: 46248 | I8: YK260900012 | J8: 46156
A9: YK261400107 | B9: 46248 | I9: YK260900015 | J9: 46248
A10: YK261400027 | B10: 46248 | I10: YK260900018 | J10: 46097
A11: YK261400132 | B11: 46248 | I11: YK260900019 | J11: 46248
A12: YK261400126 | B12: 46248 | I12: YK260900022 | J12: 46128
A13: YK261400111 | B13: 46248 | I13: YK260900023 | J13: 46248
... A230: YK261600091 | B230: 46254 | I230: YK261400094 | J230: 46248
I231: YK261400096 | J231: 46248
I232: YK261400097 | J232: 46169
I233: YK261400098 | J233: 46248
I234: YK261400099 | J234: 46248
I235: YK261400100 | J235: 46248
I236: YK261400101 | J236: 46169
I237: YK261400102 | J237: 46254
I238: YK261400103 | J238: 46254
I239: YK261400104 | J239: 46248
I240: YK261400105 | J240: 46254
I241: YK261400107 | J241: 46248
I242: YK261400108 | J242: 46248
... I582: YK261802219 | J582: 46273
I583: add

Sheet WO
A1: Unique id | C1: WO | E1: Program | F1: Type | G1: Part number | H1: Desc | I1: Qty | J1: Priority | K1: STI | L1: STI/ Comments | M1: Quote
A2: QT17IA14.00 | B2: =MID(A2,3,9) -> 17IA14.00 | C2: WIP | D2: =VLOOKUP(A2,'[1]Plan - US NPI'!$C$6:$E$192,3,0) -> #N/A | E2: AXFIA | F2: PA Assembly | G2: QTNSN095288A.X03 | H2: #N/A | I2: 70 | J2: 1 | R2: Mh lot codes to MRB
A3: QT17IA14.10 | B3: =MID(A3,3,9) -> 17IA14.10 | C3: WIP | D3: =VLOOKUP(A3,'[1]Plan - US NPI'!$C$6:$E$192,3,0) -> #N/A | E3: AXFIA | F3: PA Assembly | G3: QTNSN095289A.X03 | H3: #N/A | I3: 80 | J3: 2 | R3: Solder paste Qtys
A4: QT17IA23.00 | B4: =MID(A4,3,9) -> 17IA23.00 | C4: WIP | D4: =VLOOKUP(A4,'[1]Plan - US NPI'!$C$6:$E$192,3,0) -> #N/A | E4: AXFIA | F4: TRX/PSU/BB Assembly | G4: QTNSN095266A.X02 | H4: #N/A | I4: 25 | J4: 3
A5: QT17IA43.00 | B5: =MID(A5,3,9) -> 17IA43.00 | C5: WIP | D5: =VLOOKUP(A5,'[1]Plan - US NPI'!$C$6:$E$192,3,0) -> #N/A | E5: AXFIA | F5: RRH | G5: QTNSN476757A.X02 | H5: #N/A | I5: 20 | J5: 4
A6: QT17IA14.30 | B6: =MID(A6,3,9) -> 17IA14.30 | C6: WIP | D6: =VLOOKUP(A6,'[1]Plan - US NPI'!$C$6:$E$192,3,0) -> #N/A | E6: =VLOOKUP($A6,'[2]Plan - US NPI'!$C$6:$K$191,3,0) -> AXFIA | F6: =VLOOKUP($A6,'[2]Plan - US NPI'!$C$6:$K$191,9,0) -> PA Assembly | G6: QTNSN095288A.X11 | H6: QT PA ASSY, 095288A. REV X11, B25 PA ASSEMBLY FOR AXFIA/AXFIB | I6: 37 | J6: 5 | L6: eSTI PE53499. PE53575 add a note to remove shield and pre-drive, and for 840135A to use X1 version. PE53746 sent 03/13
A7: QT17IA14.31 | B7: =MID(A7,3,9) -> 17IA14.31 | C7: WIP | D7: =VLOOKUP(A7,'[1]Plan - US NPI'!$C$6:$E$192,3,0) -> #N/A | E7: =VLOOKUP($A7,'[2]Plan - US NPI'!$C$6:$K$191,3,0) -> AXFIA | F7: =VLOOKUP($A7,'[2]Plan - US NPI'!$C$6:$K$191,9,0) -> PA Assembly | G7: QTNSN095288A.X11 | H7: QT PA ASSY, 095288A. REV X11, B25 PA ASSEMBLY FOR AXFIA/AXFIB | I7: 37 | J7: 6 | L7: eSTI PE53499. PE53575 add a note to remove shield and pre-drive, and for 840135A to use X1 version. PE53684 sent 03/13
A8: QT17IA14.20 | B8: =MID(A8,3,9) -> 17IA14.20 | C8: WIP | D8: =VLOOKUP(A8,'[1]Plan - US NPI'!$C$6:$E$192,3,0) -> #N/A | E8: =VLOOKUP($A8,'[2]Plan - US NPI'!$C$6:$K$191,3,0) -> AXFIA | F8: =VLOOKUP($A8,'[2]Plan - US NPI'!$C$6:$K$191,9,0) -> PA Assembly | G8: QTNSN095289A.X11 | H8: QT PA ASSY, 095289A. REV X11, B66 PA ASSEMBLY FOR AXFIA/AXFIB | I8: 37 | J8: 7 | L8: STI PE53554 for 840135A to use X1 version. PE53499, .
A9: QT17IA14.21 | B9: =MID(A9,3,9) -> 17IA14.21 | C9: WIP | D9: =VLOOKUP(A9,'[1]Plan - US NPI'!$C$6:$E$192,3,0) -> #N/A | E9: =VLOOKUP($A9,'[2]Plan - US NPI'!$C$6:$K$191,3,0) -> AXFIA | F9: =VLOOKUP($A9,'[2]Plan - US NPI'!$C$6:$K$191,9,0) -> PA Assembly | G9: QTNSN095289A.X11 | H9: QT PA ASSY, 095289A. REV X11, B66 PA ASSEMBLY FOR AXFIA/AXFIB | I9: 37 | J9: 8 | L9: PE53571 for 17IA14.21,add a note to remove shield and pre-driver. Create new eSTI for 17IA14.20 adding the same note. NEW PE53611
A10: QT17IA24.00 | B10: =MID(A10,3,9) -> 17IA24.00 | C10: WIP | D10: =VLOOKUP(A10,'[1]Plan - US NPI'!$C$6:$E$192,3,0) -> #N/A | E10: AXFIA | F10: TRX/PSU/BB Assembly | G10: QTNSN095266A.X11 | H10: QT TRX ASSY, 095266A. REV X11, TRX ASSEMBLY FOR AXFIA | I10: 29 | J10: 9 | L10: PE53604, PE53707,PE53847
A11: QT17IA44.00 | B11: =MID(A11,3,9) -> 17IA44.00 | C11: WIP | D11: =VLOOKUP(A11,'[1]Plan - US NPI'!$C$6:$E$192,3,0) -> #N/A | E11: AXFIA | F11: RRH | G11: QTNSN476757A.X11 | H11: RRH X11 | I11: 15 | J11: 10 | L11: PE53701
A12: QT17IA14.50 | B12: =MID(A12,3,9) -> 17IA14.50 | C12: WIP | D12: =VLOOKUP(A12,'[1]Plan - US NPI'!$C$6:$E$192,3,0) -> #N/A | E12: =VLOOKUP($A12,'[2]Plan - US NPI'!$C$6:$K$191,3,0) -> AXFIA | F12: =VLOOKUP($A12,'[2]Plan - US NPI'!$C$6:$K$191,9,0) -> PA Assembly | G12: QTNSN095288A.X11 | H12: QT PA ASSY, 095288A. REV X11, B25 PA ASSEMBLY FOR AXFIA/AXFIB | I12: 124 | J12: 11 | L12: PE53891
A13: QT17IA14.40 | B13: =MID(A13,3,9) -> 17IA14.40 | C13: WIP | D13: =VLOOKUP(A13,'[1]Plan - US NPI'!$C$6:$E$192,3,0) -> #N/A | E13: =VLOOKUP($A13,'[2]Plan - US NPI'!$C$6:$K$191,3,0) -> AXFIA | F13: =VLOOKUP($A13,'[2]Plan - US NPI'!$C$6:$K$191,9,0) -> PA Assembly | G13: QTNSN095289A.X11 | H13: QT PA ASSY, 095289A. REV X11, B66 PA ASSEMBLY FOR AXFIA/AXFIB | I13: 124 | J13: 12 | L13: PE54018
A14: QT17IA24.10 | B14: =MID(A14,3,9) -> 17IA24.10 | C14: WIP | D14: =VLOOKUP(A14,'[1]Plan - US NPI'!$C$6:$E$192,3,0) -> #N/A | E14: =VLOOKUP($A14,'[2]Plan - US NPI'!$C$6:$K$191,3,0) -> AXFIA | F14: =VLOOKUP($A14,'[2]Plan - US NPI'!$C$6:$K$191,9,0) -> TRX/PSU/BB Assembly | G14: QTNSN095266A.X12 | H14: QT TRX ASSY, 095266A. REV X12, TRX ASSEMBLY FOR AXFIA | I14: 41 | J14: 13 | L14: X12 Bom released - PE54073
A15: QT17IA44.10 | B15: =MID(A15,3,9) -> 17IA44.10 | C15: WIP | D15: =VLOOKUP(A15,'[1]Plan - US NPI'!$C$6:$E$192,3,0) -> #N/A | E15: =VLOOKUP($A15,'[2]Plan - US NPI'!$C$6:$K$191,3,0) -> AXFIA | F15: =VLOOKUP($A15,'[2]Plan - US NPI'!$C$6:$K$191,9,0) -> RRH Unit | G15: QTNSN476757A.X12 | H15: QT T/L UNIT ASSY, 476757A. REV X12, AXFIA AirScale RRH 4T8R n25/66 720W | I15: 30 | J15: 14 | L15: Esti releasesed- Release wo- PE54404- Wo released 29-May-26 | Min of 15 units next week | Work order complete
A16: QT17IA15.80 | B16: =MID(A16,3,9) -> 17IA15.80 | C16: WIP | D16: =VLOOKUP(A16,'[1]Plan - US NPI'!$C$6:$E$192,3,0) -> #N/A | E16: AXFIA | F16: PA Assembly | G16: QTNSN095289A.X12 | H16: QT PA ASSY, 095289A. REV X12, B66 PA ASSEMBLY FOR AXFIA/AXFIB | I16: 62 | J16: 15 | L16: New PWB- Order 2 sets of stencils- new profile board needed - New profile needed - Need STI- Checkplots being worked - PE54185
A17: QT17IA15.90 | B17: =MID(A17,3,9) -> 17IA15.90 | C17: WIP | D17: =VLOOKUP(A17,'[1]Plan - US NPI'!$C$6:$E$192,3,0) -> #N/A | E17: =VLOOKUP($A17,'[2]Plan - US NPI'!$C$6:$K$191,3,0) -> AXFIA | F17: =VLOOKUP($A17,'[2]Plan - US NPI'!$C$6:$K$191,9,0) -> PA Assembly | G17: QTNSN095288A.X12 | H17: QT PA ASSY, 095288A. REV X12, B25 PA ASSEMBLY FOR AXFIA/AXFIB | I17: 62 | J17: 16 | L17: New PWB- Order 2 sets of stencils- new profile board needed - New profile needed - Need STI- Stencil 04/23- PE54164 | Q17: 46139
A18: QT19BA11.00 | B18: =MID(A18,3,9) -> 19BA11.00 | C18: WIP | D18: =VLOOKUP(A18,'[1]Plan - US NPI'!$C$6:$E$192,3,0) -> #N/A | E18: =VLOOKUP($A18,'[2]Plan - US NPI'!$C$6:$K$191,3,0) -> AXOLA | F18: =VLOOKUP($A18,'[2]Plan - US NPI'!$C$6:$K$191,9,0) -> PA Assembly | G18: QTNSN095290A.X02 | H18: QT PA ASSY, 095290A. REV X02, B71 PA ASSEMBLY FOR AXOLBA | I18: 14 | J18: 17 | L18: Stencils due on the 27- Apr- No Esti
A19: QT19BA11.10 | B19: =MID(A19,3,9) -> 19BA11.10 | C19: WIP | D19: =VLOOKUP(A19,'[1]Plan - US NPI'!$C$6:$E$192,3,0) -> #N/A | E19: =VLOOKUP($A19,'[2]Plan - US NPI'!$C$6:$K$191,3,0) -> AXOLA | F19: =VLOOKUP($A19,'[2]Plan - US NPI'!$C$6:$K$191,9,0) -> PA Assembly | G19: QTNSN095291A.X02 | H19: QT PA ASSY, 095291A. REV X02, B85 PA ASSEMBLY FOR AXOLBA | I19: 14 | J19: 18 | L19: Stencils due on the 27- Apr- No Esti- Tracking# 707296329356
A20: QT20LA21.00 | B20: =MID(A20,3,9) -> 20LA21.00 | C20: WIP | D20: =VLOOKUP(A20,'[1]Plan - US NPI'!$C$6:$E$192,3,0) -> #N/A | E20: =VLOOKUP($A20,'[2]Plan - US NPI'!$C$6:$K$191,3,0) -> AXOLA | F20: =VLOOKUP($A20,'[2]Plan - US NPI'!$C$6:$K$191,9,0) -> TRX/PSU/BB Assembly | G20: QTNSN095286A.X02 | H20: QT TRX ASSY, 095286A. REV X02, TRX ASSEMBLY FOR AXOLA | I20: 10 | J20: 19 | L20: New CP today - Check material
A21: QT17IA25.30 | B21: =MID(A21,3,9) -> 17IA25.30 | C21: WIP | D21: =VLOOKUP(A21,'[1]Plan - US NPI'!$C$6:$E$192,3,0) -> #N/A | E21: =VLOOKUP($A21,'[2]Plan - US NPI'!$C$6:$K$191,3,0) -> AXFIA | F21: =VLOOKUP($A21,'[2]Plan - US NPI'!$C$6:$K$191,9,0) -> TRX/PSU/BB Assembly | G21: QTNSN095266A.X12 | H21: QT TRX ASSY, 095266A. REV X12, TRX ASSEMBLY FOR AXFIA | I21: 47 | J21: 20 | L21: Kick off 21-May-26- ESTI -PE54408 - Released 29-May-26 | One more ESTI to be released | Stencil ETA 03-Jun-26 | PE54513- Work order relased 06/03
A22: QT17IA15.60 | B22: =MID(A22,3,9) -> 17IA15.60 | C22: WIP | D22: =VLOOKUP(A22,'[1]Plan - US NPI'!$C$6:$E$192,3,0) -> #N/A | E22: =VLOOKUP($A22,'[2]Plan - US NPI'!$C$6:$K$191,3,0) -> AXFIA | F22: =VLOOKUP($A22,'[2]Plan - US NPI'!$C$6:$K$191,9,0) -> PA Assembly | G22: QTNSN095289A.X12 | H22: QT PA ASSY, 095289A. REV X12, B66 PA ASSEMBLY FOR AXFIA/AXFIB | I22: 188 | J22: 21 | L22: Kick off 21-May-26- ESTI - PE54407- WO Released 29-May-26
A23: QT17IA15.70 | B23: =MID(A23,3,9) -> 17IA15.70 | C23: WIP | D23: =VLOOKUP(A23,'[1]Plan - US NPI'!$C$6:$E$192,3,0) -> #N/A | E23: =VLOOKUP($A23,'[2]Plan - US NPI'!$C$6:$K$191,3,0) -> AXFIA | F23: =VLOOKUP($A23,'[2]Plan - US NPI'!$C$6:$K$191,9,0) -> PA Assembly | G23: QTNSN095288A.X12 | H23: QT PA ASSY, 095288A. REV X12, B25 PA ASSEMBLY FOR AXFIA/AXFIB | I23: 188 | J23: 22 | L23: Kick off 21-May-26- ESTI - PE54405- WO Released 29-May-26
A24: QT17IA45.30 | B24: =MID(A24,3,9) -> 17IA45.30 | C24: WIP | D24: =VLOOKUP(A24,'[1]Plan - US NPI'!$C$6:$E$192,3,0) -> #N/A | E24: =VLOOKUP($A24,'[2]Plan - US NPI'!$C$6:$K$191,3,0) -> AXFIA | F24: =VLOOKUP($A24,'[2]Plan - US NPI'!$C$6:$K$191,9,0) -> RRH Unit | G24: QTNSN476757A.X12 | H24: QT T/L UNIT ASSY, 476757A. REV X12, AXFIA AirScale RRH 4T8R n25/66 720W | I24: 47 | J24: 23 | L24: PE54409 & PE54856 - Released 29-May-26_ need to release work order- Relased 15-Jun-26 | Rework on the Chassis | Committing 22 pcs for next week | P55306
A25: QT17IA45.40 | B25: =MID(A25,3,9) -> 17IA45.40 | C25: WIP | D25: =VLOOKUP(A25,'[1]Plan - US NPI'!$C$6:$E$192,3,0) -> #N/A | E25: AXFIA | F25: RRH Unit | G25: QTNSN476757A.X12 | H25: QT T/L UNIT ASSY, 476757A. REV X12, AXFIA AirScale RRH 4T8R n25/66 720W | I25: 11 | J25: 24 | L25: Kick off- ESTI PE54381 - WO released
A26: QT17IA15.95 | B26: =MID(A26,3,9) -> 17IA15.95 | C26: WIP | D26: =VLOOKUP(A26,'[1]Plan - US NPI'!$C$6:$E$192,3,0) -> #N/A | E26: =VLOOKUP($A26,'[2]Plan - US NPI'!$C$6:$K$191,3,0) -> AXFIA | F26: =VLOOKUP($A26,'[2]Plan - US NPI'!$C$6:$K$191,9,0) -> PA Assembly | G26: QTNSN095289A.X12 | H26: QT PA ASSY, 095289A. REV X12, B66 PA ASSEMBLY FOR AXFIA/AXFIB | I26: 140 | J26: 25 | L26: Stencils , same PWB, STI for Solder paste PE54356- requested to run on the 2oth of May | New profile needed for Different solder paste
A27: QT17IA15.96 | B27: =MID(A27,3,9) -> 17IA15.96 | C27: WIP | D27: =VLOOKUP(A27,'[1]Plan - US NPI'!$C$6:$E$192,3,0) -> #N/A | E27: =VLOOKUP($A27,'[2]Plan - US NPI'!$C$6:$K$191,3,0) -> AXFIA | F27: =VLOOKUP($A27,'[2]Plan - US NPI'!$C$6:$K$191,9,0) -> PA Assembly | G27: QTNSN095288A.X12 | H27: QT PA ASSY, 095288A. REV X12, B25 PA ASSEMBLY FOR AXFIA/AXFIB | I27: 140 | J27: 26 | L27: PE54357- Solder paste STI- Received | New profile needed for Different solder paste
A28: QT20LA12.00 | B28: =MID(A28,3,9) -> 20LA12.00 | C28: WIP | D28: =VLOOKUP(A28,'[1]Plan - US NPI'!$C$6:$E$192,3,0) -> #N/A | E28: =VLOOKUP($A28,'[2]Plan - US NPI'!$C$6:$K$191,3,0) -> AXOLA | F28: =VLOOKUP($A28,'[2]Plan - US NPI'!$C$6:$K$191,9,0) -> PA Assembly | G28: QTNSN095290A.X02 | H28: QT PA ASSY, 095290A. REV X02, B71 PA ASSEMBLY FOR AXOLBA | I28: 64 | J28: 27 | L28: Esti releasesed- PE54413- WO released 27-May-26- need profile approved
A29: QT20LA12.10 | B29: =MID(A29,3,9) -> 20LA12.10 | C29: WIP | D29: =VLOOKUP(A29,'[1]Plan - US NPI'!$C$6:$E$192,3,0) -> #N/A | E29: =VLOOKUP($A29,'[2]Plan - US NPI'!$C$6:$K$191,3,0) -> AXOLA | F29: =VLOOKUP($A29,'[2]Plan - US NPI'!$C$6:$K$191,9,0) -> PA Assembly | G29: QTNSN095291A.X02 | H29: QT PA ASSY, 095291A. REV X02, B85 PA ASSEMBLY FOR AXOLBA | I29: 64 | J29: 28 | L29: Esti releasesed- WO released 27-May-26- Need profile approved
A30: QT20LA41.00 | B30: =MID(A30,3,9) -> 20LA41.00 | C30: WIP | D30: =VLOOKUP(A30,'[1]Plan - US NPI'!$C$6:$E$192,3,0) -> #N/A | E30: =VLOOKUP($A30,'[2]Plan - US NPI'!$C$6:$K$191,3,0) -> AXOLA | F30: =VLOOKUP($A30,'[2]Plan - US NPI'!$C$6:$K$191,9,0) -> RRH Unit | G30: QTNSN476797A.X11 | H30: QT T/L UNIT ASSY, 476797A.REV X11, AXOLA AirScale RRH 4T4R n71/85 320W | I30: 8 | J30: 29 | L30: CTB- ESTI PE54470 | WO release today 03-Jun-26- Followed up on ESTI | TRX rework need to look at material | STI released -
A31: QT19BA21.00A | B31: =MID(A31,3,9) -> 19BA21.00 | C31: WIP | D31: =VLOOKUP(A31,'[1]Plan - US NPI'!$C$6:$E$192,3,0) -> #N/A | E31: AXOLBA | F31: TRX/PSU/BB Assembly | G31: QTNSN095804A.X11 | I31: 22 | J31: 30 | L31: Relased 06/12- Critical components | 2 pcs Skipping FT- Nokia to pick up | Parametric Data- * 8 boards need rework STI to be released- Cannot test | PE55020- Rework STI with 3 parts that we need to buy-Load independent demand- Rework quote 12 boards- Quote needed pull parts to Soka | M31: Quote sent
A32: QT19BA12.20 | B32: =MID(A32,3,9) -> 19BA12.20 | C32: WIP | D32: =VLOOKUP(A32,'[1]Plan - US NPI'!$C$6:$E$192,3,0) -> #N/A | E32: =VLOOKUP($A32,'[2]Plan - US NPI'!$C$6:$K$191,3,0) -> AXOLBA | F32: =VLOOKUP($A32,'[2]Plan - US NPI'!$C$6:$K$191,9,0) -> PA Assembly | G32: QTNSN095290A.X02 | I32: 32 | J32: 31 | L32: ESTI - Sac305 PE54542- Work order QT20LA12.00 increased to 64 units
A33: QT19BA12.30 | B33: =MID(A33,3,9) -> 19BA12.30 | C33: WIP | D33: =VLOOKUP(A33,'[1]Plan - US NPI'!$C$6:$E$192,3,0) -> #N/A | E33: =VLOOKUP($A33,'[2]Plan - US NPI'!$C$6:$K$191,3,0) -> AXOLBA | F33: =VLOOKUP($A33,'[2]Plan - US NPI'!$C$6:$K$191,9,0) -> PA Assembly | G33: QTNSN095291A.X02 | I33: 32 | J33: 32 | L33: ESTI - Sac305 PE54541- Work order QT20LA12.10 increased to 64 units
A34: QT19BA41.00 | B34: =MID(A34,3,9) -> 19BA41.00 | C34: WIP | D34: =VLOOKUP(A34,'[1]Plan - US NPI'!$C$6:$E$192,3,0) -> #N/A | E34: =VLOOKUP($A34,'[2]Plan - US NPI'!$C$6:$K$191,3,0) -> AXOLBA | F34: =VLOOKUP($A34,'[2]Plan - US NPI'!$C$6:$K$191,9,0) -> RRH Unit | G34: QTNSN476971A.X11 | I34: 8 | J34: 33 | L34: No ESTI_ Nokia checking -06/16 | Chassis and Filter check stock | ESTI to be released PE54770- Share costed bom- New CP To be loaded today | Assembly to be stopped| Commiting to 8 wk 31 | M34: Quote sent-20-Jul-26 | N34: Press plate and Carriers - Delivered from CNC
A35: QT17IA24.20 | B35: =MID(A35,3,9) -> 17IA24.20 | C35: WIP | D35: =VLOOKUP(A35,'[1]Plan - US NPI'!$C$6:$E$192,3,0) -> #N/A | E35: =VLOOKUP($A35,'[2]Plan - US NPI'!$C$6:$K$191,3,0) -> AXFIA | F35: =VLOOKUP($A35,'[2]Plan - US NPI'!$C$6:$K$191,9,0) -> TRX/PSU/BB Assembly | G35: QTNSN095266A.X21 | I35: 29 | J35: 34 | K35: PE55517 | L35: RelaseD 06/15 | Old profile can be used- Review with Jose current issues on the X12 build | Same profile as AXOLBA | Waiting on Quote for rework
A36: QT17IA14.70 | B36: =MID(A36,3,9) -> 17IA14.70 | C36: WIP | D36: AXFIA | E36: AXFIA | F36: PA Assembly | G36: QTNSN095288A.X21 | I36: 74 | J36: 35 | K36: PE55485 | L36: PE54718 | PE54609 | PE54651 - Jose Stencils- Clean released 24-Jun-26- New ESTI for preform ( )| Any date for the Macom part P620299
A37: QT17IA14.60 | B37: =MID(A37,3,9) -> 17IA14.60 | C37: WIP | D37: =VLOOKUP(A37,'[1]Plan - US NPI'!$C$6:$E$192,3,0) -> #N/A | E37: =VLOOKUP($A37,'[2]Plan - US NPI'!$C$6:$K$191,3,0) -> AXFIA | F37: =VLOOKUP($A37,'[2]Plan - US NPI'!$C$6:$K$191,9,0) -> PA Assembly | G37: QTNSN095289A.X21 | I37: 74 | J37: 36 | L37: PE54719, PE54667 ,PE54611 STI- Jose Stencils- 3 shortages- not clean- 2 MTRs to Oulu, 1 Po from Distro-New STI to be released- Labels
A38: QT18OA21.00A | B38: =MID(A38,3,9) -> 18OA21.00 | C38: WIP | D38: Need to release work order | E38: AXOA | F38: TRX/PSU/BB Assembly | G38: QTNSN095725A.X11 | I38: 11 | J38: 37 | L38: need STI for X11 Bom | 4 STIS- PE54721,PE54724,PE55044,PE55107 & New STI to be released to run 4 boards without carriers on reflow | M38: Sent 21-Aug-26
A39: QT20LA22.00 | B39: =MID(A39,3,9) -> 20LA22.00 | C39: WIP | D39: =VLOOKUP(A39,'[1]Plan - US NPI'!$C$6:$E$192,3,0) -> #N/A | E39: =VLOOKUP($A39,'[2]Plan - US NPI'!$C$6:$K$191,3,0) -> AXOLA | F39: =VLOOKUP($A39,'[2]Plan - US NPI'!$C$6:$K$191,9,0) -> TRX/PSU/BB Assembly | G39: QTNSN095803A.X03 | I39: 14 | J39: 38 | L39: 1 component dif from the 804A.X11 Build | STI PE54748 - released today | Stencil Same as 804 | ON HOLD- YK262800086 Ship "as-is" to Salvador | Bom Update needed or STI| PE55140 to skip test and bom changes for the remainning boards | Close at 4 - new build for the remainning 095286A.xo2 | M39: Quote sent 13-July-26
A40: QT20LA15.93 | B40: =MID(A40,3,9) -> 20LA15.93 | C40: WIP | E40: =VLOOKUP($A40,'[2]Plan - US NPI'!$C$6:$K$191,3,0) -> AXOLA | F40: =VLOOKUP($A40,'[2]Plan - US NPI'!$C$6:$K$191,9,0) -> PA Assembly | G40: QTNSN095290A.X02 | I40: 13 | J40: 39 | L40: PE54809- Release Work order-PWB supplier info- Clean - Complete | M40: Quote sent 16-July-26
...

Sheet Rework
A1: TRX | D1: STI | E1: Work order | F1: Qty
A2: Program | B2: Comments | C2: Priorty | D2: STI | E2: Work order | F2: QTY | G2: Part number | H2: Qty not being reworked | I2: Time | J2: Total mins
A3: AXOLA | B3: No Aoi and 5 DX no Final QC, No testing | C3: P1 | D3: PE55549 | E3: 20LA23.10 | F3: 8 | G3: 095286A.X14 | H3: 2 units shipped | I3: 10 | J3: =F3*I3 -> 80
A4: AXOLBA | B4: NO Aoi and 5 DX , Final QC and Need to test the board | C4: P2 | D4: PE55526 | E4: 19BA22.00 | F4: 56 | G4: 095804A.X12 | H4: 8 units on Radios | I4: =10+20 -> 30 | J4: =F4*I4 -> 1680
A5: AXFIA | B5: NO Aoi and 5 DX , Final QC and Need to test the board | C5: P3 | D5: PE55522 | E5: 17IA24.30 | F5: 52 | G5: 095266A.X21 | I5: =10+20 -> 30 | J5: =F5*I5 -> 1560
A6: AXFIA | B6: NO Aoi and 5 DX , Final QC and Need to test the board | C6: P3 | D6: PE55517 | E6: 17IA24.20 | F6: 16 | G6: 095266A.X21 | H6: 10 shipped and 3 radios | I6: 30 | J6: =(4*30)+(12*10) -> 240
J7: =SUM(J3:J6) -> 3560
A13: Program | B13: Comments | C13: Priorty | D13: STI | E13: Work order | F13: QTY | G13: Part number | H13: Qty not being reworked | J13: Rework time | K13: Test time | L13: Total Time
A14: AXOLA | B14: No Aoi and 5 DX , Final QC, No testing | C14: P1 | D14: PE55549 | E14: 20LA23.10 | F14: 8 | G14: 095286A.X14 | H14: 2 units shipped | I14: 10 | J14: 80 | K14: 0 | L14: =J14+K14 -> 80
A15: AXOLBA | B15: NO Aoi and 5 DX , Final QC and Need to test the board | C15: P2 | D15: PE55526 | E15: 19BA22.00 | F15: 56 | G15: 095804A.X12 | H15: 8 units on Radios | I15: 10 | J15: 560 | K15: 200 | L15: =J15+K15 -> 760 | M15: 10 boards needs to be retested
A16: AXFIA | B16: NO Aoi and 5 DX , Final QC and Need to test the board | C16: P3 | D16: PE55522 | E16: 17IA24.30 | F16: 52 | G16: 095266A.X21 | I16: 10 | J16: 520 | K16: 0 | L16: =J16+K16 -> 520
A17: AXFIA | B17: NO Aoi and 5 DX , Final QC and Need to test the board( No need to test boards that have already passed) | C17: P3 | D17: PE55517 | E17: 17IA24.20 | F17: 16 | G17: 095266A.X21 | H17: 10 shipped and 3 radios | I17: 10 | J17: 160 | K17: 80 | L17: =J17+K17 -> 240 | M17: 4 boards need to be retested
J18: 1320 | K18: 280 | L18: =SUM(L14:L17) -> 1600
A26: Program | B26: Comments | C26: Priorty | D26: STI | E26: Work order | F26: QTY | H26: Part number | I26: Qty not being reworked | J26: Rework time | K26: Test time | L26: Total Time
A27: AXOLA | B27: No Aoi and 5 DX , Final QC, No testing | C27: P1 | D27: PE55549 | E27: 20LA23.10 | F27: 8 | G27: 8 | H27: 095286A.X14 | I27: 2 units shipped | J27: 80 | K27: 0 | L27: =J27+K27 -> 80
A28: AXOLBA | B28: NO Aoi and 5 DX , Final QC and Need to test the board | C28: P2 | D28: PE55526 | E28: 19BA22.00 | F28: 56 | H28: 095804A.X12 | I28: 8 units on Radios | J28: 560 | K28: 200 | L28: =J28+K28 -> 760 | M28: 10 boards needs to be retested
A29: AXFIA | B29: NO Aoi and 5 DX , Final QC and Need to test the board | C29: P3 | D29: PE55522 | E29: 17IA24.30 | F29: 52 | H29: 095266A.X21 | J29: 520 | K29: 0 | L29: =J29+K29 -> 520
A30: AXFIA | B30: NO Aoi and 5 DX , Final QC and Need to test the board( No need to test boards that have already passed) | C30: P3 | D30: PE55517 | E30: 17IA24.20 | F30: 16 | G30: 16 | H30: 095266A.X21 | I30: 10 shipped and 3 radios | J30: 160 | K30: 80 | L30: =J30+K30 -> 240 | M30: 4 boards need to be retested
J31: 1320 | K31: 280 | L31: =SUM(L27:L30) -> 1600
