Workbook

Sheet Shop Order
A1: Serial Number | B1: Workstation | C1: Process | D1: Qty | E1: Unit Status | F1: Last Updated | G1: Work order | H1: Part number | I1: Priority | J1: Comments | K1: Shipping date | L1: asdas
A2: YK260300123 | B2: NOT-IN-PROCESS | C2: NOT-IN-PROCESS | D2: 1 | E2: Unit Component (60) | F2: 46065.449 | G2: QT17IA14.00 | H2: QTNSN095288A.X03 | I2: =VLOOKUP(G2,WO!A:L,12,0) -> 1
A3: YK260300124 | B3: NOT-IN-PROCESS | C3: NOT-IN-PROCESS | D3: 1 | E3: Unit Component (60) | F3: 46065.45 | G3: QT17IA14.00 | H3: QTNSN095288A.X03 | I3: =VLOOKUP(G3,WO!A:L,12,0) -> 1
A4: YK260300125 | B4: NOT-IN-PROCESS | C4: NOT-IN-PROCESS | D4: 1 | E4: Unit Component (60) | F4: 46071.552 | G4: QT17IA14.00 | H4: QTNSN095288A.X03 | I4: =VLOOKUP(G4,WO!A:L,12,0) -> 1
A5: YK260300126 | B5: NOT-IN-PROCESS | C5: NOT-IN-PROCESS | D5: 1 | E5: Unit Component (60) | F5: 46072.29 | G5: QT17IA14.00 | H5: QTNSN095288A.X03 | I5: =VLOOKUP(G5,WO!A:L,12,0) -> 1
A6: YK260300127 | B6: NOT-IN-PROCESS | C6: NOT-IN-PROCESS | D6: 1 | E6: Unit Component (60) | F6: 46076.37 | G6: QT17IA14.00 | H6: QTNSN095288A.X03 | I6: =VLOOKUP(G6,WO!A:L,12,0) -> 1
A7: YK260300128 | B7: SHIP Shipping | C7: Shipped to Customer | D7: 1 | E7: Shipped (40) | F7: 46112.311 | G7: QT17IA14.00 | H7: QTNSN095288A.X03 | I7: =VLOOKUP(G7,WO!A:L,12,0) -> 1
A8: YK260300129 | B8: NOT-IN-PROCESS | C8: NOT-IN-PROCESS | D8: 1 | E8: Unit Component (60) | F8: 46065.432 | G8: QT17IA14.00 | H8: QTNSN095288A.X03 | I8: =VLOOKUP(G8,WO!A:L,12,0) -> 1
A9: YK260300130 | B9: NOT-IN-PROCESS | C9: NOT-IN-PROCESS | D9: 1 | E9: Unit Component (60) | F9: 46071.282 | G9: QT17IA14.00 | H9: QTNSN095288A.X03 | I9: =VLOOKUP(G9,WO!A:L,12,0) -> 1
A10: YK260300131 | B10: NOT-IN-PROCESS | C10: NOT-IN-PROCESS | D10: 1 | E10: Unit Component (60) | F10: 46076.374 | G10: QT17IA14.00 | H10: QTNSN095288A.X03 | I10: =VLOOKUP(G10,WO!A:L,12,0) -> 1
A11: YK260300132 | B11: NOT-IN-PROCESS | C11: NOT-IN-PROCESS | D11: 1 | E11: Unit Component (60) | F11: 46065.431 | G11: QT17IA14.00 | H11: QTNSN095288A.X03 | I11: =VLOOKUP(G11,WO!A:L,12,0) -> 1
A12: YK260300133 | B12: NOT-IN-PROCESS | C12: NOT-IN-PROCESS | D12: 1 | E12: Unit Component (60) | F12: 46072.486 | G12: QT17IA14.00 | H12: QTNSN095288A.X03 | I12: =VLOOKUP(G12,WO!A:L,12,0) -> 1
A13: YK260300134 | B13: NOT-IN-PROCESS | C13: NOT-IN-PROCESS | D13: 1 | E13: Unit Component (60) | F13: 46065.449 | G13: QT17IA14.00 | H13: QTNSN095288A.X03 | I13: =VLOOKUP(G13,WO!A:L,12,0) -> 1
... A1726: YK262300824 | B1726: SHIP Shipping | C1726: Shipped to Customer | D1726: 1 | E1726: Shipped (40) | F1726: 46218.59 | G1726: QT17IA44.10 | H1726: QTNSN476757A.X12 | I1726: =VLOOKUP(G1726,WO!A:L,12,0) -> 14
A1727: YK262300825 | B1727: SHIP Shipping | C1727: Shipped to Customer | D1727: 1 | E1727: Shipped (40) | F1727: 46218.59 | G1727: QT17IA44.10 | H1727: QTNSN476757A.X12 | I1727: =VLOOKUP(G1727,WO!A:L,12,0) -> 14 | K1727: Shipped 7/10/2026
A1728: YK262700620 | B1728: SHIP Shipping | C1728: Shipped to Customer | D1728: 1 | E1728: Shipped (40) | F1728: 46218.6 | G1728: QT17IA45.30 | H1728: QTNSN476757A.X12 | I1728: =VLOOKUP(G1728,WO!A:L,12,0) -> 23
A1729: YK262700621 | B1729: SHIP Shipping | C1729: Shipped to Customer | D1729: 1 | E1729: Shipped (40) | F1729: 46218.595 | G1729: QT17IA45.30 | H1729: QTNSN476757A.X12 | I1729: =VLOOKUP(G1729,WO!A:L,12,0) -> 23
A1730: YK262700622 | B1730: VAC1 | C1730: VACCUM TEST | D1730: 1 | E1730: On The Line (20) | F1730: 46212.504 | G1730: QT17IA45.30 | H1730: QTNSN476757A.X12 | I1730: =VLOOKUP(G1730,WO!A:L,12,0) -> 23
A1731: YK262700623 | B1731: SHIP Shipping | C1731: Shipped to Customer | D1731: 1 | E1731: Shipped (40) | F1731: 46218.595 | G1731: QT17IA45.30 | H1731: QTNSN476757A.X12 | I1731: =VLOOKUP(G1731,WO!A:L,12,0) -> 23
A1732: YK262700624 | B1732: SHIP Shipping | C1732: Shipped to Customer | D1732: 1 | E1732: Shipped (40) | F1732: 46218.596 | G1732: QT17IA45.30 | H1732: QTNSN476757A.X12 | I1732: =VLOOKUP(G1732,WO!A:L,12,0) -> 23
A1733: YK262700625 | B1733: SHIP Shipping | C1733: Shipped to Customer | D1733: 1 | E1733: Shipped (40) | F1733: 46218.6 | G1733: QT17IA45.30 | H1733: QTNSN476757A.X12 | I1733: =VLOOKUP(G1733,WO!A:L,12,0) -> 23
A1734: YK262700626 | B1734: ASY5 T/L Assembly | C1734: Assembly 1-1B2 | D1734: 1 | E1734: On The Line Hold (28) | F1734: 46218.511 | G1734: QT17IA45.30 | H1734: QTNSN476757A.X12 | I1734: =VLOOKUP(G1734,WO!A:L,12,0) -> 23
A1735: YK262700627 | B1735: FUN1 Func Test | C1735: Functional Test-1 | D1735: 1 | E1735: On The Line (20) | F1735: 46219.301 | G1735: QT17IA45.30 | H1735: QTNSN476757A.X12 | I1735: =VLOOKUP(G1735,WO!A:L,12,0) -> 23
A1736: YK262700628 | B1736: FUN1 Func Test | C1736: Functional Test-1 | D1736: 1 | E1736: On The Line (20) | F1736: 46219.301 | G1736: QT17IA45.30 | H1736: QTNSN476757A.X12 | I1736: =VLOOKUP(G1736,WO!A:L,12,0) -> 23
A1737: YK262700629 | B1737: FUN1 Func Test | C1737: Functional Test-1 | D1737: 1 | E1737: On The Line (20) | F1737: 46219.611 | G1737: QT17IA45.30 | H1737: QTNSN476757A.X12 | I1737: =VLOOKUP(G1737,WO!A:L,12,0) -> 23
A1738: YK262700630 | B1738: SHIP Shipping | C1738: Shipped to Customer | D1738: 1 | E1738: Shipped (40) | F1738: 46218.597 | G1738: QT17IA45.30 | H1738: QTNSN476757A.X12 | I1738: =VLOOKUP(G1738,WO!A:L,12,0) -> 23
A1739: YK262700631 | B1739: SHIP Shipping | C1739: Shipped to Customer | D1739: 1 | E1739: Shipped (40) | F1739: 46218.597 | G1739: QT17IA45.30 | H1739: QTNSN476757A.X12 | I1739: =VLOOKUP(G1739,WO!A:L,12,0) -> 23
... A2040: YK262500734 | B2040: SHIP Shipping | C2040: Shipped to Customer | D2040: 1 | E2040: Shipped (40) | F2040: 46218.588 | G2040: QT20LA41.00 | H2040: QTNSN476797A.X11 | I2040: =VLOOKUP(G2040,WO!A:L,12,0) -> 29

Sheet Summary
A1: Row Labels | B1: Work order | C1: Part number | D1: Process | E1: Unit Status | F1: Count of Qty
A2: 1 | B2: QT17IA14.00 | C2: QTNSN095288A.X03 | D2: NOT-IN-PROCESS | E2: Unit Component (60) | F2: 64
D3: Shipped to Customer | E3: Shipped (40) | F3: 6
A4: 2 | B4: QT17IA14.10 | C4: QTNSN095289A.X03 | D4: NOT-IN-PROCESS | E4: Unit Component (60) | F4: 64
D5: Shipped to Customer | E5: Shipped (40) | F5: 16
A6: 3 | B6: QT17IA23.00 | C6: QTNSN095266A.X02 | D6: NOT-IN-PROCESS | E6: Unit Component (60) | F6: 11
D7: Shipped to Customer | E7: Shipped (40) | F7: 14
A8: 4 | B8: QT17IA43.00 | C8: QTNSN476757A.X02 | D8: Shipped to Customer | E8: Shipped (40) | F8: 20
A9: 5 | B9: QT17IA14.30 | C9: QTNSN095288A.X11 | D9: Complete | E9: Finished (30) | F9: 13
D10: Functional Test-1 | E10: On The Line (20) | F10: 2
D11: NOT-IN-PROCESS | E11: Unit Component (60) | F11: 11
D12: Shipped to Customer | E12: Shipped (40) | F12: 8
D13: UNTT | E13: On The Line (20) | F13: 1
D14: Rework-1 | E14: In Repair (25) | F14: 2
A15: 6 | B15: QT17IA14.31 | C15: QTNSN095288A.X11 | D15: Complete | E15: Finished (30) | F15: 12
D16: Functional Test-1 | E16: On The Line (20) | F16: 1
D17: NOT-IN-PROCESS | E17: Unit Component (60) | F17: 12
D18: Shipped to Customer | E18: Shipped (40) | F18: 8
D19: Xfr to Debug Test | E19: In Repair Hold (29) | F19: 1
D20: Rework-1 | E20: In Repair (25) | F20: 1
D21: Rework-3 | E21: In Repair (25) | F21: 2
A22: 7 | B22: QT17IA14.20 | C22: QTNSN095289A.X11 | D22: Complete | E22: Finished (30) | F22: 4
D23: Functional Test-1 | E23: On The Line (20) | F23: 5
D24: NOT-IN-PROCESS | E24: Unit Component (60) | F24: 8
D25: Shipped to Customer | E25: Shipped (40) | F25: 10
D26: Xfr to Debug Test | E26: In Repair Hold (29) | F26: 4
D27: Rework-1 | E27: In Repair (25) | F27: 3
D28: Rework-3 | E28: In Repair (25) | F28: 3
A29: 8 | B29: QT17IA14.21 | C29: QTNSN095289A.X11 | D29: Functional Test-1 | E29: On The Line (20) | F29: 3
D30: NOT-IN-PROCESS | E30: Unit Component (60) | F30: 20
D31: Shipped to Customer | E31: Shipped (40) | F31: 10
D32: Xfr to Debug Test | E32: In Repair Hold (29) | F32: 4
A33: 9 | B33: QT17IA24.00 | C33: QTNSN095266A.X11 | D33: NOT-IN-PROCESS | E33: Unit Component (60) | F33: 15
D34: Shipped to Customer | E34: Shipped (40) | F34: 14
A35: 10 | B35: QT17IA44.00 | C35: QTNSN476757A.X11 | D35: Shipped to Customer | E35: Shipped (40) | F35: 15
A36: 11 | B36: QT17IA14.50 | C36: QTNSN095288A.X11 | D36: Complete | E36: Finished (30) | F36: 29
D37: Functional Test-1 | E37: On The Line (20) | F37: 46
D38: NOT-IN-PROCESS | E38: Unit Component (60) | F38: 37
D39: Shipped to Customer | E39: Shipped (40) | F39: 9
D40: Xfr to Debug Test | E40: In Repair Hold (29) | F40: 7
...

Sheet WO
A1: Unique id | C1: WO | G1: Program | H1: Type | I1: Part number | J1: Desc | K1: Qty | L1: Priority | M1: STI/ Comments | N1: Quote
A2: QT17IA14.00 | B2: =MID(A2,3,11) -> 17IA14.00 | C2: =VLOOKUP(A2,[1]Summary!B:B,1,0) -> QT17IA14.00 | F2: =VLOOKUP(A2,'[2]Plan - US NPI'!$C$6:$E$192,3,0) -> #N/A | G2: =VLOOKUP($A2,'[3]Plan - US NPI'!$C$6:$K$191,3,0) -> #N/A | H2: =VLOOKUP($A2,'[3]Plan - US NPI'!$C$6:$K$191,9,0) -> #N/A | I2: QTNSN095288A.X03 | J2: #N/A | K2: 70 | L2: 1 | S2: Mh lot codes to MRB
A3: QT17IA14.10 | B3: =MID(A3,3,11) -> 17IA14.10 | C3: =VLOOKUP(A3,[1]Summary!B:B,1,0) -> QT17IA14.10 | F3: =VLOOKUP(A3,'[2]Plan - US NPI'!$C$6:$E$192,3,0) -> #N/A | G3: =VLOOKUP($A3,'[3]Plan - US NPI'!$C$6:$K$191,3,0) -> #N/A | H3: =VLOOKUP($A3,'[3]Plan - US NPI'!$C$6:$K$191,9,0) -> #N/A | I3: QTNSN095289A.X03 | J3: #N/A | K3: 80 | L3: 2 | S3: Solder paste Qtys
A4: QT17IA23.00 | B4: =MID(A4,3,11) -> 17IA23.00 | C4: =VLOOKUP(A4,[1]Summary!B:B,1,0) -> QT17IA23.00 | F4: =VLOOKUP(A4,'[2]Plan - US NPI'!$C$6:$E$192,3,0) -> #N/A | G4: =VLOOKUP($A4,'[3]Plan - US NPI'!$C$6:$K$191,3,0) -> #N/A | H4: =VLOOKUP($A4,'[3]Plan - US NPI'!$C$6:$K$191,9,0) -> #N/A | I4: QTNSN095266A.X02 | J4: #N/A | K4: 25 | L4: 3
A5: QT17IA43.00 | B5: =MID(A5,3,11) -> 17IA43.00 | C5: =VLOOKUP(A5,[1]Summary!B:B,1,0) -> QT17IA43.00 | F5: =VLOOKUP(A5,'[2]Plan - US NPI'!$C$6:$E$192,3,0) -> #N/A | G5: =VLOOKUP($A5,'[3]Plan - US NPI'!$C$6:$K$191,3,0) -> #N/A | H5: =VLOOKUP($A5,'[3]Plan - US NPI'!$C$6:$K$191,9,0) -> #N/A | I5: QTNSN476757A.X02 | J5: #N/A | K5: 20 | L5: 4
A6: QT17IA14.30 | B6: =MID(A6,3,11) -> 17IA14.30 | C6: =VLOOKUP(A6,[1]Summary!B:B,1,0) -> QT17IA14.30 | F6: =VLOOKUP(A6,'[2]Plan - US NPI'!$C$6:$E$192,3,0) -> #N/A | G6: =VLOOKUP($A6,'[3]Plan - US NPI'!$C$6:$K$191,3,0) -> AXFIA | H6: =VLOOKUP($A6,'[3]Plan - US NPI'!$C$6:$K$191,9,0) -> PA Assembly | I6: QTNSN095288A.X11 | J6: QT PA ASSY, 095288A. REV X11, B25 PA ASSEMBLY FOR AXFIA/AXFIB | K6: 37 | L6: 5 | M6: eSTI PE53499. PE53575 add a note to remove shield and pre-drive, and for 840135A to use X1 version. PE53746 sent 03/13
A7: QT17IA14.31 | B7: =MID(A7,3,11) -> 17IA14.31 | C7: =VLOOKUP(A7,[1]Summary!B:B,1,0) -> QT17IA14.31 | F7: =VLOOKUP(A7,'[2]Plan - US NPI'!$C$6:$E$192,3,0) -> #N/A | G7: =VLOOKUP($A7,'[3]Plan - US NPI'!$C$6:$K$191,3,0) -> AXFIA | H7: =VLOOKUP($A7,'[3]Plan - US NPI'!$C$6:$K$191,9,0) -> PA Assembly | I7: QTNSN095288A.X11 | J7: QT PA ASSY, 095288A. REV X11, B25 PA ASSEMBLY FOR AXFIA/AXFIB | K7: 37 | L7: 6 | M7: eSTI PE53499. PE53575 add a note to remove shield and pre-drive, and for 840135A to use X1 version. PE53684 sent 03/13
A8: QT17IA14.20 | B8: =MID(A8,3,11) -> 17IA14.20 | C8: =VLOOKUP(A8,[1]Summary!B:B,1,0) -> QT17IA14.20 | F8: =VLOOKUP(A8,'[2]Plan - US NPI'!$C$6:$E$192,3,0) -> #N/A | G8: =VLOOKUP($A8,'[3]Plan - US NPI'!$C$6:$K$191,3,0) -> AXFIA | H8: =VLOOKUP($A8,'[3]Plan - US NPI'!$C$6:$K$191,9,0) -> PA Assembly | I8: QTNSN095289A.X11 | J8: QT PA ASSY, 095289A. REV X11, B66 PA ASSEMBLY FOR AXFIA/AXFIB | K8: 37 | L8: 7 | M8: STI PE53554 for 840135A to use X1 version. PE53499, .
A9: QT17IA14.21 | B9: =MID(A9,3,11) -> 17IA14.21 | C9: =VLOOKUP(A9,[1]Summary!B:B,1,0) -> QT17IA14.21 | F9: =VLOOKUP(A9,'[2]Plan - US NPI'!$C$6:$E$192,3,0) -> #N/A | G9: =VLOOKUP($A9,'[3]Plan - US NPI'!$C$6:$K$191,3,0) -> AXFIA | H9: =VLOOKUP($A9,'[3]Plan - US NPI'!$C$6:$K$191,9,0) -> PA Assembly | I9: QTNSN095289A.X11 | J9: QT PA ASSY, 095289A. REV X11, B66 PA ASSEMBLY FOR AXFIA/AXFIB | K9: 37 | L9: 8 | M9: PE53571 for 17IA14.21,add a note to remove shield and pre-driver. Create new eSTI for 17IA14.20 adding the same note. NEW PE53611
A10: QT17IA24.00 | B10: =MID(A10,3,11) -> 17IA24.00 | C10: =VLOOKUP(A10,[1]Summary!B:B,1,0) -> QT17IA24.00 | F10: =VLOOKUP(A10,'[2]Plan - US NPI'!$C$6:$E$192,3,0) -> #N/A | G10: =VLOOKUP($A10,'[3]Plan - US NPI'!$C$6:$K$191,3,0) -> #N/A | H10: =VLOOKUP($A10,'[3]Plan - US NPI'!$C$6:$K$191,9,0) -> #N/A | I10: QTNSN095266A.X11 | J10: QT TRX ASSY, 095266A. REV X11, TRX ASSEMBLY FOR AXFIA | K10: 29 | L10: 9 | M10: PE53604, PE53707,PE53847
A11: QT17IA44.00 | B11: =MID(A11,3,11) -> 17IA44.00 | C11: =VLOOKUP(A11,[1]Summary!B:B,1,0) -> QT17IA44.00 | F11: =VLOOKUP(A11,'[2]Plan - US NPI'!$C$6:$E$192,3,0) -> #N/A | G11: =VLOOKUP($A11,'[3]Plan - US NPI'!$C$6:$K$191,3,0) -> #N/A | H11: =VLOOKUP($A11,'[3]Plan - US NPI'!$C$6:$K$191,9,0) -> #N/A | I11: QTNSN476757A.X11 | J11: RRH X11 | K11: 15 | L11: 10 | M11: PE53701
A12: QT17IA14.50 | B12: =MID(A12,3,11) -> 17IA14.50 | C12: =VLOOKUP(A12,[1]Summary!B:B,1,0) -> QT17IA14.50 | F12: =VLOOKUP(A12,'[2]Plan - US NPI'!$C$6:$E$192,3,0) -> #N/A | G12: =VLOOKUP($A12,'[3]Plan - US NPI'!$C$6:$K$191,3,0) -> AXFIA | H12: =VLOOKUP($A12,'[3]Plan - US NPI'!$C$6:$K$191,9,0) -> PA Assembly | I12: QTNSN095288A.X11 | J12: QT PA ASSY, 095288A. REV X11, B25 PA ASSEMBLY FOR AXFIA/AXFIB | K12: 124 | L12: 11 | M12: PE53891
A13: QT17IA14.40 | B13: =MID(A13,3,11) -> 17IA14.40 | C13: =VLOOKUP(A13,[1]Summary!B:B,1,0) -> QT17IA14.40 | F13: =VLOOKUP(A13,'[2]Plan - US NPI'!$C$6:$E$192,3,0) -> #N/A | G13: =VLOOKUP($A13,'[3]Plan - US NPI'!$C$6:$K$191,3,0) -> AXFIA | H13: =VLOOKUP($A13,'[3]Plan - US NPI'!$C$6:$K$191,9,0) -> PA Assembly | I13: QTNSN095289A.X11 | J13: QT PA ASSY, 095289A. REV X11, B66 PA ASSEMBLY FOR AXFIA/AXFIB | K13: 124 | L13: 12 | M13: PE54018
A14: QT17IA24.10 | B14: =MID(A14,3,11) -> 17IA24.10 | C14: =VLOOKUP(A14,[1]Summary!B:B,1,0) -> QT17IA24.10 | F14: =VLOOKUP(A14,'[2]Plan - US NPI'!$C$6:$E$192,3,0) -> #N/A | G14: =VLOOKUP($A14,'[3]Plan - US NPI'!$C$6:$K$191,3,0) -> AXFIA | H14: =VLOOKUP($A14,'[3]Plan - US NPI'!$C$6:$K$191,9,0) -> TRX/PSU/BB Assembly | I14: QTNSN095266A.X12 | J14: QT TRX ASSY, 095266A. REV X12, TRX ASSEMBLY FOR AXFIA | K14: 41 | L14: 13 | M14: X12 Bom released - PE54073
A15: QT17IA44.10 | B15: =MID(A15,3,11) -> 17IA44.10 | C15: =VLOOKUP(A15,[1]Summary!B:B,1,0) -> QT17IA44.10 | F15: =VLOOKUP(A15,'[2]Plan - US NPI'!$C$6:$E$192,3,0) -> #N/A | G15: =VLOOKUP($A15,'[3]Plan - US NPI'!$C$6:$K$191,3,0) -> AXFIA | H15: =VLOOKUP($A15,'[3]Plan - US NPI'!$C$6:$K$191,9,0) -> RRH Unit | I15: QTNSN476757A.X12 | J15: QT T/L UNIT ASSY, 476757A. REV X12, AXFIA AirScale RRH 4T8R n25/66 720W | K15: 30 | L15: 14 | M15: Esti releasesed- Release wo- PE54404- Wo released 29-May-26 | Min of 15 units next week
A16: QT17IA15.80 | B16: =MID(A16,3,11) -> 17IA15.80 | C16: =VLOOKUP(A16,[1]Summary!B:B,1,0) -> QT17IA15.80 | F16: =VLOOKUP(A16,'[2]Plan - US NPI'!$C$6:$E$192,3,0) -> #N/A | G16: =VLOOKUP($A16,'[3]Plan - US NPI'!$C$6:$K$191,3,0) -> #N/A | H16: =VLOOKUP($A16,'[3]Plan - US NPI'!$C$6:$K$191,9,0) -> #N/A | I16: QTNSN095289A.X12 | J16: QT PA ASSY, 095289A. REV X12, B66 PA ASSEMBLY FOR AXFIA/AXFIB | K16: 62 | L16: 15 | M16: New PWB- Order 2 sets of stencils- new profile board needed - New profile needed - Need STI- Checkplots being worked - PE54185
A17: QT17IA15.90 | B17: =MID(A17,3,11) -> 17IA15.90 | C17: =VLOOKUP(A17,[1]Summary!B:B,1,0) -> QT17IA15.90 | F17: =VLOOKUP(A17,'[2]Plan - US NPI'!$C$6:$E$192,3,0) -> #N/A | G17: =VLOOKUP($A17,'[3]Plan - US NPI'!$C$6:$K$191,3,0) -> AXFIA | H17: =VLOOKUP($A17,'[3]Plan - US NPI'!$C$6:$K$191,9,0) -> PA Assembly | I17: QTNSN095288A.X12 | J17: QT PA ASSY, 095288A. REV X12, B25 PA ASSEMBLY FOR AXFIA/AXFIB | K17: 62 | L17: 16 | M17: New PWB- Order 2 sets of stencils- new profile board needed - New profile needed - Need STI- Stencil 04/23- PE54164 | R17: 46139
A18: QT19BA11.00 | B18: =MID(A18,3,11) -> 19BA11.00 | C18: =VLOOKUP(A18,[1]Summary!B:B,1,0) -> QT19BA11.00 | F18: =VLOOKUP(A18,'[2]Plan - US NPI'!$C$6:$E$192,3,0) -> #N/A | G18: =VLOOKUP($A18,'[3]Plan - US NPI'!$C$6:$K$191,3,0) -> AXOLA | H18: =VLOOKUP($A18,'[3]Plan - US NPI'!$C$6:$K$191,9,0) -> PA Assembly | I18: QTNSN095290A.X02 | J18: QT PA ASSY, 095290A. REV X02, B71 PA ASSEMBLY FOR AXOLBA | K18: 14 | L18: 17 | M18: Stencils due on the 27- Apr- No Esti
A19: QT19BA11.10 | B19: =MID(A19,3,11) -> 19BA11.10 | C19: =VLOOKUP(A19,[1]Summary!B:B,1,0) -> QT19BA11.10 | F19: =VLOOKUP(A19,'[2]Plan - US NPI'!$C$6:$E$192,3,0) -> #N/A | G19: =VLOOKUP($A19,'[3]Plan - US NPI'!$C$6:$K$191,3,0) -> AXOLA | H19: =VLOOKUP($A19,'[3]Plan - US NPI'!$C$6:$K$191,9,0) -> PA Assembly | I19: QTNSN095291A.X02 | J19: QT PA ASSY, 095291A. REV X02, B85 PA ASSEMBLY FOR AXOLBA | K19: 14 | L19: 18 | M19: Stencils due on the 27- Apr- No Esti- Tracking# 707296329356
A20: QT20LA21.00 | B20: =MID(A20,3,11) -> 20LA21.00 | C20: =VLOOKUP(A20,[1]Summary!B:B,1,0) -> QT20LA21.00 | F20: =VLOOKUP(A20,'[2]Plan - US NPI'!$C$6:$E$192,3,0) -> #N/A | G20: =VLOOKUP($A20,'[3]Plan - US NPI'!$C$6:$K$191,3,0) -> AXOLA | H20: =VLOOKUP($A20,'[3]Plan - US NPI'!$C$6:$K$191,9,0) -> TRX/PSU/BB Assembly | I20: QTNSN095286A.X02 | J20: QT TRX ASSY, 095286A. REV X02, TRX ASSEMBLY FOR AXOLA | K20: 10 | L20: 19 | M20: PWB X6 | PE54313 to be cp'd rpleace P7000738 with P67 | AOI and Xray data & Dage available -Send data ASAP | PE54792 - Released 25-Jun-26
A21: QT17IA25.30 | B21: =MID(A21,3,11) -> 17IA25.30 | C21: =VLOOKUP(A21,[1]Summary!B:B,1,0) -> QT17IA25.30 | D21: =MID(A21,3,11) -> 17IA25.30 | E21: Clean | F21: =VLOOKUP(A21,'[2]Plan - US NPI'!$C$6:$E$192,3,0) -> #N/A | G21: =VLOOKUP($A21,'[3]Plan - US NPI'!$C$6:$K$191,3,0) -> AXFIA | H21: =VLOOKUP($A21,'[3]Plan - US NPI'!$C$6:$K$191,9,0) -> TRX/PSU/BB Assembly | I21: QTNSN095266A.X12 | J21: QT TRX ASSY, 095266A. REV X12, TRX ASSEMBLY FOR AXFIA | K21: 47 | L21: 20 | M21: Kick off 21-May-26- ESTI -PE54408 - Released 29-May-26 | One more ESTI to be released | Stencil ETA 03-Jun-26 | PE54513- Work order relased 06/03
A22: QT17IA15.60 | B22: =MID(A22,3,11) -> 17IA15.60 | C22: =VLOOKUP(A22,[1]Summary!B:B,1,0) -> QT17IA15.60 | F22: =VLOOKUP(A22,'[2]Plan - US NPI'!$C$6:$E$192,3,0) -> #N/A | G22: =VLOOKUP($A22,'[3]Plan - US NPI'!$C$6:$K$191,3,0) -> AXFIA | H22: =VLOOKUP($A22,'[3]Plan - US NPI'!$C$6:$K$191,9,0) -> PA Assembly | I22: QTNSN095289A.X12 | J22: QT PA ASSY, 095289A. REV X12, B66 PA ASSEMBLY FOR AXFIA/AXFIB | K22: 188 | L22: 21 | M22: Kick off 21-May-26- ESTI - PE54407- WO Released 29-May-26
A23: QT17IA15.70 | B23: =MID(A23,3,11) -> 17IA15.70 | C23: =VLOOKUP(A23,[1]Summary!B:B,1,0) -> QT17IA15.70 | F23: =VLOOKUP(A23,'[2]Plan - US NPI'!$C$6:$E$192,3,0) -> #N/A | G23: =VLOOKUP($A23,'[3]Plan - US NPI'!$C$6:$K$191,3,0) -> AXFIA | H23: =VLOOKUP($A23,'[3]Plan - US NPI'!$C$6:$K$191,9,0) -> PA Assembly | I23: QTNSN095288A.X12 | J23: QT PA ASSY, 095288A. REV X12, B25 PA ASSEMBLY FOR AXFIA/AXFIB | K23: 188 | L23: 22 | M23: Kick off 21-May-26- ESTI - PE54405- WO Released 29-May-26
A24: QT17IA45.30 | B24: =MID(A24,3,11) -> 17IA45.30 | C24: =VLOOKUP(A24,[1]Summary!B:B,1,0) -> QT17IA45.30 | D24: =MID(A24,3,11) -> 17IA45.30 | E24: Clean | F24: =VLOOKUP(A24,'[2]Plan - US NPI'!$C$6:$E$192,3,0) -> #N/A | G24: =VLOOKUP($A24,'[3]Plan - US NPI'!$C$6:$K$191,3,0) -> AXFIA | H24: =VLOOKUP($A24,'[3]Plan - US NPI'!$C$6:$K$191,9,0) -> RRH Unit | I24: QTNSN476757A.X12 | J24: QT T/L UNIT ASSY, 476757A. REV X12, AXFIA AirScale RRH 4T8R n25/66 720W | K24: 47 | L24: 23 | M24: PE54409 & PE54856 - Released 29-May-26_ need to release work order- Relased 15-Jun-26 | Rework on the Chassis | N24: Updated Quote sent of 13-Jul-26
A25: QT17IA45.40 | B25: =MID(A25,3,11) -> 17IA45.40 | C25: =VLOOKUP(A25,[1]Summary!B:B,1,0) -> QT17IA45.40 | F25: =VLOOKUP(A25,'[2]Plan - US NPI'!$C$6:$E$192,3,0) -> #N/A | G25: =VLOOKUP($A25,'[3]Plan - US NPI'!$C$6:$K$191,3,0) -> #N/A | H25: =VLOOKUP($A25,'[3]Plan - US NPI'!$C$6:$K$191,9,0) -> #N/A | I25: QTNSN476757A.X12 | J25: QT T/L UNIT ASSY, 476757A. REV X12, AXFIA AirScale RRH 4T8R n25/66 720W | K25: 11 | L25: 24 | M25: Kick off- ESTI PE54381 - WO released
A26: QT17IA15.95 | B26: =MID(A26,3,11) -> 17IA15.95 | C26: =VLOOKUP(A26,[1]Summary!B:B,1,0) -> QT17IA15.95 | F26: =VLOOKUP(A26,'[2]Plan - US NPI'!$C$6:$E$192,3,0) -> #N/A | G26: =VLOOKUP($A26,'[3]Plan - US NPI'!$C$6:$K$191,3,0) -> AXFIA | H26: =VLOOKUP($A26,'[3]Plan - US NPI'!$C$6:$K$191,9,0) -> PA Assembly | I26: QTNSN095289A.X12 | J26: QT PA ASSY, 095289A. REV X12, B66 PA ASSEMBLY FOR AXFIA/AXFIB | K26: 140 | L26: 25 | M26: Stencils , same PWB, STI for Solder paste PE54356- requested to run on the 2oth of May | New profile needed for Different solder paste
A27: QT17IA15.96 | B27: =MID(A27,3,11) -> 17IA15.96 | C27: =VLOOKUP(A27,[1]Summary!B:B,1,0) -> QT17IA15.96 | F27: =VLOOKUP(A27,'[2]Plan - US NPI'!$C$6:$E$192,3,0) -> #N/A | G27: =VLOOKUP($A27,'[3]Plan - US NPI'!$C$6:$K$191,3,0) -> AXFIA | H27: =VLOOKUP($A27,'[3]Plan - US NPI'!$C$6:$K$191,9,0) -> PA Assembly | I27: QTNSN095288A.X12 | J27: QT PA ASSY, 095288A. REV X12, B25 PA ASSEMBLY FOR AXFIA/AXFIB | K27: 140 | L27: 26 | M27: PE54357- Solder paste STI- Received | New profile needed for Different solder paste
A28: QT20LA12.00 | B28: =MID(A28,3,11) -> 20LA12.00 | C28: =VLOOKUP(A28,[1]Summary!B:B,1,0) -> QT20LA12.00 | F28: =VLOOKUP(A28,'[2]Plan - US NPI'!$C$6:$E$192,3,0) -> #N/A | G28: =VLOOKUP($A28,'[3]Plan - US NPI'!$C$6:$K$191,3,0) -> AXOLA | H28: =VLOOKUP($A28,'[3]Plan - US NPI'!$C$6:$K$191,9,0) -> PA Assembly | I28: QTNSN095290A.X02 | J28: QT PA ASSY, 095290A. REV X02, B71 PA ASSEMBLY FOR AXOLBA | K28: 64 | L28: 27 | M28: Esti releasesed- PE54413- WO released 27-May-26- need profile approved
A29: QT20LA12.10 | B29: =MID(A29,3,11) -> 20LA12.10 | C29: =VLOOKUP(A29,[1]Summary!B:B,1,0) -> QT20LA12.10 | F29: =VLOOKUP(A29,'[2]Plan - US NPI'!$C$6:$E$192,3,0) -> #N/A | G29: =VLOOKUP($A29,'[3]Plan - US NPI'!$C$6:$K$191,3,0) -> AXOLA | H29: =VLOOKUP($A29,'[3]Plan - US NPI'!$C$6:$K$191,9,0) -> PA Assembly | I29: QTNSN095291A.X02 | J29: QT PA ASSY, 095291A. REV X02, B85 PA ASSEMBLY FOR AXOLBA | K29: 64 | L29: 28 | M29: Esti releasesed- WO released 27-May-26- Need profile approved
A30: QT20LA41.00 | B30: =MID(A30,3,11) -> 20LA41.00 | C30: =VLOOKUP(A30,[1]Summary!B:B,1,0) -> QT20LA41.00 | D30: =MID(A30,3,11) -> 20LA41.00 | E30: Clean | F30: =VLOOKUP(A30,'[2]Plan - US NPI'!$C$6:$E$192,3,0) -> #N/A | G30: =VLOOKUP($A30,'[3]Plan - US NPI'!$C$6:$K$191,3,0) -> AXOLA | H30: =VLOOKUP($A30,'[3]Plan - US NPI'!$C$6:$K$191,9,0) -> RRH Unit | I30: QTNSN476797A.X11 | J30: QT T/L UNIT ASSY, 476797A.REV X11, AXOLA AirScale RRH 4T4R n71/85 320W | K30: 8 | L30: 29 | M30: CTB- ESTI PE54470 | WO release today 03-Jun-26- Followed up on ESTI | TRX rework need to look at material | STI released -
A31: QT19BA21.00A | B31: =MID(A31,3,11) -> 19BA21.00A | C31: Released | D31: =MID(A31,3,11) -> 19BA21.00A | F31: =VLOOKUP(A31,'[2]Plan - US NPI'!$C$6:$E$192,3,0) -> #N/A | G31: AXOLBA | H31: TRX/PSU/BB Assembly | I31: QTNSN095804A.X11 | K31: 22 | L31: 30 | M31: Relased 06/12- Critical components | 2 pcs Skipping FT- Nokia to pick up | Parametric Data- * 8 boards need rework STI to be released- Cannot test | PE55020- Rework STI with 3 parts that we need to buy-Load independent demand- Rework quote 14 boards | N31: Quote sent
A32: QT19BA12.20 | B32: =MID(A32,3,11) -> 19BA12.20 | C32: =VLOOKUP(A32,[1]Summary!B:B,1,0) -> #N/A | D32: =MID(A32,3,11) -> 19BA12.20 | E32: Clean | F32: =VLOOKUP(A32,'[2]Plan - US NPI'!$C$6:$E$192,3,0) -> #N/A | G32: =VLOOKUP($A32,'[3]Plan - US NPI'!$C$6:$K$191,3,0) -> AXOLBA | H32: =VLOOKUP($A32,'[3]Plan - US NPI'!$C$6:$K$191,9,0) -> PA Assembly | I32: QTNSN095290A.X02 | K32: 32 | L32: 31 | M32: ESTI - Sac305 PE54542- Work order QT20LA12.00 increased to 64 units
A33: QT19BA12.30 | B33: =MID(A33,3,11) -> 19BA12.30 | C33: =VLOOKUP(A33,[1]Summary!B:B,1,0) -> #N/A | D33: =MID(A33,3,11) -> 19BA12.30 | E33: Clean | F33: =VLOOKUP(A33,'[2]Plan - US NPI'!$C$6:$E$192,3,0) -> #N/A | G33: =VLOOKUP($A33,'[3]Plan - US NPI'!$C$6:$K$191,3,0) -> AXOLBA | H33: =VLOOKUP($A33,'[3]Plan - US NPI'!$C$6:$K$191,9,0) -> PA Assembly | I33: QTNSN095291A.X02 | K33: 32 | L33: 32 | M33: ESTI - Sac305 PE54541- Work order QT20LA12.10 increased to 64 units
A34: QT19BA41.00 | B34: =MID(A34,3,11) -> 19BA41.00 | C34: Released | D34: =MID(A34,3,11) -> 19BA41.00 | F34: =VLOOKUP(A34,'[2]Plan - US NPI'!$C$6:$E$192,3,0) -> #N/A | G34: =VLOOKUP($A34,'[3]Plan - US NPI'!$C$6:$K$191,3,0) -> AXOLBA | H34: =VLOOKUP($A34,'[3]Plan - US NPI'!$C$6:$K$191,9,0) -> RRH Unit | I34: QTNSN476971A.X11 | K34: 8 | L34: 33 | M34: No ESTI_ Nokia checking -06/16 | Chassis and Filter check stock | ESTI to be released PE54770- Share costed bom- New CP To be loaded today | Assembly to be stopped | N34: Quote
A35: QT17IA24.20 | B35: =MID(A35,3,11) -> 17IA24.20 | C35: =VLOOKUP(A35,[1]Summary!B:B,1,0) -> QT17IA24.20 | D35: =MID(A35,3,11) -> 17IA24.20 | F35: =VLOOKUP(A35,'[2]Plan - US NPI'!$C$6:$E$192,3,0) -> #N/A | G35: =VLOOKUP($A35,'[3]Plan - US NPI'!$C$6:$K$191,3,0) -> AXFIA | H35: =VLOOKUP($A35,'[3]Plan - US NPI'!$C$6:$K$191,9,0) -> TRX/PSU/BB Assembly | I35: QTNSN095266A.X21 | K35: 29 | L35: 34 | M35: RelaseD 06/15 | Old profile can be used- Review with Jose current issues on the X12 build | Same profile as AXOLBA | N35: Quote sent- 07-Jul-26
A36: QT17IA14.70 | B36: =MID(A36,3,11) -> 17IA14.70 | C36: Released | D36: =MID(A36,3,11) -> 17IA14.70 | F36: AXFIA | G36: AXFIA | H36: PA Assembly | I36: QTNSN095288A.X21 | K36: 74 | L36: 35 | M36: PE54718 | PE54609 | PE54651 - Jose Stencils- Clean released 24-Jun-26- New ESTI for preform ( )| Any date for the Macom part P620299 | N36: Quote sent 13-July-26
A37: QT17IA14.60 | B37: =MID(A37,3,11) -> 17IA14.60 | C37: Released | D37: =MID(A37,3,11) -> 17IA14.60 | F37: =VLOOKUP(A37,'[2]Plan - US NPI'!$C$6:$E$192,3,0) -> #N/A | G37: =VLOOKUP($A37,'[3]Plan - US NPI'!$C$6:$K$191,3,0) -> AXFIA | H37: =VLOOKUP($A37,'[3]Plan - US NPI'!$C$6:$K$191,9,0) -> PA Assembly | I37: QTNSN095289A.X21 | K37: 74 | L37: 36 | M37: PE54719, PE54667 ,PE54611 STI- Jose Stencils- 3 shortages- not clean- 2 MTRs to Oulu, 1 Po from Distro-New STI to be released()- ON hold | N37: Quote sent 13-July-26
A38: QT18OA21.00 | B38: =MID(A38,3,11) -> 18OA21.00 | C38: Clean | D38: =MID(A38,3,11) -> 18OA21.00 | F38: =VLOOKUP(A38,'[2]Plan - US NPI'!$C$6:$E$192,3,0) -> #N/A | G38: =VLOOKUP($A38,'[3]Plan - US NPI'!$C$6:$K$191,3,0) -> AXOA | H38: =VLOOKUP($A38,'[3]Plan - US NPI'!$C$6:$K$191,9,0) -> TRX/PSU/BB Assembly | I38: QTNSN095725A.X12 | K38: 11 | L38: 37 | M38: Bom being updated- 06/16 | 2 Boards to be built without fixtures | PE54722 -P399539 & PE54797| Oven profile needed | On Hold -22-Jul-26 New date- Tooling neds to be moved to th line | N38: Updated Quote sent of 13-Jul-26
A39: QT20LA22.00 | B39: =MID(A39,3,11) -> 20LA22.00 | C39: Released | D39: =MID(A39,3,11) -> 20LA22.00 | F39: =VLOOKUP(A39,'[2]Plan - US NPI'!$C$6:$E$192,3,0) -> #N/A | G39: =VLOOKUP($A39,'[3]Plan - US NPI'!$C$6:$K$191,3,0) -> AXOLA | H39: =VLOOKUP($A39,'[3]Plan - US NPI'!$C$6:$K$191,9,0) -> TRX/PSU/BB Assembly | I39: QTNSN095803A.X03 | K39: 14 | L39: 38 | M39: 1 component dif from the 804A.X11 Build | STI PE54748 - released today | Stencil Same as 804 | ON HOLD- YK262800086 Ship "as-is" to Salvador | N39: Quote sent 13-July-26
A40: QT20LA15.93 | B40: =MID(A40,3,11) -> 20LA15.93 | C40: Kick off 30-Jun-26 | D40: =MID(A40,3,11) -> 20LA15.93 | G40: =VLOOKUP($A40,'[3]Plan - US NPI'!$C$6:$K$191,3,0) -> AXOLA | H40: =VLOOKUP($A40,'[3]Plan - US NPI'!$C$6:$K$191,9,0) -> PA Assembly | I40: QTNSN095290A.X02 | K40: 13 | L40: 39 | M40: PE54809- Release Work order-PWB supplier info- Clean | N40: Send Quote
...

Sheet AXOLA Po
A1: Purchase | B1: Country | C1: Product | D1: Qty | E1: Comments
A2: Order | B2: Key | C2: Code
A3: 51890951 | B3: Dallas | C3: 476797A.X11 | D3: 1 | E3: ok PO | F3: 1809150 | G3: 1.1
A4: 51890954 | B4: Dallas | C4: 476797A.X11 | D4: 1 | E4: ok PO | F4: 1809146 | G4: 1.1
A5: 51890954 | B5: Dallas | C5: 476797A.X11 | D5: 1 | E5: ok PO | F5: 1809146 | G5: 2.1
A6: 51896398 | B6: Dallas | C6: 476797A.X11 | D6: 2 | E6: ok PO
A7: 51890959 | B7: Dallas | C7: 476797A.X11 | D7: 1 | E7: ok PO | F7: 1809152 | G7: 1.1
A8: 51896492 | B8: Oulu | C8: 476797A.P01--X11 | D8: 1 | E8: ok PO
