Workbook

Sheet Shop Order
A1: Serial Number | B1: Workstation | C1: Process | D1: Qty | E1: Unit Status | F1: Last Updated | G1: Work order | H1: Part number | I1: Priority | J1: Comments | K1: Shipping date | L1: asdas
A2: YK260300123 | B2: NOT-IN-PROCESS | C2: NOT-IN-PROCESS | D2: 1 | E2: Unit Component (60) | F2: 46065.449 | G2: QT17IA14.00 | H2: QTNSN095288A.X03 | I2: =VLOOKUP(G2,Sheet2!A:D,4,0) -> 1
A3: YK260300124 | B3: NOT-IN-PROCESS | C3: NOT-IN-PROCESS | D3: 1 | E3: Unit Component (60) | F3: 46065.45 | G3: QT17IA14.00 | H3: QTNSN095288A.X03 | I3: =VLOOKUP(G3,Sheet2!A:D,4,0) -> 1
A4: YK260300125 | B4: NOT-IN-PROCESS | C4: NOT-IN-PROCESS | D4: 1 | E4: Unit Component (60) | F4: 46071.552 | G4: QT17IA14.00 | H4: QTNSN095288A.X03 | I4: =VLOOKUP(G4,Sheet2!A:D,4,0) -> 1
A5: YK260300126 | B5: NOT-IN-PROCESS | C5: NOT-IN-PROCESS | D5: 1 | E5: Unit Component (60) | F5: 46072.29 | G5: QT17IA14.00 | H5: QTNSN095288A.X03 | I5: =VLOOKUP(G5,Sheet2!A:D,4,0) -> 1
A6: YK260300127 | B6: NOT-IN-PROCESS | C6: NOT-IN-PROCESS | D6: 1 | E6: Unit Component (60) | F6: 46076.37 | G6: QT17IA14.00 | H6: QTNSN095288A.X03 | I6: =VLOOKUP(G6,Sheet2!A:D,4,0) -> 1
A7: YK260300128 | B7: SHIP Shipping | C7: Shipped to Customer | D7: 1 | E7: Shipped (40) | F7: 46112.311 | G7: QT17IA14.00 | H7: QTNSN095288A.X03 | I7: =VLOOKUP(G7,Sheet2!A:D,4,0) -> 1
A8: YK260300129 | B8: NOT-IN-PROCESS | C8: NOT-IN-PROCESS | D8: 1 | E8: Unit Component (60) | F8: 46065.432 | G8: QT17IA14.00 | H8: QTNSN095288A.X03 | I8: =VLOOKUP(G8,Sheet2!A:D,4,0) -> 1
A9: YK260300130 | B9: NOT-IN-PROCESS | C9: NOT-IN-PROCESS | D9: 1 | E9: Unit Component (60) | F9: 46071.282 | G9: QT17IA14.00 | H9: QTNSN095288A.X03 | I9: =VLOOKUP(G9,Sheet2!A:D,4,0) -> 1
A10: YK260300131 | B10: NOT-IN-PROCESS | C10: NOT-IN-PROCESS | D10: 1 | E10: Unit Component (60) | F10: 46076.374 | G10: QT17IA14.00 | H10: QTNSN095288A.X03 | I10: =VLOOKUP(G10,Sheet2!A:D,4,0) -> 1
A11: YK260300132 | B11: NOT-IN-PROCESS | C11: NOT-IN-PROCESS | D11: 1 | E11: Unit Component (60) | F11: 46065.431 | G11: QT17IA14.00 | H11: QTNSN095288A.X03 | I11: =VLOOKUP(G11,Sheet2!A:D,4,0) -> 1
A12: YK260300133 | B12: NOT-IN-PROCESS | C12: NOT-IN-PROCESS | D12: 1 | E12: Unit Component (60) | F12: 46072.486 | G12: QT17IA14.00 | H12: QTNSN095288A.X03 | I12: =VLOOKUP(G12,Sheet2!A:D,4,0) -> 1
A13: YK260300134 | B13: NOT-IN-PROCESS | C13: NOT-IN-PROCESS | D13: 1 | E13: Unit Component (60) | F13: 46065.449 | G13: QT17IA14.00 | H13: QTNSN095288A.X03 | I13: =VLOOKUP(G13,Sheet2!A:D,4,0) -> 1
... A158: YK260900007 | B158: RWK1 Repair Test | C158: Rework-1 | D158: 1 | E158: In Repair (25) | F158: 46142.377 | G158: QT17IA14.20 | H158: QTNSN095289A.X11 | I158: =VLOOKUP(G158,Sheet2!A:D,4,0) -> 7
A159: YK260900008 | B159: SHIP Shipping | C159: Shipped to Customer | D159: 1 | E159: Shipped (40) | F159: 46123.268 | G159: QT17IA14.20 | H159: QTNSN095289A.X11 | I159: =VLOOKUP(G159,Sheet2!A:D,4,0) -> 7 | K159: 46105
A160: YK260900009 | B160: SHIP Shipping | C160: Shipped to Customer | D160: 1 | E160: Shipped (40) | F160: 46123.268 | G160: QT17IA14.20 | H160: QTNSN095289A.X11 | I160: =VLOOKUP(G160,Sheet2!A:D,4,0) -> 7 | K160: 46105
A161: YK260900010 | B161: RWK1 Repair Test | C161: Rework-1 | D161: 1 | E161: In Repair (25) | F161: 46135.342 | G161: QT17IA14.20 | H161: QTNSN095289A.X11 | I161: =VLOOKUP(G161,Sheet2!A:D,4,0) -> 7
A162: YK260900011 | B162: SHIP Shipping | C162: Shipped to Customer | D162: 1 | E162: Shipped (40) | F162: 46123.268 | G162: QT17IA14.20 | H162: QTNSN095289A.X11 | I162: =VLOOKUP(G162,Sheet2!A:D,4,0) -> 7 | K162: 46105
A163: YK260900012 | B163: CMP1 Complete | C163: Complete | D163: 1 | E163: Finished (30) | F163: 46142.514 | G163: QT17IA14.20 | H163: QTNSN095289A.X11 | I163: =VLOOKUP(G163,Sheet2!A:D,4,0) -> 7
A164: YK260900013 | B164: CMP1 Complete | C164: Complete | D164: 1 | E164: Finished (30) | F164: 46141.507 | G164: QT17IA14.20 | H164: QTNSN095289A.X11 | I164: =VLOOKUP(G164,Sheet2!A:D,4,0) -> 7
A165: YK260900014 | B165: NOT-IN-PROCESS | C165: NOT-IN-PROCESS | D165: 1 | E165: Unit Component (60) | F165: 46140.311 | G165: QT17IA14.20 | H165: QTNSN095289A.X11 | I165: =VLOOKUP(G165,Sheet2!A:D,4,0) -> 7
A166: YK260900015 | B166: DBG1 Debug Test | C166: Xfr to Debug Test | D166: 1 | E166: In Repair Hold (29) | F166: 46128.38 | G166: QT17IA14.20 | H166: QTNSN095289A.X11 | I166: =VLOOKUP(G166,Sheet2!A:D,4,0) -> 7
A167: YK260900016 | B167: RWK1 Repair Test | C167: Rework-1 | D167: 1 | E167: In Repair (25) | F167: 46142.398 | G167: QT17IA14.20 | H167: QTNSN095289A.X11 | I167: =VLOOKUP(G167,Sheet2!A:D,4,0) -> 7
A168: YK260900017 | B168: CMP1 Complete | C168: Complete | D168: 1 | E168: Finished (30) | F168: 46139.587 | G168: QT17IA14.20 | H168: QTNSN095289A.X11 | I168: =VLOOKUP(G168,Sheet2!A:D,4,0) -> 7
A169: YK260900018 | B169: SHIP Shipping | C169: Shipped to Customer | D169: 1 | E169: Shipped (40) | F169: 46123.268 | G169: QT17IA14.20 | H169: QTNSN095289A.X11 | I169: =VLOOKUP(G169,Sheet2!A:D,4,0) -> 7 | K169: 46097
A170: YK260900019 | B170: RWK1 Repair Test | C170: Rework-1 | D170: 1 | E170: In Repair (25) | F170: 46141.403 | G170: QT17IA14.20 | H170: QTNSN095289A.X11 | I170: =VLOOKUP(G170,Sheet2!A:D,4,0) -> 7
A171: YK260900020 | B171: RWK1 Repair Test | C171: Rework-1 | D171: 1 | E171: In Repair (25) | F171: 46134.424 | G171: QT17IA14.20 | H171: QTNSN095289A.X11 | I171: =VLOOKUP(G171,Sheet2!A:D,4,0) -> 7
A172: YK260900021 | B172: FUN1 Func Test | C172: Functional Test-1 | D172: 1 | E172: On The Line (20) | F172: 46122.381 | G172: QT17IA14.20 | H172: QTNSN095289A.X11 | I172: =VLOOKUP(G172,Sheet2!A:D,4,0) -> 7
A173: YK260900022 | B173: CMP1 Complete | C173: Complete | D173: 1 | E173: Finished (30) | F173: 46123.559 | G173: QT17IA14.20 | H173: QTNSN095289A.X11 | I173: =VLOOKUP(G173,Sheet2!A:D,4,0) -> 7 | J173: Shipped | K173: 46128
A174: YK260900023 | B174: RWK1 Repair Test | C174: Rework-1 | D174: 1 | E174: In Repair (25) | F174: 46134.411 | G174: QT17IA14.20 | H174: QTNSN095289A.X11 | I174: =VLOOKUP(G174,Sheet2!A:D,4,0) -> 7
A175: YK260900024 | B175: CMP1 Complete | C175: Complete | D175: 1 | E175: Finished (30) | F175: 46128.361 | G175: QT17IA14.20 | H175: QTNSN095289A.X11 | I175: =VLOOKUP(G175,Sheet2!A:D,4,0) -> 7
A176: YK260900025 | B176: CMP1 Complete | C176: Complete | D176: 1 | E176: Finished (30) | F176: 46135.443 | G176: QT17IA14.20 | H176: QTNSN095289A.X11 | I176: =VLOOKUP(G176,Sheet2!A:D,4,0) -> 7
A177: YK260900026 | B177: RWK1 Repair Test | C177: Rework-1 | D177: 1 | E177: In Repair (25) | F177: 46134.363 | G177: QT17IA14.20 | H177: QTNSN095289A.X11 | I177: =VLOOKUP(G177,Sheet2!A:D,4,0) -> 7
A178: YK260900027 | B178: FUN1 Func Test | C178: Functional Test-1 | D178: 1 | E178: On The Line (20) | F178: 46122.382 | G178: QT17IA14.20 | H178: QTNSN095289A.X11 | I178: =VLOOKUP(G178,Sheet2!A:D,4,0) -> 7
A179: YK260900028 | B179: CMP1 Complete | C179: Complete | D179: 1 | E179: Finished (30) | F179: 46134.597 | G179: QT17IA14.20 | H179: QTNSN095289A.X11 | I179: =VLOOKUP(G179,Sheet2!A:D,4,0) -> 7
A180: YK260900029 | B180: SHIP Shipping | C180: Shipped to Customer | D180: 1 | E180: Shipped (40) | F180: 46123.268 | G180: QT17IA14.20 | H180: QTNSN095289A.X11 | I180: =VLOOKUP(G180,Sheet2!A:D,4,0) -> 7 | K180: 46097
A181: YK260900030 | B181: SHIP Shipping | C181: Shipped to Customer | D181: 1 | E181: Shipped (40) | F181: 46123.268 | G181: QT17IA14.20 | H181: QTNSN095289A.X11 | I181: =VLOOKUP(G181,Sheet2!A:D,4,0) -> 7 | K181: 46105
A182: YK260900031 | B182: SHIP Shipping | C182: Shipped to Customer | D182: 1 | E182: Shipped (40) | F182: 46123.268 | G182: QT17IA14.20 | H182: QTNSN095289A.X11 | I182: =VLOOKUP(G182,Sheet2!A:D,4,0) -> 7 | K182: 46112
A183: YK260900032 | B183: FUN1 Func Test | C183: Functional Test-1 | D183: 1 | E183: On The Line (20) | F183: 46115.654 | G183: QT17IA14.20 | H183: QTNSN095289A.X11 | I183: =VLOOKUP(G183,Sheet2!A:D,4,0) -> 7
A184: YK260900033 | B184: DBG1 Debug Test | C184: Xfr to Debug Test | D184: 1 | E184: In Repair Hold (29) | F184: 46128.399 | G184: QT17IA14.20 | H184: QTNSN095289A.X11 | I184: =VLOOKUP(G184,Sheet2!A:D,4,0) -> 7
...

Sheet Sheet22
A1: Serial Number | B1: Workstation | C1: Process | D1: Qty | E1: Unit Status | F1: Last Updated | G1: Work order | H1: Part number | I1: Priority | J1: Comments | K1: Shipping date | L1: asdas
A2: YK261100027 | B2: FUN1 Func Test | C2: Functional Test-1 | D2: 1 | E2: On The Line (20) | F2: 46142.616 | G2: QT17IA24.00 | H2: QTNSN095266A.X11 | I2: 9
A3: YK261100023 | B3: FUN1 Func Test | C3: Functional Test-1 | D3: 1 | E3: On The Line (20) | F3: 46142.579 | G3: QT17IA24.00 | H3: QTNSN095266A.X11 | I3: 9
A4: YK261100018 | B4: FUN1 Func Test | C4: Functional Test-1 | D4: 1 | E4: On The Line (20) | F4: 46142.571 | G4: QT17IA24.00 | H4: QTNSN095266A.X11 | I4: 9
A5: YK261100013 | B5: FUN1 Func Test | C5: Functional Test-1 | D5: 1 | E5: On The Line (20) | F5: 46142.577 | G5: QT17IA24.00 | H5: QTNSN095266A.X11 | I5: 9

Sheet Sheet23
A1: Serial Number | B1: Workstation | C1: Process | D1: Qty | E1: Unit Status | F1: Last Updated | G1: Work order | H1: Part number | I1: Priority | J1: Comments | K1: Shipping date | L1: asdas
A2: YK261700019 | B2: FUN1 Func Test | C2: Functional Test-1 | D2: 1 | E2: On The Line (20) | F2: 46142.583 | G2: QT17IA24.10 | H2: QTNSN095266A.X12 | I2: 13
A3: YK261700016 | B3: FUN1 Func Test | C3: Functional Test-1 | D3: 1 | E3: On The Line (20) | F3: 46142.586 | G3: QT17IA24.10 | H3: QTNSN095266A.X12 | I3: 13
A4: YK261700014 | B4: FUN1 Func Test | C4: Functional Test-1 | D4: 1 | E4: On The Line (20) | F4: 46142.59 | G4: QT17IA24.10 | H4: QTNSN095266A.X12 | I4: 13

Sheet Summary
A1: Row Labels | B1: Work order | C1: Part number | D1: Process | E1: Unit Status | F1: Count of Qty | M1: Actions
A2: 1 | B2: QT17IA14.00 | C2: QTNSN095288A.X03 | D2: NOT-IN-PROCESS | E2: Unit Component (60) | F2: 64 | M2: P690229- CS lot code needs to be rewokrde | MH code needs to be set aside
D3: Shipped to Customer | E3: Shipped (40) | F3: 6 | M3: 32 rework PA's per day- Dedicated rework person | Test Time 3 mins ??
A4: 2 | B4: QT17IA14.10 | C4: QTNSN095289A.X03 | D4: NOT-IN-PROCESS | E4: Unit Component (60) | F4: 64 | M4: Filter set up ip issue - TJ
D5: Shipped to Customer | E5: Shipped (40) | F5: 16 | M5: RTWP- Not powered up- Connector still not here
A6: 3 | B6: QT17IA23.00 | C6: QTNSN095266A.X02 | D6: NOT-IN-PROCESS | E6: Unit Component (60) | F6: 11 | G6: Send Credit for review | M6: LBTS, Heat sink 3D weight station -IP-TJ
D7: Shipped to Customer | E7: Shipped (40) | F7: 7 | M7: Internet issue for TRX testers- Jimmy
D8: Xfr to Debug Test | E8: In Repair Hold (29) | F8: 7
A9: 4 | B9: QT17IA43.00 | C9: QTNSN476757A.X02 | D9: Shipped to Customer | E9: Shipped (40) | F9: 20
A10: 5 | B10: QT17IA14.30 | C10: QTNSN095288A.X11 | D10: Complete | E10: Finished (30) | F10: 20
D11: Functional Test-1 | E11: On The Line (20) | F11: 2
D12: Shipped to Customer | E12: Shipped (40) | F12: 5
D13: Rework-1 | E13: In Repair (25) | F13: 10
A14: 6 | B14: QT17IA14.31 | C14: QTNSN095288A.X11 | D14: Complete | E14: Finished (30) | F14: 20
D15: Functional Test-1 | E15: On The Line (20) | F15: 1
D16: NOT-IN-PROCESS | E16: Unit Component (60) | F16: 1
D17: Shipped to Customer | E17: Shipped (40) | F17: 4
D18: Xfr to Debug Test | E18: In Repair Hold (29) | F18: 2
D19: Rework-1 | E19: In Repair (25) | F19: 9
A20: 7 | B20: QT17IA14.20 | C20: QTNSN095289A.X11 | D20: Complete | E20: Finished (30) | F20: 9
D21: Functional Test-1 | E21: On The Line (20) | F21: 5
D22: NOT-IN-PROCESS | E22: Unit Component (60) | F22: 1
D23: Shipped to Customer | E23: Shipped (40) | F23: 8
D24: Xfr to Debug Test | E24: In Repair Hold (29) | F24: 5
D25: Rework-1 | E25: In Repair (25) | F25: 9
A26: 8 | B26: QT17IA14.21 | C26: QTNSN095289A.X11 | D26: Complete | E26: Finished (30) | F26: 16
D27: Functional Test-1 | E27: On The Line (20) | F27: 3
D28: NOT-IN-PROCESS | E28: Unit Component (60) | F28: 3
D29: Shipped to Customer | E29: Shipped (40) | F29: 9
D30: Xfr to Debug Test | E30: In Repair Hold (29) | F30: 2
D31: Rework-1 | E31: In Repair (25) | F31: 4
A32: 9 | B32: QT17IA24.00 | C32: QTNSN095266A.X11 | D32: Complete | E32: Finished (30) | F32: 17 | G32: Serial no 30 Damaged
D33: Functional Test-1 | E33: On The Line (20) | F33: 4
D34: NOT-IN-PROCESS | E34: Unit Component (60) | F34: 5
D35: Shipped to Customer | E35: Shipped (40) | F35: 3
A36: 10 | B36: QT17IA44.00 | C36: QTNSN476757A.X11 | D36: Complete | E36: Finished (30) | F36: 1
D37: NOT-IN-PROCESS | E37: Traveler Printed (15) | F37: 9
D38: Assembly 1 - 1B | E38: On The Line Hold (28) | F38: 1
D39: Xfr to Debug Test | E39: In Repair Hold (29) | F39: 1
D40: UNTT | E40: On The Line (20) | F40: 1
...

Sheet Sheet2
A1: Unique id | B1: Part number | C1: Qty | D1: Priority | E1: STI/ Comments
A2: QT17IA14.00 | B2: QTNSN095288A.X03 | C2: 70 | D2: 1 | K2: Mh lot codes to MRB
A3: QT17IA14.10 | B3: QTNSN095289A.X03 | C3: 80 | D3: 2
A4: QT17IA23.00 | B4: QTNSN095266A.X02 | C4: 25 | D4: 3
A5: QT17IA43.00 | B5: QTNSN476757A.X02 | C5: 20 | D5: 4
A6: QT17IA14.30 | B6: QTNSN095288A.X11 | C6: 37 | D6: 5 | E6: eSTI PE53499. PE53575 add a note to remove shield and pre-drive, and for 840135A to use X1 version. PE53746 sent 03/13
A7: QT17IA14.31 | B7: QTNSN095288A.X11 | C7: 37 | D7: 6 | E7: eSTI PE53499. PE53575 add a note to remove shield and pre-drive, and for 840135A to use X1 version. PE53684 sent 03/13
A8: QT17IA14.20 | B8: QTNSN095289A.X11 | C8: 37 | D8: 7 | E8: STI PE53554 for 840135A to use X1 version. PE53499, .
A9: QT17IA14.21 | B9: QTNSN095289A.X11 | C9: 37 | D9: 8 | E9: PE53571 for 17IA14.21,add a note to remove shield and pre-driver. Create new eSTI for 17IA14.20 adding the same note. NEW PE53611
A10: QT17IA24.00 | B10: QTNSN095266A.X11 | C10: 29 | D10: 9 | E10: PE53604, PE53707,PE53847
A11: QT17IA44.00 | B11: QTNSN476757A.X11 | C11: 15 | D11: 10 | E11: PE53701
A12: QT17IA14.50 | B12: QTNSN095288A.X11 | C12: 124 | D12: 11 | E12: PE53891
A13: QT17IA14.40 | B13: QTNSN095289A.X11 | C13: 124 | D13: 12 | E13: PE54018
A14: QT17IA24.10 | B14: QTNSN095266A.X12 | C14: 41 | D14: 13 | E14: X12 Bom released - PE54073
A15: QT17IA44.10 | B15: QTNSN476757A.X11 | C15: 30 | D15: 14 | E15: STI To be released | F15: Quote
A16: QT19BA22.10A | B16: QTNSN095741A.X02 | C16: 27 | D16: 15 | E16: PE54044, PE54111- Stencil ETA 04/23 | F16: Quote sent | G16: Cancel work order
A17: QT19BA21.00 | B17: QTNSN095741A.X01 | C17: 10 | D17: 16 | E17: PE54033,PE54110- Stencil ETA 04/23 | F17: Quote sent | H17: Profiling boards sent to Sanmina - Nicolas to check
A18: QT17IA15.80 | B18: QTNSN095289A.X12 | C18: 62 | D18: 18 | E18: New PWB- Order 2 sets of stencils- new profile board needed - New profile needed - Need STI- Checkplots being worked - PE54185 | F18: Quote | G18: Confirm SMT Date | H18: Vince
A19: QT17IA15.90 | B19: QTNSN095288A.X12 | C19: 62 | D19: 17 | E19: New PWB- Order 2 sets of stencils- new profile board needed - New profile needed - Need STI- Stencil 04/23- PE54164 | F19: Quote | G19: Confirm SMT Date | H19: Vince
A20: QT19BA11.00 | B20: QTNSN095290A.X02 | C20: 14 | D20: 19 | E20: Stencils due on the 27- Apr- No Esti- Short solder paste | G20: Last part due on the 28th | H20: Release work order
A21: QT19BA11.10 | B21: QTNSN095291A.X02 | C21: 14 | D21: 20 | E21: Stencils due on the 27- Apr- No Esti- Short solder paste | G21: PCB due 05/06 | H21: Release work order
