Workbook

Sheet Shop Order
A1: Serial Number | B1: Workstation | C1: Process | D1: Qty | E1: Unit Status | F1: Last Updated | G1: Work order | H1: Part number | I1: Priority | J1: Comments | K1: Shipping date | L1: asdas
A2: YK260300123 | B2: NOT-IN-PROCESS | C2: NOT-IN-PROCESS | D2: 1 | E2: Unit Component (60) | F2: 46065.449 | G2: QT17IA14.00 | H2: QTNSN095288A.X03 | I2: =VLOOKUP(G2,Sheet2!A:F,6,0) -> 1
A3: YK260300124 | B3: NOT-IN-PROCESS | C3: NOT-IN-PROCESS | D3: 1 | E3: Unit Component (60) | F3: 46065.45 | G3: QT17IA14.00 | H3: QTNSN095288A.X03 | I3: =VLOOKUP(G3,Sheet2!A:F,6,0) -> 1
A4: YK260300125 | B4: NOT-IN-PROCESS | C4: NOT-IN-PROCESS | D4: 1 | E4: Unit Component (60) | F4: 46071.552 | G4: QT17IA14.00 | H4: QTNSN095288A.X03 | I4: =VLOOKUP(G4,Sheet2!A:F,6,0) -> 1
A5: YK260300126 | B5: NOT-IN-PROCESS | C5: NOT-IN-PROCESS | D5: 1 | E5: Unit Component (60) | F5: 46072.29 | G5: QT17IA14.00 | H5: QTNSN095288A.X03 | I5: =VLOOKUP(G5,Sheet2!A:F,6,0) -> 1
A6: YK260300127 | B6: NOT-IN-PROCESS | C6: NOT-IN-PROCESS | D6: 1 | E6: Unit Component (60) | F6: 46076.37 | G6: QT17IA14.00 | H6: QTNSN095288A.X03 | I6: =VLOOKUP(G6,Sheet2!A:F,6,0) -> 1
A7: YK260300128 | B7: SHIP Shipping | C7: Shipped to Customer | D7: 1 | E7: Shipped (40) | F7: 46112.311 | G7: QT17IA14.00 | H7: QTNSN095288A.X03 | I7: =VLOOKUP(G7,Sheet2!A:F,6,0) -> 1
A8: YK260300129 | B8: NOT-IN-PROCESS | C8: NOT-IN-PROCESS | D8: 1 | E8: Unit Component (60) | F8: 46065.432 | G8: QT17IA14.00 | H8: QTNSN095288A.X03 | I8: =VLOOKUP(G8,Sheet2!A:F,6,0) -> 1
A9: YK260300130 | B9: NOT-IN-PROCESS | C9: NOT-IN-PROCESS | D9: 1 | E9: Unit Component (60) | F9: 46071.282 | G9: QT17IA14.00 | H9: QTNSN095288A.X03 | I9: =VLOOKUP(G9,Sheet2!A:F,6,0) -> 1
A10: YK260300131 | B10: NOT-IN-PROCESS | C10: NOT-IN-PROCESS | D10: 1 | E10: Unit Component (60) | F10: 46076.374 | G10: QT17IA14.00 | H10: QTNSN095288A.X03 | I10: =VLOOKUP(G10,Sheet2!A:F,6,0) -> 1
A11: YK260300132 | B11: NOT-IN-PROCESS | C11: NOT-IN-PROCESS | D11: 1 | E11: Unit Component (60) | F11: 46065.431 | G11: QT17IA14.00 | H11: QTNSN095288A.X03 | I11: =VLOOKUP(G11,Sheet2!A:F,6,0) -> 1
A12: YK260300133 | B12: NOT-IN-PROCESS | C12: NOT-IN-PROCESS | D12: 1 | E12: Unit Component (60) | F12: 46072.486 | G12: QT17IA14.00 | H12: QTNSN095288A.X03 | I12: =VLOOKUP(G12,Sheet2!A:F,6,0) -> 1
A13: YK260300134 | B13: NOT-IN-PROCESS | C13: NOT-IN-PROCESS | D13: 1 | E13: Unit Component (60) | F13: 46065.449 | G13: QT17IA14.00 | H13: QTNSN095288A.X03 | I13: =VLOOKUP(G13,Sheet2!A:F,6,0) -> 1
... A1101: YK262101089 | B1101: SHIP Shipping | C1101: Shipped to Customer | D1101: 1 | E1101: Shipped (40) | F1101: 46171.297 | G1101: QT17IA45.40 | H1101: QTNSN476757A.X12 | I1101: =VLOOKUP(G1101,Sheet2!A:F,6,0) -> 26
A1102: YK262101090 | B1102: UNTT Unit Test | C1102: UNTT | D1102: 1 | E1102: On The Line (20) | F1102: 46170.562 | G1102: QT17IA45.40 | H1102: QTNSN476757A.X12 | I1102: =VLOOKUP(G1102,Sheet2!A:F,6,0) -> 26 | J1102: Ricky email
A1103: YK262101091 | B1103: PACK Packout | C1103: Packout | D1103: 1 | E1103: On The Line (20) | F1103: 46171.387 | G1103: QT17IA45.40 | H1103: QTNSN476757A.X12 | I1103: =VLOOKUP(G1103,Sheet2!A:F,6,0) -> 26
A1104: YK262101092 | B1104: FNLI Final Inspect | C1104: Final Inspect-1 | D1104: 1 | E1104: On The Line (20) | F1104: 46170.608 | G1104: QT17IA45.40 | H1104: QTNSN476757A.X12 | I1104: =VLOOKUP(G1104,Sheet2!A:F,6,0) -> 26
A1105: YK262101093 | B1105: SHIP Shipping | C1105: Shipped to Customer | D1105: 1 | E1105: Shipped (40) | F1105: 46171.294 | G1105: QT17IA45.40 | H1105: QTNSN476757A.X12 | I1105: =VLOOKUP(G1105,Sheet2!A:F,6,0) -> 26
A1106: YK262101094 | B1106: PACK Packout | C1106: Packout | D1106: 1 | E1106: On The Line (20) | F1106: 46171.329 | G1106: QT17IA45.40 | H1106: QTNSN476757A.X12 | I1106: =VLOOKUP(G1106,Sheet2!A:F,6,0) -> 26
A1107: YK262101095 | B1107: PACK Packout | C1107: Packout | D1107: 1 | E1107: On The Line (20) | F1107: 46171.367 | G1107: QT17IA45.40 | H1107: QTNSN476757A.X12 | I1107: =VLOOKUP(G1107,Sheet2!A:F,6,0) -> 26
A1108: YK262101096 | B1108: UNTT Unit Test | C1108: UNTT | D1108: 1 | E1108: On The Line (20) | F1108: 46170.578 | G1108: QT17IA45.40 | H1108: QTNSN476757A.X12 | I1108: =VLOOKUP(G1108,Sheet2!A:F,6,0) -> 26
A1109: YK261900001 | B1109: FUN1 Func Test | C1109: Functional Test-1 | D1109: 1 | E1109: On The Line (20) | F1109: 46155.588 | G1109: QT19BA11.00 | H1109: QTNSN095290A.X02 | I1109: =VLOOKUP(G1109,Sheet2!A:F,6,0) -> 19
A1110: YK261900002 | B1110: CMP1 Complete | C1110: Complete | D1110: 1 | E1110: Finished (30) | F1110: 46162.552 | G1110: QT19BA11.00 | H1110: QTNSN095290A.X02 | I1110: =VLOOKUP(G1110,Sheet2!A:F,6,0) -> 19
A1111: YK261900003 | B1111: XRAY | C1111: XRAY DAGE | D1111: 1 | E1111: On The Line (20) | F1111: 46154.709 | G1111: QT19BA11.00 | H1111: QTNSN095290A.X02 | I1111: =VLOOKUP(G1111,Sheet2!A:F,6,0) -> 19
A1112: YK261900004 | B1112: FUN1 Func Test | C1112: Functional Test-1 | D1112: 1 | E1112: On The Line (20) | F1112: 46155.596 | G1112: QT19BA11.00 | H1112: QTNSN095290A.X02 | I1112: =VLOOKUP(G1112,Sheet2!A:F,6,0) -> 19
A1113: YK261900005 | B1113: FUN1 Func Test | C1113: Functional Test-1 | D1113: 1 | E1113: On The Line (20) | F1113: 46155.594 | G1113: QT19BA11.00 | H1113: QTNSN095290A.X02 | I1113: =VLOOKUP(G1113,Sheet2!A:F,6,0) -> 19
A1114: YK261900006 | B1114: FUN1 Func Test | C1114: Functional Test-1 | D1114: 1 | E1114: On The Line (20) | F1114: 46155.598 | G1114: QT19BA11.00 | H1114: QTNSN095290A.X02 | I1114: =VLOOKUP(G1114,Sheet2!A:F,6,0) -> 19
... A1173: YK262000124 | B1173: FUN1 Func Test | C1173: Functional Test-1 | D1173: 1 | E1173: On The Line (20) | F1173: 46168.575 | G1173: QT20LA21.00 | H1173: QTNSN095286A.X02 | I1173: =VLOOKUP(G1173,Sheet2!A:F,6,0) -> 21

Sheet Sheet4
A1: Serial Number | B1: Workstation | C1: Process | D1: Qty | E1: Unit Status | F1: Last Updated | G1: Work order | H1: Part number | I1: Priority | J1: Comments | K1: Shipping date | L1: asdas
A2: YK260400025 | B2: DBG1 Debug Test | C2: Xfr to Debug Test | D2: 1 | E2: In Repair Hold (29) | F2: 46091.507 | G2: QT17IA23.00 | H2: QTNSN095266A.X02 | I2: 3
A3: YK260400024 | B3: DBG1 Debug Test | C3: Xfr to Debug Test | D3: 1 | E3: In Repair Hold (29) | F3: 46101.356 | G3: QT17IA23.00 | H3: QTNSN095266A.X02 | I3: 3
A4: YK260400021 | B4: DBG1 Debug Test | C4: Xfr to Debug Test | D4: 1 | E4: In Repair Hold (29) | F4: 46101.375 | G4: QT17IA23.00 | H4: QTNSN095266A.X02 | I4: 3
A5: YK260400017 | B5: DBG1 Debug Test | C5: Xfr to Debug Test | D5: 1 | E5: In Repair Hold (29) | F5: 46101.606 | G5: QT17IA23.00 | H5: QTNSN095266A.X02 | I5: 3
A6: YK260400014 | B6: DBG1 Debug Test | C6: Xfr to Debug Test | D6: 1 | E6: In Repair Hold (29) | F6: 46091.507 | G6: QT17IA23.00 | H6: QTNSN095266A.X02 | I6: 3
A7: YK260400010 | B7: DBG1 Debug Test | C7: Xfr to Debug Test | D7: 1 | E7: In Repair Hold (29) | F7: 46094.663 | G7: QT17IA23.00 | H7: QTNSN095266A.X02 | I7: 3
A8: YK260400007 | B8: DBG1 Debug Test | C8: Xfr to Debug Test | D8: 1 | E8: In Repair Hold (29) | F8: 46101.382 | G8: QT17IA23.00 | H8: QTNSN095266A.X02 | I8: 3

Sheet Sheet5
A1: Serial Number | B1: Workstation | C1: Process | D1: Qty | E1: Unit Status | F1: Last Updated | G1: Work order | H1: Part number | I1: Priority | J1: Comments | K1: Shipping date | L1: asdas
A2: YK261700028 | B2: RWK1 Repair Test | C2: Rework-1 | D2: 1 | E2: In Repair (25) | F2: 46170.497 | G2: QT17IA24.10 | H2: QTNSN095266A.X12 | I2: 13

Sheet Sheet6
A1: Serial Number | B1: Workstation | C1: Process | D1: Qty | E1: Unit Status | F1: Last Updated | G1: Work order | H1: Part number | I1: Priority | J1: Comments | K1: Shipping date | L1: asdas
A2: YK261802245 | B2: AOR1 AOI RWK S1 | C2: AOR1 AOI Repair S1 | D2: 1 | E2: In Repair (25) | F2: 46144.383 | G2: QT17IA15.80 | H2: QTNSN095289A.X12 | I2: 18

Sheet Sheet8
A1: Serial Number | B1: Workstation | C1: Process | D1: Qty | E1: Unit Status | F1: Last Updated | G1: Work order | H1: Part number | I1: Priority | J1: Comments | K1: Shipping date | L1: asdas
A2: YK261900003 | B2: XRAY | C2: XRAY DAGE | D2: 1 | E2: On The Line (20) | F2: 46154.709 | G2: QT19BA11.00 | H2: QTNSN095290A.X02 | I2: 19

Sheet Sheet9
A1: Serial Number | B1: Workstation | C1: Process | D1: Qty | E1: Unit Status | F1: Last Updated | G1: Work order | H1: Part number | I1: Priority | J1: Comments | K1: Shipping date | L1: asdas
A2: YK261900009 | B2: FUN1 Func Test | C2: Functional Test-1 | D2: 1 | E2: On The Line (20) | F2: 46155.6 | G2: QT19BA11.00 | H2: QTNSN095290A.X02 | I2: 19
A3: YK261900007 | B3: FUN1 Func Test | C3: Functional Test-1 | D3: 1 | E3: On The Line (20) | F3: 46155.591 | G3: QT19BA11.00 | H3: QTNSN095290A.X02 | I3: 19
A4: YK261900006 | B4: FUN1 Func Test | C4: Functional Test-1 | D4: 1 | E4: On The Line (20) | F4: 46155.598 | G4: QT19BA11.00 | H4: QTNSN095290A.X02 | I4: 19
A5: YK261900005 | B5: FUN1 Func Test | C5: Functional Test-1 | D5: 1 | E5: On The Line (20) | F5: 46155.594 | G5: QT19BA11.00 | H5: QTNSN095290A.X02 | I5: 19
A6: YK261900004 | B6: FUN1 Func Test | C6: Functional Test-1 | D6: 1 | E6: On The Line (20) | F6: 46155.596 | G6: QT19BA11.00 | H6: QTNSN095290A.X02 | I6: 19
A7: YK261900001 | B7: FUN1 Func Test | C7: Functional Test-1 | D7: 1 | E7: On The Line (20) | F7: 46155.588 | G7: QT19BA11.00 | H7: QTNSN095290A.X02 | I7: 19

Sheet Summary
A1: Row Labels | B1: Work order | C1: Part number | D1: Process | E1: Unit Status | F1: Count of Qty
A2: 1 | B2: QT17IA14.00 | C2: QTNSN095288A.X03 | D2: NOT-IN-PROCESS | E2: Unit Component (60) | F2: 64
D3: Shipped to Customer | E3: Shipped (40) | F3: 6
A4: 2 | B4: QT17IA14.10 | C4: QTNSN095289A.X03 | D4: NOT-IN-PROCESS | E4: Unit Component (60) | F4: 64
D5: Shipped to Customer | E5: Shipped (40) | F5: 16
A6: 3 | B6: QT17IA23.00 | C6: QTNSN095266A.X02 | D6: NOT-IN-PROCESS | E6: Unit Component (60) | F6: 11
D7: Shipped to Customer | E7: Shipped (40) | F7: 7
D8: Xfr to Debug Test | E8: In Repair Hold (29) | F8: 7
A9: 4 | B9: QT17IA43.00 | C9: QTNSN476757A.X02 | D9: Shipped to Customer | E9: Shipped (40) | F9: 20
A10: 5 | B10: QT17IA14.30 | C10: QTNSN095288A.X11 | D10: Complete | E10: Finished (30) | F10: 13
D11: Functional Test-1 | E11: On The Line (20) | F11: 2
D12: NOT-IN-PROCESS | E12: Unit Component (60) | F12: 11
D13: Shipped to Customer | E13: Shipped (40) | F13: 8
D14: UNTT | E14: On The Line (20) | F14: 1
D15: Rework-1 | E15: In Repair (25) | F15: 2
A16: 6 | B16: QT17IA14.31 | C16: QTNSN095288A.X11 | D16: Complete | E16: Finished (30) | F16: 12
D17: Functional Test-1 | E17: On The Line (20) | F17: 1
D18: NOT-IN-PROCESS | E18: Unit Component (60) | F18: 12
D19: Shipped to Customer | E19: Shipped (40) | F19: 8
D20: Xfr to Debug Test | E20: In Repair Hold (29) | F20: 1
D21: Rework-1 | E21: In Repair (25) | F21: 1
D22: Rework-3 | E22: In Repair (25) | F22: 2
A23: 7 | B23: QT17IA14.20 | C23: QTNSN095289A.X11 | D23: Complete | E23: Finished (30) | F23: 5
D24: Functional Test-1 | E24: On The Line (20) | F24: 5
D25: NOT-IN-PROCESS | E25: Unit Component (60) | F25: 8
D26: Shipped to Customer | E26: Shipped (40) | F26: 9
D27: Xfr to Debug Test | E27: In Repair Hold (29) | F27: 4
D28: Rework-1 | E28: In Repair (25) | F28: 3
D29: Rework-3 | E29: In Repair (25) | F29: 3
A30: 8 | B30: QT17IA14.21 | C30: QTNSN095289A.X11 | D30: Complete | E30: Finished (30) | F30: 1
D31: Functional Test-1 | E31: On The Line (20) | F31: 3
D32: NOT-IN-PROCESS | E32: Unit Component (60) | F32: 20
D33: Shipped to Customer | E33: Shipped (40) | F33: 9
D34: Xfr to Debug Test | E34: In Repair Hold (29) | F34: 4
A35: 9 | B35: QT17IA24.00 | C35: QTNSN095266A.X11 | D35: Complete | E35: Finished (30) | F35: 8 | G35: All units shipped per oracle
D36: Functional Test-1 | E36: On The Line (20) | F36: 1
D37: NOT-IN-PROCESS | E37: Unit Component (60) | F37: 15
D38: Shipped to Customer | E38: Shipped (40) | F38: 4
D39: Xfr to Debug Test | E39: In Repair Hold (29) | F39: 1
A40: 10 | B40: QT17IA44.00 | C40: QTNSN476757A.X11 | D40: Shipped to Customer | E40: Shipped (40) | F40: 8
...

Sheet Sheet2
A1: Unique id | B1: WO | C1: Part number | D1: Desc | E1: Qty | F1: Priority | G1: STI/ Comments
A2: QT17IA14.00 | B2: =VLOOKUP(A2,Summary!B:B,1,0) -> QT17IA14.00 | C2: QTNSN095288A.X03 | D2: #N/A | E2: 70 | F2: 1 | M2: Mh lot codes to MRB
A3: QT17IA14.10 | B3: =VLOOKUP(A3,Summary!B:B,1,0) -> QT17IA14.10 | C3: QTNSN095289A.X03 | D3: #N/A | E3: 80 | F3: 2 | M3: Solder paste Qtys
A4: QT17IA23.00 | B4: =VLOOKUP(A4,Summary!B:B,1,0) -> QT17IA23.00 | C4: QTNSN095266A.X02 | D4: #N/A | E4: 25 | F4: 3
A5: QT17IA43.00 | B5: =VLOOKUP(A5,Summary!B:B,1,0) -> QT17IA43.00 | C5: QTNSN476757A.X02 | D5: #N/A | E5: 20 | F5: 4
A6: QT17IA14.30 | B6: =VLOOKUP(A6,Summary!B:B,1,0) -> QT17IA14.30 | C6: QTNSN095288A.X11 | D6: QT PA ASSY, 095288A. REV X11, B25 PA ASSEMBLY FOR AXFIA/AXFIB | E6: 37 | F6: 5 | G6: eSTI PE53499. PE53575 add a note to remove shield and pre-drive, and for 840135A to use X1 version. PE53746 sent 03/13
A7: QT17IA14.31 | B7: =VLOOKUP(A7,Summary!B:B,1,0) -> QT17IA14.31 | C7: QTNSN095288A.X11 | D7: QT PA ASSY, 095288A. REV X11, B25 PA ASSEMBLY FOR AXFIA/AXFIB | E7: 37 | F7: 6 | G7: eSTI PE53499. PE53575 add a note to remove shield and pre-drive, and for 840135A to use X1 version. PE53684 sent 03/13
A8: QT17IA14.20 | B8: =VLOOKUP(A8,Summary!B:B,1,0) -> QT17IA14.20 | C8: QTNSN095289A.X11 | D8: QT PA ASSY, 095289A. REV X11, B66 PA ASSEMBLY FOR AXFIA/AXFIB | E8: 37 | F8: 7 | G8: STI PE53554 for 840135A to use X1 version. PE53499, .
A9: QT17IA14.21 | B9: =VLOOKUP(A9,Summary!B:B,1,0) -> QT17IA14.21 | C9: QTNSN095289A.X11 | D9: QT PA ASSY, 095289A. REV X11, B66 PA ASSEMBLY FOR AXFIA/AXFIB | E9: 37 | F9: 8 | G9: PE53571 for 17IA14.21,add a note to remove shield and pre-driver. Create new eSTI for 17IA14.20 adding the same note. NEW PE53611
A10: QT17IA24.00 | B10: =VLOOKUP(A10,Summary!B:B,1,0) -> QT17IA24.00 | C10: QTNSN095266A.X11 | D10: QT TRX ASSY, 095266A. REV X11, TRX ASSEMBLY FOR AXFIA | E10: 29 | F10: 9 | G10: PE53604, PE53707,PE53847
A11: QT17IA44.00 | B11: =VLOOKUP(A11,Summary!B:B,1,0) -> QT17IA44.00 | C11: QTNSN476757A.X11 | D11: RRH X11 | E11: 15 | F11: 10 | G11: PE53701
A12: QT17IA14.50 | B12: =VLOOKUP(A12,Summary!B:B,1,0) -> QT17IA14.50 | C12: QTNSN095288A.X11 | D12: QT PA ASSY, 095288A. REV X11, B25 PA ASSEMBLY FOR AXFIA/AXFIB | E12: 124 | F12: 11 | G12: PE53891
A13: QT17IA14.40 | B13: =VLOOKUP(A13,Summary!B:B,1,0) -> QT17IA14.40 | C13: QTNSN095289A.X11 | D13: QT PA ASSY, 095289A. REV X11, B66 PA ASSEMBLY FOR AXFIA/AXFIB | E13: 124 | F13: 12 | G13: PE54018
A14: QT17IA24.10 | B14: =VLOOKUP(A14,Summary!B:B,1,0) -> QT17IA24.10 | C14: QTNSN095266A.X12 | D14: QT TRX ASSY, 095266A. REV X12, TRX ASSEMBLY FOR AXFIA | E14: 41 | F14: 13 | G14: X12 Bom released - PE54073
A15: QT17IA44.10 | B15: =VLOOKUP(A15,Summary!B:B,1,0) -> #N/A | C15: QTNSN476757A.X12 | D15: QT T/L UNIT ASSY, 476757A. REV X12, AXFIA AirScale RRH 4T8R n25/66 720W | E15: 30 | F15: 14 | G15: Esti releasesed- Release wo- PE54404- Wo released 29-May-26
A16: QT19BA22.10A | B16: =VLOOKUP(A16,Summary!B:B,1,0) -> QT19BA22.10A | C16: QTNSN095741A.X02 | D16: #N/A | E16: 27 | F16: 15 | G16: PE54044, PE54111- Stencil ETA 04/23- Build Cancelled | H16: Check Material report for 2 units
A17: QT19BA21.00 | B17: =VLOOKUP(A17,Summary!B:B,1,0) -> #N/A | C17: QTNSN095741A.X01 | D17: #N/A | E17: 10 | F17: 16 | G17: PE54033,PE54110- Stencil ETA 04/23- Build Cancelled | H17: Check Material report for 2 units
A18: QT17IA15.80 | B18: =VLOOKUP(A18,Summary!B:B,1,0) -> QT17IA15.80 | C18: QTNSN095289A.X12 | D18: QT PA ASSY, 095289A. REV X12, B66 PA ASSEMBLY FOR AXFIA/AXFIB | E18: 62 | F18: 18 | G18: New PWB- Order 2 sets of stencils- new profile board needed - New profile needed - Need STI- Checkplots being worked - PE54185
A19: QT17IA15.90 | B19: =VLOOKUP(A19,Summary!B:B,1,0) -> QT17IA15.90 | C19: QTNSN095288A.X12 | D19: QT PA ASSY, 095288A. REV X12, B25 PA ASSEMBLY FOR AXFIA/AXFIB | E19: 62 | F19: 17 | G19: New PWB- Order 2 sets of stencils- new profile board needed - New profile needed - Need STI- Stencil 04/23- PE54164 | L19: 46139
A20: QT19BA11.00 | B20: =VLOOKUP(A20,Summary!B:B,1,0) -> QT19BA11.00 | C20: QTNSN095290A.X02 | D20: QT PA ASSY, 095290A. REV X02, B71 PA ASSEMBLY FOR AXOLBA | E20: 14 | F20: 19 | G20: Stencils due on the 27- Apr- No Esti
A21: QT19BA11.10 | B21: =VLOOKUP(A21,Summary!B:B,1,0) -> QT19BA11.10 | C21: QTNSN095291A.X02 | D21: QT PA ASSY, 095291A. REV X02, B85 PA ASSEMBLY FOR AXOLBA | E21: 14 | F21: 20 | G21: Stencils due on the 27- Apr- No Esti- Tracking# 707296329356
A22: QT20LA21.00 | B22: =VLOOKUP(A22,Summary!B:B,1,0) -> QT20LA21.00 | C22: QTNSN095286A.X02 | D22: QT TRX ASSY, 095286A. REV X02, TRX ASSEMBLY FOR AXOLA | E22: 10 | F22: 21 | G22: PWB X6 | PE54313 to be cp'd rpleace P7000738 with P67 | AOI and Xray data & Dage available -Send data ASAP
A23: QT17IA25.30 | B23: =VLOOKUP(A23,Summary!B:B,1,0) -> #N/A | C23: QTNSN095266A.X12 | D23: QT TRX ASSY, 095266A. REV X12, TRX ASSEMBLY FOR AXFIA | E23: 47 | F23: 22 | G23: Kick off 21-May-26- ESTI -PE54408 - Released 29-May-26 | One more ESTI to be released | Stencil ETA 01-Jun-26
A24: QT17IA15.60 | B24: =VLOOKUP(A24,Summary!B:B,1,0) -> #N/A | C24: QTNSN095289A.X12 | D24: QT PA ASSY, 095289A. REV X12, B66 PA ASSEMBLY FOR AXFIA/AXFIB | E24: 188 | F24: 23 | G24: Kick off 21-May-26- ESTI - PE54407- WO Released 29-May-26 | H24: Durafuse
A25: QT17IA15.70 | B25: =VLOOKUP(A25,Summary!B:B,1,0) -> #N/A | C25: QTNSN095288A.X12 | D25: QT PA ASSY, 095288A. REV X12, B25 PA ASSEMBLY FOR AXFIA/AXFIB | E25: 188 | F25: 24 | G25: Kick off 21-May-26- ESTI - PE54405- WO Released 29-May-26 | H25: Durafuse
A26: QT17IA45.30 | B26: =VLOOKUP(A26,Summary!B:B,1,0) -> #N/A | C26: QTNSN476757A.X12 | D26: QT T/L UNIT ASSY, 476757A. REV X12, AXFIA AirScale RRH 4T8R n25/66 720W | E26: 47 | F26: 25 | G26: PE54409 - Released 29-May-26_ need to release work order
A27: QT17IA45.40 | B27: =VLOOKUP(A27,Summary!B:B,1,0) -> QT17IA45.40 | C27: QTNSN476757A.X12 | D27: QT T/L UNIT ASSY, 476757A. REV X12, AXFIA AirScale RRH 4T8R n25/66 720W | E27: 11 | F27: 26 | G27: Kick off- ESTI PE54381 - WO released
A28: QT17IA15.95 | B28: =VLOOKUP(A28,Summary!B:B,1,0) -> QT17IA15.95 | C28: QTNSN095289A.X12 | D28: QT PA ASSY, 095289A. REV X12, B66 PA ASSEMBLY FOR AXFIA/AXFIB | E28: 140 | F28: 27 | G28: Stencils , same PWB, STI for Solder paste PE54356- requested to run on the 2oth of May | New profile needed for Different solder paste | H28: Quote Sent 29-May-26
A29: QT17IA15.96 | B29: =VLOOKUP(A29,Summary!B:B,1,0) -> QT17IA15.96 | C29: QTNSN095288A.X12 | D29: QT PA ASSY, 095288A. REV X12, B25 PA ASSEMBLY FOR AXFIA/AXFIB | E29: 140 | F29: 28 | G29: PE54357- Solder paste STI- Received | New profile needed for Different solder paste | H29: Quote Sent 29-May-26
A30: QT20LA12.00 | B30: =VLOOKUP(A30,Summary!B:B,1,0) -> #N/A | C30: QTNSN095290A.X02 | D30: QT PA ASSY, 095290A. REV X02, B71 PA ASSEMBLY FOR AXOLBA | E30: 32 | F30: 29 | G30: Esti releasesed- PE54413- WO released 27-May-26
A31: QT20LA12.10 | B31: =VLOOKUP(A31,Summary!B:B,1,0) -> #N/A | C31: QTNSN095291A.X02 | D31: QT PA ASSY, 095291A. REV X02, B85 PA ASSEMBLY FOR AXOLBA | E31: 32 | F31: 30 | G31: Esti releasesed- WO released 27-May-26
A32: QT20LA41.00 | B32: =VLOOKUP(A32,Summary!B:B,1,0) -> #N/A | C32: QTNSN476797A.X11 | D32: QT T/L UNIT ASSY, 476797A.REV X11, AXOLA AirScale RRH 4T4R n71/85 320W | E32: 8 | F32: 31 | G32: CTB- ESTI PE54470
