Workbook

Sheet Shop Order
A1: Serial Number | B1: Workstation | C1: Process | D1: Qty | E1: Unit Status | F1: Last Updated | G1: Work order | H1: Part number | I1: Priority | J1: Comments | K1: Shipping date | L1: asdas
A2: YK260300123 | B2: NOT-IN-PROCESS | C2: NOT-IN-PROCESS | D2: 1 | E2: Unit Component (60) | F2: 46065.449 | G2: QT17IA14.00 | H2: QTNSN095288A.X03 | I2: =VLOOKUP(G2,Sheet2!A:H,8,0) -> 1
A3: YK260300124 | B3: NOT-IN-PROCESS | C3: NOT-IN-PROCESS | D3: 1 | E3: Unit Component (60) | F3: 46065.45 | G3: QT17IA14.00 | H3: QTNSN095288A.X03 | I3: =VLOOKUP(G3,Sheet2!A:H,8,0) -> 1
A4: YK260300125 | B4: NOT-IN-PROCESS | C4: NOT-IN-PROCESS | D4: 1 | E4: Unit Component (60) | F4: 46071.552 | G4: QT17IA14.00 | H4: QTNSN095288A.X03 | I4: =VLOOKUP(G4,Sheet2!A:H,8,0) -> 1
A5: YK260300126 | B5: NOT-IN-PROCESS | C5: NOT-IN-PROCESS | D5: 1 | E5: Unit Component (60) | F5: 46072.29 | G5: QT17IA14.00 | H5: QTNSN095288A.X03 | I5: =VLOOKUP(G5,Sheet2!A:H,8,0) -> 1
A6: YK260300127 | B6: NOT-IN-PROCESS | C6: NOT-IN-PROCESS | D6: 1 | E6: Unit Component (60) | F6: 46076.37 | G6: QT17IA14.00 | H6: QTNSN095288A.X03 | I6: =VLOOKUP(G6,Sheet2!A:H,8,0) -> 1
A7: YK260300128 | B7: SHIP Shipping | C7: Shipped to Customer | D7: 1 | E7: Shipped (40) | F7: 46112.311 | G7: QT17IA14.00 | H7: QTNSN095288A.X03 | I7: =VLOOKUP(G7,Sheet2!A:H,8,0) -> 1
A8: YK260300129 | B8: NOT-IN-PROCESS | C8: NOT-IN-PROCESS | D8: 1 | E8: Unit Component (60) | F8: 46065.432 | G8: QT17IA14.00 | H8: QTNSN095288A.X03 | I8: =VLOOKUP(G8,Sheet2!A:H,8,0) -> 1
A9: YK260300130 | B9: NOT-IN-PROCESS | C9: NOT-IN-PROCESS | D9: 1 | E9: Unit Component (60) | F9: 46071.282 | G9: QT17IA14.00 | H9: QTNSN095288A.X03 | I9: =VLOOKUP(G9,Sheet2!A:H,8,0) -> 1
A10: YK260300131 | B10: NOT-IN-PROCESS | C10: NOT-IN-PROCESS | D10: 1 | E10: Unit Component (60) | F10: 46076.374 | G10: QT17IA14.00 | H10: QTNSN095288A.X03 | I10: =VLOOKUP(G10,Sheet2!A:H,8,0) -> 1
A11: YK260300132 | B11: NOT-IN-PROCESS | C11: NOT-IN-PROCESS | D11: 1 | E11: Unit Component (60) | F11: 46065.431 | G11: QT17IA14.00 | H11: QTNSN095288A.X03 | I11: =VLOOKUP(G11,Sheet2!A:H,8,0) -> 1
A12: YK260300133 | B12: NOT-IN-PROCESS | C12: NOT-IN-PROCESS | D12: 1 | E12: Unit Component (60) | F12: 46072.486 | G12: QT17IA14.00 | H12: QTNSN095288A.X03 | I12: =VLOOKUP(G12,Sheet2!A:H,8,0) -> 1
A13: YK260300134 | B13: NOT-IN-PROCESS | C13: NOT-IN-PROCESS | D13: 1 | E13: Unit Component (60) | F13: 46065.449 | G13: QT17IA14.00 | H13: QTNSN095288A.X03 | I13: =VLOOKUP(G13,Sheet2!A:H,8,0) -> 1
... A1101: YK262100983 | B1101: NOT-IN-PROCESS | C1101: NOT-IN-PROCESS | D1101: 1 | E1101: Traveler Printed (15) | F1101: 46164.308 | G1101: QT17IA15.95 | H1101: QTNSN095289A.X12 | I1101: =VLOOKUP(G1101,Sheet2!A:H,8,0) -> 27
A1102: YK262100984 | B1102: NOT-IN-PROCESS | C1102: NOT-IN-PROCESS | D1102: 1 | E1102: Traveler Printed (15) | F1102: 46164.308 | G1102: QT17IA15.95 | H1102: QTNSN095289A.X12 | I1102: =VLOOKUP(G1102,Sheet2!A:H,8,0) -> 27 | J1102: Ricky email
A1103: YK262100985 | B1103: NOT-IN-PROCESS | C1103: NOT-IN-PROCESS | D1103: 1 | E1103: Traveler Printed (15) | F1103: 46164.308 | G1103: QT17IA15.95 | H1103: QTNSN095289A.X12 | I1103: =VLOOKUP(G1103,Sheet2!A:H,8,0) -> 27
A1104: YK262100986 | B1104: NOT-IN-PROCESS | C1104: NOT-IN-PROCESS | D1104: 1 | E1104: Traveler Printed (15) | F1104: 46164.308 | G1104: QT17IA15.95 | H1104: QTNSN095289A.X12 | I1104: =VLOOKUP(G1104,Sheet2!A:H,8,0) -> 27
A1105: YK262100987 | B1105: NOT-IN-PROCESS | C1105: NOT-IN-PROCESS | D1105: 1 | E1105: Traveler Printed (15) | F1105: 46164.308 | G1105: QT17IA15.95 | H1105: QTNSN095289A.X12 | I1105: =VLOOKUP(G1105,Sheet2!A:H,8,0) -> 27
A1106: YK262100988 | B1106: NOT-IN-PROCESS | C1106: NOT-IN-PROCESS | D1106: 1 | E1106: Traveler Printed (15) | F1106: 46164.308 | G1106: QT17IA15.95 | H1106: QTNSN095289A.X12 | I1106: =VLOOKUP(G1106,Sheet2!A:H,8,0) -> 27
A1107: YK262100989 | B1107: NOT-IN-PROCESS | C1107: NOT-IN-PROCESS | D1107: 1 | E1107: Traveler Printed (15) | F1107: 46164.308 | G1107: QT17IA15.95 | H1107: QTNSN095289A.X12 | I1107: =VLOOKUP(G1107,Sheet2!A:H,8,0) -> 27
A1108: YK262100990 | B1108: NOT-IN-PROCESS | C1108: NOT-IN-PROCESS | D1108: 1 | E1108: Traveler Printed (15) | F1108: 46164.308 | G1108: QT17IA15.95 | H1108: QTNSN095289A.X12 | I1108: =VLOOKUP(G1108,Sheet2!A:H,8,0) -> 27
A1109: YK262100991 | B1109: NOT-IN-PROCESS | C1109: NOT-IN-PROCESS | D1109: 1 | E1109: Traveler Printed (15) | F1109: 46164.308 | G1109: QT17IA15.95 | H1109: QTNSN095289A.X12 | I1109: =VLOOKUP(G1109,Sheet2!A:H,8,0) -> 27
A1110: YK262100992 | B1110: NOT-IN-PROCESS | C1110: NOT-IN-PROCESS | D1110: 1 | E1110: Traveler Printed (15) | F1110: 46164.308 | G1110: QT17IA15.95 | H1110: QTNSN095289A.X12 | I1110: =VLOOKUP(G1110,Sheet2!A:H,8,0) -> 27
A1111: YK262100993 | B1111: NOT-IN-PROCESS | C1111: NOT-IN-PROCESS | D1111: 1 | E1111: Traveler Printed (15) | F1111: 46164.308 | G1111: QT17IA15.95 | H1111: QTNSN095289A.X12 | I1111: =VLOOKUP(G1111,Sheet2!A:H,8,0) -> 27
A1112: YK262100994 | B1112: NOT-IN-PROCESS | C1112: NOT-IN-PROCESS | D1112: 1 | E1112: Traveler Printed (15) | F1112: 46164.308 | G1112: QT17IA15.95 | H1112: QTNSN095289A.X12 | I1112: =VLOOKUP(G1112,Sheet2!A:H,8,0) -> 27
A1113: YK262100995 | B1113: NOT-IN-PROCESS | C1113: NOT-IN-PROCESS | D1113: 1 | E1113: Traveler Printed (15) | F1113: 46164.308 | G1113: QT17IA15.95 | H1113: QTNSN095289A.X12 | I1113: =VLOOKUP(G1113,Sheet2!A:H,8,0) -> 27
A1114: YK262100996 | B1114: NOT-IN-PROCESS | C1114: NOT-IN-PROCESS | D1114: 1 | E1114: Traveler Printed (15) | F1114: 46164.308 | G1114: QT17IA15.95 | H1114: QTNSN095289A.X12 | I1114: =VLOOKUP(G1114,Sheet2!A:H,8,0) -> 27
... A1643: YK262000124 | B1643: FUN1 Func Test | C1643: Functional Test-1 | D1643: 1 | E1643: On The Line (20) | F1643: 46168.575 | G1643: QT20LA21.00 | H1643: QTNSN095286A.X02 | I1643: =VLOOKUP(G1643,Sheet2!A:H,8,0) -> 21

Sheet Summary
A1: Row Labels | B1: Work order | C1: Part number | D1: Process | E1: Unit Status | F1: Count of Qty
A2: 1 | B2: QT17IA14.00 | C2: QTNSN095288A.X03 | D2: NOT-IN-PROCESS | E2: Unit Component (60) | F2: 64 | L2: =MID(B2,3,11) -> 17IA14.00
D3: Shipped to Customer | E3: Shipped (40) | F3: 6 | L3: =MID(B3,3,11)
A4: 2 | B4: QT17IA14.10 | C4: QTNSN095289A.X03 | D4: NOT-IN-PROCESS | E4: Unit Component (60) | F4: 64 | L4: =MID(B4,3,11) -> 17IA14.10
D5: Shipped to Customer | E5: Shipped (40) | F5: 16 | L5: =MID(B5,3,11)
A6: 3 | B6: QT17IA23.00 | C6: QTNSN095266A.X02 | D6: NOT-IN-PROCESS | E6: Unit Component (60) | F6: 11 | L6: =MID(B6,3,11) -> 17IA23.00
D7: Shipped to Customer | E7: Shipped (40) | F7: 7 | L7: =MID(B7,3,11)
D8: Xfr to Debug Test | E8: In Repair Hold (29) | F8: 7 | L8: =MID(B8,3,11)
A9: 4 | B9: QT17IA43.00 | C9: QTNSN476757A.X02 | D9: Shipped to Customer | E9: Shipped (40) | F9: 20 | L9: =MID(B9,3,11) -> 17IA43.00
A10: 5 | B10: QT17IA14.30 | C10: QTNSN095288A.X11 | D10: Complete | E10: Finished (30) | F10: 13 | L10: =MID(B10,3,11) -> 17IA14.30
D11: Functional Test-1 | E11: On The Line (20) | F11: 2 | L11: =MID(B11,3,11)
D12: NOT-IN-PROCESS | E12: Unit Component (60) | F12: 11 | L12: =MID(B12,3,11)
D13: Shipped to Customer | E13: Shipped (40) | F13: 8 | L13: =MID(B13,3,11)
D14: UNTT | E14: On The Line (20) | F14: 1 | L14: =MID(B14,3,11)
D15: Rework-1 | E15: In Repair (25) | F15: 2 | L15: =MID(B15,3,11)
A16: 6 | B16: QT17IA14.31 | C16: QTNSN095288A.X11 | D16: Complete | E16: Finished (30) | F16: 12 | L16: =MID(B16,3,11) -> 17IA14.31
D17: Functional Test-1 | E17: On The Line (20) | F17: 1 | L17: =MID(B17,3,11)
D18: NOT-IN-PROCESS | E18: Unit Component (60) | F18: 12 | L18: =MID(B18,3,11)
D19: Shipped to Customer | E19: Shipped (40) | F19: 8 | L19: =MID(B19,3,11)
D20: Xfr to Debug Test | E20: In Repair Hold (29) | F20: 1 | L20: =MID(B20,3,11)
D21: Rework-1 | E21: In Repair (25) | F21: 1 | L21: =MID(B21,3,11)
D22: Rework-3 | E22: In Repair (25) | F22: 2 | L22: =MID(B22,3,11)
A23: 7 | B23: QT17IA14.20 | C23: QTNSN095289A.X11 | D23: Complete | E23: Finished (30) | F23: 4 | L23: =MID(B23,3,11) -> 17IA14.20
D24: Functional Test-1 | E24: On The Line (20) | F24: 5 | L24: =MID(B24,3,11)
D25: NOT-IN-PROCESS | E25: Unit Component (60) | F25: 8 | L25: =MID(B25,3,11)
D26: Shipped to Customer | E26: Shipped (40) | F26: 10 | L26: =MID(B26,3,11)
D27: Xfr to Debug Test | E27: In Repair Hold (29) | F27: 4 | L27: =MID(B27,3,11)
D28: Rework-1 | E28: In Repair (25) | F28: 3 | L28: =MID(B28,3,11)
D29: Rework-3 | E29: In Repair (25) | F29: 3 | L29: =MID(B29,3,11)
A30: 8 | B30: QT17IA14.21 | C30: QTNSN095289A.X11 | D30: Functional Test-1 | E30: On The Line (20) | F30: 3 | L30: =MID(B30,3,11) -> 17IA14.21
D31: NOT-IN-PROCESS | E31: Unit Component (60) | F31: 20 | L31: =MID(B31,3,11)
D32: Shipped to Customer | E32: Shipped (40) | F32: 10 | L32: =MID(B32,3,11)
D33: Xfr to Debug Test | E33: In Repair Hold (29) | F33: 4 | L33: =MID(B33,3,11)
A34: 9 | B34: QT17IA24.00 | C34: QTNSN095266A.X11 | D34: Complete | E34: Finished (30) | F34: 2 | L34: =MID(B34,3,11) -> 17IA24.00
D35: Functional Test-1 | E35: On The Line (20) | F35: 1 | L35: =MID(B35,3,11)
D36: NOT-IN-PROCESS | E36: Unit Component (60) | F36: 15 | L36: =MID(B36,3,11)
D37: Shipped to Customer | E37: Shipped (40) | F37: 10 | L37: =MID(B37,3,11)
D38: Xfr to Debug Test | E38: In Repair Hold (29) | F38: 1 | L38: =MID(B38,3,11)
A39: 10 | B39: QT17IA44.00 | C39: QTNSN476757A.X11 | D39: Shipped to Customer | E39: Shipped (40) | F39: 11 | L39: =MID(B39,3,11) -> 17IA44.00
D40: Packout | E40: On The Line (20) | F40: 4 | L40: =MID(B40,3,11)
...

Sheet Sheet2
A1: Unique id | B1: WO | E1: Part number | F1: Desc | G1: Qty | H1: Priority | I1: STI/ Comments
A2: QT17IA14.00 | B2: =VLOOKUP(A2,[1]Summary!B:B,1,0) -> QT17IA14.00 | E2: QTNSN095288A.X03 | F2: #N/A | G2: 70 | H2: 1 | O2: Mh lot codes to MRB
A3: QT17IA14.10 | B3: =VLOOKUP(A3,[1]Summary!B:B,1,0) -> QT17IA14.10 | E3: QTNSN095289A.X03 | F3: #N/A | G3: 80 | H3: 2 | O3: Solder paste Qtys
A4: QT17IA23.00 | B4: =VLOOKUP(A4,[1]Summary!B:B,1,0) -> QT17IA23.00 | E4: QTNSN095266A.X02 | F4: #N/A | G4: 25 | H4: 3
A5: QT17IA43.00 | B5: =VLOOKUP(A5,[1]Summary!B:B,1,0) -> QT17IA43.00 | E5: QTNSN476757A.X02 | F5: #N/A | G5: 20 | H5: 4
A6: QT17IA14.30 | B6: =VLOOKUP(A6,[1]Summary!B:B,1,0) -> QT17IA14.30 | E6: QTNSN095288A.X11 | F6: QT PA ASSY, 095288A. REV X11, B25 PA ASSEMBLY FOR AXFIA/AXFIB | G6: 37 | H6: 5 | I6: eSTI PE53499. PE53575 add a note to remove shield and pre-drive, and for 840135A to use X1 version. PE53746 sent 03/13
A7: QT17IA14.31 | B7: =VLOOKUP(A7,[1]Summary!B:B,1,0) -> QT17IA14.31 | E7: QTNSN095288A.X11 | F7: QT PA ASSY, 095288A. REV X11, B25 PA ASSEMBLY FOR AXFIA/AXFIB | G7: 37 | H7: 6 | I7: eSTI PE53499. PE53575 add a note to remove shield and pre-drive, and for 840135A to use X1 version. PE53684 sent 03/13
A8: QT17IA14.20 | B8: =VLOOKUP(A8,[1]Summary!B:B,1,0) -> QT17IA14.20 | E8: QTNSN095289A.X11 | F8: QT PA ASSY, 095289A. REV X11, B66 PA ASSEMBLY FOR AXFIA/AXFIB | G8: 37 | H8: 7 | I8: STI PE53554 for 840135A to use X1 version. PE53499, .
A9: QT17IA14.21 | B9: =VLOOKUP(A9,[1]Summary!B:B,1,0) -> QT17IA14.21 | E9: QTNSN095289A.X11 | F9: QT PA ASSY, 095289A. REV X11, B66 PA ASSEMBLY FOR AXFIA/AXFIB | G9: 37 | H9: 8 | I9: PE53571 for 17IA14.21,add a note to remove shield and pre-driver. Create new eSTI for 17IA14.20 adding the same note. NEW PE53611
A10: QT17IA24.00 | B10: =VLOOKUP(A10,[1]Summary!B:B,1,0) -> QT17IA24.00 | E10: QTNSN095266A.X11 | F10: QT TRX ASSY, 095266A. REV X11, TRX ASSEMBLY FOR AXFIA | G10: 29 | H10: 9 | I10: PE53604, PE53707,PE53847
A11: QT17IA44.00 | B11: =VLOOKUP(A11,[1]Summary!B:B,1,0) -> QT17IA44.00 | E11: QTNSN476757A.X11 | F11: RRH X11 | G11: 15 | H11: 10 | I11: PE53701
A12: QT17IA14.50 | B12: =VLOOKUP(A12,[1]Summary!B:B,1,0) -> QT17IA14.50 | E12: QTNSN095288A.X11 | F12: QT PA ASSY, 095288A. REV X11, B25 PA ASSEMBLY FOR AXFIA/AXFIB | G12: 124 | H12: 11 | I12: PE53891
A13: QT17IA14.40 | B13: =VLOOKUP(A13,[1]Summary!B:B,1,0) -> QT17IA14.40 | E13: QTNSN095289A.X11 | F13: QT PA ASSY, 095289A. REV X11, B66 PA ASSEMBLY FOR AXFIA/AXFIB | G13: 124 | H13: 12 | I13: PE54018
A14: QT17IA24.10 | B14: =VLOOKUP(A14,[1]Summary!B:B,1,0) -> QT17IA24.10 | E14: QTNSN095266A.X12 | F14: QT TRX ASSY, 095266A. REV X12, TRX ASSEMBLY FOR AXFIA | G14: 41 | H14: 13 | I14: X12 Bom released - PE54073
A15: QT17IA44.10 | B15: =VLOOKUP(A15,[1]Summary!B:B,1,0) -> QT17IA44.10 | E15: QTNSN476757A.X12 | F15: QT T/L UNIT ASSY, 476757A. REV X12, AXFIA AirScale RRH 4T8R n25/66 720W | G15: 30 | H15: 14 | I15: Esti releasesed- Release wo- PE54404- Wo released 29-May-26 | Min of 15 units next week | J15: Quote- 02-Jun-26 | K15: Send to Paula
A16: QT17IA15.80 | B16: =VLOOKUP(A16,[1]Summary!B:B,1,0) -> QT17IA15.80 | E16: QTNSN095289A.X12 | F16: QT PA ASSY, 095289A. REV X12, B66 PA ASSEMBLY FOR AXFIA/AXFIB | G16: 62 | H16: 18 | I16: New PWB- Order 2 sets of stencils- new profile board needed - New profile needed - Need STI- Checkplots being worked - PE54185
A17: QT17IA15.90 | B17: =VLOOKUP(A17,[1]Summary!B:B,1,0) -> QT17IA15.90 | E17: QTNSN095288A.X12 | F17: QT PA ASSY, 095288A. REV X12, B25 PA ASSEMBLY FOR AXFIA/AXFIB | G17: 62 | H17: 17 | I17: New PWB- Order 2 sets of stencils- new profile board needed - New profile needed - Need STI- Stencil 04/23- PE54164 | N17: 46139
A18: QT19BA11.00 | B18: =VLOOKUP(A18,[1]Summary!B:B,1,0) -> QT19BA11.00 | E18: QTNSN095290A.X02 | F18: QT PA ASSY, 095290A. REV X02, B71 PA ASSEMBLY FOR AXOLBA | G18: 14 | H18: 19 | I18: Stencils due on the 27- Apr- No Esti
A19: QT19BA11.10 | B19: =VLOOKUP(A19,[1]Summary!B:B,1,0) -> QT19BA11.10 | E19: QTNSN095291A.X02 | F19: QT PA ASSY, 095291A. REV X02, B85 PA ASSEMBLY FOR AXOLBA | G19: 14 | H19: 20 | I19: Stencils due on the 27- Apr- No Esti- Tracking# 707296329356
A20: QT20LA21.00 | B20: =VLOOKUP(A20,[1]Summary!B:B,1,0) -> QT20LA21.00 | E20: QTNSN095286A.X02 | F20: QT TRX ASSY, 095286A. REV X02, TRX ASSEMBLY FOR AXOLA | G20: 10 | H20: 21 | I20: PWB X6 | PE54313 to be cp'd rpleace P7000738 with P67 | AOI and Xray data & Dage available -Send data ASAP
A21: QT17IA25.30 | B21: =VLOOKUP(A21,[1]Summary!B:B,1,0) -> QT17IA25.30 | C21: =MID(A21,3,11) -> 17IA25.30 | D21: Clean | E21: QTNSN095266A.X12 | F21: QT TRX ASSY, 095266A. REV X12, TRX ASSEMBLY FOR AXFIA | G21: 47 | H21: 22 | I21: Kick off 21-May-26- ESTI -PE54408 - Released 29-May-26 | One more ESTI to be released | Stencil ETA 03-Jun-26 | PE54513- Work order relased 06/03 | J21: Released -06/03 | Confirm SMT Start date
A22: QT17IA15.60 | B22: =VLOOKUP(A22,[1]Summary!B:B,1,0) -> QT17IA15.60 | E22: QTNSN095289A.X12 | F22: QT PA ASSY, 095289A. REV X12, B66 PA ASSEMBLY FOR AXFIA/AXFIB | G22: 188 | H22: 23 | I22: Kick off 21-May-26- ESTI - PE54407- WO Released 29-May-26 | J22: Durafuse
A23: QT17IA15.70 | B23: =VLOOKUP(A23,[1]Summary!B:B,1,0) -> QT17IA15.70 | E23: QTNSN095288A.X12 | F23: QT PA ASSY, 095288A. REV X12, B25 PA ASSEMBLY FOR AXFIA/AXFIB | G23: 188 | H23: 24 | I23: Kick off 21-May-26- ESTI - PE54405- WO Released 29-May-26 | J23: Durafuse
A24: QT17IA45.30 | B24: =VLOOKUP(A24,[1]Summary!B:B,1,0) -> #N/A | C24: =MID(A24,3,11) -> 17IA45.30 | D24: Clean | E24: QTNSN476757A.X12 | F24: QT T/L UNIT ASSY, 476757A. REV X12, AXFIA AirScale RRH 4T8R n25/66 720W | G24: 47 | H24: 25 | I24: PE54409 - Released 29-May-26_ need to release work order- Relased 15-Jun-26 | J24: Quote avialable
A25: QT17IA45.40 | B25: =VLOOKUP(A25,[1]Summary!B:B,1,0) -> QT17IA45.40 | E25: QTNSN476757A.X12 | F25: QT T/L UNIT ASSY, 476757A. REV X12, AXFIA AirScale RRH 4T8R n25/66 720W | G25: 11 | H25: 26 | I25: Kick off- ESTI PE54381 - WO released- Quote | J25: Unit to Poland | K25: SYK262101094
A26: QT17IA15.95 | B26: =VLOOKUP(A26,[1]Summary!B:B,1,0) -> QT17IA15.95 | E26: QTNSN095289A.X12 | F26: QT PA ASSY, 095289A. REV X12, B66 PA ASSEMBLY FOR AXFIA/AXFIB | G26: 140 | H26: 27 | I26: Stencils , same PWB, STI for Solder paste PE54356- requested to run on the 2oth of May | New profile needed for Different solder paste | J26: Quote Sent 29-May-26
A27: QT17IA15.96 | B27: =VLOOKUP(A27,[1]Summary!B:B,1,0) -> QT17IA15.96 | E27: QTNSN095288A.X12 | F27: QT PA ASSY, 095288A. REV X12, B25 PA ASSEMBLY FOR AXFIA/AXFIB | G27: 140 | H27: 28 | I27: PE54357- Solder paste STI- Received | New profile needed for Different solder paste | J27: Quote Sent 29-May-26
A28: QT20LA12.00 | B28: =VLOOKUP(A28,[1]Summary!B:B,1,0) -> QT20LA12.00 | E28: QTNSN095290A.X02 | F28: QT PA ASSY, 095290A. REV X02, B71 PA ASSEMBLY FOR AXOLBA | G28: 64 | H28: 29 | I28: Esti releasesed- PE54413- WO released 27-May-26- need profile approved
A29: QT20LA12.10 | B29: =VLOOKUP(A29,[1]Summary!B:B,1,0) -> QT20LA12.10 | E29: QTNSN095291A.X02 | F29: QT PA ASSY, 095291A. REV X02, B85 PA ASSEMBLY FOR AXOLBA | G29: 64 | H29: 30 | I29: Esti releasesed- WO released 27-May-26- Need profile approved
A30: QT20LA41.00 | B30: =VLOOKUP(A30,[1]Summary!B:B,1,0) -> #N/A | C30: =MID(A30,3,11) -> 20LA41.00 | D30: Clean | E30: QTNSN476797A.X11 | F30: QT T/L UNIT ASSY, 476797A.REV X11, AXOLA AirScale RRH 4T4R n71/85 320W | G30: 8 | H30: 31 | I30: CTB- ESTI PE54470 | WO release today 03-Jun-26- Followed up on ESTI | New STI Being released- PE54673 | J30: Quote Sent 15-Jun-26
A31: QT19BA21.00A | B31: =VLOOKUP(A31,[1]Summary!B:B,1,0) -> #N/A | C31: =MID(A31,3,11) -> 19BA21.00A | E31: QTNSN095804A.X11 | G31: 22 | H31: 32 | I31: Relased 06/12- Quote | J31: Cost roll
A32: QT19BA12.20 | B32: =VLOOKUP(A32,[1]Summary!B:B,1,0) -> #N/A | C32: =MID(A32,3,11) -> 19BA12.20 | D32: Clean | E32: QTNSN095290A.X02 | G32: 32 | H32: 33 | I32: ESTI - Sac305 PE54542- Work order QT20LA12.00 increased to 64 units
A33: QT19BA12.30 | B33: =VLOOKUP(A33,[1]Summary!B:B,1,0) -> #N/A | C33: =MID(A33,3,11) -> 19BA12.30 | D33: Clean | E33: QTNSN095291A.X02 | G33: 32 | H33: 34 | I33: ESTI - Sac305 PE54541- Work order QT20LA12.10 increased to 64 units
A34: QT19BA41.00 | B34: =VLOOKUP(A34,[1]Summary!B:B,1,0) -> #N/A | C34: =MID(A34,3,11) -> 19BA41.00 | E34: QTNSN476971A.X11 | G34: 8 | H34: 36 | I34: STI to be released | Build date to be updated in Kick off
A35: QT17IA24.20 | B35: =VLOOKUP(A35,[1]Summary!B:B,1,0) -> #N/A | C35: =MID(A35,3,11) -> 17IA24.20 | E35: QTNSN095266A.X21 | G35: 29 | H35: 37 | I35: Relase 06/15-PE54608 | Quote- Work order released 15-Jun-26
A36: QT17IA14.70 | B36: =VLOOKUP(A36,[1]Summary!B:B,1,0) -> #N/A | C36: =MID(A36,3,11) -> 17IA14.70 | E36: 095288A.X21 | H36: 38
A37: QT17IA14.60 | B37: =VLOOKUP(A37,[1]Summary!B:B,1,0) -> #N/A | C37: =MID(A37,3,11) -> 17IA14.60 | E37: 095289A.P01 | H37: 39 | I37: BOM not loaded | P722374
A38: QT18OA21.00 | B38: =VLOOKUP(A38,[1]Summary!B:B,1,0) -> #N/A | C38: =MID(A38,3,11) -> 18OA21.00 | E38: QTNSN095725A.X12 | G38: 11 | H38: 40 | I38: No ESTI | 51690564- PO for tooling followed up with CNC
