Workbook

Sheet Sheet9
A1: Process | B1: (Multiple Items) | K1: Process | L1: (Multiple Items)
A2: Program | B2: (All)
K3: Row Labels | L3: Sum of Qty
A4: Sum of Qty | B4: Column Labels | K4: 5DX1 SMT 5DX | L4: 242 | T4: AXFIA | U4: P3
A5: Row Labels | B5: PA Assembly | C5: TRX/PSU/BB Assembly | D5: Grand Total | J5: =D5-55 -> #VALUE! | K5: AOI1 AOI Inspect S1 | L5: 461 | T5: AXOLA | U5: P1
A6: 5DX1 SMT 5DX | B6: 369 | C6: 5 | D6: 374 | K6: AOI2 AOI Inspect S2 | L6: 14 | T6: AXOLBA | U6: P2
A7: 5DXR 5DX RWK | B7: 19 | D7: 19 | K7: AOR1 AOI RWK S1 | L7: 38 | T7: AXOA | U7: P4
A8: AOI1 AOI Inspect S1 | B8: 197 | C8: 57 | D8: 254 | K8: AOR2 AOI RWK S2 | L8: 8
A9: AOI2 AOI Inspect S2 | C9: 17 | D9: 17 | K9: Grand Total | L9: 763
A10: AOR1 AOI RWK S1 | B10: 82 | D10: 82
A11: AOR2 AOI RWK S2 | C11: 6 | D11: 6
A12: Grand Total | B12: 667 | C12: 85 | D12: 752
A19: Sum of Qty | B19: Column Labels
A20: Row Labels | B20: PA Assembly | C20: TRX/PSU/BB Assembly | D20: Grand Total
A21: 5DX1 SMT 5DX | B21: 374 | C21: 2 | D21: 376
A22: 5DXR 5DX RWK | B22: 19 | C22: 3 | D22: 22
A23: AOI1 AOI Inspect S1 | B23: 224 | C23: 56 | D23: 280
A24: AOI2 AOI Inspect S2 | C24: 16 | D24: 16
A25: AOR1 AOI RWK S1 | B25: 53 | C25: 1 | D25: 54
A26: AOR2 AOI RWK S2 | C26: 7 | D26: 7
A27: Grand Total | B27: 670 | C27: 85 | D27: 755

Sheet Shop Order
A1: Serial Number | B1: Workstation | C1: Process | D1: Qty | E1: Unit Status | F1: Last Updated | G1: Work order | H1: Part number | I1: Priority | J1: UID | K1: Program | L1: Type | M1: Comments | N1: Shipping date | O1: asdas
A2: YK260300123 | B2: NOT-IN-PROCESS | C2: NOT-IN-PROCESS | D2: 1 | E2: Unit Component (60) | F2: 46065.449 | G2: QT17IA14.00 | H2: QTNSN095288A.X03 | I2: =VLOOKUP(G2,WO!A:J,10,0) -> 1 | J2: =MID(G2,3,9) -> 17IA14.00 | K2: =VLOOKUP(J2,WO!B:E,4,0) -> AXFIA | L2: =VLOOKUP(J2,WO!B:F,5,0) -> PA Assembly
A3: YK260300124 | B3: NOT-IN-PROCESS | C3: NOT-IN-PROCESS | D3: 1 | E3: Unit Component (60) | F3: 46065.45 | G3: QT17IA14.00 | H3: QTNSN095288A.X03 | I3: =VLOOKUP(G3,WO!A:J,10,0) -> 1 | J3: =MID(G3,3,9) -> 17IA14.00 | K3: =VLOOKUP(J3,WO!B:E,4,0) -> AXFIA | L3: =VLOOKUP(J3,WO!B:F,5,0) -> PA Assembly
A4: YK260300125 | B4: NOT-IN-PROCESS | C4: NOT-IN-PROCESS | D4: 1 | E4: Unit Component (60) | F4: 46071.552 | G4: QT17IA14.00 | H4: QTNSN095288A.X03 | I4: =VLOOKUP(G4,WO!A:J,10,0) -> 1 | J4: =MID(G4,3,9) -> 17IA14.00 | K4: =VLOOKUP(J4,WO!B:E,4,0) -> AXFIA | L4: =VLOOKUP(J4,WO!B:F,5,0) -> PA Assembly
A5: YK260300126 | B5: NOT-IN-PROCESS | C5: NOT-IN-PROCESS | D5: 1 | E5: Unit Component (60) | F5: 46072.29 | G5: QT17IA14.00 | H5: QTNSN095288A.X03 | I5: =VLOOKUP(G5,WO!A:J,10,0) -> 1 | J5: =MID(G5,3,9) -> 17IA14.00 | K5: =VLOOKUP(J5,WO!B:E,4,0) -> AXFIA | L5: =VLOOKUP(J5,WO!B:F,5,0) -> PA Assembly
A6: YK260300127 | B6: NOT-IN-PROCESS | C6: NOT-IN-PROCESS | D6: 1 | E6: Unit Component (60) | F6: 46076.37 | G6: QT17IA14.00 | H6: QTNSN095288A.X03 | I6: =VLOOKUP(G6,WO!A:J,10,0) -> 1 | J6: =MID(G6,3,9) -> 17IA14.00 | K6: =VLOOKUP(J6,WO!B:E,4,0) -> AXFIA | L6: =VLOOKUP(J6,WO!B:F,5,0) -> PA Assembly
A7: YK260300128 | B7: SHIP Shipping | C7: Shipped to Customer | D7: 1 | E7: Shipped (40) | F7: 46112.311 | G7: QT17IA14.00 | H7: QTNSN095288A.X03 | I7: =VLOOKUP(G7,WO!A:J,10,0) -> 1 | J7: =MID(G7,3,9) -> 17IA14.00 | K7: =VLOOKUP(J7,WO!B:E,4,0) -> AXFIA | L7: =VLOOKUP(J7,WO!B:F,5,0) -> PA Assembly
A8: YK260300129 | B8: NOT-IN-PROCESS | C8: NOT-IN-PROCESS | D8: 1 | E8: Unit Component (60) | F8: 46065.432 | G8: QT17IA14.00 | H8: QTNSN095288A.X03 | I8: =VLOOKUP(G8,WO!A:J,10,0) -> 1 | J8: =MID(G8,3,9) -> 17IA14.00 | K8: =VLOOKUP(J8,WO!B:E,4,0) -> AXFIA | L8: =VLOOKUP(J8,WO!B:F,5,0) -> PA Assembly
A9: YK260300130 | B9: NOT-IN-PROCESS | C9: NOT-IN-PROCESS | D9: 1 | E9: Unit Component (60) | F9: 46071.282 | G9: QT17IA14.00 | H9: QTNSN095288A.X03 | I9: =VLOOKUP(G9,WO!A:J,10,0) -> 1 | J9: =MID(G9,3,9) -> 17IA14.00 | K9: =VLOOKUP(J9,WO!B:E,4,0) -> AXFIA | L9: =VLOOKUP(J9,WO!B:F,5,0) -> PA Assembly
A10: YK260300131 | B10: NOT-IN-PROCESS | C10: NOT-IN-PROCESS | D10: 1 | E10: Unit Component (60) | F10: 46076.374 | G10: QT17IA14.00 | H10: QTNSN095288A.X03 | I10: =VLOOKUP(G10,WO!A:J,10,0) -> 1 | J10: =MID(G10,3,9) -> 17IA14.00 | K10: =VLOOKUP(J10,WO!B:E,4,0) -> AXFIA | L10: =VLOOKUP(J10,WO!B:F,5,0) -> PA Assembly
A11: YK260300132 | B11: NOT-IN-PROCESS | C11: NOT-IN-PROCESS | D11: 1 | E11: Unit Component (60) | F11: 46065.431 | G11: QT17IA14.00 | H11: QTNSN095288A.X03 | I11: =VLOOKUP(G11,WO!A:J,10,0) -> 1 | J11: =MID(G11,3,9) -> 17IA14.00 | K11: =VLOOKUP(J11,WO!B:E,4,0) -> AXFIA | L11: =VLOOKUP(J11,WO!B:F,5,0) -> PA Assembly
A12: YK260300133 | B12: NOT-IN-PROCESS | C12: NOT-IN-PROCESS | D12: 1 | E12: Unit Component (60) | F12: 46072.486 | G12: QT17IA14.00 | H12: QTNSN095288A.X03 | I12: =VLOOKUP(G12,WO!A:J,10,0) -> 1 | J12: =MID(G12,3,9) -> 17IA14.00 | K12: =VLOOKUP(J12,WO!B:E,4,0) -> AXFIA | L12: =VLOOKUP(J12,WO!B:F,5,0) -> PA Assembly
A13: YK260300134 | B13: NOT-IN-PROCESS | C13: NOT-IN-PROCESS | D13: 1 | E13: Unit Component (60) | F13: 46065.449 | G13: QT17IA14.00 | H13: QTNSN095288A.X03 | I13: =VLOOKUP(G13,WO!A:J,10,0) -> 1 | J13: =MID(G13,3,9) -> 17IA14.00 | K13: =VLOOKUP(J13,WO!B:E,4,0) -> AXFIA | L13: =VLOOKUP(J13,WO!B:F,5,0) -> PA Assembly
... A153: YK260900002 | B153: NOT-IN-PROCESS | C153: NOT-IN-PROCESS | D153: 1 | E153: Unit Component (60) | F153: 46146.277 | G153: QT17IA14.20 | H153: QTNSN095289A.X11 | I153: =VLOOKUP(G153,WO!A:J,10,0) -> 7 | J153: =MID(G153,3,9) -> 17IA14.20 | K153: =VLOOKUP(J153,WO!B:E,4,0) -> AXFIA | L153: =VLOOKUP(J153,WO!B:F,5,0) -> PA Assembly
A154: YK260900003 | B154: SHIP Shipping | C154: Shipped to Customer | D154: 1 | E154: Shipped (40) | F154: 46246.556 | G154: QT17IA14.20 | H154: QTNSN095289A.X11 | I154: =VLOOKUP(G154,WO!A:J,10,0) -> 7 | J154: =MID(G154,3,9) -> 17IA14.20 | K154: =VLOOKUP(J154,WO!B:E,4,0) -> AXFIA | L154: =VLOOKUP(J154,WO!B:F,5,0) -> PA Assembly | N154: 46248
A155: YK260900004 | B155: FUN1 Func Test | C155: Functional Test-1 | D155: 1 | E155: On The Line (20) | F155: 46122.38 | G155: QT17IA14.20 | H155: QTNSN095289A.X11 | I155: =VLOOKUP(G155,WO!A:J,10,0) -> 7 | J155: =MID(G155,3,9) -> 17IA14.20 | K155: =VLOOKUP(J155,WO!B:E,4,0) -> AXFIA | L155: =VLOOKUP(J155,WO!B:F,5,0) -> PA Assembly
A156: YK260900005 | B156: NOT-IN-PROCESS | C156: NOT-IN-PROCESS | D156: 1 | E156: Unit Component (60) | F156: 46150.392 | G156: QT17IA14.20 | H156: QTNSN095289A.X11 | I156: =VLOOKUP(G156,WO!A:J,10,0) -> 7 | J156: =MID(G156,3,9) -> 17IA14.20 | K156: =VLOOKUP(J156,WO!B:E,4,0) -> AXFIA | L156: =VLOOKUP(J156,WO!B:F,5,0) -> PA Assembly
A157: YK260900006 | B157: SHIP Shipping | C157: Shipped to Customer | D157: 1 | E157: Shipped (40) | F157: 46246.581 | G157: QT17IA14.20 | H157: QTNSN095289A.X11 | I157: =VLOOKUP(G157,WO!A:J,10,0) -> 7 | J157: =MID(G157,3,9) -> 17IA14.20 | K157: =VLOOKUP(J157,WO!B:E,4,0) -> AXFIA | L157: =VLOOKUP(J157,WO!B:F,5,0) -> PA Assembly | N157: 46248
A158: YK260900007 | B158: NOT-IN-PROCESS | C158: NOT-IN-PROCESS | D158: 1 | E158: Unit Component (60) | F158: 46150.392 | G158: QT17IA14.20 | H158: QTNSN095289A.X11 | I158: =VLOOKUP(G158,WO!A:J,10,0) -> 7 | J158: =MID(G158,3,9) -> 17IA14.20 | K158: =VLOOKUP(J158,WO!B:E,4,0) -> AXFIA | L158: =VLOOKUP(J158,WO!B:F,5,0) -> PA Assembly
A159: YK260900008 | B159: SHIP Shipping | C159: Shipped to Customer | D159: 1 | E159: Shipped (40) | F159: 46123.268 | G159: QT17IA14.20 | H159: QTNSN095289A.X11 | I159: =VLOOKUP(G159,WO!A:J,10,0) -> 7 | J159: =MID(G159,3,9) -> 17IA14.20 | K159: =VLOOKUP(J159,WO!B:E,4,0) -> AXFIA | L159: =VLOOKUP(J159,WO!B:F,5,0) -> PA Assembly | N159: 46105
A160: YK260900009 | B160: SHIP Shipping | C160: Shipped to Customer | D160: 1 | E160: Shipped (40) | F160: 46123.268 | G160: QT17IA14.20 | H160: QTNSN095289A.X11 | I160: =VLOOKUP(G160,WO!A:J,10,0) -> 7 | J160: =MID(G160,3,9) -> 17IA14.20 | K160: =VLOOKUP(J160,WO!B:E,4,0) -> AXFIA | L160: =VLOOKUP(J160,WO!B:F,5,0) -> PA Assembly | N160: 46105
A161: YK260900010 | B161: SHIP Shipping | C161: Shipped to Customer | D161: 1 | E161: Shipped (40) | F161: 46248.37 | G161: QT17IA14.20 | H161: QTNSN095289A.X11 | I161: =VLOOKUP(G161,WO!A:J,10,0) -> 7 | J161: =MID(G161,3,9) -> 17IA14.20 | K161: =VLOOKUP(J161,WO!B:E,4,0) -> AXFIA | L161: =VLOOKUP(J161,WO!B:F,5,0) -> PA Assembly | N161: 46248
A162: YK260900011 | B162: SHIP Shipping | C162: Shipped to Customer | D162: 1 | E162: Shipped (40) | F162: 46123.268 | G162: QT17IA14.20 | H162: QTNSN095289A.X11 | I162: =VLOOKUP(G162,WO!A:J,10,0) -> 7 | J162: =MID(G162,3,9) -> 17IA14.20 | K162: =VLOOKUP(J162,WO!B:E,4,0) -> AXFIA | L162: =VLOOKUP(J162,WO!B:F,5,0) -> PA Assembly | N162: 46105
A163: YK260900012 | B163: SHIP Shipping | C163: Shipped to Customer | D163: 1 | E163: Shipped (40) | F163: 46154.373 | G163: QT17IA14.20 | H163: QTNSN095289A.X11 | I163: =VLOOKUP(G163,WO!A:J,10,0) -> 7 | J163: =MID(G163,3,9) -> 17IA14.20 | K163: =VLOOKUP(J163,WO!B:E,4,0) -> AXFIA | L163: =VLOOKUP(J163,WO!B:F,5,0) -> PA Assembly | N163: 46156
A164: YK260900013 | B164: NOT-IN-PROCESS | C164: NOT-IN-PROCESS | D164: 1 | E164: Unit Component (60) | F164: 46153.505 | G164: QT17IA14.20 | H164: QTNSN095289A.X11 | I164: =VLOOKUP(G164,WO!A:J,10,0) -> 7 | J164: =MID(G164,3,9) -> 17IA14.20 | K164: =VLOOKUP(J164,WO!B:E,4,0) -> AXFIA | L164: =VLOOKUP(J164,WO!B:F,5,0) -> PA Assembly
A165: YK260900014 | B165: NOT-IN-PROCESS | C165: NOT-IN-PROCESS | D165: 1 | E165: Unit Component (60) | F165: 46140.311 | G165: QT17IA14.20 | H165: QTNSN095289A.X11 | I165: =VLOOKUP(G165,WO!A:J,10,0) -> 7 | J165: =MID(G165,3,9) -> 17IA14.20 | K165: =VLOOKUP(J165,WO!B:E,4,0) -> AXFIA | L165: =VLOOKUP(J165,WO!B:F,5,0) -> PA Assembly
A166: YK260900015 | B166: SHIP Shipping | C166: Shipped to Customer | D166: 1 | E166: Shipped (40) | F166: 46246.579 | G166: QT17IA14.20 | H166: QTNSN095289A.X11 | I166: =VLOOKUP(G166,WO!A:J,10,0) -> 7 | J166: =MID(G166,3,9) -> 17IA14.20 | K166: =VLOOKUP(J166,WO!B:E,4,0) -> AXFIA | L166: =VLOOKUP(J166,WO!B:F,5,0) -> PA Assembly | N166: 46248
A167: YK260900016 | B167: NOT-IN-PROCESS | C167: NOT-IN-PROCESS | D167: 1 | E167: Unit Component (60) | F167: 46146.277 | G167: QT17IA14.20 | H167: QTNSN095289A.X11 | I167: =VLOOKUP(G167,WO!A:J,10,0) -> 7 | J167: =MID(G167,3,9) -> 17IA14.20 | K167: =VLOOKUP(J167,WO!B:E,4,0) -> AXFIA | L167: =VLOOKUP(J167,WO!B:F,5,0) -> PA Assembly
A168: YK260900017 | B168: CMP1 Complete | C168: Complete | D168: 1 | E168: Finished (30) | F168: 46139.587 | G168: QT17IA14.20 | H168: QTNSN095289A.X11 | I168: =VLOOKUP(G168,WO!A:J,10,0) -> 7 | J168: =MID(G168,3,9) -> 17IA14.20 | K168: =VLOOKUP(J168,WO!B:E,4,0) -> AXFIA | L168: =VLOOKUP(J168,WO!B:F,5,0) -> PA Assembly
A169: YK260900018 | B169: SHIP Shipping | C169: Shipped to Customer | D169: 1 | E169: Shipped (40) | F169: 46123.268 | G169: QT17IA14.20 | H169: QTNSN095289A.X11 | I169: =VLOOKUP(G169,WO!A:J,10,0) -> 7 | J169: =MID(G169,3,9) -> 17IA14.20 | K169: =VLOOKUP(J169,WO!B:E,4,0) -> AXFIA | L169: =VLOOKUP(J169,WO!B:F,5,0) -> PA Assembly | N169: 46097
A170: YK260900019 | B170: SHIP Shipping | C170: Shipped to Customer | D170: 1 | E170: Shipped (40) | F170: 46246.583 | G170: QT17IA14.20 | H170: QTNSN095289A.X11 | I170: =VLOOKUP(G170,WO!A:J,10,0) -> 7 | J170: =MID(G170,3,9) -> 17IA14.20 | K170: =VLOOKUP(J170,WO!B:E,4,0) -> AXFIA | L170: =VLOOKUP(J170,WO!B:F,5,0) -> PA Assembly | N170: 46248
A171: YK260900020 | B171: NOT-IN-PROCESS | C171: NOT-IN-PROCESS | D171: 1 | E171: Unit Component (60) | F171: 46153.435 | G171: QT17IA14.20 | H171: QTNSN095289A.X11 | I171: =VLOOKUP(G171,WO!A:J,10,0) -> 7 | J171: =MID(G171,3,9) -> 17IA14.20 | K171: =VLOOKUP(J171,WO!B:E,4,0) -> AXFIA | L171: =VLOOKUP(J171,WO!B:F,5,0) -> PA Assembly
A172: YK260900021 | B172: FUN1 Func Test | C172: Functional Test-1 | D172: 1 | E172: On The Line (20) | F172: 46122.381 | G172: QT17IA14.20 | H172: QTNSN095289A.X11 | I172: =VLOOKUP(G172,WO!A:J,10,0) -> 7 | J172: =MID(G172,3,9) -> 17IA14.20 | K172: =VLOOKUP(J172,WO!B:E,4,0) -> AXFIA | L172: =VLOOKUP(J172,WO!B:F,5,0) -> PA Assembly
A173: YK260900022 | B173: SHIP Shipping | C173: Shipped to Customer | D173: 1 | E173: Shipped (40) | F173: 46174.475 | G173: QT17IA14.20 | H173: QTNSN095289A.X11 | I173: =VLOOKUP(G173,WO!A:J,10,0) -> 7 | J173: =MID(G173,3,9) -> 17IA14.20 | K173: =VLOOKUP(J173,WO!B:E,4,0) -> AXFIA | L173: =VLOOKUP(J173,WO!B:F,5,0) -> PA Assembly | N173: 46128
A174: YK260900023 | B174: SHIP Shipping | C174: Shipped to Customer | D174: 1 | E174: Shipped (40) | F174: 46248.401 | G174: QT17IA14.20 | H174: QTNSN095289A.X11 | I174: =VLOOKUP(G174,WO!A:J,10,0) -> 7 | J174: =MID(G174,3,9) -> 17IA14.20 | K174: =VLOOKUP(J174,WO!B:E,4,0) -> AXFIA | L174: =VLOOKUP(J174,WO!B:F,5,0) -> PA Assembly | N174: 46248
A175: YK260900024 | B175: SHIP Shipping | C175: Shipped to Customer | D175: 1 | E175: Shipped (40) | F175: 46248.4 | G175: QT17IA14.20 | H175: QTNSN095289A.X11 | I175: =VLOOKUP(G175,WO!A:J,10,0) -> 7 | J175: =MID(G175,3,9) -> 17IA14.20 | K175: =VLOOKUP(J175,WO!B:E,4,0) -> AXFIA | L175: =VLOOKUP(J175,WO!B:F,5,0) -> PA Assembly | N175: 46248
A176: YK260900025 | B176: SHIP Shipping | C176: Shipped to Customer | D176: 1 | E176: Shipped (40) | F176: 46246.556 | G176: QT17IA14.20 | H176: QTNSN095289A.X11 | I176: =VLOOKUP(G176,WO!A:J,10,0) -> 7 | J176: =MID(G176,3,9) -> 17IA14.20 | K176: =VLOOKUP(J176,WO!B:E,4,0) -> AXFIA | L176: =VLOOKUP(J176,WO!B:F,5,0) -> PA Assembly | N176: 46248
A177: YK260900026 | B177: SHIP Shipping | C177: Shipped to Customer | D177: 1 | E177: Shipped (40) | F177: 46248.401 | G177: QT17IA14.20 | H177: QTNSN095289A.X11 | I177: =VLOOKUP(G177,WO!A:J,10,0) -> 7 | J177: =MID(G177,3,9) -> 17IA14.20 | K177: =VLOOKUP(J177,WO!B:E,4,0) -> AXFIA | L177: =VLOOKUP(J177,WO!B:F,5,0) -> PA Assembly | N177: 46248
A178: YK260900027 | B178: FUN1 Func Test | C178: Functional Test-1 | D178: 1 | E178: On The Line (20) | F178: 46122.382 | G178: QT17IA14.20 | H178: QTNSN095289A.X11 | I178: =VLOOKUP(G178,WO!A:J,10,0) -> 7 | J178: =MID(G178,3,9) -> 17IA14.20 | K178: =VLOOKUP(J178,WO!B:E,4,0) -> AXFIA | L178: =VLOOKUP(J178,WO!B:F,5,0) -> PA Assembly
A179: YK260900028 | B179: SHIP Shipping | C179: Shipped to Customer | D179: 1 | E179: Shipped (40) | F179: 46246.559 | G179: QT17IA14.20 | H179: QTNSN095289A.X11 | I179: =VLOOKUP(G179,WO!A:J,10,0) -> 7 | J179: =MID(G179,3,9) -> 17IA14.20 | K179: =VLOOKUP(J179,WO!B:E,4,0) -> AXFIA | L179: =VLOOKUP(J179,WO!B:F,5,0) -> PA Assembly | N179: 46248
...

Sheet Summary
A1: Row Labels | B1: Work order | C1: Part number | D1: Process | E1: Unit Status | F1: Count of Qty
A2: 1 | B2: QT17IA14.00 | C2: QTNSN095288A.X03 | D2: NOT-IN-PROCESS | E2: Unit Component (60) | F2: 64
D3: Shipped to Customer | E3: Shipped (40) | F3: 6
A4: 2 | B4: QT17IA14.10 | C4: QTNSN095289A.X03 | D4: NOT-IN-PROCESS | E4: Unit Component (60) | F4: 64
D5: Shipped to Customer | E5: Shipped (40) | F5: 16
A6: 3 | B6: QT17IA23.00 | C6: QTNSN095266A.X02 | D6: NOT-IN-PROCESS | E6: Unit Component (60) | F6: 11
D7: Shipped to Customer | E7: Shipped (40) | F7: 14
A8: 4 | B8: QT17IA43.00 | C8: QTNSN476757A.X02 | D8: Shipped to Customer | E8: Shipped (40) | F8: 20
A9: 5 | B9: QT17IA14.30 | C9: QTNSN095288A.X11 | D9: Functional Test-1 | E9: On The Line (20) | F9: 2
D10: NOT-IN-PROCESS | E10: Unit Component (60) | F10: 11
D11: Shipped to Customer | E11: Shipped (40) | F11: 24
A12: 6 | B12: QT17IA14.31 | C12: QTNSN095288A.X11 | D12: Functional Test-1 | E12: On The Line (20) | F12: 1
D13: NOT-IN-PROCESS | E13: Unit Component (60) | F13: 12
D14: Shipped to Customer | E14: Shipped (40) | F14: 24
A15: 7 | B15: QT17IA14.20 | C15: QTNSN095289A.X11 | D15: Complete | E15: Finished (30) | F15: 1
D16: Functional Test-1 | E16: On The Line (20) | F16: 5
D17: NOT-IN-PROCESS | E17: Unit Component (60) | F17: 8
D18: Shipped to Customer | E18: Shipped (40) | F18: 23
A19: 8 | B19: QT17IA14.21 | C19: QTNSN095289A.X11 | D19: Functional Test-1 | E19: On The Line (20) | F19: 3
D20: NOT-IN-PROCESS | E20: Unit Component (60) | F20: 20
D21: Shipped to Customer | E21: Shipped (40) | F21: 14
A22: 9 | B22: QT17IA24.00 | C22: QTNSN095266A.X11 | D22: NOT-IN-PROCESS | E22: Unit Component (60) | F22: 16
D23: Shipped to Customer | E23: Shipped (40) | F23: 13
A24: 10 | B24: QT17IA44.00 | C24: QTNSN476757A.X11 | D24: Shipped to Customer | E24: Shipped (40) | F24: 15
A25: 11 | B25: QT17IA14.50 | C25: QTNSN095288A.X11 | D25: Complete | E25: Finished (30) | F25: 8
D26: Functional Test-1 | E26: On The Line (20) | F26: 5
D27: NOT-IN-PROCESS | E27: Unit Component (60) | F27: 37
D28: Shipped to Customer | E28: Shipped (40) | F28: 81
D29: Xfr to Debug Test | E29: In Repair Hold (29) | F29: 1
A30: 12 | B30: QT17IA14.40 | C30: QTNSN095289A.X11 | D30: NOT-IN-PROCESS | E30: Unit Component (60) | F30: 32
D31: Shipped to Customer | E31: Shipped (40) | F31: 100
A32: 13 | B32: QT17IA24.10 | C32: QTNSN095266A.X12 | D32: Complete | E32: Finished (30) | F32: 1
D33: Functional Test-1 | E33: On The Line (20) | F33: 1
D34: NOT-IN-PROCESS | E34: Unit Component (60) | F34: 38
D35: Rework-2 | E35: In Repair (25) | F35: 1
A36: 14 | B36: QT17IA44.10 | C36: QTNSN476757A.X12 | D36: Shipped to Customer | E36: Shipped (40) | F36: 30
A37: 15 | B37: QT17IA15.80 | C37: QTNSN095289A.X12 | D37: NOT-IN-PROCESS | E37: Unit Component (60) | F37: 44
D38: Shipped to Customer | E38: Shipped (40) | F38: 18
A39: 16 | B39: QT17IA15.90 | C39: QTNSN095288A.X12 | D39: Complete | E39: Finished (30) | F39: 1
D40: NOT-IN-PROCESS | E40: Unit Component (60) | F40: 47
...

Sheet Shipped
A1: Serial Number | B1: Ship Date | I1: Serial Number | J1: Shipping date
A2: YK262700652 | B2: 46230 | I2: YK260900003 | J2: 46248
A3: YK262700643 | B3: 46230 | I3: YK260900006 | J3: 46248
A4: YK262700652 | B4: 46248 | I4: YK260900008 | J4: 46105
A5: YK262700643 | B5: 46248 | I5: YK260900009 | J5: 46105
A6: YK261100764 | B6: 46248 | I6: YK260900010 | J6: 46248
A7: YK261400112 | B7: 46248 | I7: YK260900011 | J7: 46105
A8: YK261400076 | B8: 46248 | I8: YK260900012 | J8: 46156
A9: YK261400107 | B9: 46248 | I9: YK260900015 | J9: 46248
A10: YK261400027 | B10: 46248 | I10: YK260900018 | J10: 46097
A11: YK261400132 | B11: 46248 | I11: YK260900019 | J11: 46248
A12: YK261400126 | B12: 46248 | I12: YK260900022 | J12: 46128
A13: YK261400111 | B13: 46248 | I13: YK260900023 | J13: 46248
... A230: YK261600091 | B230: 46254 | I230: YK261400094 | J230: 46248
I231: YK261400096 | J231: 46248
I232: YK261400097 | J232: 46169
I233: YK261400098 | J233: 46248
I234: YK261400099 | J234: 46248
I235: YK261400100 | J235: 46248
I236: YK261400101 | J236: 46169
I237: YK261400102 | J237: 46254
I238: YK261400103 | J238: 46254
I239: YK261400104 | J239: 46248
I240: YK261400105 | J240: 46254
I241: YK261400107 | J241: 46248
I242: YK261400108 | J242: 46248
... I582: YK261802219 | J582: 46273

Sheet WO
A1: Unique id | C1: WO | E1: Program | F1: Type | G1: Part number | H1: Desc | I1: Qty | J1: Priority | K1: STI | L1: STI/ Comments | M1: Quote
A2: QT17IA14.00 | B2: =MID(A2,3,9) -> 17IA14.00 | C2: WIP | D2: =VLOOKUP(A2,'[1]Plan - US NPI'!$C$6:$E$192,3,0) -> #N/A | E2: AXFIA | F2: PA Assembly | G2: QTNSN095288A.X03 | H2: #N/A | I2: 70 | J2: 1 | R2: Mh lot codes to MRB
A3: QT17IA14.10 | B3: =MID(A3,3,9) -> 17IA14.10 | C3: WIP | D3: =VLOOKUP(A3,'[1]Plan - US NPI'!$C$6:$E$192,3,0) -> #N/A | E3: AXFIA | F3: PA Assembly | G3: QTNSN095289A.X03 | H3: #N/A | I3: 80 | J3: 2 | R3: Solder paste Qtys
A4: QT17IA23.00 | B4: =MID(A4,3,9) -> 17IA23.00 | C4: WIP | D4: =VLOOKUP(A4,'[1]Plan - US NPI'!$C$6:$E$192,3,0) -> #N/A | E4: AXFIA | F4: TRX/PSU/BB Assembly | G4: QTNSN095266A.X02 | H4: #N/A | I4: 25 | J4: 3
A5: QT17IA43.00 | B5: =MID(A5,3,9) -> 17IA43.00 | C5: WIP | D5: =VLOOKUP(A5,'[1]Plan - US NPI'!$C$6:$E$192,3,0) -> #N/A | E5: AXFIA | F5: RRH | G5: QTNSN476757A.X02 | H5: #N/A | I5: 20 | J5: 4
A6: QT17IA14.30 | B6: =MID(A6,3,9) -> 17IA14.30 | C6: WIP | D6: =VLOOKUP(A6,'[1]Plan - US NPI'!$C$6:$E$192,3,0) -> #N/A | E6: =VLOOKUP($A6,'[2]Plan - US NPI'!$C$6:$K$191,3,0) -> AXFIA | F6: =VLOOKUP($A6,'[2]Plan - US NPI'!$C$6:$K$191,9,0) -> PA Assembly | G6: QTNSN095288A.X11 | H6: QT PA ASSY, 095288A. REV X11, B25 PA ASSEMBLY FOR AXFIA/AXFIB | I6: 37 | J6: 5 | L6: eSTI PE53499. PE53575 add a note to remove shield and pre-drive, and for 840135A to use X1 version. PE53746 sent 03/13
A7: QT17IA14.31 | B7: =MID(A7,3,9) -> 17IA14.31 | C7: WIP | D7: =VLOOKUP(A7,'[1]Plan - US NPI'!$C$6:$E$192,3,0) -> #N/A | E7: =VLOOKUP($A7,'[2]Plan - US NPI'!$C$6:$K$191,3,0) -> AXFIA | F7: =VLOOKUP($A7,'[2]Plan - US NPI'!$C$6:$K$191,9,0) -> PA Assembly | G7: QTNSN095288A.X11 | H7: QT PA ASSY, 095288A. REV X11, B25 PA ASSEMBLY FOR AXFIA/AXFIB | I7: 37 | J7: 6 | L7: eSTI PE53499. PE53575 add a note to remove shield and pre-drive, and for 840135A to use X1 version. PE53684 sent 03/13
A8: QT17IA14.20 | B8: =MID(A8,3,9) -> 17IA14.20 | C8: WIP | D8: =VLOOKUP(A8,'[1]Plan - US NPI'!$C$6:$E$192,3,0) -> #N/A | E8: =VLOOKUP($A8,'[2]Plan - US NPI'!$C$6:$K$191,3,0) -> AXFIA | F8: =VLOOKUP($A8,'[2]Plan - US NPI'!$C$6:$K$191,9,0) -> PA Assembly | G8: QTNSN095289A.X11 | H8: QT PA ASSY, 095289A. REV X11, B66 PA ASSEMBLY FOR AXFIA/AXFIB | I8: 37 | J8: 7 | L8: STI PE53554 for 840135A to use X1 version. PE53499, .
A9: QT17IA14.21 | B9: =MID(A9,3,9) -> 17IA14.21 | C9: WIP | D9: =VLOOKUP(A9,'[1]Plan - US NPI'!$C$6:$E$192,3,0) -> #N/A | E9: =VLOOKUP($A9,'[2]Plan - US NPI'!$C$6:$K$191,3,0) -> AXFIA | F9: =VLOOKUP($A9,'[2]Plan - US NPI'!$C$6:$K$191,9,0) -> PA Assembly | G9: QTNSN095289A.X11 | H9: QT PA ASSY, 095289A. REV X11, B66 PA ASSEMBLY FOR AXFIA/AXFIB | I9: 37 | J9: 8 | L9: PE53571 for 17IA14.21,add a note to remove shield and pre-driver. Create new eSTI for 17IA14.20 adding the same note. NEW PE53611
A10: QT17IA24.00 | B10: =MID(A10,3,9) -> 17IA24.00 | C10: WIP | D10: =VLOOKUP(A10,'[1]Plan - US NPI'!$C$6:$E$192,3,0) -> #N/A | E10: AXFIA | F10: TRX/PSU/BB Assembly | G10: QTNSN095266A.X11 | H10: QT TRX ASSY, 095266A. REV X11, TRX ASSEMBLY FOR AXFIA | I10: 29 | J10: 9 | L10: PE53604, PE53707,PE53847
A11: QT17IA44.00 | B11: =MID(A11,3,9) -> 17IA44.00 | C11: WIP | D11: =VLOOKUP(A11,'[1]Plan - US NPI'!$C$6:$E$192,3,0) -> #N/A | E11: AXFIA | F11: RRH | G11: QTNSN476757A.X11 | H11: RRH X11 | I11: 15 | J11: 10 | L11: PE53701
A12: QT17IA14.50 | B12: =MID(A12,3,9) -> 17IA14.50 | C12: WIP | D12: =VLOOKUP(A12,'[1]Plan - US NPI'!$C$6:$E$192,3,0) -> #N/A | E12: =VLOOKUP($A12,'[2]Plan - US NPI'!$C$6:$K$191,3,0) -> AXFIA | F12: =VLOOKUP($A12,'[2]Plan - US NPI'!$C$6:$K$191,9,0) -> PA Assembly | G12: QTNSN095288A.X11 | H12: QT PA ASSY, 095288A. REV X11, B25 PA ASSEMBLY FOR AXFIA/AXFIB | I12: 124 | J12: 11 | L12: PE53891
A13: QT17IA14.40 | B13: =MID(A13,3,9) -> 17IA14.40 | C13: WIP | D13: =VLOOKUP(A13,'[1]Plan - US NPI'!$C$6:$E$192,3,0) -> #N/A | E13: =VLOOKUP($A13,'[2]Plan - US NPI'!$C$6:$K$191,3,0) -> AXFIA | F13: =VLOOKUP($A13,'[2]Plan - US NPI'!$C$6:$K$191,9,0) -> PA Assembly | G13: QTNSN095289A.X11 | H13: QT PA ASSY, 095289A. REV X11, B66 PA ASSEMBLY FOR AXFIA/AXFIB | I13: 124 | J13: 12 | L13: PE54018
A14: QT17IA24.10 | B14: =MID(A14,3,9) -> 17IA24.10 | C14: WIP | D14: =VLOOKUP(A14,'[1]Plan - US NPI'!$C$6:$E$192,3,0) -> #N/A | E14: =VLOOKUP($A14,'[2]Plan - US NPI'!$C$6:$K$191,3,0) -> AXFIA | F14: =VLOOKUP($A14,'[2]Plan - US NPI'!$C$6:$K$191,9,0) -> TRX/PSU/BB Assembly | G14: QTNSN095266A.X12 | H14: QT TRX ASSY, 095266A. REV X12, TRX ASSEMBLY FOR AXFIA | I14: 41 | J14: 13 | L14: X12 Bom released - PE54073
A15: QT17IA44.10 | B15: =MID(A15,3,9) -> 17IA44.10 | C15: WIP | D15: =VLOOKUP(A15,'[1]Plan - US NPI'!$C$6:$E$192,3,0) -> #N/A | E15: =VLOOKUP($A15,'[2]Plan - US NPI'!$C$6:$K$191,3,0) -> AXFIA | F15: =VLOOKUP($A15,'[2]Plan - US NPI'!$C$6:$K$191,9,0) -> RRH Unit | G15: QTNSN476757A.X12 | H15: QT T/L UNIT ASSY, 476757A. REV X12, AXFIA AirScale RRH 4T8R n25/66 720W | I15: 30 | J15: 14 | L15: Esti releasesed- Release wo- PE54404- Wo released 29-May-26 | Min of 15 units next week | Work order complete
A16: QT17IA15.80 | B16: =MID(A16,3,9) -> 17IA15.80 | C16: WIP | D16: =VLOOKUP(A16,'[1]Plan - US NPI'!$C$6:$E$192,3,0) -> #N/A | E16: AXFIA | F16: PA Assembly | G16: QTNSN095289A.X12 | H16: QT PA ASSY, 095289A. REV X12, B66 PA ASSEMBLY FOR AXFIA/AXFIB | I16: 62 | J16: 15 | L16: New PWB- Order 2 sets of stencils- new profile board needed - New profile needed - Need STI- Checkplots being worked - PE54185
A17: QT17IA15.90 | B17: =MID(A17,3,9) -> 17IA15.90 | C17: WIP | D17: =VLOOKUP(A17,'[1]Plan - US NPI'!$C$6:$E$192,3,0) -> #N/A | E17: =VLOOKUP($A17,'[2]Plan - US NPI'!$C$6:$K$191,3,0) -> AXFIA | F17: =VLOOKUP($A17,'[2]Plan - US NPI'!$C$6:$K$191,9,0) -> PA Assembly | G17: QTNSN095288A.X12 | H17: QT PA ASSY, 095288A. REV X12, B25 PA ASSEMBLY FOR AXFIA/AXFIB | I17: 62 | J17: 16 | L17: New PWB- Order 2 sets of stencils- new profile board needed - New profile needed - Need STI- Stencil 04/23- PE54164 | Q17: 46139
A18: QT19BA11.00 | B18: =MID(A18,3,9) -> 19BA11.00 | C18: WIP | D18: =VLOOKUP(A18,'[1]Plan - US NPI'!$C$6:$E$192,3,0) -> #N/A | E18: =VLOOKUP($A18,'[2]Plan - US NPI'!$C$6:$K$191,3,0) -> AXOLA | F18: =VLOOKUP($A18,'[2]Plan - US NPI'!$C$6:$K$191,9,0) -> PA Assembly | G18: QTNSN095290A.X02 | H18: QT PA ASSY, 095290A. REV X02, B71 PA ASSEMBLY FOR AXOLBA | I18: 14 | J18: 17 | L18: Stencils due on the 27- Apr- No Esti
A19: QT19BA11.10 | B19: =MID(A19,3,9) -> 19BA11.10 | C19: WIP | D19: =VLOOKUP(A19,'[1]Plan - US NPI'!$C$6:$E$192,3,0) -> #N/A | E19: =VLOOKUP($A19,'[2]Plan - US NPI'!$C$6:$K$191,3,0) -> AXOLA | F19: =VLOOKUP($A19,'[2]Plan - US NPI'!$C$6:$K$191,9,0) -> PA Assembly | G19: QTNSN095291A.X02 | H19: QT PA ASSY, 095291A. REV X02, B85 PA ASSEMBLY FOR AXOLBA | I19: 14 | J19: 18 | L19: Stencils due on the 27- Apr- No Esti- Tracking# 707296329356
A20: QT20LA21.00 | B20: =MID(A20,3,9) -> 20LA21.00 | C20: WIP | D20: =VLOOKUP(A20,'[1]Plan - US NPI'!$C$6:$E$192,3,0) -> #N/A | E20: =VLOOKUP($A20,'[2]Plan - US NPI'!$C$6:$K$191,3,0) -> AXOLA | F20: =VLOOKUP($A20,'[2]Plan - US NPI'!$C$6:$K$191,9,0) -> TRX/PSU/BB Assembly | G20: QTNSN095286A.X02 | H20: QT TRX ASSY, 095286A. REV X02, TRX ASSEMBLY FOR AXOLA | I20: 10 | J20: 19 | L20: New CP today - Check material
A21: QT17IA25.30 | B21: =MID(A21,3,9) -> 17IA25.30 | C21: WIP | D21: =VLOOKUP(A21,'[1]Plan - US NPI'!$C$6:$E$192,3,0) -> #N/A | E21: =VLOOKUP($A21,'[2]Plan - US NPI'!$C$6:$K$191,3,0) -> AXFIA | F21: =VLOOKUP($A21,'[2]Plan - US NPI'!$C$6:$K$191,9,0) -> TRX/PSU/BB Assembly | G21: QTNSN095266A.X12 | H21: QT TRX ASSY, 095266A. REV X12, TRX ASSEMBLY FOR AXFIA | I21: 47 | J21: 20 | L21: Kick off 21-May-26- ESTI -PE54408 - Released 29-May-26 | One more ESTI to be released | Stencil ETA 03-Jun-26 | PE54513- Work order relased 06/03
A22: QT17IA15.60 | B22: =MID(A22,3,9) -> 17IA15.60 | C22: WIP | D22: =VLOOKUP(A22,'[1]Plan - US NPI'!$C$6:$E$192,3,0) -> #N/A | E22: =VLOOKUP($A22,'[2]Plan - US NPI'!$C$6:$K$191,3,0) -> AXFIA | F22: =VLOOKUP($A22,'[2]Plan - US NPI'!$C$6:$K$191,9,0) -> PA Assembly | G22: QTNSN095289A.X12 | H22: QT PA ASSY, 095289A. REV X12, B66 PA ASSEMBLY FOR AXFIA/AXFIB | I22: 188 | J22: 21 | L22: Kick off 21-May-26- ESTI - PE54407- WO Released 29-May-26
A23: QT17IA15.70 | B23: =MID(A23,3,9) -> 17IA15.70 | C23: WIP | D23: =VLOOKUP(A23,'[1]Plan - US NPI'!$C$6:$E$192,3,0) -> #N/A | E23: =VLOOKUP($A23,'[2]Plan - US NPI'!$C$6:$K$191,3,0) -> AXFIA | F23: =VLOOKUP($A23,'[2]Plan - US NPI'!$C$6:$K$191,9,0) -> PA Assembly | G23: QTNSN095288A.X12 | H23: QT PA ASSY, 095288A. REV X12, B25 PA ASSEMBLY FOR AXFIA/AXFIB | I23: 188 | J23: 22 | L23: Kick off 21-May-26- ESTI - PE54405- WO Released 29-May-26
A24: QT17IA45.30 | B24: =MID(A24,3,9) -> 17IA45.30 | C24: WIP | D24: =VLOOKUP(A24,'[1]Plan - US NPI'!$C$6:$E$192,3,0) -> #N/A | E24: =VLOOKUP($A24,'[2]Plan - US NPI'!$C$6:$K$191,3,0) -> AXFIA | F24: =VLOOKUP($A24,'[2]Plan - US NPI'!$C$6:$K$191,9,0) -> RRH Unit | G24: QTNSN476757A.X12 | H24: QT T/L UNIT ASSY, 476757A. REV X12, AXFIA AirScale RRH 4T8R n25/66 720W | I24: 47 | J24: 23 | L24: PE54409 & PE54856 - Released 29-May-26_ need to release work order- Relased 15-Jun-26 | Rework on the Chassis | Committing 22 pcs for next week | P55306
A25: QT17IA45.40 | B25: =MID(A25,3,9) -> 17IA45.40 | C25: WIP | D25: =VLOOKUP(A25,'[1]Plan - US NPI'!$C$6:$E$192,3,0) -> #N/A | E25: AXFIA | F25: RRH Unit | G25: QTNSN476757A.X12 | H25: QT T/L UNIT ASSY, 476757A. REV X12, AXFIA AirScale RRH 4T8R n25/66 720W | I25: 11 | J25: 24 | L25: Kick off- ESTI PE54381 - WO released
A26: QT17IA15.95 | B26: =MID(A26,3,9) -> 17IA15.95 | C26: WIP | D26: =VLOOKUP(A26,'[1]Plan - US NPI'!$C$6:$E$192,3,0) -> #N/A | E26: =VLOOKUP($A26,'[2]Plan - US NPI'!$C$6:$K$191,3,0) -> AXFIA | F26: =VLOOKUP($A26,'[2]Plan - US NPI'!$C$6:$K$191,9,0) -> PA Assembly | G26: QTNSN095289A.X12 | H26: QT PA ASSY, 095289A. REV X12, B66 PA ASSEMBLY FOR AXFIA/AXFIB | I26: 140 | J26: 25 | L26: Stencils , same PWB, STI for Solder paste PE54356- requested to run on the 2oth of May | New profile needed for Different solder paste
A27: QT17IA15.96 | B27: =MID(A27,3,9) -> 17IA15.96 | C27: WIP | D27: =VLOOKUP(A27,'[1]Plan - US NPI'!$C$6:$E$192,3,0) -> #N/A | E27: =VLOOKUP($A27,'[2]Plan - US NPI'!$C$6:$K$191,3,0) -> AXFIA | F27: =VLOOKUP($A27,'[2]Plan - US NPI'!$C$6:$K$191,9,0) -> PA Assembly | G27: QTNSN095288A.X12 | H27: QT PA ASSY, 095288A. REV X12, B25 PA ASSEMBLY FOR AXFIA/AXFIB | I27: 140 | J27: 26 | L27: PE54357- Solder paste STI- Received | New profile needed for Different solder paste
A28: QT20LA12.00 | B28: =MID(A28,3,9) -> 20LA12.00 | C28: WIP | D28: =VLOOKUP(A28,'[1]Plan - US NPI'!$C$6:$E$192,3,0) -> #N/A | E28: =VLOOKUP($A28,'[2]Plan - US NPI'!$C$6:$K$191,3,0) -> AXOLA | F28: =VLOOKUP($A28,'[2]Plan - US NPI'!$C$6:$K$191,9,0) -> PA Assembly | G28: QTNSN095290A.X02 | H28: QT PA ASSY, 095290A. REV X02, B71 PA ASSEMBLY FOR AXOLBA | I28: 64 | J28: 27 | L28: Esti releasesed- PE54413- WO released 27-May-26- need profile approved
A29: QT20LA12.10 | B29: =MID(A29,3,9) -> 20LA12.10 | C29: WIP | D29: =VLOOKUP(A29,'[1]Plan - US NPI'!$C$6:$E$192,3,0) -> #N/A | E29: =VLOOKUP($A29,'[2]Plan - US NPI'!$C$6:$K$191,3,0) -> AXOLA | F29: =VLOOKUP($A29,'[2]Plan - US NPI'!$C$6:$K$191,9,0) -> PA Assembly | G29: QTNSN095291A.X02 | H29: QT PA ASSY, 095291A. REV X02, B85 PA ASSEMBLY FOR AXOLBA | I29: 64 | J29: 28 | L29: Esti releasesed- WO released 27-May-26- Need profile approved
A30: QT20LA41.00 | B30: =MID(A30,3,9) -> 20LA41.00 | C30: WIP | D30: =VLOOKUP(A30,'[1]Plan - US NPI'!$C$6:$E$192,3,0) -> #N/A | E30: =VLOOKUP($A30,'[2]Plan - US NPI'!$C$6:$K$191,3,0) -> AXOLA | F30: =VLOOKUP($A30,'[2]Plan - US NPI'!$C$6:$K$191,9,0) -> RRH Unit | G30: QTNSN476797A.X11 | H30: QT T/L UNIT ASSY, 476797A.REV X11, AXOLA AirScale RRH 4T4R n71/85 320W | I30: 8 | J30: 29 | L30: CTB- ESTI PE54470 | WO release today 03-Jun-26- Followed up on ESTI | TRX rework need to look at material | STI released -
A31: QT19BA21.00A | B31: =MID(A31,3,9) -> 19BA21.00 | C31: WIP | D31: =VLOOKUP(A31,'[1]Plan - US NPI'!$C$6:$E$192,3,0) -> #N/A | E31: AXOLBA | F31: TRX/PSU/BB Assembly | G31: QTNSN095804A.X11 | I31: 22 | J31: 30 | L31: Relased 06/12- Critical components | 2 pcs Skipping FT- Nokia to pick up | Parametric Data- * 8 boards need rework STI to be released- Cannot test | PE55020- Rework STI with 3 parts that we need to buy-Load independent demand- Rework quote 12 boards- Quote needed pull parts to Soka | M31: Quote sent
A32: QT19BA12.20 | B32: =MID(A32,3,9) -> 19BA12.20 | C32: WIP | D32: =VLOOKUP(A32,'[1]Plan - US NPI'!$C$6:$E$192,3,0) -> #N/A | E32: =VLOOKUP($A32,'[2]Plan - US NPI'!$C$6:$K$191,3,0) -> AXOLBA | F32: =VLOOKUP($A32,'[2]Plan - US NPI'!$C$6:$K$191,9,0) -> PA Assembly | G32: QTNSN095290A.X02 | I32: 32 | J32: 31 | L32: ESTI - Sac305 PE54542- Work order QT20LA12.00 increased to 64 units
A33: QT19BA12.30 | B33: =MID(A33,3,9) -> 19BA12.30 | C33: WIP | D33: =VLOOKUP(A33,'[1]Plan - US NPI'!$C$6:$E$192,3,0) -> #N/A | E33: =VLOOKUP($A33,'[2]Plan - US NPI'!$C$6:$K$191,3,0) -> AXOLBA | F33: =VLOOKUP($A33,'[2]Plan - US NPI'!$C$6:$K$191,9,0) -> PA Assembly | G33: QTNSN095291A.X02 | I33: 32 | J33: 32 | L33: ESTI - Sac305 PE54541- Work order QT20LA12.10 increased to 64 units
A34: QT19BA41.00 | B34: =MID(A34,3,9) -> 19BA41.00 | C34: WIP | D34: =VLOOKUP(A34,'[1]Plan - US NPI'!$C$6:$E$192,3,0) -> #N/A | E34: =VLOOKUP($A34,'[2]Plan - US NPI'!$C$6:$K$191,3,0) -> AXOLBA | F34: =VLOOKUP($A34,'[2]Plan - US NPI'!$C$6:$K$191,9,0) -> RRH Unit | G34: QTNSN476971A.X11 | I34: 8 | J34: 33 | L34: No ESTI_ Nokia checking -06/16 | Chassis and Filter check stock | ESTI to be released PE54770- Share costed bom- New CP To be loaded today | Assembly to be stopped| Commiting to 8 wk 31 | M34: Quote sent-20-Jul-26 | N34: Press plate and Carriers - Delivered from CNC
A35: QT17IA24.20 | B35: =MID(A35,3,9) -> 17IA24.20 | C35: WIP | D35: =VLOOKUP(A35,'[1]Plan - US NPI'!$C$6:$E$192,3,0) -> #N/A | E35: =VLOOKUP($A35,'[2]Plan - US NPI'!$C$6:$K$191,3,0) -> AXFIA | F35: =VLOOKUP($A35,'[2]Plan - US NPI'!$C$6:$K$191,9,0) -> TRX/PSU/BB Assembly | G35: QTNSN095266A.X21 | I35: 29 | J35: 34 | K35: PE55517 | L35: RelaseD 06/15 | Old profile can be used- Review with Jose current issues on the X12 build | Same profile as AXOLBA | Waiting on Quote for rework
A36: QT17IA14.70 | B36: =MID(A36,3,9) -> 17IA14.70 | C36: WIP | D36: AXFIA | E36: AXFIA | F36: PA Assembly | G36: QTNSN095288A.X21 | I36: 74 | J36: 35 | K36: PE55485 | L36: PE54718 | PE54609 | PE54651 - Jose Stencils- Clean released 24-Jun-26- New ESTI for preform ( )| Any date for the Macom part P620299
A37: QT17IA14.60 | B37: =MID(A37,3,9) -> 17IA14.60 | C37: WIP | D37: =VLOOKUP(A37,'[1]Plan - US NPI'!$C$6:$E$192,3,0) -> #N/A | E37: =VLOOKUP($A37,'[2]Plan - US NPI'!$C$6:$K$191,3,0) -> AXFIA | F37: =VLOOKUP($A37,'[2]Plan - US NPI'!$C$6:$K$191,9,0) -> PA Assembly | G37: QTNSN095289A.X21 | I37: 74 | J37: 36 | L37: PE54719, PE54667 ,PE54611 STI- Jose Stencils- 3 shortages- not clean- 2 MTRs to Oulu, 1 Po from Distro-New STI to be released- Labels
A38: QT18OA21.00A | B38: =MID(A38,3,9) -> 18OA21.00 | C38: WIP | D38: Need to release work order | E38: AXOA | F38: TRX/PSU/BB Assembly | G38: QTNSN095725A.X11 | I38: 11 | J38: 37 | L38: need STI for X11 Bom | 4 STIS- PE54721,PE54724,PE55044,PE55107 & New STI to be released to run 4 boards without carriers on reflow | M38: Sent 21-Aug-26
A39: QT20LA22.00 | B39: =MID(A39,3,9) -> 20LA22.00 | C39: WIP | D39: =VLOOKUP(A39,'[1]Plan - US NPI'!$C$6:$E$192,3,0) -> #N/A | E39: =VLOOKUP($A39,'[2]Plan - US NPI'!$C$6:$K$191,3,0) -> AXOLA | F39: =VLOOKUP($A39,'[2]Plan - US NPI'!$C$6:$K$191,9,0) -> TRX/PSU/BB Assembly | G39: QTNSN095803A.X03 | I39: 14 | J39: 38 | L39: 1 component dif from the 804A.X11 Build | STI PE54748 - released today | Stencil Same as 804 | ON HOLD- YK262800086 Ship "as-is" to Salvador | Bom Update needed or STI| PE55140 to skip test and bom changes for the remainning boards | Close at 4 - new build for the remainning 095286A.xo2 | M39: Quote sent 13-July-26
A40: QT20LA15.93 | B40: =MID(A40,3,9) -> 20LA15.93 | C40: WIP | E40: =VLOOKUP($A40,'[2]Plan - US NPI'!$C$6:$K$191,3,0) -> AXOLA | F40: =VLOOKUP($A40,'[2]Plan - US NPI'!$C$6:$K$191,9,0) -> PA Assembly | G40: QTNSN095290A.X02 | I40: 13 | J40: 39 | L40: PE54809- Release Work order-PWB supplier info- Clean - Complete | M40: Quote sent 16-July-26
...

Sheet Rework
A1: TRX | D1: STI | E1: Work order | F1: Qty
A2: Program | B2: Comments | C2: Priorty | D2: STI | E2: Work order | F2: QTY | G2: Part number | H2: Qty not being reworked | I2: Time | J2: Total mins
A3: AXOLA | B3: No Aoi and 5 DX no Final QC, No testing | C3: P1 | D3: PE55549 | E3: 20LA23.10 | F3: 8 | G3: 095286A.X14 | H3: 2 units shipped | I3: 10 | J3: =F3*I3 -> 80
A4: AXOLBA | B4: NO Aoi and 5 DX , Final QC and Need to test the board | C4: P2 | D4: PE55526 | E4: 19BA22.00 | F4: 56 | G4: 095804A.X12 | H4: 8 units on Radios | I4: =10+20 -> 30 | J4: =F4*I4 -> 1680
A5: AXFIA | B5: NO Aoi and 5 DX , Final QC and Need to test the board | C5: P3 | D5: PE55522 | E5: 17IA24.30 | F5: 52 | G5: 095266A.X21 | I5: =10+20 -> 30 | J5: =F5*I5 -> 1560
A6: AXFIA | B6: NO Aoi and 5 DX , Final QC and Need to test the board | C6: P3 | D6: PE55517 | E6: 17IA24.20 | F6: 16 | G6: 095266A.X21 | H6: 10 shipped and 3 radios | I6: 30 | J6: =(4*30)+(12*10) -> 240
J7: =SUM(J3:J6) -> 3560
A13: Program | B13: Comments | C13: Priorty | D13: STI | E13: Work order | F13: QTY | G13: Part number | H13: Qty not being reworked | J13: Rework time | K13: Test time | L13: Total Time
A14: AXOLA | B14: No Aoi and 5 DX , Final QC, No testing | C14: P1 | D14: PE55549 | E14: 20LA23.10 | F14: 8 | G14: 095286A.X14 | H14: 2 units shipped | I14: 10 | J14: 80 | K14: 0 | L14: =J14+K14 -> 80
A15: AXOLBA | B15: NO Aoi and 5 DX , Final QC and Need to test the board | C15: P2 | D15: PE55526 | E15: 19BA22.00 | F15: 56 | G15: 095804A.X12 | H15: 8 units on Radios | I15: 10 | J15: 560 | K15: 200 | L15: =J15+K15 -> 760 | M15: 10 boards needs to be retested
A16: AXFIA | B16: NO Aoi and 5 DX , Final QC and Need to test the board | C16: P3 | D16: PE55522 | E16: 17IA24.30 | F16: 52 | G16: 095266A.X21 | I16: 10 | J16: 520 | K16: 0 | L16: =J16+K16 -> 520
A17: AXFIA | B17: NO Aoi and 5 DX , Final QC and Need to test the board( No need to test boards that have already passed) | C17: P3 | D17: PE55517 | E17: 17IA24.20 | F17: 16 | G17: 095266A.X21 | H17: 10 shipped and 3 radios | I17: 10 | J17: 160 | K17: 80 | L17: =J17+K17 -> 240 | M17: 4 boards need to be retested
J18: 1320 | K18: 280 | L18: =SUM(L14:L17) -> 1600
A26: Program | B26: Comments | C26: Priorty | D26: STI | E26: Work order | F26: QTY | H26: Part number | I26: Qty not being reworked | J26: Rework time | K26: Test time | L26: Total Time
A27: AXOLA | B27: No Aoi and 5 DX , Final QC, No testing | C27: P1 | D27: PE55549 | E27: 20LA23.10 | F27: 8 | G27: 8 | H27: 095286A.X14 | I27: 2 units shipped | J27: 80 | K27: 0 | L27: =J27+K27 -> 80
A28: AXOLBA | B28: NO Aoi and 5 DX , Final QC and Need to test the board | C28: P2 | D28: PE55526 | E28: 19BA22.00 | F28: 56 | H28: 095804A.X12 | I28: 8 units on Radios | J28: 560 | K28: 200 | L28: =J28+K28 -> 760 | M28: 10 boards needs to be retested
A29: AXFIA | B29: NO Aoi and 5 DX , Final QC and Need to test the board | C29: P3 | D29: PE55522 | E29: 17IA24.30 | F29: 52 | H29: 095266A.X21 | J29: 520 | K29: 0 | L29: =J29+K29 -> 520
A30: AXFIA | B30: NO Aoi and 5 DX , Final QC and Need to test the board( No need to test boards that have already passed) | C30: P3 | D30: PE55517 | E30: 17IA24.20 | F30: 16 | G30: 16 | H30: 095266A.X21 | I30: 10 shipped and 3 radios | J30: 160 | K30: 80 | L30: =J30+K30 -> 240 | M30: 4 boards need to be retested
J31: 1320 | K31: 280 | L31: =SUM(L27:L30) -> 1600
