Workbook

Sheet Shop Order
A1: Serial Number | B1: Workstation | C1: Process | D1: Qty | E1: Unit Status | F1: Last Updated | G1: Work order | H1: Part number | I1: Priority | J1: Comments | K1: Shipping date | L1: asdas
A2: YK260300123 | B2: NOT-IN-PROCESS | C2: NOT-IN-PROCESS | D2: 1 | E2: Unit Component (60) | F2: 46065.449 | G2: QT17IA14.00 | H2: QTNSN095288A.X03 | I2: =VLOOKUP(G2,Sheet2!A:H,8,0) -> 1
A3: YK260300124 | B3: NOT-IN-PROCESS | C3: NOT-IN-PROCESS | D3: 1 | E3: Unit Component (60) | F3: 46065.45 | G3: QT17IA14.00 | H3: QTNSN095288A.X03 | I3: =VLOOKUP(G3,Sheet2!A:H,8,0) -> 1
A4: YK260300125 | B4: NOT-IN-PROCESS | C4: NOT-IN-PROCESS | D4: 1 | E4: Unit Component (60) | F4: 46071.552 | G4: QT17IA14.00 | H4: QTNSN095288A.X03 | I4: =VLOOKUP(G4,Sheet2!A:H,8,0) -> 1
A5: YK260300126 | B5: NOT-IN-PROCESS | C5: NOT-IN-PROCESS | D5: 1 | E5: Unit Component (60) | F5: 46072.29 | G5: QT17IA14.00 | H5: QTNSN095288A.X03 | I5: =VLOOKUP(G5,Sheet2!A:H,8,0) -> 1
A6: YK260300127 | B6: NOT-IN-PROCESS | C6: NOT-IN-PROCESS | D6: 1 | E6: Unit Component (60) | F6: 46076.37 | G6: QT17IA14.00 | H6: QTNSN095288A.X03 | I6: =VLOOKUP(G6,Sheet2!A:H,8,0) -> 1
A7: YK260300128 | B7: SHIP Shipping | C7: Shipped to Customer | D7: 1 | E7: Shipped (40) | F7: 46112.311 | G7: QT17IA14.00 | H7: QTNSN095288A.X03 | I7: =VLOOKUP(G7,Sheet2!A:H,8,0) -> 1
A8: YK260300129 | B8: NOT-IN-PROCESS | C8: NOT-IN-PROCESS | D8: 1 | E8: Unit Component (60) | F8: 46065.432 | G8: QT17IA14.00 | H8: QTNSN095288A.X03 | I8: =VLOOKUP(G8,Sheet2!A:H,8,0) -> 1
A9: YK260300130 | B9: NOT-IN-PROCESS | C9: NOT-IN-PROCESS | D9: 1 | E9: Unit Component (60) | F9: 46071.282 | G9: QT17IA14.00 | H9: QTNSN095288A.X03 | I9: =VLOOKUP(G9,Sheet2!A:H,8,0) -> 1
A10: YK260300131 | B10: NOT-IN-PROCESS | C10: NOT-IN-PROCESS | D10: 1 | E10: Unit Component (60) | F10: 46076.374 | G10: QT17IA14.00 | H10: QTNSN095288A.X03 | I10: =VLOOKUP(G10,Sheet2!A:H,8,0) -> 1
A11: YK260300132 | B11: NOT-IN-PROCESS | C11: NOT-IN-PROCESS | D11: 1 | E11: Unit Component (60) | F11: 46065.431 | G11: QT17IA14.00 | H11: QTNSN095288A.X03 | I11: =VLOOKUP(G11,Sheet2!A:H,8,0) -> 1
A12: YK260300133 | B12: NOT-IN-PROCESS | C12: NOT-IN-PROCESS | D12: 1 | E12: Unit Component (60) | F12: 46072.486 | G12: QT17IA14.00 | H12: QTNSN095288A.X03 | I12: =VLOOKUP(G12,Sheet2!A:H,8,0) -> 1
A13: YK260300134 | B13: NOT-IN-PROCESS | C13: NOT-IN-PROCESS | D13: 1 | E13: Unit Component (60) | F13: 46065.449 | G13: QT17IA14.00 | H13: QTNSN095288A.X03 | I13: =VLOOKUP(G13,Sheet2!A:H,8,0) -> 1
... A158: YK260900007 | B158: NOT-IN-PROCESS | C158: NOT-IN-PROCESS | D158: 1 | E158: Unit Component (60) | F158: 46150.392 | G158: QT17IA14.20 | H158: QTNSN095289A.X11 | I158: =VLOOKUP(G158,Sheet2!A:H,8,0) -> 7
A159: YK260900008 | B159: SHIP Shipping | C159: Shipped to Customer | D159: 1 | E159: Shipped (40) | F159: 46123.268 | G159: QT17IA14.20 | H159: QTNSN095289A.X11 | I159: =VLOOKUP(G159,Sheet2!A:H,8,0) -> 7 | K159: 46105
A160: YK260900009 | B160: SHIP Shipping | C160: Shipped to Customer | D160: 1 | E160: Shipped (40) | F160: 46123.268 | G160: QT17IA14.20 | H160: QTNSN095289A.X11 | I160: =VLOOKUP(G160,Sheet2!A:H,8,0) -> 7 | K160: 46105
A161: YK260900010 | B161: RWK1 Repair Test | C161: Rework-1 | D161: 1 | E161: In Repair (25) | F161: 46135.342 | G161: QT17IA14.20 | H161: QTNSN095289A.X11 | I161: =VLOOKUP(G161,Sheet2!A:H,8,0) -> 7
A162: YK260900011 | B162: SHIP Shipping | C162: Shipped to Customer | D162: 1 | E162: Shipped (40) | F162: 46123.268 | G162: QT17IA14.20 | H162: QTNSN095289A.X11 | I162: =VLOOKUP(G162,Sheet2!A:H,8,0) -> 7 | K162: 46105
A163: YK260900012 | B163: SHIP Shipping | C163: Shipped to Customer | D163: 1 | E163: Shipped (40) | F163: 46154.373 | G163: QT17IA14.20 | H163: QTNSN095289A.X11 | I163: =VLOOKUP(G163,Sheet2!A:H,8,0) -> 7 | K163: 46156
A164: YK260900013 | B164: NOT-IN-PROCESS | C164: NOT-IN-PROCESS | D164: 1 | E164: Unit Component (60) | F164: 46153.505 | G164: QT17IA14.20 | H164: QTNSN095289A.X11 | I164: =VLOOKUP(G164,Sheet2!A:H,8,0) -> 7
A165: YK260900014 | B165: NOT-IN-PROCESS | C165: NOT-IN-PROCESS | D165: 1 | E165: Unit Component (60) | F165: 46140.311 | G165: QT17IA14.20 | H165: QTNSN095289A.X11 | I165: =VLOOKUP(G165,Sheet2!A:H,8,0) -> 7
A166: YK260900015 | B166: DBG1 Debug Test | C166: Xfr to Debug Test | D166: 1 | E166: In Repair Hold (29) | F166: 46128.38 | G166: QT17IA14.20 | H166: QTNSN095289A.X11 | I166: =VLOOKUP(G166,Sheet2!A:H,8,0) -> 7
A167: YK260900016 | B167: NOT-IN-PROCESS | C167: NOT-IN-PROCESS | D167: 1 | E167: Unit Component (60) | F167: 46146.277 | G167: QT17IA14.20 | H167: QTNSN095289A.X11 | I167: =VLOOKUP(G167,Sheet2!A:H,8,0) -> 7
A168: YK260900017 | B168: CMP1 Complete | C168: Complete | D168: 1 | E168: Finished (30) | F168: 46139.587 | G168: QT17IA14.20 | H168: QTNSN095289A.X11 | I168: =VLOOKUP(G168,Sheet2!A:H,8,0) -> 7
A169: YK260900018 | B169: SHIP Shipping | C169: Shipped to Customer | D169: 1 | E169: Shipped (40) | F169: 46123.268 | G169: QT17IA14.20 | H169: QTNSN095289A.X11 | I169: =VLOOKUP(G169,Sheet2!A:H,8,0) -> 7 | K169: 46097
A170: YK260900019 | B170: RWK3 Repair Test | C170: Rework-3 | D170: 1 | E170: In Repair (25) | F170: 46148.356 | G170: QT17IA14.20 | H170: QTNSN095289A.X11 | I170: =VLOOKUP(G170,Sheet2!A:H,8,0) -> 7
A171: YK260900020 | B171: NOT-IN-PROCESS | C171: NOT-IN-PROCESS | D171: 1 | E171: Unit Component (60) | F171: 46153.435 | G171: QT17IA14.20 | H171: QTNSN095289A.X11 | I171: =VLOOKUP(G171,Sheet2!A:H,8,0) -> 7
A172: YK260900021 | B172: FUN1 Func Test | C172: Functional Test-1 | D172: 1 | E172: On The Line (20) | F172: 46122.381 | G172: QT17IA14.20 | H172: QTNSN095289A.X11 | I172: =VLOOKUP(G172,Sheet2!A:H,8,0) -> 7
A173: YK260900022 | B173: SHIP Shipping | C173: Shipped to Customer | D173: 1 | E173: Shipped (40) | F173: 46174.475 | G173: QT17IA14.20 | H173: QTNSN095289A.X11 | I173: =VLOOKUP(G173,Sheet2!A:H,8,0) -> 7 | K173: 46128
A174: YK260900023 | B174: RWK1 Repair Test | C174: Rework-1 | D174: 1 | E174: In Repair (25) | F174: 46134.411 | G174: QT17IA14.20 | H174: QTNSN095289A.X11 | I174: =VLOOKUP(G174,Sheet2!A:H,8,0) -> 7
A175: YK260900024 | B175: CMP1 Complete | C175: Complete | D175: 1 | E175: Finished (30) | F175: 46128.361 | G175: QT17IA14.20 | H175: QTNSN095289A.X11 | I175: =VLOOKUP(G175,Sheet2!A:H,8,0) -> 7
A176: YK260900025 | B176: CMP1 Complete | C176: Complete | D176: 1 | E176: Finished (30) | F176: 46135.443 | G176: QT17IA14.20 | H176: QTNSN095289A.X11 | I176: =VLOOKUP(G176,Sheet2!A:H,8,0) -> 7
A177: YK260900026 | B177: RWK1 Repair Test | C177: Rework-1 | D177: 1 | E177: In Repair (25) | F177: 46134.363 | G177: QT17IA14.20 | H177: QTNSN095289A.X11 | I177: =VLOOKUP(G177,Sheet2!A:H,8,0) -> 7
A178: YK260900027 | B178: FUN1 Func Test | C178: Functional Test-1 | D178: 1 | E178: On The Line (20) | F178: 46122.382 | G178: QT17IA14.20 | H178: QTNSN095289A.X11 | I178: =VLOOKUP(G178,Sheet2!A:H,8,0) -> 7
A179: YK260900028 | B179: CMP1 Complete | C179: Complete | D179: 1 | E179: Finished (30) | F179: 46134.597 | G179: QT17IA14.20 | H179: QTNSN095289A.X11 | I179: =VLOOKUP(G179,Sheet2!A:H,8,0) -> 7
A180: YK260900029 | B180: SHIP Shipping | C180: Shipped to Customer | D180: 1 | E180: Shipped (40) | F180: 46123.268 | G180: QT17IA14.20 | H180: QTNSN095289A.X11 | I180: =VLOOKUP(G180,Sheet2!A:H,8,0) -> 7 | K180: 46097
A181: YK260900030 | B181: SHIP Shipping | C181: Shipped to Customer | D181: 1 | E181: Shipped (40) | F181: 46123.268 | G181: QT17IA14.20 | H181: QTNSN095289A.X11 | I181: =VLOOKUP(G181,Sheet2!A:H,8,0) -> 7 | K181: 46105
A182: YK260900031 | B182: SHIP Shipping | C182: Shipped to Customer | D182: 1 | E182: Shipped (40) | F182: 46123.268 | G182: QT17IA14.20 | H182: QTNSN095289A.X11 | I182: =VLOOKUP(G182,Sheet2!A:H,8,0) -> 7 | K182: 46112
A183: YK260900032 | B183: FUN1 Func Test | C183: Functional Test-1 | D183: 1 | E183: On The Line (20) | F183: 46115.654 | G183: QT17IA14.20 | H183: QTNSN095289A.X11 | I183: =VLOOKUP(G183,Sheet2!A:H,8,0) -> 7
A184: YK260900033 | B184: DBG1 Debug Test | C184: Xfr to Debug Test | D184: 1 | E184: In Repair Hold (29) | F184: 46128.399 | G184: QT17IA14.20 | H184: QTNSN095289A.X11 | I184: =VLOOKUP(G184,Sheet2!A:H,8,0) -> 7
...

Sheet Sheet1
A1: Serial Number | B1: Workstation | C1: Process | D1: Qty | E1: Unit Status | F1: Last Updated | G1: Work order | H1: Part number | I1: Priority | J1: Comments | K1: Shipping date | L1: asdas
A2: YK262300810 | B2: 1DBG Debug Test | C2: Debug Test-1 | D2: 1 | E2: In Repair (25) | F2: 46190.566 | G2: QT17IA44.10 | H2: QTNSN476757A.X12 | I2: 14
A3: YK262300809 | B3: 1DBG Debug Test | C3: Debug Test-1 | D3: 1 | E3: In Repair (25) | F3: 46191.387 | G3: QT17IA44.10 | H3: QTNSN476757A.X12 | I3: 14
A4: YK262300805 | B4: 1DBG Debug Test | C4: Debug Test-1 | D4: 1 | E4: In Repair (25) | F4: 46191.388 | G4: QT17IA44.10 | H4: QTNSN476757A.X12 | I4: 14
A5: YK262300802 | B5: 1DBG Debug Test | C5: Debug Test-1 | D5: 1 | E5: In Repair (25) | F5: 46191.382 | G5: QT17IA44.10 | H5: QTNSN476757A.X12 | I5: 14

Sheet Sheet3
A1: Serial Number | B1: Workstation | C1: Process | D1: Qty | E1: Unit Status | F1: Last Updated | G1: Work order | H1: Part number | I1: Priority | J1: Comments | K1: Shipping date | L1: asdas
A2: YK262300825 | B2: NOT-IN-PROCESS | C2: NOT-IN-PROCESS | D2: 1 | E2: Traveler Printed (15) | F2: 46174.554 | G2: QT17IA44.10 | H2: QTNSN476757A.X12 | I2: 14
A3: YK262300824 | B3: NOT-IN-PROCESS | C3: NOT-IN-PROCESS | D3: 1 | E3: Traveler Printed (15) | F3: 46174.554 | G3: QT17IA44.10 | H3: QTNSN476757A.X12 | I3: 14
A4: YK262300823 | B4: NOT-IN-PROCESS | C4: NOT-IN-PROCESS | D4: 1 | E4: Traveler Printed (15) | F4: 46174.554 | G4: QT17IA44.10 | H4: QTNSN476757A.X12 | I4: 14
A5: YK262300822 | B5: NOT-IN-PROCESS | C5: NOT-IN-PROCESS | D5: 1 | E5: Traveler Printed (15) | F5: 46174.554 | G5: QT17IA44.10 | H5: QTNSN476757A.X12 | I5: 14
A6: YK262300821 | B6: NOT-IN-PROCESS | C6: NOT-IN-PROCESS | D6: 1 | E6: Traveler Printed (15) | F6: 46174.554 | G6: QT17IA44.10 | H6: QTNSN476757A.X12 | I6: 14
A7: YK262300820 | B7: NOT-IN-PROCESS | C7: NOT-IN-PROCESS | D7: 1 | E7: Traveler Printed (15) | F7: 46174.554 | G7: QT17IA44.10 | H7: QTNSN476757A.X12 | I7: 14
A8: YK262300819 | B8: NOT-IN-PROCESS | C8: NOT-IN-PROCESS | D8: 1 | E8: Traveler Printed (15) | F8: 46174.554 | G8: QT17IA44.10 | H8: QTNSN476757A.X12 | I8: 14
A9: YK262300818 | B9: NOT-IN-PROCESS | C9: NOT-IN-PROCESS | D9: 1 | E9: Traveler Printed (15) | F9: 46174.554 | G9: QT17IA44.10 | H9: QTNSN476757A.X12 | I9: 14
A10: YK262300817 | B10: NOT-IN-PROCESS | C10: NOT-IN-PROCESS | D10: 1 | E10: Traveler Printed (15) | F10: 46174.554 | G10: QT17IA44.10 | H10: QTNSN476757A.X12 | I10: 14
A11: YK262300816 | B11: NOT-IN-PROCESS | C11: NOT-IN-PROCESS | D11: 1 | E11: Traveler Printed (15) | F11: 46174.554 | G11: QT17IA44.10 | H11: QTNSN476757A.X12 | I11: 14
A12: YK262300815 | B12: NOT-IN-PROCESS | C12: NOT-IN-PROCESS | D12: 1 | E12: Traveler Printed (15) | F12: 46174.554 | G12: QT17IA44.10 | H12: QTNSN476757A.X12 | I12: 14
A13: YK262300814 | B13: NOT-IN-PROCESS | C13: NOT-IN-PROCESS | D13: 1 | E13: Traveler Printed (15) | F13: 46174.554 | G13: QT17IA44.10 | H13: QTNSN476757A.X12 | I13: 14

Sheet Sheet4
A1: Serial Number | B1: Workstation | C1: Process | D1: Qty | E1: Unit Status | F1: Last Updated | G1: Work order | H1: Part number | I1: Priority | J1: Comments | K1: Shipping date | L1: asdas
A2: YK262000121 | B2: CMP1 Complete | C2: Complete | D2: 1 | E2: Finished (30) | F2: 46191.678 | G2: QT20LA21.00 | H2: QTNSN095286A.X02 | I2: 21
A3: YK262000116 | B3: CMP1 Complete | C3: Complete | D3: 1 | E3: Finished (30) | F3: 46191.405 | G3: QT20LA21.00 | H3: QTNSN095286A.X02 | I3: 21

Sheet Summary
A1: Row Labels | B1: Work order | C1: Part number | D1: Process | E1: Unit Status | F1: Count of Qty
A2: 1 | B2: QT17IA14.00 | C2: QTNSN095288A.X03 | D2: NOT-IN-PROCESS | E2: Unit Component (60) | F2: 64 | I2: =MID(B2,3,21) -> 17IA14.00
D3: Shipped to Customer | E3: Shipped (40) | F3: 6 | I3: =MID(B3,3,21)
A4: 2 | B4: QT17IA14.10 | C4: QTNSN095289A.X03 | D4: NOT-IN-PROCESS | E4: Unit Component (60) | F4: 64 | I4: =MID(B4,3,21) -> 17IA14.10
D5: Shipped to Customer | E5: Shipped (40) | F5: 16 | I5: =MID(B5,3,21)
A6: 3 | B6: QT17IA23.00 | C6: QTNSN095266A.X02 | D6: NOT-IN-PROCESS | E6: Unit Component (60) | F6: 11 | I6: =MID(B6,3,21) -> 17IA23.00
D7: Shipped to Customer | E7: Shipped (40) | F7: 14 | I7: =MID(B7,3,21)
A8: 4 | B8: QT17IA43.00 | C8: QTNSN476757A.X02 | D8: Shipped to Customer | E8: Shipped (40) | F8: 20 | I8: =MID(B8,3,21) -> 17IA43.00
A9: 5 | B9: QT17IA14.30 | C9: QTNSN095288A.X11 | D9: Complete | E9: Finished (30) | F9: 13 | I9: =MID(B9,3,21) -> 17IA14.30
D10: Functional Test-1 | E10: On The Line (20) | F10: 2 | I10: =MID(B10,3,21)
D11: NOT-IN-PROCESS | E11: Unit Component (60) | F11: 11 | I11: =MID(B11,3,21)
D12: Shipped to Customer | E12: Shipped (40) | F12: 8 | I12: =MID(B12,3,21)
D13: UNTT | E13: On The Line (20) | F13: 1 | I13: =MID(B13,3,21)
D14: Rework-1 | E14: In Repair (25) | F14: 2 | I14: =MID(B14,3,21)
A15: 6 | B15: QT17IA14.31 | C15: QTNSN095288A.X11 | D15: Complete | E15: Finished (30) | F15: 12 | I15: =MID(B15,3,21) -> 17IA14.31
D16: Functional Test-1 | E16: On The Line (20) | F16: 1 | I16: =MID(B16,3,21)
D17: NOT-IN-PROCESS | E17: Unit Component (60) | F17: 12 | I17: =MID(B17,3,21)
D18: Shipped to Customer | E18: Shipped (40) | F18: 8 | I18: =MID(B18,3,21)
D19: Xfr to Debug Test | E19: In Repair Hold (29) | F19: 1 | I19: =MID(B19,3,21)
D20: Rework-1 | E20: In Repair (25) | F20: 1 | I20: =MID(B20,3,21)
D21: Rework-3 | E21: In Repair (25) | F21: 2 | I21: =MID(B21,3,21)
A22: 7 | B22: QT17IA14.20 | C22: QTNSN095289A.X11 | D22: Complete | E22: Finished (30) | F22: 4 | I22: =MID(B22,3,21) -> 17IA14.20
D23: Functional Test-1 | E23: On The Line (20) | F23: 5 | I23: =MID(B23,3,21)
D24: NOT-IN-PROCESS | E24: Unit Component (60) | F24: 8 | I24: =MID(B24,3,21)
D25: Shipped to Customer | E25: Shipped (40) | F25: 10 | I25: =MID(B25,3,21)
D26: Xfr to Debug Test | E26: In Repair Hold (29) | F26: 4 | I26: =MID(B26,3,21)
D27: Rework-1 | E27: In Repair (25) | F27: 3 | I27: =MID(B27,3,21)
D28: Rework-3 | E28: In Repair (25) | F28: 3 | I28: =MID(B28,3,21)
A29: 8 | B29: QT17IA14.21 | C29: QTNSN095289A.X11 | D29: Functional Test-1 | E29: On The Line (20) | F29: 3 | I29: =MID(B29,3,21) -> 17IA14.21
D30: NOT-IN-PROCESS | E30: Unit Component (60) | F30: 20 | I30: =MID(B30,3,21)
D31: Shipped to Customer | E31: Shipped (40) | F31: 10 | I31: =MID(B31,3,21)
D32: Xfr to Debug Test | E32: In Repair Hold (29) | F32: 4 | I32: =MID(B32,3,21)
A33: 9 | B33: QT17IA24.00 | C33: QTNSN095266A.X11 | D33: NOT-IN-PROCESS | E33: Unit Component (60) | F33: 15 | I33: =MID(B33,3,21) -> 17IA24.00
D34: Shipped to Customer | E34: Shipped (40) | F34: 14 | I34: =MID(B34,3,21)
A35: 10 | B35: QT17IA44.00 | C35: QTNSN476757A.X11 | D35: Shipped to Customer | E35: Shipped (40) | F35: 11 | I35: =MID(B35,3,21) -> 17IA44.00
D36: Packout | E36: On The Line (20) | F36: 4 | I36: =MID(B36,3,21)
A37: 11 | B37: QT17IA14.50 | C37: QTNSN095288A.X11 | D37: Complete | E37: Finished (30) | F37: 29 | I37: =MID(B37,3,21) -> 17IA14.50
D38: Functional Test-1 | E38: On The Line (20) | F38: 46 | I38: =MID(B38,3,21)
D39: NOT-IN-PROCESS | E39: Unit Component (60) | F39: 37 | I39: =MID(B39,3,21)
D40: Shipped to Customer | E40: Shipped (40) | F40: 9 | I40: =MID(B40,3,21)
...

Sheet Sheet2
A1: Unique id | B1: WO | E1: Part number | F1: Desc | G1: Qty | H1: Priority | I1: STI/ Comments
A2: QT17IA14.00 | B2: =VLOOKUP(A2,Summary!B:B,1,0) -> QT17IA14.00 | E2: QTNSN095288A.X03 | F2: #N/A | G2: 70 | H2: 1 | O2: Mh lot codes to MRB
A3: QT17IA14.10 | B3: =VLOOKUP(A3,Summary!B:B,1,0) -> QT17IA14.10 | E3: QTNSN095289A.X03 | F3: #N/A | G3: 80 | H3: 2 | O3: Solder paste Qtys
A4: QT17IA23.00 | B4: =VLOOKUP(A4,Summary!B:B,1,0) -> QT17IA23.00 | E4: QTNSN095266A.X02 | F4: #N/A | G4: 25 | H4: 3
A5: QT17IA43.00 | B5: =VLOOKUP(A5,Summary!B:B,1,0) -> QT17IA43.00 | E5: QTNSN476757A.X02 | F5: #N/A | G5: 20 | H5: 4
A6: QT17IA14.30 | B6: =VLOOKUP(A6,Summary!B:B,1,0) -> QT17IA14.30 | E6: QTNSN095288A.X11 | F6: QT PA ASSY, 095288A. REV X11, B25 PA ASSEMBLY FOR AXFIA/AXFIB | G6: 37 | H6: 5 | I6: eSTI PE53499. PE53575 add a note to remove shield and pre-drive, and for 840135A to use X1 version. PE53746 sent 03/13
A7: QT17IA14.31 | B7: =VLOOKUP(A7,Summary!B:B,1,0) -> QT17IA14.31 | E7: QTNSN095288A.X11 | F7: QT PA ASSY, 095288A. REV X11, B25 PA ASSEMBLY FOR AXFIA/AXFIB | G7: 37 | H7: 6 | I7: eSTI PE53499. PE53575 add a note to remove shield and pre-drive, and for 840135A to use X1 version. PE53684 sent 03/13
A8: QT17IA14.20 | B8: =VLOOKUP(A8,Summary!B:B,1,0) -> QT17IA14.20 | E8: QTNSN095289A.X11 | F8: QT PA ASSY, 095289A. REV X11, B66 PA ASSEMBLY FOR AXFIA/AXFIB | G8: 37 | H8: 7 | I8: STI PE53554 for 840135A to use X1 version. PE53499, .
A9: QT17IA14.21 | B9: =VLOOKUP(A9,Summary!B:B,1,0) -> QT17IA14.21 | E9: QTNSN095289A.X11 | F9: QT PA ASSY, 095289A. REV X11, B66 PA ASSEMBLY FOR AXFIA/AXFIB | G9: 37 | H9: 8 | I9: PE53571 for 17IA14.21,add a note to remove shield and pre-driver. Create new eSTI for 17IA14.20 adding the same note. NEW PE53611
A10: QT17IA24.00 | B10: =VLOOKUP(A10,Summary!B:B,1,0) -> QT17IA24.00 | E10: QTNSN095266A.X11 | F10: QT TRX ASSY, 095266A. REV X11, TRX ASSEMBLY FOR AXFIA | G10: 29 | H10: 9 | I10: PE53604, PE53707,PE53847
A11: QT17IA44.00 | B11: =VLOOKUP(A11,Summary!B:B,1,0) -> QT17IA44.00 | E11: QTNSN476757A.X11 | F11: RRH X11 | G11: 15 | H11: 10 | I11: PE53701
A12: QT17IA14.50 | B12: =VLOOKUP(A12,Summary!B:B,1,0) -> QT17IA14.50 | E12: QTNSN095288A.X11 | F12: QT PA ASSY, 095288A. REV X11, B25 PA ASSEMBLY FOR AXFIA/AXFIB | G12: 124 | H12: 11 | I12: PE53891
A13: QT17IA14.40 | B13: =VLOOKUP(A13,Summary!B:B,1,0) -> QT17IA14.40 | E13: QTNSN095289A.X11 | F13: QT PA ASSY, 095289A. REV X11, B66 PA ASSEMBLY FOR AXFIA/AXFIB | G13: 124 | H13: 12 | I13: PE54018
A14: QT17IA24.10 | B14: =VLOOKUP(A14,Summary!B:B,1,0) -> QT17IA24.10 | E14: QTNSN095266A.X12 | F14: QT TRX ASSY, 095266A. REV X12, TRX ASSEMBLY FOR AXFIA | G14: 41 | H14: 13 | I14: X12 Bom released - PE54073
A15: QT17IA44.10 | B15: =VLOOKUP(A15,Summary!B:B,1,0) -> QT17IA44.10 | E15: QTNSN476757A.X12 | F15: QT T/L UNIT ASSY, 476757A. REV X12, AXFIA AirScale RRH 4T8R n25/66 720W | G15: 30 | H15: 14 | I15: Esti releasesed- Release wo- PE54404- Wo released 29-May-26 | Min of 15 units next week
A16: QT17IA15.80 | B16: =VLOOKUP(A16,Summary!B:B,1,0) -> QT17IA15.80 | E16: QTNSN095289A.X12 | F16: QT PA ASSY, 095289A. REV X12, B66 PA ASSEMBLY FOR AXFIA/AXFIB | G16: 62 | H16: 18 | I16: New PWB- Order 2 sets of stencils- new profile board needed - New profile needed - Need STI- Checkplots being worked - PE54185
A17: QT17IA15.90 | B17: =VLOOKUP(A17,Summary!B:B,1,0) -> QT17IA15.90 | E17: QTNSN095288A.X12 | F17: QT PA ASSY, 095288A. REV X12, B25 PA ASSEMBLY FOR AXFIA/AXFIB | G17: 62 | H17: 17 | I17: New PWB- Order 2 sets of stencils- new profile board needed - New profile needed - Need STI- Stencil 04/23- PE54164 | N17: 46139
A18: QT19BA11.00 | B18: =VLOOKUP(A18,Summary!B:B,1,0) -> QT19BA11.00 | E18: QTNSN095290A.X02 | F18: QT PA ASSY, 095290A. REV X02, B71 PA ASSEMBLY FOR AXOLBA | G18: 14 | H18: 19 | I18: Stencils due on the 27- Apr- No Esti
A19: QT19BA11.10 | B19: =VLOOKUP(A19,Summary!B:B,1,0) -> QT19BA11.10 | E19: QTNSN095291A.X02 | F19: QT PA ASSY, 095291A. REV X02, B85 PA ASSEMBLY FOR AXOLBA | G19: 14 | H19: 20 | I19: Stencils due on the 27- Apr- No Esti- Tracking# 707296329356
A20: QT20LA21.00 | B20: =VLOOKUP(A20,Summary!B:B,1,0) -> QT20LA21.00 | E20: QTNSN095286A.X02 | F20: QT TRX ASSY, 095286A. REV X02, TRX ASSEMBLY FOR AXOLA | G20: 10 | H20: 21 | I20: PWB X6 | PE54313 to be cp'd rpleace P7000738 with P67 | AOI and Xray data & Dage available -Send data ASAP
A21: QT17IA25.30 | B21: =VLOOKUP(A21,Summary!B:B,1,0) -> QT17IA25.30 | C21: =MID(A21,3,11) -> 17IA25.30 | D21: Clean | E21: QTNSN095266A.X12 | F21: QT TRX ASSY, 095266A. REV X12, TRX ASSEMBLY FOR AXFIA | G21: 47 | H21: 22 | I21: Kick off 21-May-26- ESTI -PE54408 - Released 29-May-26 | One more ESTI to be released | Stencil ETA 03-Jun-26 | PE54513- Work order relased 06/03 | J21: Released -06/03 | Confirm SMT Start date
A22: QT17IA15.60 | B22: =VLOOKUP(A22,Summary!B:B,1,0) -> QT17IA15.60 | E22: QTNSN095289A.X12 | F22: QT PA ASSY, 095289A. REV X12, B66 PA ASSEMBLY FOR AXFIA/AXFIB | G22: 188 | H22: 23 | I22: Kick off 21-May-26- ESTI - PE54407- WO Released 29-May-26 | J22: Durafuse
A23: QT17IA15.70 | B23: =VLOOKUP(A23,Summary!B:B,1,0) -> QT17IA15.70 | E23: QTNSN095288A.X12 | F23: QT PA ASSY, 095288A. REV X12, B25 PA ASSEMBLY FOR AXFIA/AXFIB | G23: 188 | H23: 24 | I23: Kick off 21-May-26- ESTI - PE54405- WO Released 29-May-26 | J23: Durafuse
A24: QT17IA45.30 | B24: =VLOOKUP(A24,Summary!B:B,1,0) -> QT17IA45.30 | C24: =MID(A24,3,11) -> 17IA45.30 | D24: Clean | E24: QTNSN476757A.X12 | F24: QT T/L UNIT ASSY, 476757A. REV X12, AXFIA AirScale RRH 4T8R n25/66 720W | G24: 47 | H24: 25 | I24: PE54409 - Released 29-May-26_ need to release work order- Relased 15-Jun-26 | J24: Quote avialable
A25: QT17IA45.40 | B25: =VLOOKUP(A25,Summary!B:B,1,0) -> QT17IA45.40 | E25: QTNSN476757A.X12 | F25: QT T/L UNIT ASSY, 476757A. REV X12, AXFIA AirScale RRH 4T8R n25/66 720W | G25: 11 | H25: 26 | I25: Kick off- ESTI PE54381 - WO released
A26: QT17IA15.95 | B26: =VLOOKUP(A26,Summary!B:B,1,0) -> QT17IA15.95 | E26: QTNSN095289A.X12 | F26: QT PA ASSY, 095289A. REV X12, B66 PA ASSEMBLY FOR AXFIA/AXFIB | G26: 140 | H26: 27 | I26: Stencils , same PWB, STI for Solder paste PE54356- requested to run on the 2oth of May | New profile needed for Different solder paste
A27: QT17IA15.96 | B27: =VLOOKUP(A27,Summary!B:B,1,0) -> QT17IA15.96 | E27: QTNSN095288A.X12 | F27: QT PA ASSY, 095288A. REV X12, B25 PA ASSEMBLY FOR AXFIA/AXFIB | G27: 140 | H27: 28 | I27: PE54357- Solder paste STI- Received | New profile needed for Different solder paste
A28: QT20LA12.00 | B28: =VLOOKUP(A28,Summary!B:B,1,0) -> QT20LA12.00 | E28: QTNSN095290A.X02 | F28: QT PA ASSY, 095290A. REV X02, B71 PA ASSEMBLY FOR AXOLBA | G28: 64 | H28: 29 | I28: Esti releasesed- PE54413- WO released 27-May-26- need profile approved
A29: QT20LA12.10 | B29: =VLOOKUP(A29,Summary!B:B,1,0) -> QT20LA12.10 | E29: QTNSN095291A.X02 | F29: QT PA ASSY, 095291A. REV X02, B85 PA ASSEMBLY FOR AXOLBA | G29: 64 | H29: 30 | I29: Esti releasesed- WO released 27-May-26- Need profile approved
A30: QT20LA41.00 | B30: =VLOOKUP(A30,Summary!B:B,1,0) -> QT20LA41.00 | C30: =MID(A30,3,11) -> 20LA41.00 | D30: Clean | E30: QTNSN476797A.X11 | F30: QT T/L UNIT ASSY, 476797A.REV X11, AXOLA AirScale RRH 4T4R n71/85 320W | G30: 8 | H30: 31 | I30: CTB- ESTI PE54470 | WO release today 03-Jun-26- Followed up on ESTI
A31: QT19BA21.00 | B31: =VLOOKUP(A31,Summary!B:B,1,0) -> #N/A | C31: =MID(A31,3,11) -> 19BA21.00 | E31: QTNSN095804A.X11 | G31: 22 | H31: 32 | I31: Relased 06/12 | J31: Quote
A32: QT19BA12.20 | B32: =VLOOKUP(A32,Summary!B:B,1,0) -> #N/A | C32: =MID(A32,3,11) -> 19BA12.20 | D32: Clean | E32: QTNSN095290A.X02 | G32: 32 | H32: 33 | I32: ESTI - Sac305 PE54542- Work order QT20LA12.00 increased to 64 units
A33: QT19BA12.30 | B33: =VLOOKUP(A33,Summary!B:B,1,0) -> #N/A | C33: =MID(A33,3,11) -> 19BA12.30 | D33: Clean | E33: QTNSN095291A.X02 | G33: 32 | H33: 34 | I33: ESTI - Sac305 PE54541- Work order QT20LA12.10 increased to 64 units
A34: QT19BA41.00 | B34: =VLOOKUP(A34,Summary!B:B,1,0) -> #N/A | C34: =MID(A34,3,11) -> 19BA41.00 | E34: QTNSN476971A.X11 | G34: 8 | H34: 35 | I34: No ESTI_ Nokia checking -06/16
A35: QT17IA24.20 | B35: =VLOOKUP(A35,Summary!B:B,1,0) -> QT17IA24.20 | C35: =MID(A35,3,11) -> 17IA24.20 | E35: QTNSN095266A.X21 | G35: 29 | H35: 37 | I35: RelaseD 06/15 | Old profile can be used
A36: QT17IA14.70 | B36: =VLOOKUP(A36,Summary!B:B,1,0) -> #N/A | C36: =MID(A36,3,11) -> 17IA14.70 | E36: QTNSN095288A.X21 | G36: 74 | H36: 39 | I36: PE54718 | PE54609 | PE54651 - Jose Stencils | J36: Quote
A37: QT17IA14.60 | B37: =VLOOKUP(A37,Summary!B:B,1,0) -> #N/A | C37: =MID(A37,3,11) -> 17IA14.60 | E37: QTNSN095289A.X21 | G37: 74 | H37: 40 | I37: BOM not loaded | P722374 | PE54719, PE54667 ,PE54611 STI- Jose Stencils | J37: Quote
A38: QT18OA21.00 | B38: =VLOOKUP(A38,Summary!B:B,1,0) -> #N/A | C38: =MID(A38,3,11) -> 18OA21.00 | E38: QTNSN095725A.X12 | G38: 11 | H38: 41 | I38: Bom being updated- 06/16 | 2 Boards to be built without fixtures

Sheet Ko This week
A1: QT17IA24.20 | C1: AXFIA | D1: RF8 | E1: 0-Series | F1: 095266A.X21
A2: QT19BA21.00 | C2: AXOLBA | D2: RF8 | E2: P1 | F2: 095804A.X11
A3: QT17IA14.70 | B3: B25 | C3: AXFIA | D3: RF8 | E3: 0-Series | F3: 095288A.X21
A4: QT17IA14.60 | B4: B66 | C4: AXFIA | D4: RF8 | E4: 0-Series | F4: 095289A.P01 | G4: 095289A.X21
A5: QT18OA21.00 | B5: FF3 | C5: AXOA | D5: RF8 | E5: P1 | F5: 095725A.X12
A8: 51690564 | B8: Follow up for IPR
